File: mtex-5.1.1/data/PoleFigure/bruker.UXD
; E:\data\texture\Zhangxinming\lili\Deepdrawing1_R.raw(Diffrac Plus V1.01 file) converted by XCH V1.0
_FILEVERSION=2
_SITE='China'
_USER='Administrator'
_GONIOMETER_CODE=3349
; D8 Theta/Theta; Special
_SAMPLE_CHANGER_CODE=0
_ATTACHMENTS_CODE=0
_GONIOMETER_RADIUS=250.000000
_FIXED_DIVSLIT=0.600000
_FIXED_SAMPLESLIT=0.000000
_FIXED_DETSLIT=0.100000
_MONOCHROMATOR=0
; None
_THIN_FILM='N'
_BETA_FILTER='Y'
_FIXED_ANTISLIT=0.600000
_ANALYZER_CODE=0
; None
_DATEMEASURED='24-Sep-2008 10:09:34'
_WL_UNIT='A'
_WL1=1.540600
_WL2=1.544390
_WL3=1.392220
_WLRATIO=0.500000
_ANODE='Cu'
; (Data for Range number 1)
_DRIVE='PHI'
_STEPTIME=1.000000
_STEPSIZE=5.000000
_STEPMODE='C'
_START=0.000000
_THETA=17.200001
_2THETA=34.400002
_KHI=0.000000
_PHI=0.000000
_X=0.876000
_Y=9.952000
_Z=0.085500
_DIVERGENCE=0.200000
_ANTISCATTER=0.200000
_DETECTOR=1
; S.C.
_HV=584.000000
_GAIN=80.000000
_LLD=0.494000
_ULD=2.094000
_DETECTORSLIT='unkn'
_AUX1=0.000000
_AUX2=0.000000
_AUX3=0.000000
_TIMESTARTED=15.000000
_TEMP_RATE=0.000000
_TEMP_DELAY=0.000000
_KV=40
_MA=40
_RANGE_WL=1.540600
_3DPLANE=0
_2THETACPS
   0.0000    2436.0
   5.0000    2464.0
  10.0000    2412.0
  15.0000    2319.0
  20.0000    2270.0
  25.0000    2263.0
  30.0000    2276.0
  35.0000    2238.0
  40.0000    2180.0
  45.0000    2196.0
  50.0000    2314.0
  55.0000    2407.0
  60.0000    2656.0
  65.0000    2644.0
  70.0000    2537.0
  75.0000    2475.0
  80.0000    2321.0
  85.0000    2329.0
  90.0000    2228.0
  95.0000    2222.0
 100.0000    2162.0
 105.0000    2260.0
 110.0000    2156.0
 115.0000    2132.0
 120.0000    2179.0
 125.0000    2200.0
 130.0000    2184.0
 135.0000    2018.0
 140.0000    2122.0
 145.0000    2142.0
 150.0000    2004.0
 155.0000    1932.0
 160.0000    1950.0
 165.0000    1898.0
 170.0000    1855.0
 175.0000    1953.0
 180.0000    1970.0
 185.0000    2005.0
 190.0000    1980.0
 195.0000    2079.0
 200.0000    2237.0
 205.0000    2182.0
 210.0000    2263.0
 215.0000    2216.0
 220.0000    2464.0
 225.0000    2286.0
 230.0000    2331.0
 235.0000    2418.0
 240.0000    2654.0
 245.0000    2609.0
 250.0000    2595.0
 255.0000    2484.0
 260.0000    2510.0
 265.0000    2477.0
 270.0000    2560.0
 275.0000    2786.0
 280.0000    2906.0
 285.0000    2879.0
 290.0000    2692.0
 295.0000    2556.0
 300.0000    2465.0
 305.0000    2366.0
 310.0000    2445.0
 315.0000    2537.0
 320.0000    2561.0
 325.0000    2456.0
 330.0000    2295.0
 335.0000    2261.0
 340.0000    2461.0
 345.0000    2538.0
 350.0000    2588.0
 355.0000    2461.0
; (Data for Range number 2)
_DRIVE='PHI'
_STEPTIME=1.000000
_STEPSIZE=5.000000
_STEPMODE='C'
_START=0.000000
_THETA=17.200001
_2THETA=34.400002
_KHI=5.000000
_PHI=0.000000
_X=0.876000
_Y=9.952000
_Z=0.085500
_DIVERGENCE=0.200000
_ANTISCATTER=0.200000
_DETECTOR=1
; S.C.
_HV=584.000000
_GAIN=80.000000
_LLD=0.494000
_ULD=2.094000
_DETECTORSLIT='unkn'
_AUX1=0.000000
_AUX2=0.000000
_AUX3=0.000000
_TIMESTARTED=93.000000
_TEMP_RATE=0.000000
_TEMP_DELAY=0.000000
_KV=40
_MA=40
_RANGE_WL=1.540600
_3DPLANE=0
_2THETACPS
   0.0000    2829.0
   5.0000    2649.0
  10.0000    2378.0
  15.0000    2139.0
  20.0000    2176.0
  25.0000    2181.0
  30.0000    2337.0
  35.0000    2384.0
  40.0000    2226.0
  45.0000    2202.0
  50.0000    2346.0
  55.0000    2430.0
  60.0000    2440.0
  65.0000    2414.0
  70.0000    2330.0
  75.0000    2215.0
  80.0000    2220.0
  85.0000    2348.0
  90.0000    2367.0
  95.0000    2309.0
 100.0000    2388.0
 105.0000    2344.0
 110.0000    2349.0
 115.0000    2386.0
 120.0000    2523.0
 125.0000    2436.0
 130.0000    2503.0
 135.0000    2335.0
 140.0000    2359.0
 145.0000    2247.0
 150.0000    2295.0
 155.0000    2247.0
 160.0000    2239.0
 165.0000    2187.0
 170.0000    2165.0
 175.0000    2242.0
 180.0000    2389.0
 185.0000    2353.0
 190.0000    2342.0
 195.0000    2308.0
 200.0000    2409.0
 205.0000    2658.0
 210.0000    2663.0
 215.0000    2604.0
 220.0000    2609.0
 225.0000    2587.0
 230.0000    2657.0
 235.0000    2590.0
 240.0000    2628.0
 245.0000    2366.0
 250.0000    2363.0
 255.0000    2357.0
 260.0000    2563.0
 265.0000    2500.0
 270.0000    2636.0
 275.0000    2874.0
 280.0000    3062.0
 285.0000    2851.0
 290.0000    2557.0
 295.0000    2469.0
 300.0000    2471.0
 305.0000    2424.0
 310.0000    2242.0
 315.0000    2117.0
 320.0000    2142.0
 325.0000    1991.0
 330.0000    1973.0
 335.0000    1988.0
 340.0000    2113.0
 345.0000    2171.0
 350.0000    2405.0
 355.0000    2529.0
; (Data for Range number 3)
_DRIVE='PHI'
_STEPTIME=1.000000
_STEPSIZE=5.000000
_STEPMODE='C'
_START=0.000000
_THETA=17.200001
_2THETA=34.400002
_KHI=10.000000
_PHI=0.000000
_X=0.876000
_Y=9.952000
_Z=0.085500
_DIVERGENCE=0.200000
_ANTISCATTER=0.200000
_DETECTOR=1
; S.C.
_HV=584.000000
_GAIN=80.000000
_LLD=0.494000
_ULD=2.094000
_DETECTORSLIT='unkn'
_AUX1=0.000000
_AUX2=0.000000
_AUX3=0.000000
_TIMESTARTED=171.000000
_TEMP_RATE=0.000000
_TEMP_DELAY=0.000000
_KV=40
_MA=40
_RANGE_WL=1.540600
_3DPLANE=0
_2THETACPS
   0.0000    2546.0
   5.0000    2465.0
  10.0000    2064.0
  15.0000    1998.0
  20.0000    1930.0
  25.0000    1890.0
  30.0000    1905.0
  35.0000    2154.0
  40.0000    2045.0
  45.0000    2120.0
  50.0000    2103.0
  55.0000    2097.0
  60.0000    2126.0
  65.0000    2184.0
  70.0000    2235.0
  75.0000    2382.0
  80.0000    2546.0
  85.0000    2527.0
  90.0000    2551.0
  95.0000    2599.0
 100.0000    2644.0
 105.0000    2989.0
 110.0000    2954.0
 115.0000    3097.0
 120.0000    2998.0
 125.0000    2985.0
 130.0000    2921.0
 135.0000    2712.0
 140.0000    2640.0
 145.0000    2565.0
 150.0000    2416.0
 155.0000    2521.0
 160.0000    2282.0
 165.0000    2185.0
 170.0000    2281.0
 175.0000    2449.0
 180.0000    2302.0
 185.0000    2198.0
 190.0000    2211.0
 195.0000    2103.0
 200.0000    2141.0
 205.0000    2293.0
 210.0000    2415.0
 215.0000    2481.0
 220.0000    2835.0
 225.0000    2656.0
 230.0000    2653.0
 235.0000    2572.0
 240.0000    2403.0
 245.0000    2328.0
 250.0000    2390.0
 255.0000    2460.0
 260.0000    2451.0
 265.0000    2651.0
 270.0000    2766.0
 275.0000    2813.0
 280.0000    2823.0
 285.0000    2468.0
 290.0000    2494.0
 295.0000    2654.0
 300.0000    2783.0
 305.0000    2813.0
 310.0000    2778.0
 315.0000    2718.0
 320.0000    2569.0
 325.0000    2559.0
 330.0000    2679.0
 335.0000    2756.0
 340.0000    2601.0
 345.0000    2578.0
 350.0000    2519.0
 355.0000    2573.0
; (Data for Range number 4)
_DRIVE='PHI'
_STEPTIME=1.000000
_STEPSIZE=5.000000
_STEPMODE='C'
_START=0.000000
_THETA=17.200001
_2THETA=34.400002
_KHI=15.000000
_PHI=0.000000
_X=0.876000
_Y=9.952000
_Z=0.085500
_DIVERGENCE=0.200000
_ANTISCATTER=0.200000
_DETECTOR=1
; S.C.
_HV=584.000000
_GAIN=80.000000
_LLD=0.494000
_ULD=2.094000
_DETECTORSLIT='unkn'
_AUX1=0.000000
_AUX2=0.000000
_AUX3=0.000000
_TIMESTARTED=250.000000
_TEMP_RATE=0.000000
_TEMP_DELAY=0.000000
_KV=40
_MA=40
_RANGE_WL=1.540600
_3DPLANE=0
_2THETACPS
   0.0000    2251.0
   5.0000    2222.0
  10.0000    2237.0
  15.0000    1857.0
  20.0000    1710.0
  25.0000    1803.0
  30.0000    2001.0
  35.0000    2204.0
  40.0000    2261.0
  45.0000    2297.0
  50.0000    2263.0
  55.0000    2382.0
  60.0000    2430.0
  65.0000    2402.0
  70.0000    2476.0
  75.0000    2576.0
  80.0000    2609.0
  85.0000    2901.0
  90.0000    2861.0
  95.0000    2798.0
 100.0000    2824.0
 105.0000    2941.0
 110.0000    2741.0
 115.0000    2562.0
 120.0000    2503.0
 125.0000    2508.0
 130.0000    2503.0
 135.0000    2259.0
 140.0000    2227.0
 145.0000    2279.0
 150.0000    2192.0
 155.0000    2290.0
 160.0000    1888.0
 165.0000    1726.0
 170.0000    1720.0
 175.0000    1897.0
 180.0000    1736.0
 185.0000    1904.0
 190.0000    1853.0
 195.0000    1874.0
 200.0000    2031.0
 205.0000    2071.0
 210.0000    2290.0
 215.0000    2554.0
 220.0000    2632.0
 225.0000    2640.0
 230.0000    2419.0
 235.0000    2322.0
 240.0000    2135.0
 245.0000    2111.0
 250.0000    2137.0
 255.0000    2256.0
 260.0000    2460.0
 265.0000    2627.0
 270.0000    2609.0
 275.0000    2632.0
 280.0000    2579.0
 285.0000    2746.0
 290.0000    2720.0
 295.0000    2864.0
 300.0000    2879.0
 305.0000    2716.0
 310.0000    2677.0
 315.0000    2510.0
 320.0000    2316.0
 325.0000    2136.0
 330.0000    2099.0
 335.0000    2106.0
 340.0000    1986.0
 345.0000    2077.0
 350.0000    2122.0
 355.0000    2262.0
; (Data for Range number 5)
_DRIVE='PHI'
_STEPTIME=1.000000
_STEPSIZE=5.000000
_STEPMODE='C'
_START=0.000000
_THETA=17.200001
_2THETA=34.400002
_KHI=20.000000
_PHI=0.000000
_X=0.876000
_Y=9.952000
_Z=0.085500
_DIVERGENCE=0.200000
_ANTISCATTER=0.200000
_DETECTOR=1
; S.C.
_HV=584.000000
_GAIN=80.000000
_LLD=0.494000
_ULD=2.094000
_DETECTORSLIT='unkn'
_AUX1=0.000000
_AUX2=0.000000
_AUX3=0.000000
_TIMESTARTED=328.000000
_TEMP_RATE=0.000000
_TEMP_DELAY=0.000000
_KV=40
_MA=40
_RANGE_WL=1.540600
_3DPLANE=0
_2THETACPS
   0.0000    1624.0
   5.0000    1748.0
  10.0000    1867.0
  15.0000    2047.0
  20.0000    2053.0
  25.0000    1828.0
  30.0000    1801.0
  35.0000    1775.0
  40.0000    1862.0
  45.0000    1724.0
  50.0000    1912.0
  55.0000    2291.0
  60.0000    2454.0
  65.0000    2266.0
  70.0000    2250.0
  75.0000    2260.0
  80.0000    2365.0
  85.0000    2540.0
  90.0000    2719.0
  95.0000    2830.0
 100.0000    2673.0
 105.0000    2653.0
 110.0000    2335.0
 115.0000    2949.0
 120.0000    2533.0
 125.0000    2499.0
 130.0000    2466.0
 135.0000    2112.0
 140.0000    1820.0
 145.0000    1830.0
 150.0000    1667.0
 155.0000    1657.0
 160.0000    1634.0
 165.0000    1507.0
 170.0000    1545.0
 175.0000    1475.0
 180.0000    1442.0
 185.0000    1288.0
 190.0000    1423.0
 195.0000    1415.0
 200.0000    1493.0
 205.0000    1547.0
 210.0000    1741.0
 215.0000    1672.0
 220.0000    1678.0
 225.0000    1872.0
 230.0000    1987.0
 235.0000    2084.0
 240.0000    2137.0
 245.0000    1940.0
 250.0000    2054.0
 255.0000    2104.0
 260.0000    2231.0
 265.0000    2427.0
 270.0000    2494.0
 275.0000    2537.0
 280.0000    2404.0
 285.0000    2393.0
 290.0000    2814.0
 295.0000    2709.0
 300.0000    2557.0
 305.0000    2381.0
 310.0000    2184.0
 315.0000    2112.0
 320.0000    2056.0
 325.0000    1824.0
 330.0000    1860.0
 335.0000    1755.0
 340.0000    1610.0
 345.0000    1686.0
 350.0000    1701.0
 355.0000    1534.0
; (Data for Range number 6)
_DRIVE='PHI'
_STEPTIME=1.000000
_STEPSIZE=5.000000
_STEPMODE='C'
_START=0.000000
_THETA=17.200001
_2THETA=34.400002
_KHI=25.000000
_PHI=0.000000
_X=0.876000
_Y=9.952000
_Z=0.085500
_DIVERGENCE=0.200000
_ANTISCATTER=0.200000
_DETECTOR=1
; S.C.
_HV=584.000000
_GAIN=80.000000
_LLD=0.494000
_ULD=2.094000
_DETECTORSLIT='unkn'
_AUX1=0.000000
_AUX2=0.000000
_AUX3=0.000000
_TIMESTARTED=407.000000
_TEMP_RATE=0.000000
_TEMP_DELAY=0.000000
_KV=40
_MA=40
_RANGE_WL=1.540600
_3DPLANE=0
_2THETACPS
   0.0000    1236.0
   5.0000    1219.0
  10.0000    1265.0
  15.0000    1274.0
  20.0000    1376.0
  25.0000    1362.0
  30.0000    1395.0
  35.0000    1350.0
  40.0000    1348.0
  45.0000    1309.0
  50.0000    1393.0
  55.0000    1651.0
  60.0000    1637.0
  65.0000    1682.0
  70.0000    1649.0
  75.0000    1712.0
  80.0000    1981.0
  85.0000    1919.0
  90.0000    2113.0
  95.0000    2373.0
 100.0000    2371.0
 105.0000    2095.0
 110.0000    1960.0
 115.0000    1937.0
 120.0000    1907.0
 125.0000    2098.0
 130.0000    2139.0
 135.0000    1845.0
 140.0000    1477.0
 145.0000    1316.0
 150.0000    1261.0
 155.0000    1261.0
 160.0000    1216.0
 165.0000    1159.0
 170.0000    1155.0
 175.0000    980.00
 180.0000    917.00
 185.0000    924.00
 190.0000    990.00
 195.0000    977.00
 200.0000    1099.0
 205.0000    1266.0
 210.0000    1301.0
 215.0000    1374.0
 220.0000    1348.0
 225.0000    1314.0
 230.0000    1424.0
 235.0000    1525.0
 240.0000    1600.0
 245.0000    1818.0
 250.0000    1881.0
 255.0000    1922.0
 260.0000    2022.0
 265.0000    1945.0
 270.0000    2103.0
 275.0000    2127.0
 280.0000    2228.0
 285.0000    2124.0
 290.0000    2375.0
 295.0000    2411.0
 300.0000    2325.0
 305.0000    2042.0
 310.0000    2004.0
 315.0000    1904.0
 320.0000    1702.0
 325.0000    1543.0
 330.0000    1377.0
 335.0000    1231.0
 340.0000    1185.0
 345.0000    1098.0
 350.0000    1038.0
 355.0000    1180.0
; (Data for Range number 7)
_DRIVE='PHI'
_STEPTIME=1.000000
_STEPSIZE=5.000000
_STEPMODE='C'
_START=0.000000
_THETA=17.200001
_2THETA=34.400002
_KHI=30.000000
_PHI=0.000000
_X=0.876000
_Y=9.952000
_Z=0.085500
_DIVERGENCE=0.200000
_ANTISCATTER=0.200000
_DETECTOR=1
; S.C.
_HV=584.000000
_GAIN=80.000000
_LLD=0.494000
_ULD=2.094000
_DETECTORSLIT='unkn'
_AUX1=0.000000
_AUX2=0.000000
_AUX3=0.000000
_TIMESTARTED=485.000000
_TEMP_RATE=0.000000
_TEMP_DELAY=0.000000
_KV=40
_MA=40
_RANGE_WL=1.540600
_3DPLANE=0
_2THETACPS
   0.0000    758.00
   5.0000    804.00
  10.0000    746.00
  15.0000    794.00
  20.0000    884.00
  25.0000    933.00
  30.0000    1089.0
  35.0000    1008.0
  40.0000    1117.0
  45.0000    1073.0
  50.0000    976.00
  55.0000    1173.0
  60.0000    1388.0
  65.0000    1285.0
  70.0000    1364.0
  75.0000    1478.0
  80.0000    1393.0
  85.0000    1444.0
  90.0000    1793.0
  95.0000    1984.0
 100.0000    1948.0
 105.0000    1826.0
 110.0000    1429.0
 115.0000    1371.0
 120.0000    1392.0
 125.0000    1529.0
 130.0000    1476.0
 135.0000    1249.0
 140.0000    1168.0
 145.0000    1178.0
 150.0000    1059.0
 155.0000    847.00
 160.0000    841.00
 165.0000    824.00
 170.0000    758.00
 175.0000    725.00
 180.0000    730.00
 185.0000    696.00
 190.0000    778.00
 195.0000    833.00
 200.0000    910.00
 205.0000    906.00
 210.0000    905.00
 215.0000    909.00
 220.0000    1096.0
 225.0000    1140.0
 230.0000    1189.0
 235.0000    1167.0
 240.0000    1264.0
 245.0000    1380.0
 250.0000    1716.0
 255.0000    1832.0
 260.0000    1710.0
 265.0000    1651.0
 270.0000    1828.0
 275.0000    1949.0
 280.0000    2131.0
 285.0000    1933.0
 290.0000    1737.0
 295.0000    1992.0
 300.0000    2145.0
 305.0000    1681.0
 310.0000    1327.0
 315.0000    1107.0
 320.0000    1021.0
 325.0000    924.00
 330.0000    854.00
 335.0000    736.00
 340.0000    877.00
 345.0000    824.00
 350.0000    899.00
 355.0000    883.00
; (Data for Range number 8)
_DRIVE='PHI'
_STEPTIME=1.000000
_STEPSIZE=5.000000
_STEPMODE='C'
_START=0.000000
_THETA=17.200001
_2THETA=34.400002
_KHI=35.000000
_PHI=0.000000
_X=0.876000
_Y=9.952000
_Z=0.085500
_DIVERGENCE=0.200000
_ANTISCATTER=0.200000
_DETECTOR=1
; S.C.
_HV=584.000000
_GAIN=80.000000
_LLD=0.494000
_ULD=2.094000
_DETECTORSLIT='unkn'
_AUX1=0.000000
_AUX2=0.000000
_AUX3=0.000000
_TIMESTARTED=563.000000
_TEMP_RATE=0.000000
_TEMP_DELAY=0.000000
_KV=40
_MA=40
_RANGE_WL=1.540600
_3DPLANE=0
_2THETACPS
   0.0000    592.00
   5.0000    642.00
  10.0000    629.00
  15.0000    577.00
  20.0000    736.00
  25.0000    692.00
  30.0000    733.00
  35.0000    794.00
  40.0000    717.00
  45.0000    846.00
  50.0000    878.00
  55.0000    1018.0
  60.0000    1014.0
  65.0000    937.00
  70.0000    991.00
  75.0000    1022.0
  80.0000    1097.0
  85.0000    1368.0
  90.0000    1446.0
  95.0000    1392.0
 100.0000    1457.0
 105.0000    1312.0
 110.0000    1120.0
 115.0000    1127.0
 120.0000    1022.0
 125.0000    964.00
 130.0000    923.00
 135.0000    763.00
 140.0000    691.00
 145.0000    697.00
 150.0000    598.00
 155.0000    587.00
 160.0000    594.00
 165.0000    573.00
 170.0000    576.00
 175.0000    507.00
 180.0000    552.00
 185.0000    601.00
 190.0000    601.00
 195.0000    691.00
 200.0000    721.00
 205.0000    709.00
 210.0000    754.00
 215.0000    789.00
 220.0000    834.00
 225.0000    940.00
 230.0000    944.00
 235.0000    1015.0
 240.0000    1098.0
 245.0000    1105.0
 250.0000    1262.0
 255.0000    1275.0
 260.0000    1400.0
 265.0000    1466.0
 270.0000    1999.0
 275.0000    1866.0
 280.0000    1798.0
 285.0000    1780.0
 290.0000    1413.0
 295.0000    1284.0
 300.0000    1112.0
 305.0000    992.00
 310.0000    942.00
 315.0000    838.00
 320.0000    754.00
 325.0000    676.00
 330.0000    648.00
 335.0000    606.00
 340.0000    575.00
 345.0000    638.00
 350.0000    571.00
 355.0000    604.00
; (Data for Range number 9)
_DRIVE='PHI'
_STEPTIME=1.000000
_STEPSIZE=5.000000
_STEPMODE='C'
_START=0.000000
_THETA=17.200001
_2THETA=34.400002
_KHI=40.000000
_PHI=0.000000
_X=0.876000
_Y=9.952000
_Z=0.085500
_DIVERGENCE=0.200000
_ANTISCATTER=0.200000
_DETECTOR=1
; S.C.
_HV=584.000000
_GAIN=80.000000
_LLD=0.494000
_ULD=2.094000
_DETECTORSLIT='unkn'
_AUX1=0.000000
_AUX2=0.000000
_AUX3=0.000000
_TIMESTARTED=642.000000
_TEMP_RATE=0.000000
_TEMP_DELAY=0.000000
_KV=40
_MA=40
_RANGE_WL=1.540600
_3DPLANE=0
_2THETACPS
   0.0000    537.00
   5.0000    576.00
  10.0000    558.00
  15.0000    555.00
  20.0000    541.00
  25.0000    612.00
  30.0000    596.00
  35.0000    653.00
  40.0000    690.00
  45.0000    720.00
  50.0000    796.00
  55.0000    840.00
  60.0000    845.00
  65.0000    863.00
  70.0000    789.00
  75.0000    749.00
  80.0000    817.00
  85.0000    1070.0
  90.0000    1054.0
  95.0000    1041.0
 100.0000    1013.0
 105.0000    1054.0
 110.0000    923.00
 115.0000    742.00
 120.0000    697.00
 125.0000    678.00
 130.0000    625.00
 135.0000    535.00
 140.0000    523.00
 145.0000    520.00
 150.0000    545.00
 155.0000    489.00
 160.0000    437.00
 165.0000    486.00
 170.0000    524.00
 175.0000    504.00
 180.0000    482.00
 185.0000    539.00
 190.0000    556.00
 195.0000    619.00
 200.0000    629.00
 205.0000    564.00
 210.0000    659.00
 215.0000    694.00
 220.0000    754.00
 225.0000    787.00
 230.0000    828.00
 235.0000    744.00
 240.0000    899.00
 245.0000    943.00
 250.0000    968.00
 255.0000    1046.0
 260.0000    1146.0
 265.0000    1163.0
 270.0000    1205.0
 275.0000    1333.0
 280.0000    1366.0
 285.0000    1302.0
 290.0000    1020.0
 295.0000    848.00
 300.0000    826.00
 305.0000    776.00
 310.0000    739.00
 315.0000    601.00
 320.0000    609.00
 325.0000    565.00
 330.0000    544.00
 335.0000    589.00
 340.0000    564.00
 345.0000    557.00
 350.0000    548.00
 355.0000    543.00
; (Data for Range number 10)
_DRIVE='PHI'
_STEPTIME=1.000000
_STEPSIZE=5.000000
_STEPMODE='C'
_START=0.000000
_THETA=17.200001
_2THETA=34.400002
_KHI=45.000000
_PHI=0.000000
_X=0.876000
_Y=9.952000
_Z=0.085500
_DIVERGENCE=0.200000
_ANTISCATTER=0.200000
_DETECTOR=1
; S.C.
_HV=584.000000
_GAIN=80.000000
_LLD=0.494000
_ULD=2.094000
_DETECTORSLIT='unkn'
_AUX1=0.000000
_AUX2=0.000000
_AUX3=0.000000
_TIMESTARTED=720.000000
_TEMP_RATE=0.000000
_TEMP_DELAY=0.000000
_KV=40
_MA=40
_RANGE_WL=1.540600
_3DPLANE=0
_2THETACPS
   0.0000    526.00
   5.0000    539.00
  10.0000    510.00
  15.0000    549.00
  20.0000    496.00
  25.0000    546.00
  30.0000    519.00
  35.0000    575.00
  40.0000    600.00
  45.0000    663.00
  50.0000    726.00
  55.0000    713.00
  60.0000    753.00
  65.0000    720.00
  70.0000    748.00
  75.0000    699.00
  80.0000    653.00
  85.0000    852.00
  90.0000    740.00
  95.0000    786.00
 100.0000    710.00
 105.0000    634.00
 110.0000    685.00
 115.0000    552.00
 120.0000    561.00
 125.0000    579.00
 130.0000    539.00
 135.0000    491.00
 140.0000    491.00
 145.0000    485.00
 150.0000    465.00
 155.0000    459.00
 160.0000    518.00
 165.0000    494.00
 170.0000    497.00
 175.0000    469.00
 180.0000    476.00
 185.0000    523.00
 190.0000    521.00
 195.0000    495.00
 200.0000    537.00
 205.0000    549.00
 210.0000    666.00
 215.0000    580.00
 220.0000    569.00
 225.0000    614.00
 230.0000    630.00
 235.0000    663.00
 240.0000    649.00
 245.0000    916.00
 250.0000    875.00
 255.0000    911.00
 260.0000    885.00
 265.0000    850.00
 270.0000    905.00
 275.0000    902.00
 280.0000    901.00
 285.0000    918.00
 290.0000    835.00
 295.0000    715.00
 300.0000    742.00
 305.0000    653.00
 310.0000    605.00
 315.0000    575.00
 320.0000    498.00
 325.0000    517.00
 330.0000    508.00
 335.0000    584.00
 340.0000    559.00
 345.0000    536.00
 350.0000    503.00
 355.0000    525.00
; (Data for Range number 11)
_DRIVE='PHI'
_STEPTIME=1.000000
_STEPSIZE=5.000000
_STEPMODE='C'
_START=0.000000
_THETA=17.200001
_2THETA=34.400002
_KHI=50.000000
_PHI=0.000000
_X=0.876000
_Y=9.952000
_Z=0.085500
_DIVERGENCE=0.200000
_ANTISCATTER=0.200000
_DETECTOR=1
; S.C.
_HV=584.000000
_GAIN=80.000000
_LLD=0.494000
_ULD=2.094000
_DETECTORSLIT='unkn'
_AUX1=0.000000
_AUX2=0.000000
_AUX3=0.000000
_TIMESTARTED=798.000000
_TEMP_RATE=0.000000
_TEMP_DELAY=0.000000
_KV=40
_MA=40
_RANGE_WL=1.540600
_3DPLANE=0
_2THETACPS
   0.0000    505.00
   5.0000    520.00
  10.0000    486.00
  15.0000    421.00
  20.0000    464.00
  25.0000    491.00
  30.0000    520.00
  35.0000    496.00
  40.0000    527.00
  45.0000    572.00
  50.0000    628.00
  55.0000    704.00
  60.0000    697.00
  65.0000    682.00
  70.0000    702.00
  75.0000    567.00
  80.0000    582.00
  85.0000    639.00
  90.0000    579.00
  95.0000    601.00
 100.0000    550.00
 105.0000    505.00
 110.0000    555.00
 115.0000    498.00
 120.0000    511.00
 125.0000    514.00
 130.0000    483.00
 135.0000    452.00
 140.0000    461.00
 145.0000    459.00
 150.0000    464.00
 155.0000    480.00
 160.0000    435.00
 165.0000    461.00
 170.0000    468.00
 175.0000    472.00
 180.0000    480.00
 185.0000    462.00
 190.0000    510.00
 195.0000    505.00
 200.0000    498.00
 205.0000    531.00
 210.0000    494.00
 215.0000    497.00
 220.0000    617.00
 225.0000    549.00
 230.0000    511.00
 235.0000    591.00
 240.0000    634.00
 245.0000    643.00
 250.0000    704.00
 255.0000    671.00
 260.0000    701.00
 265.0000    734.00
 270.0000    703.00
 275.0000    740.00
 280.0000    684.00
 285.0000    647.00
 290.0000    671.00
 295.0000    625.00
 300.0000    615.00
 305.0000    541.00
 310.0000    528.00
 315.0000    509.00
 320.0000    457.00
 325.0000    497.00
 330.0000    534.00
 335.0000    500.00
 340.0000    529.00
 345.0000    498.00
 350.0000    472.00
 355.0000    476.00
; (Data for Range number 12)
_DRIVE='PHI'
_STEPTIME=1.000000
_STEPSIZE=5.000000
_STEPMODE='C'
_START=0.000000
_THETA=17.200001
_2THETA=34.400002
_KHI=55.000000
_PHI=0.000000
_X=0.876000
_Y=9.952000
_Z=0.085500
_DIVERGENCE=0.200000
_ANTISCATTER=0.200000
_DETECTOR=1
; S.C.
_HV=584.000000
_GAIN=80.000000
_LLD=0.494000
_ULD=2.094000
_DETECTORSLIT='unkn'
_AUX1=0.000000
_AUX2=0.000000
_AUX3=0.000000
_TIMESTARTED=876.000000
_TEMP_RATE=0.000000
_TEMP_DELAY=0.000000
_KV=40
_MA=40
_RANGE_WL=1.540600
_3DPLANE=0
_2THETACPS
   0.0000    457.00
   5.0000    458.00
  10.0000    488.00
  15.0000    465.00
  20.0000    445.00
  25.0000    444.00
  30.0000    516.00
  35.0000    475.00
  40.0000    478.00
  45.0000    531.00
  50.0000    509.00
  55.0000    531.00
  60.0000    609.00
  65.0000    517.00
  70.0000    462.00
  75.0000    502.00
  80.0000    547.00
  85.0000    526.00
  90.0000    540.00
  95.0000    540.00
 100.0000    499.00
 105.0000    493.00
 110.0000    467.00
 115.0000    495.00
 120.0000    522.00
 125.0000    472.00
 130.0000    459.00
 135.0000    458.00
 140.0000    465.00
 145.0000    433.00
 150.0000    427.00
 155.0000    467.00
 160.0000    459.00
 165.0000    437.00
 170.0000    445.00
 175.0000    465.00
 180.0000    479.00
 185.0000    461.00
 190.0000    457.00
 195.0000    496.00
 200.0000    467.00
 205.0000    433.00
 210.0000    415.00
 215.0000    431.00
 220.0000    517.00
 225.0000    473.00
 230.0000    551.00
 235.0000    592.00
 240.0000    500.00
 245.0000    538.00
 250.0000    526.00
 255.0000    529.00
 260.0000    510.00
 265.0000    579.00
 270.0000    593.00
 275.0000    563.00
 280.0000    549.00
 285.0000    545.00
 290.0000    532.00
 295.0000    516.00
 300.0000    496.00
 305.0000    457.00
 310.0000    468.00
 315.0000    471.00
 320.0000    407.00
 325.0000    454.00
 330.0000    448.00
 335.0000    471.00
 340.0000    447.00
 345.0000    504.00
 350.0000    443.00
 355.0000    459.00
; (Data for Range number 13)
_DRIVE='PHI'
_STEPTIME=1.000000
_STEPSIZE=5.000000
_STEPMODE='C'
_START=0.000000
_THETA=17.200001
_2THETA=34.400002
_KHI=60.000000
_PHI=0.000000
_X=0.876000
_Y=9.952000
_Z=0.085500
_DIVERGENCE=0.200000
_ANTISCATTER=0.200000
_DETECTOR=1
; S.C.
_HV=584.000000
_GAIN=80.000000
_LLD=0.494000
_ULD=2.094000
_DETECTORSLIT='unkn'
_AUX1=0.000000
_AUX2=0.000000
_AUX3=0.000000
_TIMESTARTED=954.000000
_TEMP_RATE=0.000000
_TEMP_DELAY=0.000000
_KV=40
_MA=40
_RANGE_WL=1.540600
_3DPLANE=0
_2THETACPS
   0.0000    471.00
   5.0000    460.00
  10.0000    467.00
  15.0000    429.00
  20.0000    419.00
  25.0000    375.00
  30.0000    408.00
  35.0000    396.00
  40.0000    433.00
  45.0000    486.00
  50.0000    476.00
  55.0000    522.00
  60.0000    510.00
  65.0000    483.00
  70.0000    469.00
  75.0000    439.00
  80.0000    406.00
  85.0000    412.00
  90.0000    444.00
  95.0000    490.00
 100.0000    476.00
 105.0000    466.00
 110.0000    462.00
 115.0000    465.00
 120.0000    490.00
 125.0000    468.00
 130.0000    425.00
 135.0000    438.00
 140.0000    443.00
 145.0000    432.00
 150.0000    396.00
 155.0000    418.00
 160.0000    460.00
 165.0000    420.00
 170.0000    443.00
 175.0000    465.00
 180.0000    485.00
 185.0000    493.00
 190.0000    441.00
 195.0000    478.00
 200.0000    432.00
 205.0000    429.00
 210.0000    409.00
 215.0000    446.00
 220.0000    483.00
 225.0000    481.00
 230.0000    492.00
 235.0000    515.00
 240.0000    479.00
 245.0000    485.00
 250.0000    464.00
 255.0000    433.00
 260.0000    393.00
 265.0000    415.00
 270.0000    488.00
 275.0000    432.00
 280.0000    495.00
 285.0000    478.00
 290.0000    483.00
 295.0000    449.00
 300.0000    448.00
 305.0000    514.00
 310.0000    465.00
 315.0000    414.00
 320.0000    409.00
 325.0000    449.00
 330.0000    425.00
 335.0000    428.00
 340.0000    396.00
 345.0000    470.00
 350.0000    486.00
 355.0000    432.00
; (Data for Range number 14)
_DRIVE='PHI'
_STEPTIME=1.000000
_STEPSIZE=5.000000
_STEPMODE='C'
_START=0.000000
_THETA=17.200001
_2THETA=34.400002
_KHI=65.000000
_PHI=0.000000
_X=0.876000
_Y=9.952000
_Z=0.085500
_DIVERGENCE=0.200000
_ANTISCATTER=0.200000
_DETECTOR=1
; S.C.
_HV=584.000000
_GAIN=80.000000
_LLD=0.494000
_ULD=2.094000
_DETECTORSLIT='unkn'
_AUX1=0.000000
_AUX2=0.000000
_AUX3=0.000000
_TIMESTARTED=1033.000000
_TEMP_RATE=0.000000
_TEMP_DELAY=0.000000
_KV=40
_MA=40
_RANGE_WL=1.540600
_3DPLANE=0
_2THETACPS
   0.0000    421.00
   5.0000    394.00
  10.0000    379.00
  15.0000    379.00
  20.0000    382.00
  25.0000    385.00
  30.0000    366.00
  35.0000    429.00
  40.0000    402.00
  45.0000    410.00
  50.0000    410.00
  55.0000    440.00
  60.0000    424.00
  65.0000    451.00
  70.0000    395.00
  75.0000    394.00
  80.0000    398.00
  85.0000    385.00
  90.0000    426.00
  95.0000    460.00
 100.0000    416.00
 105.0000    399.00
 110.0000    470.00
 115.0000    471.00
 120.0000    498.00
 125.0000    454.00
 130.0000    424.00
 135.0000    439.00
 140.0000    434.00
 145.0000    431.00
 150.0000    432.00
 155.0000    419.00
 160.0000    401.00
 165.0000    394.00
 170.0000    412.00
 175.0000    414.00
 180.0000    391.00
 185.0000    401.00
 190.0000    431.00
 195.0000    449.00
 200.0000    451.00
 205.0000    472.00
 210.0000    428.00
 215.0000    419.00
 220.0000    425.00
 225.0000    449.00
 230.0000    411.00
 235.0000    387.00
 240.0000    459.00
 245.0000    448.00
 250.0000    403.00
 255.0000    424.00
 260.0000    403.00
 265.0000    399.00
 270.0000    394.00
 275.0000    429.00
 280.0000    458.00
 285.0000    439.00
 290.0000    414.00
 295.0000    404.00
 300.0000    428.00
 305.0000    412.00
 310.0000    399.00
 315.0000    413.00
 320.0000    405.00
 325.0000    407.00
 330.0000    352.00
 335.0000    383.00
 340.0000    411.00
 345.0000    434.00
 350.0000    434.00
 355.0000    394.00
; (Data for Range number 15)
_DRIVE='PHI'
_STEPTIME=1.000000
_STEPSIZE=5.000000
_STEPMODE='C'
_START=0.000000
_THETA=17.200001
_2THETA=34.400002
_KHI=70.000000
_PHI=0.000000
_X=0.876000
_Y=9.952000
_Z=0.085500
_DIVERGENCE=0.200000
_ANTISCATTER=0.200000
_DETECTOR=1
; S.C.
_HV=584.000000
_GAIN=80.000000
_LLD=0.494000
_ULD=2.094000
_DETECTORSLIT='unkn'
_AUX1=0.000000
_AUX2=0.000000
_AUX3=0.000000
_TIMESTARTED=1111.000000
_TEMP_RATE=0.000000
_TEMP_DELAY=0.000000
_KV=40
_MA=40
_RANGE_WL=1.540600
_3DPLANE=0
_2THETACPS
   0.0000    422.00
   5.0000    358.00
  10.0000    336.00
  15.0000    376.00
  20.0000    370.00
  25.0000    381.00
  30.0000    383.00
  35.0000    381.00
  40.0000    344.00
  45.0000    431.00
  50.0000    378.00
  55.0000    373.00
  60.0000    368.00
  65.0000    377.00
  70.0000    354.00
  75.0000    373.00
  80.0000    392.00
  85.0000    379.00
  90.0000    399.00
  95.0000    381.00
 100.0000    411.00
 105.0000    389.00
 110.0000    433.00
 115.0000    419.00
 120.0000    392.00
 125.0000    392.00
 130.0000    351.00
 135.0000    379.00
 140.0000    339.00
 145.0000    368.00
 150.0000    384.00
 155.0000    314.00
 160.0000    351.00
 165.0000    333.00
 170.0000    354.00
 175.0000    364.00
 180.0000    355.00
 185.0000    365.00
 190.0000    376.00
 195.0000    371.00
 200.0000    389.00
 205.0000    323.00
 210.0000    369.00
 215.0000    411.00
 220.0000    391.00
 225.0000    371.00
 230.0000    384.00
 235.0000    403.00
 240.0000    388.00
 245.0000    397.00
 250.0000    410.00
 255.0000    377.00
 260.0000    347.00
 265.0000    371.00
 270.0000    380.00
 275.0000    388.00
 280.0000    416.00
 285.0000    394.00
 290.0000    386.00
 295.0000    404.00
 300.0000    380.00
 305.0000    358.00
 310.0000    394.00
 315.0000    345.00
 320.0000    366.00
 325.0000    357.00
 330.0000    377.00
 335.0000    370.00
 340.0000    407.00
 345.0000    399.00
 350.0000    400.00
 355.0000    379.00
; (Data for Range number 16)
_DRIVE='PHI'
_STEPTIME=1.000000
_STEPSIZE=5.000000
_STEPMODE='C'
_START=0.000000
_THETA=17.200001
_2THETA=34.400002
_KHI=75.000000
_PHI=0.000000
_X=0.876000
_Y=9.952000
_Z=0.085500
_DIVERGENCE=0.200000
_ANTISCATTER=0.200000
_DETECTOR=1
; S.C.
_HV=584.000000
_GAIN=80.000000
_LLD=0.494000
_ULD=2.094000
_DETECTORSLIT='unkn'
_AUX1=0.000000
_AUX2=0.000000
_AUX3=0.000000
_TIMESTARTED=1189.000000
_TEMP_RATE=0.000000
_TEMP_DELAY=0.000000
_KV=40
_MA=40
_RANGE_WL=1.540600
_3DPLANE=0
_2THETACPS
   0.0000    311.00
   5.0000    323.00
  10.0000    330.00
  15.0000    311.00
  20.0000    297.00
  25.0000    301.00
  30.0000    308.00
  35.0000    313.00
  40.0000    267.00
  45.0000    327.00
  50.0000    305.00
  55.0000    304.00
  60.0000    348.00
  65.0000    337.00
  70.0000    293.00
  75.0000    325.00
  80.0000    315.00
  85.0000    344.00
  90.0000    317.00
  95.0000    317.00
 100.0000    347.00
 105.0000    322.00
 110.0000    339.00
 115.0000    324.00
 120.0000    345.00
 125.0000    295.00
 130.0000    315.00
 135.0000    307.00
 140.0000    270.00
 145.0000    304.00
 150.0000    260.00
 155.0000    282.00
 160.0000    317.00
 165.0000    304.00
 170.0000    287.00
 175.0000    288.00
 180.0000    305.00
 185.0000    341.00
 190.0000    291.00
 195.0000    280.00
 200.0000    293.00
 205.0000    296.00
 210.0000    283.00
 215.0000    324.00
 220.0000    323.00
 225.0000    315.00
 230.0000    325.00
 235.0000    332.00
 240.0000    357.00
 245.0000    317.00
 250.0000    319.00
 255.0000    273.00
 260.0000    269.00
 265.0000    293.00
 270.0000    321.00
 275.0000    306.00
 280.0000    341.00
 285.0000    361.00
 290.0000    323.00
 295.0000    316.00
 300.0000    317.00
 305.0000    315.00
 310.0000    336.00
 315.0000    330.00
 320.0000    337.00
 325.0000    266.00
 330.0000    315.00
 335.0000    320.00
 340.0000    300.00
 345.0000    303.00
 350.0000    326.00
 355.0000    341.00
; (Data for Range number 17)
_DRIVE='PHI'
_STEPTIME=1.000000
_STEPSIZE=5.000000
_STEPMODE='C'
_START=0.000000
_THETA=17.200001
_2THETA=34.400002
_KHI=80.000000
_PHI=0.000000
_X=0.876000
_Y=9.952000
_Z=0.085500
_DIVERGENCE=0.200000
_ANTISCATTER=0.200000
_DETECTOR=1
; S.C.
_HV=584.000000
_GAIN=80.000000
_LLD=0.494000
_ULD=2.094000
_DETECTORSLIT='unkn'
_AUX1=0.000000
_AUX2=0.000000
_AUX3=0.000000
_TIMESTARTED=1267.000000
_TEMP_RATE=0.000000
_TEMP_DELAY=0.000000
_KV=40
_MA=40
_RANGE_WL=1.540600
_3DPLANE=0
_2THETACPS
   0.0000    219.00
   5.0000    271.00
  10.0000    231.00
  15.0000    237.00
  20.0000    231.00
  25.0000    213.00
  30.0000    232.00
  35.0000    215.00
  40.0000    237.00
  45.0000    251.00
  50.0000    196.00
  55.0000    205.00
  60.0000    229.00
  65.0000    228.00
  70.0000    242.00
  75.0000    226.00
  80.0000    224.00
  85.0000    209.00
  90.0000    204.00
  95.0000    213.00
 100.0000    262.00
 105.0000    228.00
 110.0000    235.00
 115.0000    246.00
 120.0000    210.00
 125.0000    204.00
 130.0000    244.00
 135.0000    190.00
 140.0000    221.00
 145.0000    252.00
 150.0000    202.00
 155.0000    187.00
 160.0000    232.00
 165.0000    191.00
 170.0000    227.00
 175.0000    241.00
 180.0000    221.00
 185.0000    199.00
 190.0000    217.00
 195.0000    181.00
 200.0000    235.00
 205.0000    235.00
 210.0000    223.00
 215.0000    234.00
 220.0000    225.00
 225.0000    235.00
 230.0000    189.00
 235.0000    230.00
 240.0000    229.00
 245.0000    228.00
 250.0000    208.00
 255.0000    193.00
 260.0000    198.00
 265.0000    201.00
 270.0000    200.00
 275.0000    223.00
 280.0000    228.00
 285.0000    234.00
 290.0000    230.00
 295.0000    259.00
 300.0000    291.00
 305.0000    237.00
 310.0000    259.00
 315.0000    252.00
 320.0000    250.00
 325.0000    242.00
 330.0000    228.00
 335.0000    225.00
 340.0000    257.00
 345.0000    261.00
 350.0000    264.00
 355.0000    242.00
; (Data for Range number 18)
_DRIVE='PHI'
_STEPTIME=1.000000
_STEPSIZE=5.000000
_STEPMODE='C'
_START=0.000000
_THETA=18.225000
_2THETA=36.450001
_KHI=0.000000
_PHI=0.000000
_X=0.876000
_Y=9.952000
_Z=0.085500
_DIVERGENCE=0.200000
_ANTISCATTER=0.200000
_DETECTOR=1
; S.C.
_HV=584.000000
_GAIN=80.000000
_LLD=0.494000
_ULD=2.094000
_DETECTORSLIT='unkn'
_AUX1=0.000000
_AUX2=0.000000
_AUX3=0.000000
_TIMESTARTED=1371.000000
_TEMP_RATE=0.000000
_TEMP_DELAY=0.000000
_KV=40
_MA=40
_RANGE_WL=1.540600
_3DPLANE=0
_2THETACPS
   0.0000    379.00
   5.0000    425.00
  10.0000    434.00
  15.0000    400.00
  20.0000    405.00
  25.0000    378.00
  30.0000    374.00
  35.0000    352.00
  40.0000    366.00
  45.0000    348.00
  50.0000    378.00
  55.0000    398.00
  60.0000    397.00
  65.0000    416.00
  70.0000    380.00
  75.0000    373.00
  80.0000    392.00
  85.0000    363.00
  90.0000    371.00
  95.0000    351.00
 100.0000    362.00
 105.0000    387.00
 110.0000    345.00
 115.0000    395.00
 120.0000    379.00
 125.0000    370.00
 130.0000    345.00
 135.0000    368.00
 140.0000    390.00
 145.0000    348.00
 150.0000    352.00
 155.0000    317.00
 160.0000    375.00
 165.0000    349.00
 170.0000    351.00
 175.0000    340.00
 180.0000    323.00
 185.0000    359.00
 190.0000    348.00
 195.0000    388.00
 200.0000    384.00
 205.0000    371.00
 210.0000    381.00
 215.0000    417.00
 220.0000    378.00
 225.0000    375.00
 230.0000    396.00
 235.0000    379.00
 240.0000    369.00
 245.0000    385.00
 250.0000    353.00
 255.0000    429.00
 260.0000    340.00
 265.0000    387.00
 270.0000    376.00
 275.0000    402.00
 280.0000    356.00
 285.0000    364.00
 290.0000    391.00
 295.0000    408.00
 300.0000    357.00
 305.0000    416.00
 310.0000    399.00
 315.0000    405.00
 320.0000    391.00
 325.0000    378.00
 330.0000    374.00
 335.0000    337.00
 340.0000    372.00
 345.0000    415.00
 350.0000    330.00
 355.0000    378.00
; (Data for Range number 19)
_DRIVE='PHI'
_STEPTIME=1.000000
_STEPSIZE=5.000000
_STEPMODE='C'
_START=0.000000
_THETA=18.225000
_2THETA=36.450001
_KHI=5.000000
_PHI=0.000000
_X=0.876000
_Y=9.952000
_Z=0.085500
_DIVERGENCE=0.200000
_ANTISCATTER=0.200000
_DETECTOR=1
; S.C.
_HV=584.000000
_GAIN=80.000000
_LLD=0.494000
_ULD=2.094000
_DETECTORSLIT='unkn'
_AUX1=0.000000
_AUX2=0.000000
_AUX3=0.000000
_TIMESTARTED=1449.000000
_TEMP_RATE=0.000000
_TEMP_DELAY=0.000000
_KV=40
_MA=40
_RANGE_WL=1.540600
_3DPLANE=0
_2THETACPS
   0.0000    366.00
   5.0000    388.00
  10.0000    377.00
  15.0000    415.00
  20.0000    404.00
  25.0000    400.00
  30.0000    396.00
  35.0000    395.00
  40.0000    360.00
  45.0000    419.00
  50.0000    390.00
  55.0000    396.00
  60.0000    398.00
  65.0000    400.00
  70.0000    400.00
  75.0000    422.00
  80.0000    419.00
  85.0000    412.00
  90.0000    420.00
  95.0000    416.00
 100.0000    414.00
 105.0000    427.00
 110.0000    432.00
 115.0000    404.00
 120.0000    418.00
 125.0000    396.00
 130.0000    374.00
 135.0000    397.00
 140.0000    368.00
 145.0000    377.00
 150.0000    366.00
 155.0000    363.00
 160.0000    409.00
 165.0000    332.00
 170.0000    373.00
 175.0000    385.00
 180.0000    363.00
 185.0000    379.00
 190.0000    375.00
 195.0000    338.00
 200.0000    357.00
 205.0000    407.00
 210.0000    377.00
 215.0000    397.00
 220.0000    365.00
 225.0000    358.00
 230.0000    425.00
 235.0000    433.00
 240.0000    363.00
 245.0000    370.00
 250.0000    373.00
 255.0000    360.00
 260.0000    387.00
 265.0000    372.00
 270.0000    366.00
 275.0000    373.00
 280.0000    396.00
 285.0000    382.00
 290.0000    383.00
 295.0000    392.00
 300.0000    415.00
 305.0000    357.00
 310.0000    423.00
 315.0000    413.00
 320.0000    409.00
 325.0000    387.00
 330.0000    400.00
 335.0000    423.00
 340.0000    378.00
 345.0000    382.00
 350.0000    380.00
 355.0000    380.00
; (Data for Range number 20)
_DRIVE='PHI'
_STEPTIME=1.000000
_STEPSIZE=5.000000
_STEPMODE='C'
_START=0.000000
_THETA=18.225000
_2THETA=36.450001
_KHI=10.000000
_PHI=0.000000
_X=0.876000
_Y=9.952000
_Z=0.085500
_DIVERGENCE=0.200000
_ANTISCATTER=0.200000
_DETECTOR=1
; S.C.
_HV=584.000000
_GAIN=80.000000
_LLD=0.494000
_ULD=2.094000
_DETECTORSLIT='unkn'
_AUX1=0.000000
_AUX2=0.000000
_AUX3=0.000000
_TIMESTARTED=1527.000000
_TEMP_RATE=0.000000
_TEMP_DELAY=0.000000
_KV=40
_MA=40
_RANGE_WL=1.540600
_3DPLANE=0
_2THETACPS
   0.0000    417.00
   5.0000    439.00
  10.0000    425.00
  15.0000    439.00
  20.0000    443.00
  25.0000    460.00
  30.0000    481.00
  35.0000    444.00
  40.0000    486.00
  45.0000    469.00
  50.0000    456.00
  55.0000    452.00
  60.0000    432.00
  65.0000    429.00
  70.0000    437.00
  75.0000    446.00
  80.0000    471.00
  85.0000    487.00
  90.0000    480.00
  95.0000    469.00
 100.0000    439.00
 105.0000    463.00
 110.0000    444.00
 115.0000    424.00
 120.0000    440.00
 125.0000    445.00
 130.0000    444.00
 135.0000    433.00
 140.0000    415.00
 145.0000    395.00
 150.0000    378.00
 155.0000    422.00
 160.0000    369.00
 165.0000    367.00
 170.0000    424.00
 175.0000    364.00
 180.0000    355.00
 185.0000    359.00
 190.0000    343.00
 195.0000    381.00
 200.0000    408.00
 205.0000    427.00
 210.0000    408.00
 215.0000    448.00
 220.0000    410.00
 225.0000    420.00
 230.0000    409.00
 235.0000    445.00
 240.0000    369.00
 245.0000    413.00
 250.0000    421.00
 255.0000    404.00
 260.0000    382.00
 265.0000    393.00
 270.0000    363.00
 275.0000    394.00
 280.0000    404.00
 285.0000    389.00
 290.0000    391.00
 295.0000    392.00
 300.0000    413.00
 305.0000    429.00
 310.0000    457.00
 315.0000    471.00
 320.0000    421.00
 325.0000    456.00
 330.0000    394.00
 335.0000    426.00
 340.0000    397.00
 345.0000    445.00
 350.0000    407.00
 355.0000    429.00
; (Data for Range number 21)
_DRIVE='PHI'
_STEPTIME=1.000000
_STEPSIZE=5.000000
_STEPMODE='C'
_START=0.000000
_THETA=18.225000
_2THETA=36.450001
_KHI=15.000000
_PHI=0.000000
_X=0.876000
_Y=9.952000
_Z=0.085500
_DIVERGENCE=0.200000
_ANTISCATTER=0.200000
_DETECTOR=1
; S.C.
_HV=584.000000
[...]
 255.0000    437.00
 260.0000    434.00
 265.0000    419.00
 270.0000    439.00
 275.0000    452.00
 280.0000    464.00
 285.0000    465.00
 290.0000    527.00
 295.0000    538.00
 300.0000    556.00
 305.0000    541.00
 310.0000    526.00
 315.0000    521.00
 320.0000    495.00
 325.0000    494.00
 330.0000    540.00
 335.0000    512.00
 340.0000    509.00
 345.0000    488.00
 350.0000    498.00
 355.0000    531.00
; (Data for Range number 59)
_DRIVE='PHI'
_STEPTIME=1.000000
_STEPSIZE=5.000000
_STEPMODE='C'
_START=0.000000
_THETA=23.900000
_2THETA=47.799999
_KHI=35.000000
_PHI=0.000000
_X=0.876000
_Y=9.952000
_Z=0.085500
_DIVERGENCE=0.200000
_ANTISCATTER=0.200000
_DETECTOR=1
; S.C.
_HV=584.000000
_GAIN=80.000000
_LLD=0.494000
_ULD=2.094000
_DETECTORSLIT='unkn'
_AUX1=0.000000
_AUX2=0.000000
_AUX3=0.000000
_TIMESTARTED=4627.000000
_TEMP_RATE=0.000000
_TEMP_DELAY=0.000000
_KV=40
_MA=40
_RANGE_WL=1.540600
_3DPLANE=0
_2THETACPS
   0.0000    493.00
   5.0000    493.00
  10.0000    471.00
  15.0000    512.00
  20.0000    508.00
  25.0000    549.00
  30.0000    518.00
  35.0000    527.00
  40.0000    562.00
  45.0000    560.00
  50.0000    512.00
  55.0000    468.00
  60.0000    440.00
  65.0000    409.00
  70.0000    419.00
  75.0000    391.00
  80.0000    422.00
  85.0000    397.00
  90.0000    444.00
  95.0000    429.00
 100.0000    414.00
 105.0000    462.00
 110.0000    504.00
 115.0000    432.00
 120.0000    435.00
 125.0000    457.00
 130.0000    469.00
 135.0000    429.00
 140.0000    452.00
 145.0000    440.00
 150.0000    495.00
 155.0000    463.00
 160.0000    458.00
 165.0000    426.00
 170.0000    451.00
 175.0000    437.00
 180.0000    469.00
 185.0000    503.00
 190.0000    518.00
 195.0000    514.00
 200.0000    504.00
 205.0000    500.00
 210.0000    527.00
 215.0000    555.00
 220.0000    531.00
 225.0000    498.00
 230.0000    465.00
 235.0000    507.00
 240.0000    425.00
 245.0000    405.00
 250.0000    436.00
 255.0000    420.00
 260.0000    375.00
 265.0000    400.00
 270.0000    435.00
 275.0000    408.00
 280.0000    438.00
 285.0000    470.00
 290.0000    511.00
 295.0000    502.00
 300.0000    505.00
 305.0000    569.00
 310.0000    470.00
 315.0000    434.00
 320.0000    483.00
 325.0000    492.00
 330.0000    461.00
 335.0000    542.00
 340.0000    513.00
 345.0000    493.00
 350.0000    490.00
 355.0000    460.00
; (Data for Range number 60)
_DRIVE='PHI'
_STEPTIME=1.000000
_STEPSIZE=5.000000
_STEPMODE='C'
_START=0.000000
_THETA=23.900000
_2THETA=47.799999
_KHI=40.000000
_PHI=0.000000
_X=0.876000
_Y=9.952000
_Z=0.085500
_DIVERGENCE=0.200000
_ANTISCATTER=0.200000
_DETECTOR=1
; S.C.
_HV=584.000000
_GAIN=80.000000
_LLD=0.494000
_ULD=2.094000
_DETECTORSLIT='unkn'
_AUX1=0.000000
_AUX2=0.000000
_AUX3=0.000000
_TIMESTARTED=4705.000000
_TEMP_RATE=0.000000
_TEMP_DELAY=0.000000
_KV=40
_MA=40
_RANGE_WL=1.540600
_3DPLANE=0
_2THETACPS
   0.0000    476.00
   5.0000    467.00
  10.0000    464.00
  15.0000    460.00
  20.0000    518.00
  25.0000    496.00
  30.0000    488.00
  35.0000    542.00
  40.0000    497.00
  45.0000    523.00
  50.0000    465.00
  55.0000    441.00
  60.0000    463.00
  65.0000    446.00
  70.0000    423.00
  75.0000    427.00
  80.0000    428.00
  85.0000    404.00
  90.0000    426.00
  95.0000    391.00
 100.0000    398.00
 105.0000    403.00
 110.0000    428.00
 115.0000    471.00
 120.0000    437.00
 125.0000    451.00
 130.0000    392.00
 135.0000    416.00
 140.0000    475.00
 145.0000    437.00
 150.0000    492.00
 155.0000    450.00
 160.0000    423.00
 165.0000    408.00
 170.0000    438.00
 175.0000    422.00
 180.0000    422.00
 185.0000    436.00
 190.0000    478.00
 195.0000    454.00
 200.0000    508.00
 205.0000    500.00
 210.0000    506.00
 215.0000    500.00
 220.0000    513.00
 225.0000    510.00
 230.0000    445.00
 235.0000    450.00
 240.0000    475.00
 245.0000    474.00
 250.0000    408.00
 255.0000    413.00
 260.0000    370.00
 265.0000    397.00
 270.0000    431.00
 275.0000    443.00
 280.0000    388.00
 285.0000    409.00
 290.0000    500.00
 295.0000    477.00
 300.0000    458.00
 305.0000    471.00
 310.0000    449.00
 315.0000    518.00
 320.0000    427.00
 325.0000    449.00
 330.0000    447.00
 335.0000    461.00
 340.0000    461.00
 345.0000    463.00
 350.0000    426.00
 355.0000    457.00
; (Data for Range number 61)
_DRIVE='PHI'
_STEPTIME=1.000000
_STEPSIZE=5.000000
_STEPMODE='C'
_START=0.000000
_THETA=23.900000
_2THETA=47.799999
_KHI=45.000000
_PHI=0.000000
_X=0.876000
_Y=9.952000
_Z=0.085500
_DIVERGENCE=0.200000
_ANTISCATTER=0.200000
_DETECTOR=1
; S.C.
_HV=584.000000
_GAIN=80.000000
_LLD=0.494000
_ULD=2.094000
_DETECTORSLIT='unkn'
_AUX1=0.000000
_AUX2=0.000000
_AUX3=0.000000
_TIMESTARTED=4783.000000
_TEMP_RATE=0.000000
_TEMP_DELAY=0.000000
_KV=40
_MA=40
_RANGE_WL=1.540600
_3DPLANE=0
_2THETACPS
   0.0000    453.00
   5.0000    434.00
  10.0000    437.00
  15.0000    426.00
  20.0000    454.00
  25.0000    444.00
  30.0000    458.00
  35.0000    443.00
  40.0000    432.00
  45.0000    411.00
  50.0000    433.00
  55.0000    410.00
  60.0000    405.00
  65.0000    434.00
  70.0000    404.00
  75.0000    404.00
  80.0000    370.00
  85.0000    391.00
  90.0000    369.00
  95.0000    424.00
 100.0000    420.00
 105.0000    427.00
 110.0000    436.00
 115.0000    399.00
 120.0000    410.00
 125.0000    412.00
 130.0000    407.00
 135.0000    388.00
 140.0000    408.00
 145.0000    377.00
 150.0000    427.00
 155.0000    403.00
 160.0000    395.00
 165.0000    406.00
 170.0000    415.00
 175.0000    405.00
 180.0000    439.00
 185.0000    439.00
 190.0000    453.00
 195.0000    440.00
 200.0000    443.00
 205.0000    431.00
 210.0000    442.00
 215.0000    454.00
 220.0000    486.00
 225.0000    404.00
 230.0000    410.00
 235.0000    362.00
 240.0000    389.00
 245.0000    423.00
 250.0000    458.00
 255.0000    432.00
 260.0000    418.00
 265.0000    428.00
 270.0000    425.00
 275.0000    389.00
 280.0000    414.00
 285.0000    357.00
 290.0000    438.00
 295.0000    407.00
 300.0000    419.00
 305.0000    394.00
 310.0000    428.00
 315.0000    419.00
 320.0000    471.00
 325.0000    495.00
 330.0000    444.00
 335.0000    454.00
 340.0000    463.00
 345.0000    409.00
 350.0000    420.00
 355.0000    452.00
; (Data for Range number 62)
_DRIVE='PHI'
_STEPTIME=1.000000
_STEPSIZE=5.000000
_STEPMODE='C'
_START=0.000000
_THETA=23.900000
_2THETA=47.799999
_KHI=50.000000
_PHI=0.000000
_X=0.876000
_Y=9.952000
_Z=0.085500
_DIVERGENCE=0.200000
_ANTISCATTER=0.200000
_DETECTOR=1
; S.C.
_HV=584.000000
_GAIN=80.000000
_LLD=0.494000
_ULD=2.094000
_DETECTORSLIT='unkn'
_AUX1=0.000000
_AUX2=0.000000
_AUX3=0.000000
_TIMESTARTED=4862.000000
_TEMP_RATE=0.000000
_TEMP_DELAY=0.000000
_KV=40
_MA=40
_RANGE_WL=1.540600
_3DPLANE=0
_2THETACPS
   0.0000    394.00
   5.0000    367.00
  10.0000    394.00
  15.0000    421.00
  20.0000    426.00
  25.0000    428.00
  30.0000    430.00
  35.0000    370.00
  40.0000    418.00
  45.0000    415.00
  50.0000    361.00
  55.0000    373.00
  60.0000    428.00
  65.0000    433.00
  70.0000    442.00
  75.0000    377.00
  80.0000    368.00
  85.0000    379.00
  90.0000    386.00
  95.0000    414.00
 100.0000    410.00
 105.0000    404.00
 110.0000    396.00
 115.0000    401.00
 120.0000    375.00
 125.0000    361.00
 130.0000    405.00
 135.0000    398.00
 140.0000    351.00
 145.0000    357.00
 150.0000    360.00
 155.0000    370.00
 160.0000    350.00
 165.0000    372.00
 170.0000    387.00
 175.0000    410.00
 180.0000    437.00
 185.0000    420.00
 190.0000    415.00
 195.0000    414.00
 200.0000    395.00
 205.0000    403.00
 210.0000    435.00
 215.0000    414.00
 220.0000    452.00
 225.0000    404.00
 230.0000    423.00
 235.0000    464.00
 240.0000    388.00
 245.0000    405.00
 250.0000    381.00
 255.0000    370.00
 260.0000    393.00
 265.0000    401.00
 270.0000    422.00
 275.0000    398.00
 280.0000    377.00
 285.0000    412.00
 290.0000    418.00
 295.0000    406.00
 300.0000    421.00
 305.0000    405.00
 310.0000    376.00
 315.0000    399.00
 320.0000    437.00
 325.0000    429.00
 330.0000    452.00
 335.0000    421.00
 340.0000    445.00
 345.0000    450.00
 350.0000    377.00
 355.0000    455.00
; (Data for Range number 63)
_DRIVE='PHI'
_STEPTIME=1.000000
_STEPSIZE=5.000000
_STEPMODE='C'
_START=0.000000
_THETA=23.900000
_2THETA=47.799999
_KHI=55.000000
_PHI=0.000000
_X=0.876000
_Y=9.952000
_Z=0.085500
_DIVERGENCE=0.200000
_ANTISCATTER=0.200000
_DETECTOR=1
; S.C.
_HV=584.000000
_GAIN=80.000000
_LLD=0.494000
_ULD=2.094000
_DETECTORSLIT='unkn'
_AUX1=0.000000
_AUX2=0.000000
_AUX3=0.000000
_TIMESTARTED=4940.000000
_TEMP_RATE=0.000000
_TEMP_DELAY=0.000000
_KV=40
_MA=40
_RANGE_WL=1.540600
_3DPLANE=0
_2THETACPS
   0.0000    354.00
   5.0000    348.00
  10.0000    353.00
  15.0000    364.00
  20.0000    355.00
  25.0000    348.00
  30.0000    343.00
  35.0000    339.00
  40.0000    361.00
  45.0000    341.00
  50.0000    362.00
  55.0000    400.00
  60.0000    331.00
  65.0000    365.00
  70.0000    377.00
  75.0000    353.00
  80.0000    377.00
  85.0000    388.00
  90.0000    376.00
  95.0000    334.00
 100.0000    320.00
 105.0000    353.00
 110.0000    383.00
 115.0000    354.00
 120.0000    399.00
 125.0000    333.00
 130.0000    365.00
 135.0000    347.00
 140.0000    365.00
 145.0000    354.00
 150.0000    367.00
 155.0000    332.00
 160.0000    356.00
 165.0000    372.00
 170.0000    358.00
 175.0000    365.00
 180.0000    381.00
 185.0000    360.00
 190.0000    343.00
 195.0000    346.00
 200.0000    336.00
 205.0000    339.00
 210.0000    351.00
 215.0000    402.00
 220.0000    380.00
 225.0000    394.00
 230.0000    402.00
 235.0000    421.00
 240.0000    403.00
 245.0000    357.00
 250.0000    390.00
 255.0000    346.00
 260.0000    406.00
 265.0000    384.00
 270.0000    371.00
 275.0000    365.00
 280.0000    359.00
 285.0000    402.00
 290.0000    414.00
 295.0000    342.00
 300.0000    409.00
 305.0000    391.00
 310.0000    389.00
 315.0000    392.00
 320.0000    371.00
 325.0000    397.00
 330.0000    372.00
 335.0000    394.00
 340.0000    414.00
 345.0000    393.00
 350.0000    378.00
 355.0000    412.00
; (Data for Range number 64)
_DRIVE='PHI'
_STEPTIME=1.000000
_STEPSIZE=5.000000
_STEPMODE='C'
_START=0.000000
_THETA=23.900000
_2THETA=47.799999
_KHI=60.000000
_PHI=0.000000
_X=0.876000
_Y=9.952000
_Z=0.085500
_DIVERGENCE=0.200000
_ANTISCATTER=0.200000
_DETECTOR=1
; S.C.
_HV=584.000000
_GAIN=80.000000
_LLD=0.494000
_ULD=2.094000
_DETECTORSLIT='unkn'
_AUX1=0.000000
_AUX2=0.000000
_AUX3=0.000000
_TIMESTARTED=5018.000000
_TEMP_RATE=0.000000
_TEMP_DELAY=0.000000
_KV=40
_MA=40
_RANGE_WL=1.540600
_3DPLANE=0
_2THETACPS
   0.0000    316.00
   5.0000    316.00
  10.0000    331.00
  15.0000    321.00
  20.0000    319.00
  25.0000    289.00
  30.0000    321.00
  35.0000    277.00
  40.0000    333.00
  45.0000    324.00
  50.0000    320.00
  55.0000    339.00
  60.0000    344.00
  65.0000    325.00
  70.0000    309.00
  75.0000    344.00
  80.0000    330.00
  85.0000    331.00
  90.0000    291.00
  95.0000    341.00
 100.0000    348.00
 105.0000    341.00
 110.0000    345.00
 115.0000    308.00
 120.0000    310.00
 125.0000    348.00
 130.0000    302.00
 135.0000    321.00
 140.0000    329.00
 145.0000    315.00
 150.0000    317.00
 155.0000    293.00
 160.0000    321.00
 165.0000    339.00
 170.0000    314.00
 175.0000    328.00
 180.0000    313.00
 185.0000    272.00
 190.0000    312.00
 195.0000    295.00
 200.0000    338.00
 205.0000    308.00
 210.0000    318.00
 215.0000    295.00
 220.0000    327.00
 225.0000    296.00
 230.0000    351.00
 235.0000    365.00
 240.0000    381.00
 245.0000    355.00
 250.0000    358.00
 255.0000    348.00
 260.0000    341.00
 265.0000    286.00
 270.0000    309.00
 275.0000    299.00
 280.0000    309.00
 285.0000    383.00
 290.0000    371.00
 295.0000    394.00
 300.0000    347.00
 305.0000    321.00
 310.0000    365.00
 315.0000    336.00
 320.0000    337.00
 325.0000    295.00
 330.0000    313.00
 335.0000    325.00
 340.0000    343.00
 345.0000    335.00
 350.0000    381.00
 355.0000    315.00
; (Data for Range number 65)
_DRIVE='PHI'
_STEPTIME=1.000000
_STEPSIZE=5.000000
_STEPMODE='C'
_START=0.000000
_THETA=23.900000
_2THETA=47.799999
_KHI=65.000000
_PHI=0.000000
_X=0.876000
_Y=9.952000
_Z=0.085500
_DIVERGENCE=0.200000
_ANTISCATTER=0.200000
_DETECTOR=1
; S.C.
_HV=584.000000
_GAIN=80.000000
_LLD=0.494000
_ULD=2.094000
_DETECTORSLIT='unkn'
_AUX1=0.000000
_AUX2=0.000000
_AUX3=0.000000
_TIMESTARTED=5096.000000
_TEMP_RATE=0.000000
_TEMP_DELAY=0.000000
_KV=40
_MA=40
_RANGE_WL=1.540600
_3DPLANE=0
_2THETACPS
   0.0000    281.00
   5.0000    280.00
  10.0000    275.00
  15.0000    262.00
  20.0000    246.00
  25.0000    286.00
  30.0000    249.00
  35.0000    265.00
  40.0000    247.00
  45.0000    274.00
  50.0000    281.00
  55.0000    290.00
  60.0000    269.00
  65.0000    307.00
  70.0000    316.00
  75.0000    265.00
  80.0000    321.00
  85.0000    246.00
  90.0000    267.00
  95.0000    309.00
 100.0000    313.00
 105.0000    286.00
 110.0000    356.00
 115.0000    352.00
 120.0000    359.00
 125.0000    295.00
 130.0000    304.00
 135.0000    312.00
 140.0000    280.00
 145.0000    260.00
 150.0000    253.00
 155.0000    271.00
 160.0000    289.00
 165.0000    286.00
 170.0000    288.00
 175.0000    269.00
 180.0000    286.00
 185.0000    293.00
 190.0000    270.00
 195.0000    260.00
 200.0000    276.00
 205.0000    265.00
 210.0000    270.00
 215.0000    244.00
 220.0000    261.00
 225.0000    266.00
 230.0000    282.00
 235.0000    292.00
 240.0000    301.00
 245.0000    293.00
 250.0000    304.00
 255.0000    307.00
 260.0000    284.00
 265.0000    277.00
 270.0000    289.00
 275.0000    311.00
 280.0000    317.00
 285.0000    315.00
 290.0000    314.00
 295.0000    318.00
 300.0000    293.00
 305.0000    321.00
 310.0000    307.00
 315.0000    306.00
 320.0000    290.00
 325.0000    271.00
 330.0000    292.00
 335.0000    277.00
 340.0000    318.00
 345.0000    287.00
 350.0000    311.00
 355.0000    293.00
; (Data for Range number 66)
_DRIVE='PHI'
_STEPTIME=1.000000
_STEPSIZE=5.000000
_STEPMODE='C'
_START=0.000000
_THETA=23.900000
_2THETA=47.799999
_KHI=70.000000
_PHI=0.000000
_X=0.876000
_Y=9.952000
_Z=0.085500
_DIVERGENCE=0.200000
_ANTISCATTER=0.200000
_DETECTOR=1
; S.C.
_HV=584.000000
_GAIN=80.000000
_LLD=0.494000
_ULD=2.094000
_DETECTORSLIT='unkn'
_AUX1=0.000000
_AUX2=0.000000
_AUX3=0.000000
_TIMESTARTED=5174.000000
_TEMP_RATE=0.000000
_TEMP_DELAY=0.000000
_KV=40
_MA=40
_RANGE_WL=1.540600
_3DPLANE=0
_2THETACPS
   0.0000    206.00
   5.0000    223.00
  10.0000    207.00
  15.0000    220.00
  20.0000    215.00
  25.0000    235.00
  30.0000    230.00
  35.0000    198.00
  40.0000    245.00
  45.0000    254.00
  50.0000    227.00
  55.0000    249.00
  60.0000    219.00
  65.0000    256.00
  70.0000    264.00
  75.0000    265.00
  80.0000    251.00
  85.0000    223.00
  90.0000    252.00
  95.0000    281.00
 100.0000    286.00
 105.0000    282.00
 110.0000    274.00
 115.0000    296.00
 120.0000    280.00
 125.0000    292.00
 130.0000    283.00
 135.0000    261.00
 140.0000    261.00
 145.0000    269.00
 150.0000    262.00
 155.0000    237.00
 160.0000    236.00
 165.0000    231.00
 170.0000    228.00
 175.0000    246.00
 180.0000    260.00
 185.0000    233.00
 190.0000    220.00
 195.0000    181.00
 200.0000    207.00
 205.0000    242.00
 210.0000    225.00
 215.0000    250.00
 220.0000    227.00
 225.0000    218.00
 230.0000    249.00
 235.0000    256.00
 240.0000    239.00
 245.0000    271.00
 250.0000    255.00
 255.0000    266.00
 260.0000    275.00
 265.0000    237.00
 270.0000    271.00
 275.0000    237.00
 280.0000    284.00
 285.0000    292.00
 290.0000    262.00
 295.0000    270.00
 300.0000    263.00
 305.0000    276.00
 310.0000    248.00
 315.0000    273.00
 320.0000    210.00
 325.0000    252.00
 330.0000    243.00
 335.0000    241.00
 340.0000    204.00
 345.0000    234.00
 350.0000    212.00
 355.0000    234.00
; (Data for Range number 67)
_DRIVE='PHI'
_STEPTIME=1.000000
_STEPSIZE=5.000000
_STEPMODE='C'
_START=0.000000
_THETA=23.900000
_2THETA=47.799999
_KHI=75.000000
_PHI=0.000000
_X=0.876000
_Y=9.952000
_Z=0.085500
_DIVERGENCE=0.200000
_ANTISCATTER=0.200000
_DETECTOR=1
; S.C.
_HV=584.000000
_GAIN=80.000000
_LLD=0.494000
_ULD=2.094000
_DETECTORSLIT='unkn'
_AUX1=0.000000
_AUX2=0.000000
_AUX3=0.000000
_TIMESTARTED=5252.000000
_TEMP_RATE=0.000000
_TEMP_DELAY=0.000000
_KV=40
_MA=40
_RANGE_WL=1.540600
_3DPLANE=0
_2THETACPS
   0.0000    171.00
   5.0000    178.00
  10.0000    168.00
  15.0000    181.00
  20.0000    183.00
  25.0000    196.00
  30.0000    178.00
  35.0000    182.00
  40.0000    163.00
  45.0000    198.00
  50.0000    177.00
  55.0000    196.00
  60.0000    196.00
  65.0000    189.00
  70.0000    191.00
  75.0000    168.00
  80.0000    194.00
  85.0000    193.00
  90.0000    217.00
  95.0000    221.00
 100.0000    203.00
 105.0000    213.00
 110.0000    241.00
 115.0000    198.00
 120.0000    256.00
 125.0000    190.00
 130.0000    184.00
 135.0000    190.00
 140.0000    201.00
 145.0000    202.00
 150.0000    167.00
 155.0000    179.00
 160.0000    183.00
 165.0000    165.00
 170.0000    165.00
 175.0000    172.00
 180.0000    205.00
 185.0000    203.00
 190.0000    192.00
 195.0000    193.00
 200.0000    196.00
 205.0000    213.00
 210.0000    200.00
 215.0000    180.00
 220.0000    156.00
 225.0000    155.00
 230.0000    201.00
 235.0000    210.00
 240.0000    188.00
 245.0000    191.00
 250.0000    199.00
 255.0000    190.00
 260.0000    196.00
 265.0000    215.00
 270.0000    194.00
 275.0000    220.00
 280.0000    218.00
 285.0000    185.00
 290.0000    199.00
 295.0000    205.00
 300.0000    215.00
 305.0000    187.00
 310.0000    222.00
 315.0000    201.00
 320.0000    173.00
 325.0000    180.00
 330.0000    190.00
 335.0000    182.00
 340.0000    187.00
 345.0000    202.00
 350.0000    181.00
 355.0000    179.00
; (Data for Range number 68)
_DRIVE='PHI'
_STEPTIME=1.000000
_STEPSIZE=5.000000
_STEPMODE='C'
_START=0.000000
_THETA=23.900000
_2THETA=47.799999
_KHI=80.000000
_PHI=0.000000
_X=0.876000
_Y=9.952000
_Z=0.085500
_DIVERGENCE=0.200000
_ANTISCATTER=0.200000
_DETECTOR=1
; S.C.
_HV=584.000000
_GAIN=80.000000
_LLD=0.494000
_ULD=2.094000
_DETECTORSLIT='unkn'
_AUX1=0.000000
_AUX2=0.000000
_AUX3=0.000000
_TIMESTARTED=5330.000000
_TEMP_RATE=0.000000
_TEMP_DELAY=0.000000
_KV=40
_MA=40
_RANGE_WL=1.540600
_3DPLANE=0
_2THETACPS
   0.0000    151.00
   5.0000    131.00
  10.0000    128.00
  15.0000    147.00
  20.0000    123.00
  25.0000    140.00
  30.0000    116.00
  35.0000    166.00
  40.0000    149.00
  45.0000    147.00
  50.0000    108.00
  55.0000    154.00
  60.0000    141.00
  65.0000    148.00
  70.0000    147.00
  75.0000    146.00
  80.0000    145.00
  85.0000    177.00
  90.0000    155.00
  95.0000    182.00
 100.0000    151.00
 105.0000    159.00
 110.0000    159.00
 115.0000    136.00
 120.0000    167.00
 125.0000    177.00
 130.0000    153.00
 135.0000    137.00
 140.0000    147.00
 145.0000    119.00
 150.0000    145.00
 155.0000    120.00
 160.0000    125.00
 165.0000    140.00
 170.0000    122.00
 175.0000    145.00
 180.0000    123.00
 185.0000    143.00
 190.0000    126.00
 195.0000    142.00
 200.0000    139.00
 205.0000    134.00
 210.0000    151.00
 215.0000    136.00
 220.0000    124.00
 225.0000    134.00
 230.0000    131.00
 235.0000    126.00
 240.0000    172.00
 245.0000    136.00
 250.0000    172.00
 255.0000    157.00
 260.0000    152.00
 265.0000    143.00
 270.0000    159.00
 275.0000    172.00
 280.0000    176.00
 285.0000    158.00
 290.0000    147.00
 295.0000    177.00
 300.0000    156.00
 305.0000    172.00
 310.0000    147.00
 315.0000    123.00
 320.0000    142.00
 325.0000    139.00
 330.0000    141.00
 335.0000    129.00
 340.0000    133.00
 345.0000    144.00
 350.0000    137.00
 355.0000    160.00