File: mtex-5.1.1/data/PoleFigure/Bruker_xrd_10-10.ras
*RAS_DATA_START
*RAS_HEADER_START
*DISP_FMT_X "%.0f"
*DISP_FMT_Y "%.0f"
*DISP_FULLSCALE "1485.6000000000"
*DISP_LINE_COLOR "255.0000000000"
*DISP_LINE_STYLE "0.0000000000"
*DISP_LINE_WIDTH "0.2500000000"
*DISP_NOTE "Collected Data-1"
*DISP_OFFSET_Y "0.0000000000"
*DISP_PEAKSEARCH_UNIT_Y "cps"
*DISP_RANGE_BOTTOM "0.0000000000"
*DISP_RANGE_LEFT "0.0000000000"
*DISP_RANGE_LOGCUTOFF "0.0100000000"
*DISP_RANGE_RIGHT "360.0000000000"
*DISP_RANGE_TOP "1485.6000000000"
*DISP_SCALE_MODE_Y "0.0000000000"
*DISP_TAB_NAME "Phi"
*DISP_TITLE_Y "Intensity"
*DISP_UNIT_Y "cps"
*DISP_WINDOW_NAME "MSG_MACROENGINE"
*FILE_COMMENT " "
*FILE_DATA_TYPE "RAS_3DE_POLEFIG"
*FILE_MD5 ""
*FILE_MEMO "3-23-2009"
*FILE_OPERATOR "SmartLab_User"
*FILE_SAMPLE "am30 ED 25 10-10"
*FILE_TYPE "RAS_RAW"
*FILE_USERGROUP "System Manager"
*FILE_VERSION "1.0000000000"
*HW_ATTACHMENT_ID "ATT0025"
*HW_ATTACHMENT_NAME "Standard|Standard"
*HW_COUNTER_ID-0 "CUT0021"
*HW_COUNTER_ID-1 ""
*HW_COUNTER_ID-2 ""
*HW_COUNTER_ID-3 "CSL0021"
*HW_COUNTER_ID-4 "CMC0021"
*HW_COUNTER_NAME-0 "SC-70|SC-70"
*HW_COUNTER_NAME-1 ""
*HW_COUNTER_NAME-2 ""
*HW_COUNTER_NAME-3 "BBM|BBM"
*HW_COUNTER_NAME-4 "検出器モノクロメータ|Detector monochromator"
*HW_ECP_HV "681.5000000000"
*HW_ECP_HV_UNIT "V"
*HW_GONIOMETER_ID "GON0022"
*HW_GONIOMETER_NAME "SmartLab(インプレーン)|SmartLab(In-plane)"
*HW_GONIOMETER_RADIUS-0 "90.0"
*HW_GONIOMETER_RADIUS-1 "114.0"
*HW_GONIOMETER_RADIUS-2 "190.0"
*HW_GONIOMETER_RADIUS-3 "300.0"
*HW_GONIOMETER_RADIUS-4 "187.0"
*HW_GONIOMETER_RADIUS-5 "300.0"
*HW_GONIOMETER_RADIUS-6 "113.0"
*HW_GONIOMETER_RADIUS-7 "331.0"
*HW_I_OPT_ID-0 "CBO0021"
*HW_I_OPT_ID-1 "ICR0023"
*HW_I_OPT_ID-2 "ISL0021"
*HW_I_OPT_ID-3 "ISO0021"
*HW_I_OPT_ID-4 "IAD0021"
*HW_I_OPT_NAME-0 "CBOユニット|CBO unit"
*HW_I_OPT_NAME-1 "標準入射光学ユニット|Standard incident optical unit"
*HW_I_OPT_NAME-2 "標準入射スリットボックス|Standard incident slit box"
*HW_I_OPT_NAME-3 "入射平行スリット|Incident parallel slit"
*HW_I_OPT_NAME-4 "長手制限スリット|Length limiting slit"
*HW_R_ATTENUATER_AUTOMODE "1"
*HW_R_OPT_ID-0 "RSS0021"
*HW_R_OPT_ID-1 "RCR0022"
*HW_R_OPT_ID-2 "RSO0021"
*HW_R_OPT_ID-3 "RRS0021"
*HW_R_OPT_ID-4 "ATN0021"
*HW_R_OPT_ID-5 "RFL0021"
*HW_R_OPT_ID-6 "RAD0021"
*HW_R_OPT_NAME-0 "標準受光スリットボックス1|Standard receiving slit box # 1"
*HW_R_OPT_NAME-1 "標準受光光学ユニット1|Standard receiving unit # 1"
*HW_R_OPT_NAME-2 "標準受光光学ユニット2|Standard receiving optical unit # 2"
*HW_R_OPT_NAME-3 "標準受光スリットボックス2|Standard receiving slit box # 2"
*HW_R_OPT_NAME-4 "標準アッテネータ|Standard Attenuator"
*HW_R_OPT_NAME-5 "Cu Kβ|Cu K-beta"
*HW_R_OPT_NAME-6 "調整用受光スリット|Alignment receiving slit"
*HW_SAMPLE_HOLDER_ID "SMP0021"
*HW_SAMPLE_HOLDER_NAME "標準χクレードル|Std. chi cradle"
*HW_XG_CURRENT_MAX "60"
*HW_XG_CURRENT_MIN "2"
*HW_XG_CURRENT_RESOLUTION "1"
*HW_XG_CURRENT_UNIT "mA"
*HW_XG_FOCUS "1mm x 10mm"
*HW_XG_FOCUS_TYPE "Normal"
*HW_XG_ID ""
*HW_XG_NAME "3kW 封入管|3kW Sealed tube"
*HW_XG_TARGET_ATOMIC_NUMBER "29.0000000000"
*HW_XG_TARGET_NAME "Cu"
*HW_XG_TYPE "Hermetic"
*HW_XG_VOLTAGE_MAX "60"
*HW_XG_VOLTAGE_MIN "20"
*HW_XG_VOLTAGE_RESOLUTION "1"
*HW_XG_VOLTAGE_UNIT "kV"
*HW_XG_WATT_MAX "2"
*HW_XG_WATT_UNIT "kW"
*HW_XG_WAVE_LENGTH_ALPHA1 "1.540593"
*HW_XG_WAVE_LENGTH_ALPHA2 "1.544414"
*HW_XG_WAVE_LENGTH_BETA "1.392250"
*MEAS_3DE_ALPHA_ANGLE "0.0"
*MEAS_3DE_ALPHA_START "0.0"
*MEAS_3DE_ALPHA_STEP "5.0000"
*MEAS_3DE_ALPHA_STOP "90.0"
*MEAS_3DE_BG_HIGH_ANGLE "32.6165"
*MEAS_3DE_BG_HIGH_EXEC "1"
*MEAS_3DE_BG_HIGH_INT "479"
*MEAS_3DE_BG_HIGH_TIME "0.5"
*MEAS_3DE_BG_LOW_ANGLE "31.8726"
*MEAS_3DE_BG_LOW_EXEC "1"
*MEAS_3DE_BG_LOW_INT "538"
*MEAS_3DE_BG_LOW_TIME "0.5"
*MEAS_3DE_BG_MODE "2"
*MEAS_3DE_TWOTHETA_ANGLE "32.2446"
*MEAS_COND_AXIS_NAME-0 "Theta/2-Theta"
*MEAS_COND_AXIS_NAME-1 "2-Theta"
*MEAS_COND_AXIS_NAME-2 "Omega"
*MEAS_COND_AXIS_NAME-3 "2-Theta/Omega"
*MEAS_COND_AXIS_NAME-4 "Chi"
*MEAS_COND_AXIS_NAME-5 "Phi"
*MEAS_COND_AXIS_NAME-6 "2-ThetaChi"
*MEAS_COND_AXIS_NAME-7 "2-ThetaChi/Phi"
*MEAS_COND_AXIS_NAME-8 "Alpha"
*MEAS_COND_AXIS_NAME-9 "Beta"
*MEAS_COND_AXIS_NAME-10 "Z"
*MEAS_COND_AXIS_NAME-11 "Attenuator"
*MEAS_COND_AXIS_NAME-12 "Theta_s"
*MEAS_COND_AXIS_NAME-13 "Theta_d"
*MEAS_COND_AXIS_NAME-14 "Ts"
*MEAS_COND_AXIS_NAME-15 "M"
*MEAS_COND_AXIS_NAME-16 "Incident slit"
*MEAS_COND_AXIS_NAME-17 ""
*MEAS_COND_AXIS_NAME-18 "Zs"
*MEAS_COND_AXIS_NAME-19 "Receiving slit # 1"
*MEAS_COND_AXIS_NAME-20 ""
*MEAS_COND_AXIS_NAME-21 "Receiving slit # 2"
*MEAS_COND_AXIS_NAME-22 ""
*MEAS_COND_AXIS_NAME-23 "Zd"
*MEAS_COND_AXIS_NAME-24 "CBO selection slit"
*MEAS_COND_AXIS_NAME-25 "Incident monochromator"
*MEAS_COND_AXIS_NAME-26 "Incident parallel slit"
*MEAS_COND_AXIS_NAME-27 "Length limiting slit"
*MEAS_COND_AXIS_NAME-28 "Center slit"
*MEAS_COND_AXIS_NAME-29 "Filter"
*MEAS_COND_AXIS_NAME-30 "Recieving optical device"
*MEAS_COND_AXIS_NAME-31 "Receiving parallel slit"
*MEAS_COND_AXIS_NAME-32 "Alignment receiving slit"
*MEAS_COND_AXIS_NAME-33 "Diffracted beam monochromator"
*MEAS_COND_AXIS_NAME-34 "Monochromator slit"
*MEAS_COND_AXIS_NAME-35 "2-ThetaB"
*MEAS_COND_AXIS_NAME-36 "HV"
*MEAS_COND_AXIS_NAME-37 "PHA"
*MEAS_COND_AXIS_NAME_INTERNAL-0 "TwoThetaTheta"
*MEAS_COND_AXIS_NAME_INTERNAL-1 "TwoTheta"
*MEAS_COND_AXIS_NAME_INTERNAL-2 "Omega"
*MEAS_COND_AXIS_NAME_INTERNAL-3 "TwoThetaOmega"
*MEAS_COND_AXIS_NAME_INTERNAL-4 "Chi"
*MEAS_COND_AXIS_NAME_INTERNAL-5 "Phi"
*MEAS_COND_AXIS_NAME_INTERNAL-6 "TwoThetaChi"
*MEAS_COND_AXIS_NAME_INTERNAL-7 "TwoThetaChiPhi"
*MEAS_COND_AXIS_NAME_INTERNAL-8 "Alpha"
*MEAS_COND_AXIS_NAME_INTERNAL-9 "Beta"
*MEAS_COND_AXIS_NAME_INTERNAL-10 "Z"
*MEAS_COND_AXIS_NAME_INTERNAL-11 "Attenuator"
*MEAS_COND_AXIS_NAME_INTERNAL-12 "ThetaS"
*MEAS_COND_AXIS_NAME_INTERNAL-13 "ThetaD"
*MEAS_COND_AXIS_NAME_INTERNAL-14 "Ts"
*MEAS_COND_AXIS_NAME_INTERNAL-15 "CBO-M"
*MEAS_COND_AXIS_NAME_INTERNAL-16 "IncidentSlitBox"
*MEAS_COND_AXIS_NAME_INTERNAL-17 "IncidentSlitBox-_Axis"
*MEAS_COND_AXIS_NAME_INTERNAL-18 "Zs"
*MEAS_COND_AXIS_NAME_INTERNAL-19 "ReceivingSlitBox1"
*MEAS_COND_AXIS_NAME_INTERNAL-20 "ReceivingSlitBox1-_Axis"
*MEAS_COND_AXIS_NAME_INTERNAL-21 "ReceivingSlitBox2"
*MEAS_COND_AXIS_NAME_INTERNAL-22 "ReceivingSlitBox2-_Axis"
*MEAS_COND_AXIS_NAME_INTERNAL-23 "ReceivingSlitBox2-Zd"
*MEAS_COND_AXIS_NAME_INTERNAL-24 "CBO"
*MEAS_COND_AXIS_NAME_INTERNAL-25 "IncidentMonochromator"
*MEAS_COND_AXIS_NAME_INTERNAL-26 "IncidentSollerSlit"
*MEAS_COND_AXIS_NAME_INTERNAL-27 "IncidentAxdSlit"
*MEAS_COND_AXIS_NAME_INTERNAL-28 "CenterSlit"
*MEAS_COND_AXIS_NAME_INTERNAL-29 "Filter"
*MEAS_COND_AXIS_NAME_INTERNAL-30 "ReceivingOptics"
*MEAS_COND_AXIS_NAME_INTERNAL-31 "ReceivingSollerSlit"
*MEAS_COND_AXIS_NAME_INTERNAL-32 "ReceivingAxdSlit"
*MEAS_COND_AXIS_NAME_INTERNAL-33 "CounterMonochromator"
*MEAS_COND_AXIS_NAME_INTERNAL-34 "CounterSlit"
*MEAS_COND_AXIS_NAME_INTERNAL-35 "TwoThetaB"
*MEAS_COND_AXIS_NAME_INTERNAL-36 "HV"
*MEAS_COND_AXIS_NAME_INTERNAL-37 "PHA"
*MEAS_COND_AXIS_NAME_MAGICNO-0 "83951616.0000000000"
*MEAS_COND_AXIS_NAME_MAGICNO-1 "268632064.0000000000"
*MEAS_COND_AXIS_NAME_MAGICNO-2 "268500992.0000000000"
*MEAS_COND_AXIS_NAME_MAGICNO-3 "83951616.0000000000"
*MEAS_COND_AXIS_NAME_MAGICNO-4 "268500992.0000000000"
*MEAS_COND_AXIS_NAME_MAGICNO-5 "268500992.0000000000"
*MEAS_COND_AXIS_NAME_MAGICNO-6 "268632064.0000000000"
*MEAS_COND_AXIS_NAME_MAGICNO-7 "83951616.0000000000"
*MEAS_COND_AXIS_NAME_MAGICNO-8 "17039360.0000000000"
*MEAS_COND_AXIS_NAME_MAGICNO-9 "17039360.0000000000"
*MEAS_COND_AXIS_NAME_MAGICNO-10 "285278208.0000000000"
*MEAS_COND_AXIS_NAME_MAGICNO-11 "17301505.0000000000"
*MEAS_COND_AXIS_NAME_MAGICNO-12 "131072.0000000000"
*MEAS_COND_AXIS_NAME_MAGICNO-13 "131072.0000000000"
*MEAS_COND_AXIS_NAME_MAGICNO-14 "318898176.0000000000"
*MEAS_COND_AXIS_NAME_MAGICNO-15 "285343744.0000000000"
*MEAS_COND_AXIS_NAME_MAGICNO-16 "22020097.0000000000"
*MEAS_COND_AXIS_NAME_MAGICNO-17 "25165824.0000000000"
*MEAS_COND_AXIS_NAME_MAGICNO-18 "318898176.0000000000"
*MEAS_COND_AXIS_NAME_MAGICNO-19 "23068673.0000000000"
*MEAS_COND_AXIS_NAME_MAGICNO-20 "25165824.0000000000"
*MEAS_COND_AXIS_NAME_MAGICNO-21 "23068673.0000000000"
*MEAS_COND_AXIS_NAME_MAGICNO-22 "25165824.0000000000"
*MEAS_COND_AXIS_NAME_MAGICNO-23 "285343744.0000000000"
*MEAS_COND_AXIS_NAME_MAGICNO-24 "20971521.0000000000"
*MEAS_COND_AXIS_NAME_MAGICNO-25 "1.0000000000"
*MEAS_COND_AXIS_NAME_MAGICNO-26 "20971521.0000000000"
*MEAS_COND_AXIS_NAME_MAGICNO-27 "20971521.0000000000"
*MEAS_COND_AXIS_NAME_MAGICNO-28 "20971521.0000000000"
*MEAS_COND_AXIS_NAME_MAGICNO-29 "20971521.0000000000"
*MEAS_COND_AXIS_NAME_MAGICNO-30 "20971521.0000000000"
*MEAS_COND_AXIS_NAME_MAGICNO-31 "20971521.0000000000"
*MEAS_COND_AXIS_NAME_MAGICNO-32 "20971521.0000000000"
*MEAS_COND_AXIS_NAME_MAGICNO-33 "20971521.0000000000"
*MEAS_COND_AXIS_NAME_MAGICNO-34 "20971521.0000000000"
*MEAS_COND_AXIS_NAME_MAGICNO-35 "17039360.0000000000"
*MEAS_COND_AXIS_NAME_MAGICNO-36 "0.0000000000"
*MEAS_COND_AXIS_NAME_MAGICNO-37 "0.0000000000"
*MEAS_COND_AXIS_OFFSET-0 "-"
*MEAS_COND_AXIS_OFFSET-1 "0.6672000000"
*MEAS_COND_AXIS_OFFSET-2 "0.8653000000"
*MEAS_COND_AXIS_OFFSET-3 "-"
*MEAS_COND_AXIS_OFFSET-4 "0.0000000000"
*MEAS_COND_AXIS_OFFSET-5 "0.0000000000"
*MEAS_COND_AXIS_OFFSET-6 "0.0000000000"
*MEAS_COND_AXIS_OFFSET-7 "-"
*MEAS_COND_AXIS_OFFSET-8 "-"
*MEAS_COND_AXIS_OFFSET-9 "-"
*MEAS_COND_AXIS_OFFSET-10 "-"
*MEAS_COND_AXIS_OFFSET-11 "-"
*MEAS_COND_AXIS_OFFSET-12 "0.8653000000"
*MEAS_COND_AXIS_OFFSET-13 "-0.1981000000"
*MEAS_COND_AXIS_OFFSET-14 "-"
*MEAS_COND_AXIS_OFFSET-15 "-"
*MEAS_COND_AXIS_OFFSET-16 "-"
*MEAS_COND_AXIS_OFFSET-17 "-"
*MEAS_COND_AXIS_OFFSET-18 "-"
*MEAS_COND_AXIS_OFFSET-19 "-"
*MEAS_COND_AXIS_OFFSET-20 "-"
*MEAS_COND_AXIS_OFFSET-21 "-"
*MEAS_COND_AXIS_OFFSET-22 "-"
*MEAS_COND_AXIS_OFFSET-23 "-"
*MEAS_COND_AXIS_OFFSET-24 "-"
*MEAS_COND_AXIS_OFFSET-25 "-"
*MEAS_COND_AXIS_OFFSET-26 "-"
*MEAS_COND_AXIS_OFFSET-27 "-"
*MEAS_COND_AXIS_OFFSET-28 "-"
*MEAS_COND_AXIS_OFFSET-29 "-"
*MEAS_COND_AXIS_OFFSET-30 "-"
*MEAS_COND_AXIS_OFFSET-31 "-"
*MEAS_COND_AXIS_OFFSET-32 "-"
*MEAS_COND_AXIS_OFFSET-33 "-"
*MEAS_COND_AXIS_OFFSET-34 "-"
*MEAS_COND_AXIS_OFFSET-35 "-"
*MEAS_COND_AXIS_OFFSET-36 "-"
*MEAS_COND_AXIS_OFFSET-37 "-"
*MEAS_COND_AXIS_POSITION-0 "32.2446000000"
*MEAS_COND_AXIS_POSITION-1 "32.2446000000"
*MEAS_COND_AXIS_POSITION-2 "16.1223000000"
*MEAS_COND_AXIS_POSITION-3 "32.2446000000"
*MEAS_COND_AXIS_POSITION-4 "90.0000000000"
*MEAS_COND_AXIS_POSITION-5 "-2.5000000000"
*MEAS_COND_AXIS_POSITION-6 "0.0000000000"
*MEAS_COND_AXIS_POSITION-7 "0.0000000000"
*MEAS_COND_AXIS_POSITION-8 "90.0000000000"
*MEAS_COND_AXIS_POSITION-9 "-2.5000000000"
*MEAS_COND_AXIS_POSITION-10 "0.1194000000"
*MEAS_COND_AXIS_POSITION-11 "1/10000"
*MEAS_COND_AXIS_POSITION-12 "16.1223000000"
*MEAS_COND_AXIS_POSITION-13 "16.1223000000"
*MEAS_COND_AXIS_POSITION-14 "-1.2998100000"
*MEAS_COND_AXIS_POSITION-15 "0.0000000000"
*MEAS_COND_AXIS_POSITION-16 "1.000mm"
*MEAS_COND_AXIS_POSITION-17 "1.0000000000"
*MEAS_COND_AXIS_POSITION-18 "-2.0200000000"
*MEAS_COND_AXIS_POSITION-19 "10.000mm"
*MEAS_COND_AXIS_POSITION-20 "10.0000000000"
*MEAS_COND_AXIS_POSITION-21 "10.000mm"
*MEAS_COND_AXIS_POSITION-22 "10.0000000000"
*MEAS_COND_AXIS_POSITION-23 "-0.1168800000"
*MEAS_COND_AXIS_POSITION-24 "PB"
*MEAS_COND_AXIS_POSITION-25 "0.0000000000"
*MEAS_COND_AXIS_POSITION-26 "Soller_slit_5.0deg"
*MEAS_COND_AXIS_POSITION-27 "5.0mm"
*MEAS_COND_AXIS_POSITION-28 "None"
*MEAS_COND_AXIS_POSITION-29 "None"
*MEAS_COND_AXIS_POSITION-30 "PSA_open"
*MEAS_COND_AXIS_POSITION-31 "Soller_slit_5.0deg"
*MEAS_COND_AXIS_POSITION-32 "None"
*MEAS_COND_AXIS_POSITION-33 "None"
*MEAS_COND_AXIS_POSITION-34 "None"
*MEAS_COND_AXIS_POSITION-35 "32.2446000000"
*MEAS_COND_AXIS_POSITION-36 "681.5000000000"
*MEAS_COND_AXIS_POSITION-37 "505.0000000000"
*MEAS_COND_AXIS_UNIT-0 "deg"
*MEAS_COND_AXIS_UNIT-1 "deg"
*MEAS_COND_AXIS_UNIT-2 "deg"
*MEAS_COND_AXIS_UNIT-3 "deg"
*MEAS_COND_AXIS_UNIT-4 "deg"
*MEAS_COND_AXIS_UNIT-5 "deg"
*MEAS_COND_AXIS_UNIT-6 "deg"
*MEAS_COND_AXIS_UNIT-7 "deg"
*MEAS_COND_AXIS_UNIT-8 "deg"
*MEAS_COND_AXIS_UNIT-9 "deg"
*MEAS_COND_AXIS_UNIT-10 "mm"
*MEAS_COND_AXIS_UNIT-11 ""
*MEAS_COND_AXIS_UNIT-12 "deg"
*MEAS_COND_AXIS_UNIT-13 "deg"
*MEAS_COND_AXIS_UNIT-14 "mm"
*MEAS_COND_AXIS_UNIT-15 "pulse"
*MEAS_COND_AXIS_UNIT-16 ""
*MEAS_COND_AXIS_UNIT-17 "mm"
*MEAS_COND_AXIS_UNIT-18 "mm"
*MEAS_COND_AXIS_UNIT-19 ""
*MEAS_COND_AXIS_UNIT-20 "mm"
*MEAS_COND_AXIS_UNIT-21 ""
*MEAS_COND_AXIS_UNIT-22 "mm"
*MEAS_COND_AXIS_UNIT-23 "mm"
*MEAS_COND_AXIS_UNIT-24 ""
*MEAS_COND_AXIS_UNIT-25 ""
*MEAS_COND_AXIS_UNIT-26 ""
*MEAS_COND_AXIS_UNIT-27 ""
*MEAS_COND_AXIS_UNIT-28 ""
*MEAS_COND_AXIS_UNIT-29 ""
*MEAS_COND_AXIS_UNIT-30 ""
*MEAS_COND_AXIS_UNIT-31 ""
*MEAS_COND_AXIS_UNIT-32 ""
*MEAS_COND_AXIS_UNIT-33 ""
*MEAS_COND_AXIS_UNIT-34 ""
*MEAS_COND_AXIS_UNIT-35 "deg"
*MEAS_COND_AXIS_UNIT-36 "V"
*MEAS_COND_AXIS_UNIT-37 "mV"
*MEAS_COND_COUNTER_CNTLOSS_CORR "1.0000000000"
*MEAS_COND_COUNTER_PHABASE "505.0000000000"
*MEAS_COND_COUNTER_PHAWINDOW "950.0000000000"
*MEAS_COND_COUNTER_PHA_UNIT "mV"
*MEAS_COND_COUNTER_TAUDIFF "0.2366790000"
*MEAS_COND_COUNTER_TAUINT "0.5939810000"
*MEAS_COND_OPT_ATTR "Medium resolution parallel beam/RS"
*MEAS_COND_OPT_NAME "@Medium resolution PB"
*MEAS_COND_XG_CURRENT "36.0000000000"
*MEAS_COND_XG_VOLTAGE "60.0000000000"
*MEAS_COND_XG_WAVE_TYPE "Ka"
*MEAS_DATA_COUNT "73.0000000000"
*MEAS_SCAN_AXIS_X "Phi"
*MEAS_SCAN_AXIS_X_INTERNAL "Phi"
*MEAS_SCAN_MODE "CONTINUOUS"
*MEAS_SCAN_MONITOR "0"
*MEAS_SCAN_RESOLUTION_X "0.002"
*MEAS_SCAN_SPEED "200.000"
*MEAS_SCAN_SPEED_UNIT "deg/min"
*MEAS_SCAN_START "0.000"
*MEAS_SCAN_START_TIME "03/23/09 16:25:45"
*MEAS_SCAN_STEP "5.000"
*MEAS_SCAN_STOP "360.000"
*MEAS_SCAN_UNIT_X "deg"
*MEAS_SCAN_UNIT_Y "counts"
*RAS_HEADER_END
*RAS_INT_START
0.000 1522.000 1.000
5.000 1513.000 1.000
10.000 1532.000 1.000
15.000 1573.000 1.000
20.000 1606.000 1.000
25.000 1581.000 1.000
30.000 1629.000 1.000
35.000 1558.000 1.000
40.000 1575.000 1.000
45.000 1561.000 1.000
50.000 1663.000 1.000
55.000 1681.000 1.000
60.000 1634.000 1.000
65.000 1624.000 1.000
70.000 1563.000 1.000
75.000 1669.000 1.000
80.000 1625.000 1.000
85.000 1789.000 1.000
90.000 1758.000 1.000
95.000 1668.000 1.000
100.000 1569.000 1.000
105.000 1601.000 1.000
110.000 1546.000 1.000
115.000 1612.000 1.000
120.000 1649.000 1.000
125.000 1578.000 1.000
130.000 1573.000 1.000
135.000 1512.000 1.000
140.000 1528.000 1.000
145.000 1622.000 1.000
150.000 1558.000 1.000
155.000 1496.000 1.000
160.000 1546.000 1.000
165.000 1526.000 1.000
170.000 1554.000 1.000
175.000 1614.000 1.000
180.000 1600.000 1.000
185.000 1574.000 1.000
190.000 1609.000 1.000
195.000 1580.000 1.000
200.000 1581.000 1.000
205.000 1551.000 1.000
210.000 1594.000 1.000
215.000 1531.000 1.000
220.000 1574.000 1.000
225.000 1624.000 1.000
230.000 1591.000 1.000
235.000 1723.000 1.000
240.000 1599.000 1.000
245.000 1537.000 1.000
250.000 1590.000 1.000
255.000 1643.000 1.000
260.000 1677.000 1.000
265.000 1808.000 1.000
270.000 1747.000 1.000
275.000 1584.000 1.000
280.000 1627.000 1.000
285.000 1672.000 1.000
290.000 1548.000 1.000
295.000 1764.000 1.000
300.000 1857.000 1.000
305.000 1504.000 1.000
310.000 1571.000 1.000
315.000 1510.000 1.000
320.000 1540.000 1.000
325.000 1594.000 1.000
330.000 1592.000 1.000
335.000 1580.000 1.000
340.000 1519.000 1.000
345.000 1596.000 1.000
350.000 1592.000 1.000
355.000 1540.000 1.000
360.000 1527.000 1.000
*RAS_INT_END
*RAS_HEADER_START
*DISP_FMT_X "%.0f"
*DISP_FMT_Y "%.0f"
*DISP_FULLSCALE "4230.4000000000"
*DISP_LINE_COLOR "255.0000000000"
*DISP_LINE_STYLE "0.0000000000"
*DISP_LINE_WIDTH "0.2500000000"
*DISP_NOTE "Collected Data-2"
*DISP_OFFSET_Y "0.0000000000"
*DISP_PEAKSEARCH_UNIT_Y "cps"
*DISP_RANGE_BOTTOM "0.0000000000"
*DISP_RANGE_LEFT "0.0000000000"
*DISP_RANGE_LOGCUTOFF "0.0100000000"
*DISP_RANGE_RIGHT "360.0000000000"
*DISP_RANGE_TOP "4230.4000000000"
*DISP_SCALE_MODE_Y "0.0000000000"
*DISP_TAB_NAME "Phi"
*DISP_TITLE_Y "Intensity"
*DISP_UNIT_Y "cps"
*DISP_WINDOW_NAME "MSG_MACROENGINE"
*FILE_COMMENT " "
*FILE_DATA_TYPE "RAS_3DE_POLEFIG"
*FILE_MD5 ""
*FILE_MEMO "3-23-2009"
*FILE_OPERATOR "SmartLab_User"
*FILE_SAMPLE "am30 ED 25 10-10"
*FILE_TYPE "RAS_RAW"
*FILE_USERGROUP "System Manager"
*FILE_VERSION "1.0000000000"
*HW_ATTACHMENT_ID "ATT0025"
*HW_ATTACHMENT_NAME "Standard|Standard"
*HW_COUNTER_ID-0 "CUT0021"
*HW_COUNTER_ID-1 ""
*HW_COUNTER_ID-2 ""
*HW_COUNTER_ID-3 "CSL0021"
*HW_COUNTER_ID-4 "CMC0021"
*HW_COUNTER_NAME-0 "SC-70|SC-70"
*HW_COUNTER_NAME-1 ""
*HW_COUNTER_NAME-2 ""
*HW_COUNTER_NAME-3 "BBM|BBM"
*HW_COUNTER_NAME-4 "検出器モノクロメータ|Detector monochromator"
*HW_ECP_HV "681.5000000000"
*HW_ECP_HV_UNIT "V"
*HW_GONIOMETER_ID "GON0022"
*HW_GONIOMETER_NAME "SmartLab(インプレーン)|SmartLab(In-plane)"
*HW_GONIOMETER_RADIUS-0 "90.0"
*HW_GONIOMETER_RADIUS-1 "114.0"
*HW_GONIOMETER_RADIUS-2 "190.0"
*HW_GONIOMETER_RADIUS-3 "300.0"
*HW_GONIOMETER_RADIUS-4 "187.0"
*HW_GONIOMETER_RADIUS-5 "300.0"
*HW_GONIOMETER_RADIUS-6 "113.0"
*HW_GONIOMETER_RADIUS-7 "331.0"
*HW_I_OPT_ID-0 "CBO0021"
*HW_I_OPT_ID-1 "ICR0023"
*HW_I_OPT_ID-2 "ISL0021"
*HW_I_OPT_ID-3 "ISO0021"
*HW_I_OPT_ID-4 "IAD0021"
*HW_I_OPT_NAME-0 "CBOユニット|CBO unit"
*HW_I_OPT_NAME-1 "標準入射光学ユニット|Standard incident optical unit"
*HW_I_OPT_NAME-2 "標準入射スリットボックス|Standard incident slit box"
*HW_I_OPT_NAME-3 "入射平行スリット|Incident parallel slit"
*HW_I_OPT_NAME-4 "長手制限スリット|Length limiting slit"
*HW_R_ATTENUATER_AUTOMODE "1"
*HW_R_OPT_ID-0 "RSS0021"
*HW_R_OPT_ID-1 "RCR0022"
*HW_R_OPT_ID-2 "RSO0021"
*HW_R_OPT_ID-3 "RRS0021"
*HW_R_OPT_ID-4 "ATN0021"
*HW_R_OPT_ID-5 "RFL0021"
*HW_R_OPT_ID-6 "RAD0021"
*HW_R_OPT_NAME-0 "標準受光スリットボックス1|Standard receiving slit box # 1"
*HW_R_OPT_NAME-1 "標準受光光学ユニット1|Standard receiving unit # 1"
*HW_R_OPT_NAME-2 "標準受光光学ユニット2|Standard receiving optical unit # 2"
*HW_R_OPT_NAME-3 "標準受光スリットボックス2|Standard receiving slit box # 2"
*HW_R_OPT_NAME-4 "標準アッテネータ|Standard Attenuator"
*HW_R_OPT_NAME-5 "Cu Kβ|Cu K-beta"
*HW_R_OPT_NAME-6 "調整用受光スリット|Alignment receiving slit"
*HW_SAMPLE_HOLDER_ID "SMP0021"
*HW_SAMPLE_HOLDER_NAME "標準χクレードル|Std. chi cradle"
*HW_XG_CURRENT_MAX "60"
*HW_XG_CURRENT_MIN "2"
*HW_XG_CURRENT_RESOLUTION "1"
*HW_XG_CURRENT_UNIT "mA"
*HW_XG_FOCUS "1mm x 10mm"
*HW_XG_FOCUS_TYPE "Normal"
*HW_XG_ID ""
*HW_XG_NAME "3kW 封入管|3kW Sealed tube"
*HW_XG_TARGET_ATOMIC_NUMBER "29.0000000000"
*HW_XG_TARGET_NAME "Cu"
*HW_XG_TYPE "Hermetic"
*HW_XG_VOLTAGE_MAX "60"
*HW_XG_VOLTAGE_MIN "20"
*HW_XG_VOLTAGE_RESOLUTION "1"
*HW_XG_VOLTAGE_UNIT "kV"
*HW_XG_WATT_MAX "2"
*HW_XG_WATT_UNIT "kW"
*HW_XG_WAVE_LENGTH_ALPHA1 "1.540593"
*HW_XG_WAVE_LENGTH_ALPHA2 "1.544414"
*HW_XG_WAVE_LENGTH_BETA "1.392250"
*MEAS_3DE_ALPHA_ANGLE "5.0"
*MEAS_3DE_ALPHA_START "0.0"
*MEAS_3DE_ALPHA_STEP "5.0000"
*MEAS_3DE_ALPHA_STOP "90.0"
*MEAS_3DE_BG_HIGH_ANGLE "32.6165"
*MEAS_3DE_BG_HIGH_EXEC "1"
*MEAS_3DE_BG_HIGH_INT "725"
*MEAS_3DE_BG_HIGH_TIME "0.5"
*MEAS_3DE_BG_LOW_ANGLE "31.8726"
*MEAS_3DE_BG_LOW_EXEC "1"
*MEAS_3DE_BG_LOW_INT "814"
*MEAS_3DE_BG_LOW_TIME "0.5"
*MEAS_3DE_BG_MODE "2"
*MEAS_3DE_TWOTHETA_ANGLE "32.2446"
*MEAS_COND_AXIS_NAME-0 "Theta/2-Theta"
*MEAS_COND_AXIS_NAME-1 "2-Theta"
*MEAS_COND_AXIS_NAME-2 "Omega"
*MEAS_COND_AXIS_NAME-3 "2-Theta/Omega"
*MEAS_COND_AXIS_NAME-4 "Chi"
*MEAS_COND_AXIS_NAME-5 "Phi"
*MEAS_COND_AXIS_NAME-6 "2-ThetaChi"
*MEAS_COND_AXIS_NAME-7 "2-ThetaChi/Phi"
*MEAS_COND_AXIS_NAME-8 "Alpha"
*MEAS_COND_AXIS_NAME-9 "Beta"
*MEAS_COND_AXIS_NAME-10 "Z"
*MEAS_COND_AXIS_NAME-11 "Attenuator"
*MEAS_COND_AXIS_NAME-12 "Theta_s"
*MEAS_COND_AXIS_NAME-13 "Theta_d"
*MEAS_COND_AXIS_NAME-14 "Ts"
*MEAS_COND_AXIS_NAME-15 "M"
*MEAS_COND_AXIS_NAME-16 "Incident slit"
*MEAS_COND_AXIS_NAME-17 ""
*MEAS_COND_AXIS_NAME-18 "Zs"
*MEAS_COND_AXIS_NAME-19 "Receiving slit # 1"
*MEAS_COND_AXIS_NAME-20 ""
*MEAS_COND_AXIS_NAME-21 "Receiving slit # 2"
*MEAS_COND_AXIS_NAME-22 ""
*MEAS_COND_AXIS_NAME-23 "Zd"
*MEAS_COND_AXIS_NAME-24 "CBO selection slit"
*MEAS_COND_AXIS_NAME-25 "Incident monochromator"
*MEAS_COND_AXIS_NAME-26 "Incident parallel slit"
*MEAS_COND_AXIS_NAME-27 "Length limiting slit"
*MEAS_COND_AXIS_NAME-28 "Center slit"
*MEAS_COND_AXIS_NAME-29 "Filter"
*MEAS_COND_AXIS_NAME-30 "Recieving optical device"
*MEAS_COND_AXIS_NAME-31 "Receiving parallel slit"
*MEAS_COND_AXIS_NAME-32 "Alignment receiving slit"
*MEAS_COND_AXIS_NAME-33 "Diffracted beam monochromator"
*MEAS_COND_AXIS_NAME-34 "Monochromator slit"
*MEAS_COND_AXIS_NAME-35 "2-ThetaB"
*MEAS_COND_AXIS_NAME-36 "HV"
*MEAS_COND_AXIS_NAME-37 "PHA"
*MEAS_COND_AXIS_NAME_INTERNAL-0 "TwoThetaTheta"
*MEAS_COND_AXIS_NAME_INTERNAL-1 "TwoTheta"
*MEAS_COND_AXIS_NAME_INTERNAL-2 "Omega"
*MEAS_COND_AXIS_NAME_INTERNAL-3 "TwoThetaOmega"
*MEAS_COND_AXIS_NAME_INTERNAL-4 "Chi"
*MEAS_COND_AXIS_NAME_INTERNAL-5 "Phi"
*MEAS_COND_AXIS_NAME_INTERNAL-6 "TwoThetaChi"
*MEAS_COND_AXIS_NAME_INTERNAL-7 "TwoThetaChiPhi"
*MEAS_COND_AXIS_NAME_INTERNAL-8 "Alpha"
*MEAS_COND_AXIS_NAME_INTERNAL-9 "Beta"
*MEAS_COND_AXIS_NAME_INTERNAL-10 "Z"
*MEAS_COND_AXIS_NAME_INTERNAL-11 "Attenuator"
*MEAS_COND_AXIS_NAME_INTERNAL-12 "ThetaS"
*MEAS_COND_AXIS_NAME_INTERNAL-13 "ThetaD"
*MEAS_COND_AXIS_NAME_INTERNAL-14 "Ts"
*MEAS_COND_AXIS_NAME_INTERNAL-15 "CBO-M"
*MEAS_COND_AXIS_NAME_INTERNAL-16 "IncidentSlitBox"
*MEAS_COND_AXIS_NAME_INTERNAL-17 "IncidentSlitBox-_Axis"
*MEAS_COND_AXIS_NAME_INTERNAL-18 "Zs"
*MEAS_COND_AXIS_NAME_INTERNAL-19 "ReceivingSlitBox1"
*MEAS_COND_AXIS_NAME_INTERNAL-20 "ReceivingSlitBox1-_Axis"
*MEAS_COND_AXIS_NAME_INTERNAL-21 "ReceivingSlitBox2"
*MEAS_COND_AXIS_NAME_INTERNAL-22 "ReceivingSlitBox2-_Axis"
*MEAS_COND_AXIS_NAME_INTERNAL-23 "ReceivingSlitBox2-Zd"
*MEAS_COND_AXIS_NAME_INTERNAL-24 "CBO"
*MEAS_COND_AXIS_NAME_INTERNAL-25 "IncidentMonochromator"
*MEAS_COND_AXIS_NAME_INTERNAL-26 "IncidentSollerSlit"
*MEAS_COND_AXIS_NAME_INTERNAL-27 "IncidentAxdSlit"
*MEAS_COND_AXIS_NAME_INTERNAL-28 "CenterSlit"
*MEAS_COND_AXIS_NAME_INTERNAL-29 "Filter"
*MEAS_COND_AXIS_NAME_INTERNAL-30 "ReceivingOptics"
*MEAS_COND_AXIS_NAME_INTERNAL-31 "ReceivingSollerSlit"
*MEAS_COND_AXIS_NAME_INTERNAL-32 "ReceivingAxdSlit"
*MEAS_COND_AXIS_NAME_INTERNAL-33 "CounterMonochromator"
*MEAS_COND_AXIS_NAME_INTERNAL-34 "CounterSlit"
*MEAS_COND_AXIS_NAME_INTERNAL-35 "TwoThetaB"
*MEAS_COND_AXIS_NAME_INTERNAL-36 "HV"
*MEAS_COND_AXIS_NAME_INTERNAL-37 "PHA"
*MEAS_COND_AXIS_NAME_MAGICNO-0 "83951616.0000000000"
*MEAS_COND_AXIS_NAME_MAGICNO-1 "268632064.0000000000"
*MEAS_COND_AXIS_NAME_MAGICNO-2 "268500992.0000000000"
*MEAS_COND_AXIS_NAME_MAGICNO-3 "83951616.0000000000"
*MEAS_COND_AXIS_NAME_MAGICNO-4 "268500992.0000000000"
*MEAS_COND_AXIS_NAME_MAGICNO-5 "268500992.0000000000"
*MEAS_COND_AXIS_NAME_MAGICNO-6 "268632064.0000000000"
*MEAS_COND_AXIS_NAME_MAGICNO-7 "83951616.0000000000"
*MEAS_COND_AXIS_NAME_MAGICNO-8 "17039360.0000000000"
*MEAS_COND_AXIS_NAME_MAGICNO-9 "17039360.0000000000"
*MEAS_COND_AXIS_NAME_MAGICNO-10 "285278208.0000000000"
*MEAS_COND_AXIS_NAME_MAGICNO-11 "17301505.0000000000"
*MEAS_COND_AXIS_NAME_MAGICNO-12 "131072.0000000000"
*MEAS_COND_AXIS_NAME_MAGICNO-13 "131072.0000000000"
*MEAS_COND_AXIS_NAME_MAGICNO-14 "318898176.0000000000"
*MEAS_COND_AXIS_NAME_MAGICNO-15 "285343744.0000000000"
*MEAS_COND_AXIS_NAME_MAGICNO-16 "22020097.0000000000"
*MEAS_COND_AXIS_NAME_MAGICNO-17 "25165824.0000000000"
*MEAS_COND_AXIS_NAME_MAGICNO-18 "318898176.0000000000"
*MEAS_COND_AXIS_NAME_MAGICNO-19 "23068673.0000000000"
*MEAS_COND_AXIS_NAME_MAGICNO-20 "25165824.0000000000"
*MEAS_COND_AXIS_NAME_MAGICNO-21 "23068673.0000000000"
*MEAS_COND_AXIS_NAME_MAGICNO-22 "25165824.0000000000"
*MEAS_COND_AXIS_NAME_MAGICNO-23 "285343744.0000000000"
*MEAS_COND_AXIS_NAME_MAGICNO-24 "20971521.0000000000"
*MEAS_COND_AXIS_NAME_MAGICNO-25 "1.0000000000"
*MEAS_COND_AXIS_NAME_MAGICNO-26 "20971521.0000000000"
*MEAS_COND_AXIS_NAME_MAGICNO-27 "20971521.0000000000"
*MEAS_COND_AXIS_NAME_MAGICNO-28 "20971521.0000000000"
*MEAS_COND_AXIS_NAME_MAGICNO-29 "20971521.0000000000"
*MEAS_COND_AXIS_NAME_MAGICNO-30 "20971521.0000000000"
*MEAS_COND_AXIS_NAME_MAGICNO-31 "20971521.0000000000"
*MEAS_COND_AXIS_NAME_MAGICNO-32 "20971521.0000000000"
*MEAS_COND_AXIS_NAME_MAGICNO-33 "20971521.0000000000"
*MEAS_COND_AXIS_NAME_MAGICNO-34 "20971521.0000000000"
*MEAS_COND_AXIS_NAME_MAGICNO-35 "17039360.0000000000"
*MEAS_COND_AXIS_NAME_MAGICNO-36 "0.0000000000"
*MEAS_COND_AXIS_NAME_MAGICNO-37 "0.0000000000"
*MEAS_COND_AXIS_OFFSET-0 "-"
*MEAS_COND_AXIS_OFFSET-1 "0.6672000000"
*MEAS_COND_AXIS_OFFSET-2 "0.8653000000"
*MEAS_COND_AXIS_OFFSET-3 "-"
*MEAS_COND_AXIS_OFFSET-4 "0.0000000000"
*MEAS_COND_AXIS_OFFSET-5 "0.0000000000"
*MEAS_COND_AXIS_OFFSET-6 "0.0000000000"
*MEAS_COND_AXIS_OFFSET-7 "-"
*MEAS_COND_AXIS_OFFSET-8 "-"
*MEAS_COND_AXIS_OFFSET-9 "-"
*MEAS_COND_AXIS_OFFSET-10 "-"
*MEAS_COND_AXIS_OFFSET-11 "-"
*MEAS_COND_AXIS_OFFSET-12 "0.8653000000"
*MEAS_COND_AXIS_OFFSET-13 "-0.1981000000"
*MEAS_COND_AXIS_OFFSET-14 "-"
*MEAS_COND_AXIS_OFFSET-15 "-"
*MEAS_COND_AXIS_OFFSET-16 "-"
*MEAS_COND_AXIS_OFFSET-17 "-"
*MEAS_COND_AXIS_OFFSET-18 "-"
*MEAS_COND_AXIS_OFFSET-19 "-"
*MEAS_COND_AXIS_OFFSET-20 "-"
*MEAS_COND_AXIS_OFFSET-21 "-"
*MEAS_COND_AXIS_OFFSET-22 "-"
*MEAS_COND_AXIS_OFFSET-23 "-"
*MEAS_COND_AXIS_OFFSET-24 "-"
*MEAS_COND_AXIS_OFFSET-25 "-"
*MEAS_COND_AXIS_OFFSET-26 "-"
*MEAS_COND_AXIS_OFFSET-27 "-"
*MEAS_COND_AXIS_OFFSET-28 "-"
*MEAS_COND_AXIS_OFFSET-29 "-"
*MEAS_COND_AXIS_OFFSET-30 "-"
*MEAS_COND_AXIS_OFFSET-31 "-"
*MEAS_COND_AXIS_OFFSET-32 "-"
*MEAS_COND_AXIS_OFFSET-33 "-"
*MEAS_COND_AXIS_OFFSET-34 "-"
*MEAS_COND_AXIS_OFFSET-35 "-"
*MEAS_COND_AXIS_OFFSET-36 "-"
*MEAS_COND_AXIS_OFFSET-37 "-"
*MEAS_COND_AXIS_POSITION-0 "32.2446000000"
*MEAS_COND_AXIS_POSITION-1 "32.2446000000"
*MEAS_COND_AXIS_POSITION-2 "16.1223000000"
*MEAS_COND_AXIS_POSITION-3 "32.2446000000"
*MEAS_COND_AXIS_POSITION-4 "85.0000000000"
*MEAS_COND_AXIS_POSITION-5 "-2.5000000000"
*MEAS_COND_AXIS_POSITION-6 "0.0000000000"
*MEAS_COND_AXIS_POSITION-7 "0.0000000000"
*MEAS_COND_AXIS_POSITION-8 "90.0000000000"
*MEAS_COND_AXIS_POSITION-9 "-2.5000000000"
*MEAS_COND_AXIS_POSITION-10 "0.1194000000"
*MEAS_COND_AXIS_POSITION-11 "1/10000"
*MEAS_COND_AXIS_POSITION-12 "16.1223000000"
*MEAS_COND_AXIS_POSITION-13 "16.1223000000"
*MEAS_COND_AXIS_POSITION-14 "-1.2998100000"
*MEAS_COND_AXIS_POSITION-15 "0.0000000000"
*MEAS_COND_AXIS_POSITION-16 "1.000mm"
*MEAS_COND_AXIS_POSITION-17 "1.0000000000"
*MEAS_COND_AXIS_POSITION-18 "-2.0200000000"
*MEAS_COND_AXIS_POSITION-19 "10.000mm"
*MEAS_COND_AXIS_POSITION-20 "10.0000000000"
*MEAS_COND_AXIS_POSITION-21 "10.000mm"
*MEAS_COND_AXIS_POSITION-22 "10.0000000000"
*MEAS_COND_AXIS_POSITION-23 "-0.1168800000"
*MEAS_COND_AXIS_POSITION-24 "PB"
*MEAS_COND_AXIS_POSITION-25 "0.0000000000"
*MEAS_COND_AXIS_POSITION-26 "Soller_slit_5.0deg"
*MEAS_COND_AXIS_POSITION-27 "5.0mm"
*MEAS_COND_AXIS_POSITION-28 "None"
*MEAS_COND_AXIS_POSITION-29 "None"
*MEAS_COND_AXIS_POSITION-30 "PSA_open"
*MEAS_COND_AXIS_POSITION-31 "Soller_slit_5.0deg"
*MEAS_COND_AXIS_POSITION-32 "None"
*MEAS_COND_AXIS_POSITION-33 "None"
*MEAS_COND_AXIS_POSITION-34 "None"
*MEAS_COND_AXIS_POSITION-35 "32.2446000000"
*MEAS_COND_AXIS_POSITION-36 "681.5000000000"
*MEAS_COND_AXIS_POSITION-37 "505.0000000000"
*MEAS_COND_AXIS_UNIT-0 "deg"
*MEAS_COND_AXIS_UNIT-1 "deg"
*MEAS_COND_AXIS_UNIT-2 "deg"
*MEAS_COND_AXIS_UNIT-3 "deg"
*MEAS_COND_AXIS_UNIT-4 "deg"
*MEAS_COND_AXIS_UNIT-5 "deg"
*MEAS_COND_AXIS_UNIT-6 "deg"
*MEAS_COND_AXIS_UNIT-7 "deg"
*MEAS_COND_AXIS_UNIT-8 "deg"
*MEAS_COND_AXIS_UNIT-9 "deg"
*MEAS_COND_AXIS_UNIT-10 "mm"
*MEAS_COND_AXIS_UNIT-11 ""
*MEAS_COND_AXIS_UNIT-12 "deg"
*MEAS_COND_AXIS_UNIT-13 "deg"
*MEAS_COND_AXIS_UNIT-14 "mm"
*MEAS_COND_AXIS_UNIT-15 "pulse"
*MEAS_COND_AXIS_UNIT-16 ""
*MEAS_COND_AXIS_UNIT-17 "mm"
*MEAS_COND_AXIS_UNIT-18 "mm"
*MEAS_COND_AXIS_UNIT-19 ""
*MEAS_COND_AXIS_UNIT-20 "mm"
*MEAS_COND_AXIS_UNIT-21 ""
*MEAS_COND_AXIS_UNIT-22 "mm"
*MEAS_COND_AXIS_UNIT-23 "mm"
*MEAS_COND_AXIS_UNIT-24 ""
*MEAS_COND_AXIS_UNIT-25 ""
*MEAS_COND_AXIS_UNIT-26 ""
*MEAS_COND_AXIS_UNIT-27 ""
*MEAS_COND_AXIS_UNIT-28 ""
*MEAS_COND_AXIS_UNIT-29 ""
*MEAS_COND_AXIS_UNIT-30 ""
*MEAS_COND_AXIS_UNIT-31 ""
*MEAS_COND_AXIS_UNIT-32 ""
*MEAS_COND_AXIS_UNIT-33 ""
*MEAS_COND_AXIS_UNIT-34 ""
*MEAS_COND_AXIS_UNIT-35 "deg"
*MEAS_COND_AXIS_UNIT-36 "V"
*MEAS_COND_AXIS_UNIT-37 "mV"
*MEAS_COND_COUNTER_CNTLOSS_CORR "1.0000000000"
*MEAS_COND_COUNTER_PHABASE "505.0000000000"
*MEAS_COND_COUNTER_PHAWINDOW "950.0000000000"
*MEAS_COND_COUNTER_PHA_UNIT "mV"
*MEAS_COND_COUNTER_TAUDIFF "0.2366790000"
*MEAS_COND_COUNTER_TAUINT "0.5939810000"
*MEAS_COND_OPT_ATTR "Medium resolution parallel beam/RS"
*MEAS_COND_OPT_NAME "@Medium resolution PB"
*MEAS_COND_XG_CURRENT "36.0000000000"
*MEAS_COND_XG_VOLTAGE "60.0000000000"
*MEAS_COND_XG_WAVE_TYPE "Ka"
*MEAS_DATA_COUNT "73.0000000000"
*MEAS_SCAN_AXIS_X "Phi"
*MEAS_SCAN_AXIS_X_INTERNAL "Phi"
*MEAS_SCAN_MODE "CONTINUOUS"
*MEAS_SCAN_MONITOR "0"
*MEAS_SCAN_RESOLUTION_X "0.002"
*MEAS_SCAN_SPEED "200.000"
*MEAS_SCAN_SPEED_UNIT "deg/min"
*MEAS_SCAN_START "0.000"
*MEAS_SCAN_START_TIME "03/23/09 16:28:33"
*MEAS_SCAN_STEP "5.000"
*MEAS_SCAN_STOP "360.000"
*MEAS_SCAN_UNIT_X "deg"
*MEAS_SCAN_UNIT_Y "counts"
*RAS_HEADER_END
*RAS_INT_START
0.000 2551.000 1.000
5.000 2438.000 1.000
10.000 2433.000 1.000
15.000 2736.000 1.000
20.000 2965.000 1.000
25.000 3382.000 1.000
30.000 3077.000 1.000
35.000 2753.000 1.000
40.000 3022.000 1.000
45.000 3451.000 1.000
50.000 3105.000 1.000
55.000 3118.000 1.000
60.000 4182.000 1.000
65.000 2508.000 1.000
70.000 2803.000 1.000
75.000 3193.000 1.000
80.000 3919.000 1.000
85.000 5079.000 1.000
90.000 4626.000 1.000
95.000 3477.000 1.000
100.000 3020.000 1.000
105.000 2763.000 1.000
110.000 3981.000 1.000
115.000 5288.000 1.000
120.000 2706.000 1.000
125.000 2400.000 1.000
130.000 2405.000 1.000
135.000 2481.000 1.000
140.000 2639.000 1.000
145.000 2896.000 1.000
150.000 2845.000 1.000
155.000 2304.000 1.000
160.000 2446.000 1.000
165.000 2430.000 1.000
170.000 2540.000 1.000
175.000 2528.000 1.000
180.000 2279.000 1.000
185.000 2442.000 1.000
190.000 2321.000 1.000
195.000 2575.000 1.000
200.000 2892.000 1.000
205.000 3063.000 1.000
210.000 2973.000 1.000
215.000 2485.000 1.000
220.000 2426.000 1.000
225.000 2511.000 1.000
230.000 2760.000 1.000
235.000 4771.000 1.000
240.000 3288.000 1.000
245.000 2456.000 1.000
250.000 2698.000 1.000
255.000 2943.000 1.000
260.000 3531.000 1.000
265.000 4555.000 1.000
270.000 4351.000 1.000
275.000 2971.000 1.000
280.000 3118.000 1.000
285.000 3577.000 1.000
290.000 3731.000 1.000
295.000 3713.000 1.000
300.000 3354.000 1.000
305.000 2405.000 1.000
310.000 2314.000 1.000
315.000 2407.000 1.000
320.000 2662.000 1.000
325.000 2824.000 1.000
330.000 2783.000 1.000
335.000 2538.000 1.000
340.000 2313.000 1.000
345.000 2737.000 1.000
350.000 2375.000 1.000
355.000 2470.000 1.000
360.000 2615.000 1.000
*RAS_INT_END
*RAS_HEADER_START
*DISP_FMT_X "%.0f"
*DISP_FMT_Y "%.0f"
*DISP_FULLSCALE "8164.0000000000"
*DISP_LINE_COLOR "255.0000000000"
*DISP_LINE_STYLE "0.0000000000"
*DISP_LINE_WIDTH "0.2500000000"
*DISP_NOTE "Collected Data-3"
*DISP_OFFSET_Y "0.0000000000"
*DISP_PEAKSEARCH_UNIT_Y "cps"
*DISP_RANGE_BOTTOM "0.0000000000"
*DISP_RANGE_LEFT "0.0000000000"
*DISP_RANGE_LOGCUTOFF "0.0100000000"
*DISP_RANGE_RIGHT "360.0000000000"
*DISP_RANGE_TOP "8164.0000000000"
*DISP_SCALE_MODE_Y "0.0000000000"
*DISP_TAB_NAME "Phi"
*DISP_TITLE_Y "Intensity"
*DISP_UNIT_Y "cps"
*DISP_WINDOW_NAME "MSG_MACROENGINE"
*FILE_COMMENT " "
*FILE_DATA_TYPE "RAS_3DE_POLEFIG"
*FILE_MD5 ""
*FILE_MEMO "3-23-2009"
*FILE_OPERATOR "SmartLab_User"
*FILE_SAMPLE "am30 ED 25 10-10"
*FILE_TYPE "RAS_RAW"
*FILE_USERGROUP "System Manager"
*FILE_VERSION "1.0000000000"
*HW_ATTACHMENT_ID "ATT0025"
*HW_ATTACHMENT_NAME "Standard|Standard"
*HW_COUNTER_ID-0 "CUT0021"
*HW_COUNTER_ID-1 ""
*HW_COUNTER_ID-2 ""
*HW_COUNTER_ID-3 "CSL0021"
*HW_COUNTER_ID-4 "CMC0021"
*HW_COUNTER_NAME-0 "SC-70|SC-70"
*HW_COUNTER_NAME-1 ""
*HW_COUNTER_NAME-2 ""
*HW_COUNTER_NAME-3 "BBM|BBM"
*HW_COUNTER_NAME-4 "検出器モノクロメータ|Detector monochromator"
*HW_ECP_HV "681.5000000000"
*HW_ECP_HV_UNIT "V"
*HW_GONIOMETER_ID "GON0022"
*HW_GONIOMETER_NAME "SmartLab(インプレーン)|SmartLab(In-plane)"
*HW_GONIOMETER_RADIUS-0 "90.0"
*HW_GONIOMETER_RADIUS-1 "114.0"
*HW_GONIOMETER_RADIUS-2 "190.0"
*HW_GONIOMETER_RADIUS-3 "300.0"
*HW_GONIOMETER_RADIUS-4 "187.0"
*HW_GONIOMETER_RADIUS-5 "300.0"
*HW_GONIOMETER_RADIUS-6 "113.0"
*HW_GONIOMETER_RADIUS-7 "331.0"
*HW_I_OPT_ID-0 "CBO0021"
*HW_I_OPT_ID-1 "ICR0023"
*HW_I_OPT_ID-2 "ISL0021"
*HW_I_OPT_ID-3 "ISO0021"
*HW_I_OPT_ID-4 "IAD0021"
*HW_I_OPT_NAME-0 "CBOユニット|CBO unit"
*HW_I_OPT_NAME-1 "標準入射光学ユニット|Standard incident optical unit"
*HW_I_OPT_NAME-2 "標準入射スリットボックス|Standard incident slit box"
*HW_I_OPT_NAME-3 "入射平行スリット|Incident parallel slit"
*HW_I_OPT_NAME-4 "長手制限スリット|Length limiting slit"
*HW_R_ATTENUATER_AUTOMODE "1"
*HW_R_OPT_ID-0 "RSS0021"
*HW_R_OPT_ID-1 "RCR0022"
*HW_R_OPT_ID-2 "RSO0021"
*HW_R_OPT_ID-3 "RRS0021"
*HW_R_OPT_ID-4 "ATN0021"
*HW_R_OPT_ID-5 "RFL0021"
*HW_R_OPT_ID-6 "RAD0021"
*HW_R_OPT_NAME-0 "標準受光スリットボックス1|Standard receiving slit box # 1"
*HW_R_OPT_NAME-1 "標準受光光学ユニット1|Standard receiving unit # 1"
*HW_R_OPT_NAME-2 "標準受光光学ユニット2|Standard receiving optical unit # 2"
*HW_R_OPT_NAME-3 "標準受光スリットボックス2|Standard receiving slit box # 2"
*HW_R_OPT_NAME-4 "標準アッテネータ|Standard Attenuator"
*HW_R_OPT_NAME-5 "Cu Kβ|Cu K-beta"
*HW_R_OPT_NAME-6 "調整用受光スリット|Alignment receiving slit"
*HW_SAMPLE_HOLDER_ID "SMP0021"
*HW_SAMPLE_HOLDER_NAME "標準χクレードル|Std. chi cradle"
*HW_XG_CURRENT_MAX "60"
*HW_XG_CURRENT_MIN "2"
*HW_XG_CURRENT_RESOLUTION "1"
*HW_XG_CURRENT_UNIT "mA"
*HW_XG_FOCUS "1mm x 10mm"
*HW_XG_FOCUS_TYPE "Normal"
*HW_XG_ID ""
*HW_XG_NAME "3kW 封入管|3kW Sealed tube"
*HW_XG_TARGET_ATOMIC_NUMBER "29.0000000000"
*HW_XG_TARGET_NAME "Cu"
*HW_XG_TYPE "Hermetic"
*HW_XG_VOLTAGE_MAX "60"
*HW_XG_VOLTAGE_MIN "20"
*HW_XG_VOLTAGE_RESOLUTION "1"
*HW_XG_VOLTAGE_UNIT "kV"
*HW_XG_WATT_MAX "2"
*HW_XG_WATT_UNIT "kW"
*HW_XG_WAVE_LENGTH_ALPHA1 "1.540593"
*HW_XG_WAVE_LENGTH_ALPHA2 "1.544414"
*HW_XG_WAVE_LENGTH_BETA "1.392250"
*MEAS_3DE_ALPHA_ANGLE "10.0"
*MEAS_3DE_ALPHA_START "0.0"
*MEAS_3DE_ALPHA_STEP "5.0000"
*MEAS_3DE_ALPHA_STOP "90.0"
*MEAS_3DE_BG_HIGH_ANGLE "32.6165"
*MEAS_3DE_BG_HIGH_EXEC "1"
*MEAS_3DE_BG_HIGH_INT "1081"
*MEAS_3DE_BG_HIGH_TIME "0.5"
*MEAS_3DE_BG_LOW_ANGLE "31.8726"
*MEAS_3DE_BG_LOW_EXEC "1"
*MEAS_3DE_BG_LOW_INT "1140"
*MEAS_3DE_BG_LOW_TIME "0.5"
*MEAS_3DE_BG_MODE "2"
*MEAS_3DE_TWOTHETA_ANGLE "32.2446"
*MEAS_COND_AXIS_NAME-0 "Theta/2-Theta"
*MEAS_COND_AXIS_NAME-1 "2-Theta"
*MEAS_COND_AXIS_NAME-2 "Omega"
*MEAS_COND_AXIS_NAME-3 "2-Theta/Omega"
*MEAS_COND_AXIS_NAME-4 "Chi"
*MEAS_COND_AXIS_NAME-5 "Phi"
*MEAS_COND_AXIS_NAME-6 "2-ThetaChi"
*MEAS_COND_AXIS_NAME-7 "2-ThetaChi/Phi"
*MEAS_COND_AXIS_NAME-8 "Alpha"
*MEAS_COND_AXIS_NAME-9 "Beta"
*MEAS_COND_AXIS_NAME-10 "Z"
*MEAS_COND_AXIS_NAME-11 "Attenuator"
*MEAS_COND_AXIS_NAME-12 "Theta_s"
*MEAS_COND_AXIS_NAME-13 "Theta_d"
*MEAS_COND_AXIS_NAME-14 "Ts"
*MEAS_COND_AXIS_NAME-15 "M"
*MEAS_COND_AXIS_NAME-16 "Incident slit"
*MEAS_COND_AXIS_NAME-17 ""
*MEAS_COND_AXIS_NAME-18 "Zs"
*MEAS_COND_AXIS_NAME-19 "Receiving slit # 1"
*MEAS_COND_AXIS_NAME-20 ""
*MEAS_COND_AXIS_NAME-21 "Receiving slit # 2"
*MEAS_COND_AXIS_NAME-22 ""
*MEAS_COND_AXIS_NAME-23 "Zd"
*MEAS_COND_AXIS_NAME-24 "CBO selection slit"
*MEAS_COND_AXIS_NAME-25 "Incident monochromator"
*MEAS_COND_AXIS_NAME-26 "Incident parallel slit"
*MEAS_COND_AXIS_NAME-27 "Length limiting slit"
*MEAS_COND_AXIS_NAME-28 "Center slit"
*MEAS_COND_AXIS_NAME-29 "Filter"
*MEAS_COND_AXIS_NAME-30 "Recieving optical device"
*MEAS_COND_AXIS_NAME-31 "Receiving parallel slit"
*MEAS_COND_AXIS_NAME-32 "Alignment receiving slit"
*MEAS_COND_AXIS_NAME-33 "Diffracted beam monochromator"
*MEAS_COND_AXIS_NAME-34 "Monochromator slit"
*MEAS_COND_AXIS_NAME-35 "2-ThetaB"
*MEAS_COND_AXIS_NAME-36 "HV"
*MEAS_COND_AXIS_NAME-37 "PHA"
*MEAS_COND_AXIS_NAME_INTERNAL-0 "TwoThetaTheta"
*MEAS_COND_AXIS_NAME_INTERNAL-1 "TwoTheta"
*MEAS_COND_AXIS_NAME_INTERNAL-2 "Omega"
*MEAS_COND_AXIS_NAME_INTERNAL-3 "TwoThetaOmega"
*MEAS_COND_AXIS_NAME_INTERNAL-4 "Chi"
*MEAS_COND_AXIS_NAME_INTERNAL-5 "Phi"
*MEAS_COND_AXIS_NAME_INTERNAL-6 "TwoThetaChi"
*MEAS_COND_AXIS_NAME_INTERNAL-7 "TwoThetaChiPhi"
*MEAS_COND_AXIS_NAME_INTERNAL-8 "Alpha"
*MEAS_COND_AXIS_NAME_INTERNAL-9 "Beta"
*MEAS_COND_AXIS_NAME_INTERNAL-10 "Z"
*MEAS_COND_AXIS_NAME_INTERNAL-11 "Attenuator"
*MEAS_COND_AXIS_NAME_INTERNAL-12 "ThetaS"
*MEAS_COND_AXIS_NAME_INTERNAL-13 "ThetaD"
*MEAS_COND_AXIS_NAME_INTERNAL-14 "Ts"
*MEAS_COND_AXIS_NAME_INTERNAL-15 "CBO-M"
*MEAS_COND_AXIS_NAME_INTERNAL-16 "IncidentSlitBox"
*MEAS_COND_AXIS_NAME_INTERNAL-17 "IncidentSlitBox-_Axis"
*MEAS_COND_AXIS_NAME_INTERNAL-18 "Zs"
*MEAS_COND_AXIS_NAME_INTERNAL-19 "ReceivingSlitBox1"
*MEAS_COND_AXIS_NAME_INTERNAL-20 "ReceivingSlitBox1-_Axis"
*MEAS_COND_AXIS_NAME_INTERNAL-21 "ReceivingSlitBox2"
*MEAS_COND_AXIS_NAME_INTERNAL-22 "ReceivingSlitBox2-_Axis"
*MEAS_COND_AXIS_NAME_INTERNAL-23 "ReceivingSlitBox2-Zd"
*MEAS_COND_AXIS_NAME_INTERNAL-24 "CBO"
*MEAS_COND_AXIS_NAME_INTERNAL-25 "IncidentMonochromator"
*MEAS_COND_AXIS_NAME_INTERNAL-26 "IncidentSollerSlit"
*MEAS_COND_AXIS_NAME_INTERNAL-27 "IncidentAxdSlit"
*MEAS_COND_AXIS_NAME_INTERNAL-28 "CenterSlit"
*MEAS_COND_AXIS_NAME_INTERNAL-29 "Filter"
*MEAS_COND_AXIS_NAME_INTERNAL-30 "ReceivingOptics"
*MEAS_COND_AXIS_NAME_INTERNAL-31 "ReceivingSollerSlit"
*MEAS_COND_AXIS_NAME_INTERNAL-32 "ReceivingAxdSlit"
*MEAS_COND_AXIS_NAME_INTERNAL-33 "CounterMonochromator"
*MEAS_COND_AXIS_NAME_INTERNAL-34 "CounterSlit"
*MEAS_COND_AXIS_NAME_INTERNAL-35 "TwoThetaB"
*MEAS_COND_AXIS_NAME_INTERNAL-36 "HV"
*MEAS_COND_AXIS_NAME_INTERNAL-37 "PHA"
*MEAS_COND_AXIS_NAME_MAGICNO-0 "83951616.0000000000"
*MEAS_COND_AXIS_NAME_MAGICNO-1 "268632064.0000000000"
*MEAS_COND_AXIS_NAME_MAGICNO-2 "268500992.0000000000"
*MEAS_COND_AXIS_NAME_MAGICNO-3 "83951616.0000000000"
*MEAS_COND_AXIS_NAME_MAGICNO-4 "268500992.0000000000"
*MEAS_COND_AXIS_NAME_MAGICNO-5 "268500992.0000000000"
*MEAS_COND_AXIS_NAME_MAGICNO-6 "268632064.0000000000"
*MEAS_COND_AXIS_NAME_MAGICNO-7 "83951616.0000000000"
*MEAS_COND_AXIS_NAME_MAGICNO-8 "17039360.0000000000"
*MEAS_COND_AXIS_NAME_MAGICNO-9 "17039360.0000000000"
*MEAS_COND_AXIS_NAME_MAGICNO-10 "285278208.0000000000"
*MEAS_COND_AXIS_NAME_MAGICNO-11 "17301505.0000000000"
*MEAS_COND_AXIS_NAME_MAGICNO-12 "131072.0000000000"
*MEAS_COND_AXIS_NAME_MAGICNO-13 "131072.0000000000"
*MEAS_COND_AXIS_NAME_MAGICNO-14 "318898176.0000000000"
*MEAS_COND_AXIS_NAME_MAGICNO-15 "285343744.0000000000"
*MEAS_COND_AXIS_NAME_MAGICNO-16 "22020097.0000000000"
*MEAS_COND_AXIS_NAME_MAGICNO-17 "25165824.0000000000"
*MEAS_COND_AXIS_NAME_MAGICNO-18 "318898176.0000000000"
*MEAS_COND_AXIS_NAME_MAGICNO-19 "23068673.0000000000"
*MEAS_COND_AXIS_NAME_MAGICNO-20 "25165824.0000000000"
*MEAS_COND_AXIS_NAME_MAGICNO-21 "23068673.0000000000"
*MEAS_COND_AXIS_NAME_MAGICNO-22 "25165824.0000000000"
*MEAS_COND_AXIS_NAME_MAGICNO-23 "285343744.0000000000"
*MEAS_COND_AXIS_NAME_MAGICNO-24 "20971521.0000000000"
*MEAS_COND_AXIS_NAME_MAGICNO-25 "1.0000000000"
*MEAS_COND_AXIS_NAME_MAGICNO-26 "20971521.0000000000"
*MEAS_COND_AXIS_NAME_MAGICNO-27 "20971521.0000000000"
*MEAS_COND_AXIS_NAME_MAGICNO-28 "20971521.0000000000"
*MEAS_COND_AXIS_NAME_MAGICNO-29 "20971521.0000000000"
*MEAS_COND_AXIS_NAME_MAGICNO-30 "20971521.0000000000"
*MEAS_COND_AXIS_NAME_MAGICNO-31 "20971521.0000000000"
*MEAS_COND_AXIS_NAME_MAGICNO-32 "20971521.0000000000"
*MEAS_COND_AXIS_NAME_MAGICNO-33 "20971521.0000000000"
*MEAS_COND_AXIS_NAME_MAGICNO-34 "20971521.0000000000"
*MEAS_COND_AXIS_NAME_MAGICNO-35 "17039360.0000000000"
*MEAS_COND_AXIS_NAME_MAGICNO-36 "0.0000000000"
*MEAS_COND_AXIS_NAME_MAGICNO-37 "0.0000000000"
*MEAS_COND_AXIS_OFFSET-0 "-"
*MEAS_COND_AXIS_OFFSET-1 "0.6672000000"
*MEAS_COND_AXIS_OFFSET-2 "0.8653000000"
*MEAS_COND_AXIS_OFFSET-3 "-"
*MEAS_COND_AXIS_OFFSET-4 "0.0000000000"
*MEAS_COND_AXIS_OFFSET-5 "0.0000000000"
*MEAS_COND_AXIS_OFFSET-6 "0.0000000000"
*MEAS_COND_AXIS_OFFSET-7 "-"
*MEAS_COND_AXIS_OFFSET-8 "-"
*MEAS_COND_AXIS_OFFSET-9 "-"
*MEAS_COND_AXIS_OFFSET-10 "-"
*MEAS_COND_AXIS_OFFSET-11 "-"
*MEAS_COND_AXIS_OFFSET-12 "0.8653000000"
*MEAS_COND_AXIS_OFFSET-13 "-0.1981000000"
*MEAS_COND_AXIS_OFFSET-14 "-"
*MEAS_COND_AXIS_OFFSET-15 "-"
*MEAS_COND_AXIS_OFFSET-16 "-"
*MEAS_COND_AXIS_OFFSET-17 "-"
*MEAS_COND_AXIS_OFFSET-18 "-"
*MEAS_COND_AXIS_OFFSET-19 "-"
*MEAS_COND_AXIS_OFFSET-20 "-"
*MEAS_COND_AXIS_OFFSET-21 "-"
*MEAS_COND_AXIS_OFFSET-22 "-"
*MEAS_COND_AXIS_OFFSET-23 "-"
[...]
*MEAS_COND_AXIS_POSITION-14 "-1.2998100000"
*MEAS_COND_AXIS_POSITION-15 "0.0000000000"
*MEAS_COND_AXIS_POSITION-16 "1.000mm"
*MEAS_COND_AXIS_POSITION-17 "1.0000000000"
*MEAS_COND_AXIS_POSITION-18 "-2.0200000000"
*MEAS_COND_AXIS_POSITION-19 "10.000mm"
*MEAS_COND_AXIS_POSITION-20 "10.0000000000"
*MEAS_COND_AXIS_POSITION-21 "10.000mm"
*MEAS_COND_AXIS_POSITION-22 "10.0000000000"
*MEAS_COND_AXIS_POSITION-23 "-0.1168800000"
*MEAS_COND_AXIS_POSITION-24 "PB"
*MEAS_COND_AXIS_POSITION-25 "0.0000000000"
*MEAS_COND_AXIS_POSITION-26 "Soller_slit_5.0deg"
*MEAS_COND_AXIS_POSITION-27 "5.0mm"
*MEAS_COND_AXIS_POSITION-28 "None"
*MEAS_COND_AXIS_POSITION-29 "None"
*MEAS_COND_AXIS_POSITION-30 "PSA_open"
*MEAS_COND_AXIS_POSITION-31 "Soller_slit_5.0deg"
*MEAS_COND_AXIS_POSITION-32 "None"
*MEAS_COND_AXIS_POSITION-33 "None"
*MEAS_COND_AXIS_POSITION-34 "None"
*MEAS_COND_AXIS_POSITION-35 "32.2446000000"
*MEAS_COND_AXIS_POSITION-36 "681.5000000000"
*MEAS_COND_AXIS_POSITION-37 "505.0000000000"
*MEAS_COND_AXIS_UNIT-0 "deg"
*MEAS_COND_AXIS_UNIT-1 "deg"
*MEAS_COND_AXIS_UNIT-2 "deg"
*MEAS_COND_AXIS_UNIT-3 "deg"
*MEAS_COND_AXIS_UNIT-4 "deg"
*MEAS_COND_AXIS_UNIT-5 "deg"
*MEAS_COND_AXIS_UNIT-6 "deg"
*MEAS_COND_AXIS_UNIT-7 "deg"
*MEAS_COND_AXIS_UNIT-8 "deg"
*MEAS_COND_AXIS_UNIT-9 "deg"
*MEAS_COND_AXIS_UNIT-10 "mm"
*MEAS_COND_AXIS_UNIT-11 ""
*MEAS_COND_AXIS_UNIT-12 "deg"
*MEAS_COND_AXIS_UNIT-13 "deg"
*MEAS_COND_AXIS_UNIT-14 "mm"
*MEAS_COND_AXIS_UNIT-15 "pulse"
*MEAS_COND_AXIS_UNIT-16 ""
*MEAS_COND_AXIS_UNIT-17 "mm"
*MEAS_COND_AXIS_UNIT-18 "mm"
*MEAS_COND_AXIS_UNIT-19 ""
*MEAS_COND_AXIS_UNIT-20 "mm"
*MEAS_COND_AXIS_UNIT-21 ""
*MEAS_COND_AXIS_UNIT-22 "mm"
*MEAS_COND_AXIS_UNIT-23 "mm"
*MEAS_COND_AXIS_UNIT-24 ""
*MEAS_COND_AXIS_UNIT-25 ""
*MEAS_COND_AXIS_UNIT-26 ""
*MEAS_COND_AXIS_UNIT-27 ""
*MEAS_COND_AXIS_UNIT-28 ""
*MEAS_COND_AXIS_UNIT-29 ""
*MEAS_COND_AXIS_UNIT-30 ""
*MEAS_COND_AXIS_UNIT-31 ""
*MEAS_COND_AXIS_UNIT-32 ""
*MEAS_COND_AXIS_UNIT-33 ""
*MEAS_COND_AXIS_UNIT-34 ""
*MEAS_COND_AXIS_UNIT-35 "deg"
*MEAS_COND_AXIS_UNIT-36 "V"
*MEAS_COND_AXIS_UNIT-37 "mV"
*MEAS_COND_COUNTER_CNTLOSS_CORR "1.0000000000"
*MEAS_COND_COUNTER_PHABASE "505.0000000000"
*MEAS_COND_COUNTER_PHAWINDOW "950.0000000000"
*MEAS_COND_COUNTER_PHA_UNIT "mV"
*MEAS_COND_COUNTER_TAUDIFF "0.2366790000"
*MEAS_COND_COUNTER_TAUINT "0.5939810000"
*MEAS_COND_OPT_ATTR "Medium resolution parallel beam/RS"
*MEAS_COND_OPT_NAME "@Medium resolution PB"
*MEAS_COND_XG_CURRENT "36.0000000000"
*MEAS_COND_XG_VOLTAGE "60.0000000000"
*MEAS_COND_XG_WAVE_TYPE "Ka"
*MEAS_DATA_COUNT "73.0000000000"
*MEAS_SCAN_AXIS_X "Phi"
*MEAS_SCAN_AXIS_X_INTERNAL "Phi"
*MEAS_SCAN_MODE "CONTINUOUS"
*MEAS_SCAN_MONITOR "0"
*MEAS_SCAN_RESOLUTION_X "0.002"
*MEAS_SCAN_SPEED "200.000"
*MEAS_SCAN_SPEED_UNIT "deg/min"
*MEAS_SCAN_START "0.000"
*MEAS_SCAN_START_TIME "03/23/09 17:13:20"
*MEAS_SCAN_STEP "5.000"
*MEAS_SCAN_STOP "360.000"
*MEAS_SCAN_UNIT_X "deg"
*MEAS_SCAN_UNIT_Y "counts"
*RAS_HEADER_END
*RAS_INT_START
0.000 17415.000 1.000
5.000 15503.000 1.000
10.000 11808.000 1.000
15.000 10822.000 1.000
20.000 12607.000 1.000
25.000 14706.000 1.000
30.000 12059.000 1.000
35.000 10440.000 1.000
40.000 12547.000 1.000
45.000 13796.000 1.000
50.000 11458.000 1.000
55.000 10612.000 1.000
60.000 12676.000 1.000
65.000 11315.000 1.000
70.000 12428.000 1.000
75.000 11660.000 1.000
80.000 13052.000 1.000
85.000 14528.000 1.000
90.000 17442.000 1.000
95.000 12666.000 1.000
100.000 16161.000 1.000
105.000 13403.000 1.000
110.000 11816.000 1.000
115.000 13286.000 1.000
120.000 15058.000 1.000
125.000 9254.000 1.000
130.000 14338.000 1.000
135.000 10647.000 1.000
140.000 11888.000 1.000
145.000 13337.000 1.000
150.000 15329.000 1.000
155.000 10964.000 1.000
160.000 10510.000 1.000
165.000 10666.000 1.000
170.000 11723.000 1.000
175.000 10462.000 1.000
180.000 9593.000 1.000
185.000 14271.000 1.000
190.000 9909.000 1.000
195.000 9307.000 1.000
200.000 9847.000 1.000
205.000 11302.000 1.000
210.000 13597.000 1.000
215.000 10294.000 1.000
220.000 10321.000 1.000
225.000 14991.000 1.000
230.000 9891.000 1.000
235.000 10595.000 1.000
240.000 8830.000 1.000
245.000 10184.000 1.000
250.000 10731.000 1.000
255.000 11502.000 1.000
260.000 11506.000 1.000
265.000 12209.000 1.000
270.000 11017.000 1.000
275.000 9648.000 1.000
280.000 10089.000 1.000
285.000 17753.000 1.000
290.000 11795.000 1.000
295.000 17551.000 1.000
300.000 12842.000 1.000
305.000 11404.000 1.000
310.000 10179.000 1.000
315.000 10992.000 1.000
320.000 11689.000 1.000
325.000 12502.000 1.000
330.000 13540.000 1.000
335.000 12612.000 1.000
340.000 12860.000 1.000
345.000 13064.000 1.000
350.000 12153.000 1.000
355.000 12834.000 1.000
360.000 17511.000 1.000
*RAS_INT_END
*RAS_HEADER_START
*DISP_FMT_X "%.0f"
*DISP_FMT_Y "%.0f"
*DISP_FULLSCALE "30010.4000000000"
*DISP_LINE_COLOR "255.0000000000"
*DISP_LINE_STYLE "0.0000000000"
*DISP_LINE_WIDTH "0.2500000000"
*DISP_NOTE "Collected Data-19"
*DISP_OFFSET_Y "0.0000000000"
*DISP_PEAKSEARCH_UNIT_Y "cps"
*DISP_RANGE_BOTTOM "0.0000000000"
*DISP_RANGE_LEFT "0.0000000000"
*DISP_RANGE_LOGCUTOFF "0.0100000000"
*DISP_RANGE_RIGHT "360.0000000000"
*DISP_RANGE_TOP "30010.4000000000"
*DISP_SCALE_MODE_Y "0.0000000000"
*DISP_TAB_NAME "Phi"
*DISP_TITLE_Y "Intensity"
*DISP_UNIT_Y "cps"
*DISP_WINDOW_NAME "MSG_MACROENGINE"
*FILE_COMMENT " "
*FILE_DATA_TYPE "RAS_3DE_POLEFIG"
*FILE_MD5 ""
*FILE_MEMO "3-23-2009"
*FILE_OPERATOR "SmartLab_User"
*FILE_SAMPLE "am30 ED 25 10-10"
*FILE_TYPE "RAS_RAW"
*FILE_USERGROUP "System Manager"
*FILE_VERSION "1.0000000000"
*HW_ATTACHMENT_ID "ATT0025"
*HW_ATTACHMENT_NAME "Standard|Standard"
*HW_COUNTER_ID-0 "CUT0021"
*HW_COUNTER_ID-1 ""
*HW_COUNTER_ID-2 ""
*HW_COUNTER_ID-3 "CSL0021"
*HW_COUNTER_ID-4 "CMC0021"
*HW_COUNTER_NAME-0 "SC-70|SC-70"
*HW_COUNTER_NAME-1 ""
*HW_COUNTER_NAME-2 ""
*HW_COUNTER_NAME-3 "BBM|BBM"
*HW_COUNTER_NAME-4 "検出器モノクロメータ|Detector monochromator"
*HW_ECP_HV "681.5000000000"
*HW_ECP_HV_UNIT "V"
*HW_GONIOMETER_ID "GON0022"
*HW_GONIOMETER_NAME "SmartLab(インプレーン)|SmartLab(In-plane)"
*HW_GONIOMETER_RADIUS-0 "90.0"
*HW_GONIOMETER_RADIUS-1 "114.0"
*HW_GONIOMETER_RADIUS-2 "190.0"
*HW_GONIOMETER_RADIUS-3 "300.0"
*HW_GONIOMETER_RADIUS-4 "187.0"
*HW_GONIOMETER_RADIUS-5 "300.0"
*HW_GONIOMETER_RADIUS-6 "113.0"
*HW_GONIOMETER_RADIUS-7 "331.0"
*HW_I_OPT_ID-0 "CBO0021"
*HW_I_OPT_ID-1 "ICR0023"
*HW_I_OPT_ID-2 "ISL0021"
*HW_I_OPT_ID-3 "ISO0021"
*HW_I_OPT_ID-4 "IAD0021"
*HW_I_OPT_NAME-0 "CBOユニット|CBO unit"
*HW_I_OPT_NAME-1 "標準入射光学ユニット|Standard incident optical unit"
*HW_I_OPT_NAME-2 "標準入射スリットボックス|Standard incident slit box"
*HW_I_OPT_NAME-3 "入射平行スリット|Incident parallel slit"
*HW_I_OPT_NAME-4 "長手制限スリット|Length limiting slit"
*HW_R_ATTENUATER_AUTOMODE "1"
*HW_R_OPT_ID-0 "RSS0021"
*HW_R_OPT_ID-1 "RCR0022"
*HW_R_OPT_ID-2 "RSO0021"
*HW_R_OPT_ID-3 "RRS0021"
*HW_R_OPT_ID-4 "ATN0021"
*HW_R_OPT_ID-5 "RFL0021"
*HW_R_OPT_ID-6 "RAD0021"
*HW_R_OPT_NAME-0 "標準受光スリットボックス1|Standard receiving slit box # 1"
*HW_R_OPT_NAME-1 "標準受光光学ユニット1|Standard receiving unit # 1"
*HW_R_OPT_NAME-2 "標準受光光学ユニット2|Standard receiving optical unit # 2"
*HW_R_OPT_NAME-3 "標準受光スリットボックス2|Standard receiving slit box # 2"
*HW_R_OPT_NAME-4 "標準アッテネータ|Standard Attenuator"
*HW_R_OPT_NAME-5 "Cu Kβ|Cu K-beta"
*HW_R_OPT_NAME-6 "調整用受光スリット|Alignment receiving slit"
*HW_SAMPLE_HOLDER_ID "SMP0021"
*HW_SAMPLE_HOLDER_NAME "標準χクレードル|Std. chi cradle"
*HW_XG_CURRENT_MAX "60"
*HW_XG_CURRENT_MIN "2"
*HW_XG_CURRENT_RESOLUTION "1"
*HW_XG_CURRENT_UNIT "mA"
*HW_XG_FOCUS "1mm x 10mm"
*HW_XG_FOCUS_TYPE "Normal"
*HW_XG_ID ""
*HW_XG_NAME "3kW 封入管|3kW Sealed tube"
*HW_XG_TARGET_ATOMIC_NUMBER "29.0000000000"
*HW_XG_TARGET_NAME "Cu"
*HW_XG_TYPE "Hermetic"
*HW_XG_VOLTAGE_MAX "60"
*HW_XG_VOLTAGE_MIN "20"
*HW_XG_VOLTAGE_RESOLUTION "1"
*HW_XG_VOLTAGE_UNIT "kV"
*HW_XG_WATT_MAX "2"
*HW_XG_WATT_UNIT "kW"
*HW_XG_WAVE_LENGTH_ALPHA1 "1.540593"
*HW_XG_WAVE_LENGTH_ALPHA2 "1.544414"
*HW_XG_WAVE_LENGTH_BETA "1.392250"
*MEAS_3DE_ALPHA_ANGLE "90.0"
*MEAS_3DE_ALPHA_START "0.0"
*MEAS_3DE_ALPHA_STEP "5.0000"
*MEAS_3DE_ALPHA_STOP "90.0"
*MEAS_3DE_BG_HIGH_ANGLE "32.6165"
*MEAS_3DE_BG_HIGH_EXEC "1"
*MEAS_3DE_BG_HIGH_INT "5263"
*MEAS_3DE_BG_HIGH_TIME "0.5"
*MEAS_3DE_BG_LOW_ANGLE "31.8726"
*MEAS_3DE_BG_LOW_EXEC "1"
*MEAS_3DE_BG_LOW_INT "4800"
*MEAS_3DE_BG_LOW_TIME "0.5"
*MEAS_3DE_BG_MODE "2"
*MEAS_3DE_TWOTHETA_ANGLE "32.2446"
*MEAS_COND_AXIS_NAME-0 "Theta/2-Theta"
*MEAS_COND_AXIS_NAME-1 "2-Theta"
*MEAS_COND_AXIS_NAME-2 "Omega"
*MEAS_COND_AXIS_NAME-3 "2-Theta/Omega"
*MEAS_COND_AXIS_NAME-4 "Chi"
*MEAS_COND_AXIS_NAME-5 "Phi"
*MEAS_COND_AXIS_NAME-6 "2-ThetaChi"
*MEAS_COND_AXIS_NAME-7 "2-ThetaChi/Phi"
*MEAS_COND_AXIS_NAME-8 "Alpha"
*MEAS_COND_AXIS_NAME-9 "Beta"
*MEAS_COND_AXIS_NAME-10 "Z"
*MEAS_COND_AXIS_NAME-11 "Attenuator"
*MEAS_COND_AXIS_NAME-12 "Theta_s"
*MEAS_COND_AXIS_NAME-13 "Theta_d"
*MEAS_COND_AXIS_NAME-14 "Ts"
*MEAS_COND_AXIS_NAME-15 "M"
*MEAS_COND_AXIS_NAME-16 "Incident slit"
*MEAS_COND_AXIS_NAME-17 ""
*MEAS_COND_AXIS_NAME-18 "Zs"
*MEAS_COND_AXIS_NAME-19 "Receiving slit # 1"
*MEAS_COND_AXIS_NAME-20 ""
*MEAS_COND_AXIS_NAME-21 "Receiving slit # 2"
*MEAS_COND_AXIS_NAME-22 ""
*MEAS_COND_AXIS_NAME-23 "Zd"
*MEAS_COND_AXIS_NAME-24 "CBO selection slit"
*MEAS_COND_AXIS_NAME-25 "Incident monochromator"
*MEAS_COND_AXIS_NAME-26 "Incident parallel slit"
*MEAS_COND_AXIS_NAME-27 "Length limiting slit"
*MEAS_COND_AXIS_NAME-28 "Center slit"
*MEAS_COND_AXIS_NAME-29 "Filter"
*MEAS_COND_AXIS_NAME-30 "Recieving optical device"
*MEAS_COND_AXIS_NAME-31 "Receiving parallel slit"
*MEAS_COND_AXIS_NAME-32 "Alignment receiving slit"
*MEAS_COND_AXIS_NAME-33 "Diffracted beam monochromator"
*MEAS_COND_AXIS_NAME-34 "Monochromator slit"
*MEAS_COND_AXIS_NAME-35 "2-ThetaB"
*MEAS_COND_AXIS_NAME-36 "HV"
*MEAS_COND_AXIS_NAME-37 "PHA"
*MEAS_COND_AXIS_NAME_INTERNAL-0 "TwoThetaTheta"
*MEAS_COND_AXIS_NAME_INTERNAL-1 "TwoTheta"
*MEAS_COND_AXIS_NAME_INTERNAL-2 "Omega"
*MEAS_COND_AXIS_NAME_INTERNAL-3 "TwoThetaOmega"
*MEAS_COND_AXIS_NAME_INTERNAL-4 "Chi"
*MEAS_COND_AXIS_NAME_INTERNAL-5 "Phi"
*MEAS_COND_AXIS_NAME_INTERNAL-6 "TwoThetaChi"
*MEAS_COND_AXIS_NAME_INTERNAL-7 "TwoThetaChiPhi"
*MEAS_COND_AXIS_NAME_INTERNAL-8 "Alpha"
*MEAS_COND_AXIS_NAME_INTERNAL-9 "Beta"
*MEAS_COND_AXIS_NAME_INTERNAL-10 "Z"
*MEAS_COND_AXIS_NAME_INTERNAL-11 "Attenuator"
*MEAS_COND_AXIS_NAME_INTERNAL-12 "ThetaS"
*MEAS_COND_AXIS_NAME_INTERNAL-13 "ThetaD"
*MEAS_COND_AXIS_NAME_INTERNAL-14 "Ts"
*MEAS_COND_AXIS_NAME_INTERNAL-15 "CBO-M"
*MEAS_COND_AXIS_NAME_INTERNAL-16 "IncidentSlitBox"
*MEAS_COND_AXIS_NAME_INTERNAL-17 "IncidentSlitBox-_Axis"
*MEAS_COND_AXIS_NAME_INTERNAL-18 "Zs"
*MEAS_COND_AXIS_NAME_INTERNAL-19 "ReceivingSlitBox1"
*MEAS_COND_AXIS_NAME_INTERNAL-20 "ReceivingSlitBox1-_Axis"
*MEAS_COND_AXIS_NAME_INTERNAL-21 "ReceivingSlitBox2"
*MEAS_COND_AXIS_NAME_INTERNAL-22 "ReceivingSlitBox2-_Axis"
*MEAS_COND_AXIS_NAME_INTERNAL-23 "ReceivingSlitBox2-Zd"
*MEAS_COND_AXIS_NAME_INTERNAL-24 "CBO"
*MEAS_COND_AXIS_NAME_INTERNAL-25 "IncidentMonochromator"
*MEAS_COND_AXIS_NAME_INTERNAL-26 "IncidentSollerSlit"
*MEAS_COND_AXIS_NAME_INTERNAL-27 "IncidentAxdSlit"
*MEAS_COND_AXIS_NAME_INTERNAL-28 "CenterSlit"
*MEAS_COND_AXIS_NAME_INTERNAL-29 "Filter"
*MEAS_COND_AXIS_NAME_INTERNAL-30 "ReceivingOptics"
*MEAS_COND_AXIS_NAME_INTERNAL-31 "ReceivingSollerSlit"
*MEAS_COND_AXIS_NAME_INTERNAL-32 "ReceivingAxdSlit"
*MEAS_COND_AXIS_NAME_INTERNAL-33 "CounterMonochromator"
*MEAS_COND_AXIS_NAME_INTERNAL-34 "CounterSlit"
*MEAS_COND_AXIS_NAME_INTERNAL-35 "TwoThetaB"
*MEAS_COND_AXIS_NAME_INTERNAL-36 "HV"
*MEAS_COND_AXIS_NAME_INTERNAL-37 "PHA"
*MEAS_COND_AXIS_NAME_MAGICNO-0 "83951616.0000000000"
*MEAS_COND_AXIS_NAME_MAGICNO-1 "268632064.0000000000"
*MEAS_COND_AXIS_NAME_MAGICNO-2 "268500992.0000000000"
*MEAS_COND_AXIS_NAME_MAGICNO-3 "83951616.0000000000"
*MEAS_COND_AXIS_NAME_MAGICNO-4 "268500992.0000000000"
*MEAS_COND_AXIS_NAME_MAGICNO-5 "268500992.0000000000"
*MEAS_COND_AXIS_NAME_MAGICNO-6 "268632064.0000000000"
*MEAS_COND_AXIS_NAME_MAGICNO-7 "83951616.0000000000"
*MEAS_COND_AXIS_NAME_MAGICNO-8 "17039360.0000000000"
*MEAS_COND_AXIS_NAME_MAGICNO-9 "17039360.0000000000"
*MEAS_COND_AXIS_NAME_MAGICNO-10 "285278208.0000000000"
*MEAS_COND_AXIS_NAME_MAGICNO-11 "17301505.0000000000"
*MEAS_COND_AXIS_NAME_MAGICNO-12 "131072.0000000000"
*MEAS_COND_AXIS_NAME_MAGICNO-13 "131072.0000000000"
*MEAS_COND_AXIS_NAME_MAGICNO-14 "318898176.0000000000"
*MEAS_COND_AXIS_NAME_MAGICNO-15 "285343744.0000000000"
*MEAS_COND_AXIS_NAME_MAGICNO-16 "22020097.0000000000"
*MEAS_COND_AXIS_NAME_MAGICNO-17 "25165824.0000000000"
*MEAS_COND_AXIS_NAME_MAGICNO-18 "318898176.0000000000"
*MEAS_COND_AXIS_NAME_MAGICNO-19 "23068673.0000000000"
*MEAS_COND_AXIS_NAME_MAGICNO-20 "25165824.0000000000"
*MEAS_COND_AXIS_NAME_MAGICNO-21 "23068673.0000000000"
*MEAS_COND_AXIS_NAME_MAGICNO-22 "25165824.0000000000"
*MEAS_COND_AXIS_NAME_MAGICNO-23 "285343744.0000000000"
*MEAS_COND_AXIS_NAME_MAGICNO-24 "20971521.0000000000"
*MEAS_COND_AXIS_NAME_MAGICNO-25 "1.0000000000"
*MEAS_COND_AXIS_NAME_MAGICNO-26 "20971521.0000000000"
*MEAS_COND_AXIS_NAME_MAGICNO-27 "20971521.0000000000"
*MEAS_COND_AXIS_NAME_MAGICNO-28 "20971521.0000000000"
*MEAS_COND_AXIS_NAME_MAGICNO-29 "20971521.0000000000"
*MEAS_COND_AXIS_NAME_MAGICNO-30 "20971521.0000000000"
*MEAS_COND_AXIS_NAME_MAGICNO-31 "20971521.0000000000"
*MEAS_COND_AXIS_NAME_MAGICNO-32 "20971521.0000000000"
*MEAS_COND_AXIS_NAME_MAGICNO-33 "20971521.0000000000"
*MEAS_COND_AXIS_NAME_MAGICNO-34 "20971521.0000000000"
*MEAS_COND_AXIS_NAME_MAGICNO-35 "17039360.0000000000"
*MEAS_COND_AXIS_NAME_MAGICNO-36 "0.0000000000"
*MEAS_COND_AXIS_NAME_MAGICNO-37 "0.0000000000"
*MEAS_COND_AXIS_OFFSET-0 "-"
*MEAS_COND_AXIS_OFFSET-1 "0.6672000000"
*MEAS_COND_AXIS_OFFSET-2 "0.8653000000"
*MEAS_COND_AXIS_OFFSET-3 "-"
*MEAS_COND_AXIS_OFFSET-4 "0.0000000000"
*MEAS_COND_AXIS_OFFSET-5 "0.0000000000"
*MEAS_COND_AXIS_OFFSET-6 "0.0000000000"
*MEAS_COND_AXIS_OFFSET-7 "-"
*MEAS_COND_AXIS_OFFSET-8 "-"
*MEAS_COND_AXIS_OFFSET-9 "-"
*MEAS_COND_AXIS_OFFSET-10 "-"
*MEAS_COND_AXIS_OFFSET-11 "-"
*MEAS_COND_AXIS_OFFSET-12 "0.8653000000"
*MEAS_COND_AXIS_OFFSET-13 "-0.1981000000"
*MEAS_COND_AXIS_OFFSET-14 "-"
*MEAS_COND_AXIS_OFFSET-15 "-"
*MEAS_COND_AXIS_OFFSET-16 "-"
*MEAS_COND_AXIS_OFFSET-17 "-"
*MEAS_COND_AXIS_OFFSET-18 "-"
*MEAS_COND_AXIS_OFFSET-19 "-"
*MEAS_COND_AXIS_OFFSET-20 "-"
*MEAS_COND_AXIS_OFFSET-21 "-"
*MEAS_COND_AXIS_OFFSET-22 "-"
*MEAS_COND_AXIS_OFFSET-23 "-"
*MEAS_COND_AXIS_OFFSET-24 "-"
*MEAS_COND_AXIS_OFFSET-25 "-"
*MEAS_COND_AXIS_OFFSET-26 "-"
*MEAS_COND_AXIS_OFFSET-27 "-"
*MEAS_COND_AXIS_OFFSET-28 "-"
*MEAS_COND_AXIS_OFFSET-29 "-"
*MEAS_COND_AXIS_OFFSET-30 "-"
*MEAS_COND_AXIS_OFFSET-31 "-"
*MEAS_COND_AXIS_OFFSET-32 "-"
*MEAS_COND_AXIS_OFFSET-33 "-"
*MEAS_COND_AXIS_OFFSET-34 "-"
*MEAS_COND_AXIS_OFFSET-35 "-"
*MEAS_COND_AXIS_OFFSET-36 "-"
*MEAS_COND_AXIS_OFFSET-37 "-"
*MEAS_COND_AXIS_POSITION-0 "32.2446000000"
*MEAS_COND_AXIS_POSITION-1 "32.2446000000"
*MEAS_COND_AXIS_POSITION-2 "16.1223000000"
*MEAS_COND_AXIS_POSITION-3 "32.2446000000"
*MEAS_COND_AXIS_POSITION-4 "0.0000000000"
*MEAS_COND_AXIS_POSITION-5 "-2.5000000000"
*MEAS_COND_AXIS_POSITION-6 "0.0000000000"
*MEAS_COND_AXIS_POSITION-7 "0.0000000000"
*MEAS_COND_AXIS_POSITION-8 "90.0000000000"
*MEAS_COND_AXIS_POSITION-9 "-2.5000000000"
*MEAS_COND_AXIS_POSITION-10 "0.1194000000"
*MEAS_COND_AXIS_POSITION-11 "1/10000"
*MEAS_COND_AXIS_POSITION-12 "16.1223000000"
*MEAS_COND_AXIS_POSITION-13 "16.1223000000"
*MEAS_COND_AXIS_POSITION-14 "-1.2998100000"
*MEAS_COND_AXIS_POSITION-15 "0.0000000000"
*MEAS_COND_AXIS_POSITION-16 "1.000mm"
*MEAS_COND_AXIS_POSITION-17 "1.0000000000"
*MEAS_COND_AXIS_POSITION-18 "-2.0200000000"
*MEAS_COND_AXIS_POSITION-19 "10.000mm"
*MEAS_COND_AXIS_POSITION-20 "10.0000000000"
*MEAS_COND_AXIS_POSITION-21 "10.000mm"
*MEAS_COND_AXIS_POSITION-22 "10.0000000000"
*MEAS_COND_AXIS_POSITION-23 "-0.1168800000"
*MEAS_COND_AXIS_POSITION-24 "PB"
*MEAS_COND_AXIS_POSITION-25 "0.0000000000"
*MEAS_COND_AXIS_POSITION-26 "Soller_slit_5.0deg"
*MEAS_COND_AXIS_POSITION-27 "5.0mm"
*MEAS_COND_AXIS_POSITION-28 "None"
*MEAS_COND_AXIS_POSITION-29 "None"
*MEAS_COND_AXIS_POSITION-30 "PSA_open"
*MEAS_COND_AXIS_POSITION-31 "Soller_slit_5.0deg"
*MEAS_COND_AXIS_POSITION-32 "None"
*MEAS_COND_AXIS_POSITION-33 "None"
*MEAS_COND_AXIS_POSITION-34 "None"
*MEAS_COND_AXIS_POSITION-35 "32.2446000000"
*MEAS_COND_AXIS_POSITION-36 "681.5000000000"
*MEAS_COND_AXIS_POSITION-37 "505.0000000000"
*MEAS_COND_AXIS_UNIT-0 "deg"
*MEAS_COND_AXIS_UNIT-1 "deg"
*MEAS_COND_AXIS_UNIT-2 "deg"
*MEAS_COND_AXIS_UNIT-3 "deg"
*MEAS_COND_AXIS_UNIT-4 "deg"
*MEAS_COND_AXIS_UNIT-5 "deg"
*MEAS_COND_AXIS_UNIT-6 "deg"
*MEAS_COND_AXIS_UNIT-7 "deg"
*MEAS_COND_AXIS_UNIT-8 "deg"
*MEAS_COND_AXIS_UNIT-9 "deg"
*MEAS_COND_AXIS_UNIT-10 "mm"
*MEAS_COND_AXIS_UNIT-11 ""
*MEAS_COND_AXIS_UNIT-12 "deg"
*MEAS_COND_AXIS_UNIT-13 "deg"
*MEAS_COND_AXIS_UNIT-14 "mm"
*MEAS_COND_AXIS_UNIT-15 "pulse"
*MEAS_COND_AXIS_UNIT-16 ""
*MEAS_COND_AXIS_UNIT-17 "mm"
*MEAS_COND_AXIS_UNIT-18 "mm"
*MEAS_COND_AXIS_UNIT-19 ""
*MEAS_COND_AXIS_UNIT-20 "mm"
*MEAS_COND_AXIS_UNIT-21 ""
*MEAS_COND_AXIS_UNIT-22 "mm"
*MEAS_COND_AXIS_UNIT-23 "mm"
*MEAS_COND_AXIS_UNIT-24 ""
*MEAS_COND_AXIS_UNIT-25 ""
*MEAS_COND_AXIS_UNIT-26 ""
*MEAS_COND_AXIS_UNIT-27 ""
*MEAS_COND_AXIS_UNIT-28 ""
*MEAS_COND_AXIS_UNIT-29 ""
*MEAS_COND_AXIS_UNIT-30 ""
*MEAS_COND_AXIS_UNIT-31 ""
*MEAS_COND_AXIS_UNIT-32 ""
*MEAS_COND_AXIS_UNIT-33 ""
*MEAS_COND_AXIS_UNIT-34 ""
*MEAS_COND_AXIS_UNIT-35 "deg"
*MEAS_COND_AXIS_UNIT-36 "V"
*MEAS_COND_AXIS_UNIT-37 "mV"
*MEAS_COND_COUNTER_CNTLOSS_CORR "1.0000000000"
*MEAS_COND_COUNTER_PHABASE "505.0000000000"
*MEAS_COND_COUNTER_PHAWINDOW "950.0000000000"
*MEAS_COND_COUNTER_PHA_UNIT "mV"
*MEAS_COND_COUNTER_TAUDIFF "0.2366790000"
*MEAS_COND_COUNTER_TAUINT "0.5939810000"
*MEAS_COND_OPT_ATTR "Medium resolution parallel beam/RS"
*MEAS_COND_OPT_NAME "@Medium resolution PB"
*MEAS_COND_XG_CURRENT "36.0000000000"
*MEAS_COND_XG_VOLTAGE "60.0000000000"
*MEAS_COND_XG_WAVE_TYPE "Ka"
*MEAS_DATA_COUNT "73.0000000000"
*MEAS_SCAN_AXIS_X "Phi"
*MEAS_SCAN_AXIS_X_INTERNAL "Phi"
*MEAS_SCAN_MODE "CONTINUOUS"
*MEAS_SCAN_MONITOR "0"
*MEAS_SCAN_RESOLUTION_X "0.002"
*MEAS_SCAN_SPEED "200.000"
*MEAS_SCAN_SPEED_UNIT "deg/min"
*MEAS_SCAN_START "0.000"
*MEAS_SCAN_START_TIME "03/23/09 17:16:09"
*MEAS_SCAN_STEP "5.000"
*MEAS_SCAN_STOP "360.000"
*MEAS_SCAN_UNIT_X "deg"
*MEAS_SCAN_UNIT_Y "counts"
*RAS_HEADER_END
*RAS_INT_START
0.000 25045.000 1.000
5.000 28745.000 1.000
10.000 27080.000 1.000
15.000 16094.000 1.000
20.000 15940.000 1.000
25.000 17427.000 1.000
30.000 16675.000 1.000
35.000 16208.000 1.000
40.000 18646.000 1.000
45.000 14326.000 1.000
50.000 12457.000 1.000
55.000 10647.000 1.000
60.000 13795.000 1.000
65.000 12122.000 1.000
70.000 19024.000 1.000
75.000 12307.000 1.000
80.000 11633.000 1.000
85.000 11159.000 1.000
90.000 12605.000 1.000
95.000 11575.000 1.000
100.000 16281.000 1.000
105.000 13541.000 1.000
110.000 12740.000 1.000
115.000 11899.000 1.000
120.000 11042.000 1.000
125.000 10745.000 1.000
130.000 10916.000 1.000
135.000 10338.000 1.000
140.000 10615.000 1.000
145.000 11511.000 1.000
150.000 15695.000 1.000
155.000 13976.000 1.000
160.000 13461.000 1.000
165.000 16599.000 1.000
170.000 16402.000 1.000
175.000 14993.000 1.000
180.000 14704.000 1.000
185.000 16214.000 1.000
190.000 22997.000 1.000
195.000 20786.000 1.000
200.000 17036.000 1.000
205.000 11930.000 1.000
210.000 11039.000 1.000
215.000 10263.000 1.000
220.000 9513.000 1.000
225.000 10569.000 1.000
230.000 10595.000 1.000
235.000 14299.000 1.000
240.000 12641.000 1.000
245.000 11770.000 1.000
250.000 10409.000 1.000
255.000 10631.000 1.000
260.000 12782.000 1.000
265.000 37513.000 1.000
270.000 28775.000 1.000
275.000 11559.000 1.000
280.000 10049.000 1.000
285.000 9660.000 1.000
290.000 10194.000 1.000
295.000 10752.000 1.000
300.000 11730.000 1.000
305.000 11216.000 1.000
310.000 12148.000 1.000
315.000 10160.000 1.000
320.000 12161.000 1.000
325.000 13131.000 1.000
330.000 14863.000 1.000
335.000 14251.000 1.000
340.000 12268.000 1.000
345.000 13040.000 1.000
350.000 13796.000 1.000
355.000 14403.000 1.000
360.000 24976.000 1.000
*RAS_INT_END
*RAS_DATA_END