File: mtex-5.1.1/data/PoleFigure/ZnCuTi/ZnCuTi_defocusing_PF_102_R.UXD
; C:\Users\Stanis³aw\OneDrive\Documents\paracamgr\DANE DO MGR\24.03.2015\tekstura\TExtura\Defokusacja\ZnCuTi_defokusacja_PF_102_R.raw(Diffrac Plus V1.01 file) converted by XCH V1.0
_FILEVERSION=2
_SITE='Poland'
_USER='Administrator'
_SAMPLE_CHANGER_CODE=0
_ATTACHMENTS_CODE=0
_GONIOMETER_RADIUS=300.000000
_FIXED_DIVSLIT=0.600000
_FIXED_SAMPLESLIT=1.000000
_FIXED_DETSLIT=0.100000
_MONOCHROMATOR=0
; None
_THIN_FILM='N'
_BETA_FILTER='N'
_FIXED_ANTISLIT=0.600000
_ANALYZER_CODE=0
; None
_DATEMEASURED='01-Apr-2015 05:54:09'
_WL_UNIT='A'
_WL1=1.540600
_WL2=1.544390
_WL3=1.392220
_WLRATIO=0.500000
_ANODE='Cu'
; (Data for Range number 1)
_DRIVE='PHI'
_STEPTIME=11.999800
_STEPSIZE=5.000000
_STEPMODE='C'
_START=0.000000
_THETA=27.283001
_2THETA=54.566002
_KHI=0.000000
_PHI=0.000000
_X=0.000000
_Y=0.000000
_Z=0.000000
_DIVERGENCE=0.200000
_ANTISCATTER=0.200000
_DETECTOR=1
; S.C.
_HV=683.500000
_GAIN=80.000000
_LLD=0.788000
_ULD=2.160000
_DETECTORSLIT='out'
_AUX1=0.000000
_AUX2=0.000000
_AUX3=0.000000
_TIMESTARTED=22.000000
_TEMP_RATE=0.000000
_TEMP_DELAY=0.000000
_KV=40
_MA=30
_RANGE_WL=1.540600
_3DPLANE=0
_2THETACPS
   0.0000    158.67
   5.0000    159.92
  10.0000    163.84
  15.0000    157.42
  20.0000    159.17
  25.0000    168.42
  30.0000    174.75
  35.0000    176.42
  40.0000    201.00
  45.0000    174.59
  50.0000    172.75
  55.0000    172.84
  60.0000    165.50
  65.0000    157.50
  70.0000    155.50
  75.0000    154.50
  80.0000    168.00
  85.0000    172.00
  90.0000    153.34
  95.0000    166.92
 100.0000    160.59
 105.0000    167.00
 110.0000    183.84
 115.0000    183.84
 120.0000    187.50
 125.0000    181.67
 130.0000    180.25
 135.0000    179.34
 140.0000    173.42
 145.0000    173.59
 150.0000    178.17
 155.0000    173.00
 160.0000    181.34
 165.0000    170.84
 170.0000    174.34
 175.0000    167.09
 180.0000    161.09
 185.0000    163.34
 190.0000    159.67
 195.0000    159.75
 200.0000    169.09
 205.0000    173.67
 210.0000    188.92
 215.0000    176.67
 220.0000    168.17
 225.0000    162.17
 230.0000    160.42
 235.0000    160.34
 240.0000    161.59
 245.0000    152.25
 250.0000    147.67
 255.0000    152.50
 260.0000    155.17
 265.0000    149.75
 270.0000    149.17
 275.0000    157.17
 280.0000    154.50
 285.0000    152.00
 290.0000    152.67
 295.0000    157.25
 300.0000    164.34
 305.0000    169.34
 310.0000    172.09
 315.0000    154.59
 320.0000    153.84
 325.0000    151.34
 330.0000    147.84
 335.0000    153.67
 340.0000    149.92
 345.0000    154.92
 350.0000    149.09
 355.0000    161.34
; (Data for Range number 2)
_DRIVE='PHI'
_STEPTIME=11.999800
_STEPSIZE=5.000000
_STEPMODE='C'
_START=0.000000
_THETA=27.283001
_2THETA=54.566002
_KHI=5.000000
_PHI=0.000000
_X=0.000000
_Y=0.000000
_Z=0.000000
_DIVERGENCE=0.200000
_ANTISCATTER=0.200000
_DETECTOR=1
; S.C.
_HV=683.500000
_GAIN=80.000000
_LLD=0.788000
_ULD=2.160000
_DETECTORSLIT='out'
_AUX1=0.000000
_AUX2=0.000000
_AUX3=0.000000
_TIMESTARTED=890.000000
_TEMP_RATE=0.000000
_TEMP_DELAY=0.000000
_KV=40
_MA=30
_RANGE_WL=1.540600
_3DPLANE=0
_2THETACPS
   0.0000    153.42
   5.0000    162.09
  10.0000    172.67
  15.0000    202.75
  20.0000    180.92
  25.0000    162.67
  30.0000    166.92
  35.0000    155.09
  40.0000    156.50
  45.0000    158.17
  50.0000    161.09
  55.0000    163.67
  60.0000    159.59
  65.0000    167.59
  70.0000    157.75
  75.0000    163.25
  80.0000    166.50
  85.0000    168.84
  90.0000    191.17
  95.0000    171.25
 100.0000    173.50
 105.0000    176.84
 110.0000    170.75
 115.0000    182.59
 120.0000    170.17
 125.0000    186.42
 130.0000    180.42
 135.0000    180.17
 140.0000    195.84
 145.0000    181.75
 150.0000    205.50
 155.0000    192.00
 160.0000    179.00
 165.0000    183.09
 170.0000    174.84
 175.0000    194.92
 180.0000    218.00
 185.0000    185.17
 190.0000    178.59
 195.0000    178.92
 200.0000    179.59
 205.0000    173.09
 210.0000    176.67
 215.0000    179.75
 220.0000    166.59
 225.0000    159.00
 230.0000    171.67
 235.0000    160.42
 240.0000    157.75
 245.0000    174.09
 250.0000    168.84
 255.0000    150.00
 260.0000    144.59
 265.0000    151.09
 270.0000    147.25
 275.0000    156.59
 280.0000    162.34
 285.0000    155.09
 290.0000    148.50
 295.0000    155.84
 300.0000    172.34
 305.0000    177.34
 310.0000    157.92
 315.0000    155.00
 320.0000    152.84
 325.0000    154.59
 330.0000    164.75
 335.0000    156.50
 340.0000    156.84
 345.0000    159.34
 350.0000    162.25
 355.0000    165.00
; (Data for Range number 3)
_DRIVE='PHI'
_STEPTIME=11.999800
_STEPSIZE=5.000000
_STEPMODE='C'
_START=0.000000
_THETA=27.283001
_2THETA=54.566002
_KHI=10.000000
_PHI=0.000000
_X=0.000000
_Y=0.000000
_Z=0.000000
_DIVERGENCE=0.200000
_ANTISCATTER=0.200000
_DETECTOR=1
; S.C.
_HV=683.500000
_GAIN=80.000000
_LLD=0.788000
_ULD=2.160000
_DETECTORSLIT='out'
_AUX1=0.000000
_AUX2=0.000000
_AUX3=0.000000
_TIMESTARTED=1759.000000
_TEMP_RATE=0.000000
_TEMP_DELAY=0.000000
_KV=40
_MA=30
_RANGE_WL=1.540600
_3DPLANE=0
_2THETACPS
   0.0000    178.50
   5.0000    162.50
  10.0000    173.00
  15.0000    161.84
  20.0000    170.34
  25.0000    165.84
  30.0000    165.00
  35.0000    158.67
  40.0000    161.92
  45.0000    161.84
  50.0000    161.00
  55.0000    156.09
  60.0000    164.59
  65.0000    171.34
  70.0000    164.75
  75.0000    160.92
  80.0000    162.25
  85.0000    164.42
  90.0000    179.50
  95.0000    162.50
 100.0000    158.59
 105.0000    187.50
 110.0000    171.75
 115.0000    192.67
 120.0000    169.42
 125.0000    196.34
 130.0000    176.75
 135.0000    180.42
 140.0000    180.25
 145.0000    179.09
 150.0000    183.09
 155.0000    189.42
 160.0000    201.75
 165.0000    170.92
 170.0000    180.34
 175.0000    193.50
 180.0000    180.84
 185.0000    180.59
 190.0000    173.67
 195.0000    177.50
 200.0000    169.59
 205.0000    180.00
 210.0000    173.59
 215.0000    169.17
 220.0000    164.42
 225.0000    170.34
 230.0000    162.92
 235.0000    166.34
 240.0000    164.34
 245.0000    156.75
 250.0000    163.75
 255.0000    164.59
 260.0000    152.50
 265.0000    143.92
 270.0000    141.75
 275.0000    145.75
 280.0000    149.75
 285.0000    153.50
 290.0000    149.84
 295.0000    163.25
 300.0000    160.00
 305.0000    157.42
 310.0000    164.09
 315.0000    168.34
 320.0000    160.67
 325.0000    170.42
 330.0000    160.75
 335.0000    174.25
 340.0000    161.59
 345.0000    177.59
 350.0000    181.09
 355.0000    173.50
; (Data for Range number 4)
_DRIVE='PHI'
_STEPTIME=11.999800
_STEPSIZE=5.000000
_STEPMODE='C'
_START=0.000000
_THETA=27.283001
_2THETA=54.566002
_KHI=15.000000
_PHI=0.000000
_X=0.000000
_Y=0.000000
_Z=0.000000
_DIVERGENCE=0.200000
_ANTISCATTER=0.200000
_DETECTOR=1
; S.C.
_HV=683.500000
_GAIN=80.000000
_LLD=0.788000
_ULD=2.160000
_DETECTORSLIT='out'
_AUX1=0.000000
_AUX2=0.000000
_AUX3=0.000000
_TIMESTARTED=2627.000000
_TEMP_RATE=0.000000
_TEMP_DELAY=0.000000
_KV=40
_MA=30
_RANGE_WL=1.540600
_3DPLANE=0
_2THETACPS
   0.0000    162.34
   5.0000    184.59
  10.0000    162.17
  15.0000    166.17
  20.0000    169.09
  25.0000    160.42
  30.0000    167.75
  35.0000    164.09
  40.0000    156.17
  45.0000    153.17
  50.0000    162.67
  55.0000    175.34
  60.0000    164.34
  65.0000    163.17
  70.0000    155.00
  75.0000    157.50
  80.0000    156.09
  85.0000    161.84
  90.0000    154.34
  95.0000    164.09
 100.0000    162.67
 105.0000    166.59
 110.0000    171.00
 115.0000    171.92
 120.0000    176.84
 125.0000    173.75
 130.0000    168.59
 135.0000    179.00
 140.0000    194.50
 145.0000    193.17
 150.0000    185.25
 155.0000    182.00
 160.0000    193.67
 165.0000    179.92
 170.0000    178.00
 175.0000    189.25
 180.0000    173.84
 185.0000    183.84
 190.0000    176.25
 195.0000    188.25
 200.0000    195.00
 205.0000    181.09
 210.0000    174.50
 215.0000    168.17
 220.0000    161.17
 225.0000    172.50
 230.0000    171.17
 235.0000    160.59
 240.0000    165.00
 245.0000    163.42
 250.0000    146.59
 255.0000    155.34
 260.0000    142.50
 265.0000    143.17
 270.0000    145.84
 275.0000    140.00
 280.0000    145.84
 285.0000    139.84
 290.0000    150.92
 295.0000    170.34
 300.0000    185.75
 305.0000    165.75
 310.0000    163.42
 315.0000    157.34
 320.0000    167.17
 325.0000    163.50
 330.0000    164.17
 335.0000    162.25
 340.0000    160.17
 345.0000    161.75
 350.0000    163.34
 355.0000    170.67
; (Data for Range number 5)
_DRIVE='PHI'
_STEPTIME=11.999800
_STEPSIZE=5.000000
_STEPMODE='C'
_START=0.000000
_THETA=27.283001
_2THETA=54.566002
_KHI=20.000000
_PHI=0.000000
_X=0.000000
_Y=0.000000
_Z=0.000000
_DIVERGENCE=0.200000
_ANTISCATTER=0.200000
_DETECTOR=1
; S.C.
_HV=683.500000
_GAIN=80.000000
_LLD=0.788000
_ULD=2.160000
_DETECTORSLIT='out'
_AUX1=0.000000
_AUX2=0.000000
_AUX3=0.000000
_TIMESTARTED=3496.000000
_TEMP_RATE=0.000000
_TEMP_DELAY=0.000000
_KV=40
_MA=30
_RANGE_WL=1.540600
_3DPLANE=0
_2THETACPS
   0.0000    164.75
   5.0000    175.00
  10.0000    158.17
  15.0000    168.84
  20.0000    162.84
  25.0000    178.34
  30.0000    169.84
  35.0000    172.84
  40.0000    165.84
  45.0000    165.50
  50.0000    157.17
  55.0000    158.00
  60.0000    155.25
  65.0000    166.00
  70.0000    163.42
  75.0000    157.25
  80.0000    149.25
  85.0000    159.34
  90.0000    153.67
  95.0000    155.09
 100.0000    167.00
 105.0000    160.00
 110.0000    166.67
 115.0000    160.67
 120.0000    186.00
 125.0000    165.00
 130.0000    164.25
 135.0000    189.25
 140.0000    175.17
 145.0000    182.17
 150.0000    187.25
 155.0000    182.25
 160.0000    186.00
 165.0000    169.67
 170.0000    168.09
 175.0000    170.84
 180.0000    166.59
 185.0000    186.75
 190.0000    188.75
 195.0000    176.00
 200.0000    191.09
 205.0000    178.09
 210.0000    175.92
 215.0000    175.84
 220.0000    166.59
 225.0000    166.50
 230.0000    162.84
 235.0000    164.34
 240.0000    170.25
 245.0000    166.17
 250.0000    158.42
 255.0000    151.84
 260.0000    135.84
 265.0000    141.67
 270.0000    138.92
 275.0000    140.67
 280.0000    142.42
 285.0000    138.00
 290.0000    141.50
 295.0000    156.92
 300.0000    147.92
 305.0000    170.17
 310.0000    170.59
 315.0000    162.25
 320.0000    170.09
 325.0000    169.00
 330.0000    163.75
 335.0000    165.67
 340.0000    158.00
 345.0000    168.09
 350.0000    169.59
 355.0000    168.34
; (Data for Range number 6)
_DRIVE='PHI'
_STEPTIME=11.999800
_STEPSIZE=5.000000
_STEPMODE='C'
_START=0.000000
_THETA=27.283001
_2THETA=54.566002
_KHI=25.000000
_PHI=0.000000
_X=0.000000
_Y=0.000000
_Z=0.000000
_DIVERGENCE=0.200000
_ANTISCATTER=0.200000
_DETECTOR=1
; S.C.
_HV=683.500000
_GAIN=80.000000
_LLD=0.788000
_ULD=2.160000
_DETECTORSLIT='out'
_AUX1=0.000000
_AUX2=0.000000
_AUX3=0.000000
_TIMESTARTED=4365.000000
_TEMP_RATE=0.000000
_TEMP_DELAY=0.000000
_KV=40
_MA=30
_RANGE_WL=1.540600
_3DPLANE=0
_2THETACPS
   0.0000    165.00
   5.0000    162.59
  10.0000    176.17
  15.0000    175.42
  20.0000    173.84
  25.0000    165.84
  30.0000    156.75
  35.0000    177.67
  40.0000    161.75
  45.0000    159.17
  50.0000    161.92
  55.0000    160.42
  60.0000    169.59
  65.0000    162.25
  70.0000    149.67
  75.0000    148.00
  80.0000    143.42
  85.0000    151.34
  90.0000    144.42
  95.0000    152.00
 100.0000    144.92
 105.0000    150.25
 110.0000    156.75
 115.0000    151.17
 120.0000    166.75
 125.0000    170.25
 130.0000    173.50
 135.0000    182.42
 140.0000    170.84
 145.0000    183.50
 150.0000    182.17
 155.0000    182.59
 160.0000    173.67
 165.0000    174.84
 170.0000    168.92
 175.0000    172.34
 180.0000    166.17
 185.0000    169.67
 190.0000    170.09
 195.0000    174.00
 200.0000    186.09
 205.0000    172.42
 210.0000    180.09
 215.0000    169.59
 220.0000    165.50
 225.0000    166.67
 230.0000    163.92
 235.0000    169.00
 240.0000    159.00
 245.0000    160.42
 250.0000    162.67
 255.0000    162.00
 260.0000    147.50
 265.0000    146.42
 270.0000    134.67
 275.0000    142.42
 280.0000    136.17
 285.0000    141.84
 290.0000    143.25
 295.0000    153.75
 300.0000    157.75
 305.0000    157.67
 310.0000    160.25
 315.0000    173.09
 320.0000    176.17
 325.0000    161.84
 330.0000    162.75
 335.0000    165.25
 340.0000    173.84
 345.0000    167.34
 350.0000    168.84
 355.0000    167.84
; (Data for Range number 7)
_DRIVE='PHI'
_STEPTIME=11.999800
_STEPSIZE=5.000000
_STEPMODE='C'
_START=0.000000
_THETA=27.283001
_2THETA=54.566002
_KHI=30.000000
_PHI=0.000000
_X=0.000000
_Y=0.000000
_Z=0.000000
_DIVERGENCE=0.200000
_ANTISCATTER=0.200000
_DETECTOR=1
; S.C.
_HV=683.500000
_GAIN=80.000000
_LLD=0.788000
_ULD=2.160000
_DETECTORSLIT='out'
_AUX1=0.000000
_AUX2=0.000000
_AUX3=0.000000
_TIMESTARTED=5233.000000
_TEMP_RATE=0.000000
_TEMP_DELAY=0.000000
_KV=40
_MA=30
_RANGE_WL=1.540600
_3DPLANE=0
_2THETACPS
   0.0000    167.09
   5.0000    170.09
  10.0000    160.59
  15.0000    167.34
  20.0000    170.75
  25.0000    168.59
  30.0000    163.42
  35.0000    161.67
  40.0000    155.59
  45.0000    163.09
  50.0000    166.67
  55.0000    151.92
  60.0000    152.25
  65.0000    157.67
  70.0000    149.17
  75.0000    146.17
  80.0000    144.09
  85.0000    145.92
  90.0000    151.92
  95.0000    141.92
 100.0000    148.92
 105.0000    164.34
 110.0000    148.50
 115.0000    148.50
 120.0000    154.42
 125.0000    155.84
 130.0000    160.75
 135.0000    173.25
 140.0000    164.75
 145.0000    175.75
 150.0000    172.92
 155.0000    181.17
 160.0000    179.34
 165.0000    160.59
 170.0000    159.67
 175.0000    153.59
 180.0000    162.75
 185.0000    162.50
 190.0000    169.67
 195.0000    178.50
 200.0000    170.59
 205.0000    180.67
 210.0000    176.67
 215.0000    178.00
 220.0000    163.00
 225.0000    160.75
 230.0000    162.34
 235.0000    166.09
 240.0000    153.42
 245.0000    160.67
 250.0000    150.34
 255.0000    156.00
 260.0000    148.50
 265.0000    147.59
 270.0000    135.67
 275.0000    134.92
 280.0000    142.17
 285.0000    138.00
 290.0000    136.00
 295.0000    141.50
 300.0000    152.42
 305.0000    160.25
 310.0000    157.92
 315.0000    165.00
 320.0000    172.92
 325.0000    160.34
 330.0000    155.59
 335.0000    163.50
 340.0000    165.17
 345.0000    169.34
 350.0000    163.59
 355.0000    167.42
; (Data for Range number 8)
_DRIVE='PHI'
_STEPTIME=11.999800
_STEPSIZE=5.000000
_STEPMODE='C'
_START=0.000000
_THETA=27.283001
_2THETA=54.566002
_KHI=35.000000
_PHI=0.000000
_X=0.000000
_Y=0.000000
_Z=0.000000
_DIVERGENCE=0.200000
_ANTISCATTER=0.200000
_DETECTOR=1
; S.C.
_HV=683.500000
_GAIN=80.000000
_LLD=0.788000
_ULD=2.160000
_DETECTORSLIT='out'
_AUX1=0.000000
_AUX2=0.000000
_AUX3=0.000000
_TIMESTARTED=6102.000000
_TEMP_RATE=0.000000
_TEMP_DELAY=0.000000
_KV=40
_MA=30
_RANGE_WL=1.540600
_3DPLANE=0
_2THETACPS
   0.0000    171.75
   5.0000    166.00
  10.0000    161.50
  15.0000    169.25
  20.0000    156.34
  25.0000    151.34
  30.0000    149.50
  35.0000    151.59
  40.0000    157.84
  45.0000    151.42
  50.0000    160.34
  55.0000    151.67
  60.0000    153.09
  65.0000    149.59
  70.0000    155.25
  75.0000    141.00
  80.0000    140.34
  85.0000    143.34
  90.0000    147.17
  95.0000    143.92
 100.0000    145.00
 105.0000    141.50
 110.0000    144.17
 115.0000    147.09
 120.0000    155.09
 125.0000    150.75
 130.0000    162.09
 135.0000    163.25
 140.0000    169.42
 145.0000    162.25
 150.0000    167.67
 155.0000    173.84
 160.0000    161.42
 165.0000    163.34
 170.0000    162.00
 175.0000    152.84
 180.0000    156.25
 185.0000    165.09
 190.0000    170.75
 195.0000    175.34
 200.0000    173.25
 205.0000    169.17
 210.0000    167.09
 215.0000    163.25
 220.0000    156.09
 225.0000    157.75
 230.0000    158.34
 235.0000    164.34
 240.0000    157.00
 245.0000    151.75
 250.0000    155.25
 255.0000    154.59
 260.0000    152.92
 265.0000    143.50
 270.0000    137.84
 275.0000    137.67
 280.0000    130.34
 285.0000    137.67
 290.0000    138.59
 295.0000    141.25
 300.0000    142.75
 305.0000    145.42
 310.0000    147.42
 315.0000    157.25
 320.0000    159.84
 325.0000    155.75
 330.0000    157.59
 335.0000    160.00
 340.0000    159.09
 345.0000    163.67
 350.0000    159.84
 355.0000    162.50
; (Data for Range number 9)
_DRIVE='PHI'
_STEPTIME=11.999800
_STEPSIZE=5.000000
_STEPMODE='C'
_START=0.000000
_THETA=27.283001
_2THETA=54.566002
_KHI=40.000000
_PHI=0.000000
_X=0.000000
_Y=0.000000
_Z=0.000000
_DIVERGENCE=0.200000
_ANTISCATTER=0.200000
_DETECTOR=1
; S.C.
_HV=683.500000
_GAIN=80.000000
_LLD=0.788000
_ULD=2.160000
_DETECTORSLIT='out'
_AUX1=0.000000
_AUX2=0.000000
_AUX3=0.000000
_TIMESTARTED=6971.000000
_TEMP_RATE=0.000000
_TEMP_DELAY=0.000000
_KV=40
_MA=30
_RANGE_WL=1.540600
_3DPLANE=0
_2THETACPS
   0.0000    157.50
   5.0000    156.92
  10.0000    159.17
  15.0000    164.92
  20.0000    155.84
  25.0000    157.92
  30.0000    160.17
  35.0000    154.92
  40.0000    145.09
  45.0000    158.92
  50.0000    154.34
  55.0000    160.34
  60.0000    151.50
  65.0000    144.67
  70.0000    143.00
  75.0000    136.17
  80.0000    138.42
  85.0000    134.75
  90.0000    140.00
  95.0000    140.92
 100.0000    136.00
 105.0000    144.17
 110.0000    134.09
 115.0000    143.00
 120.0000    147.75
 125.0000    149.59
 130.0000    158.00
 135.0000    162.25
 140.0000    161.42
 145.0000    172.34
 150.0000    166.09
 155.0000    167.84
 160.0000    159.25
 165.0000    165.59
 170.0000    160.17
 175.0000    151.59
 180.0000    156.25
 185.0000    152.92
 190.0000    161.92
 195.0000    171.17
 200.0000    173.67
 205.0000    166.75
 210.0000    167.50
 215.0000    157.00
 220.0000    164.50
 225.0000    157.42
 230.0000    152.34
 235.0000    153.17
 240.0000    147.67
 245.0000    151.42
 250.0000    156.17
 255.0000    148.75
 260.0000    143.84
 265.0000    140.92
 270.0000    138.25
 275.0000    136.42
 280.0000    129.17
 285.0000    130.17
 290.0000    129.00
 295.0000    139.17
 300.0000    134.67
 305.0000    142.50
 310.0000    143.59
 315.0000    151.67
 320.0000    150.50
 325.0000    149.92
 330.0000    159.17
 335.0000    163.50
 340.0000    152.17
 345.0000    156.84
 350.0000    152.59
 355.0000    160.75
; (Data for Range number 10)
_DRIVE='PHI'
_STEPTIME=11.999800
_STEPSIZE=5.000000
_STEPMODE='C'
_START=0.000000
_THETA=27.283001
_2THETA=54.566002
_KHI=45.000000
_PHI=0.000000
_X=0.000000
_Y=0.000000
_Z=0.000000
_DIVERGENCE=0.200000
_ANTISCATTER=0.200000
_DETECTOR=1
; S.C.
_HV=683.500000
_GAIN=80.000000
_LLD=0.788000
_ULD=2.160000
_DETECTORSLIT='out'
_AUX1=0.000000
_AUX2=0.000000
_AUX3=0.000000
_TIMESTARTED=7839.000000
_TEMP_RATE=0.000000
_TEMP_DELAY=0.000000
_KV=40
_MA=30
_RANGE_WL=1.540600
_3DPLANE=0
_2THETACPS
   0.0000    162.84
   5.0000    156.59
  10.0000    158.84
  15.0000    153.92
  20.0000    162.67
  25.0000    160.17
  30.0000    144.34
  35.0000    151.00
  40.0000    150.42
  45.0000    159.67
  50.0000    149.75
  55.0000    140.42
  60.0000    144.50
  65.0000    137.09
  70.0000    137.00
  75.0000    140.34
  80.0000    132.50
  85.0000    139.34
  90.0000    136.17
  95.0000    137.59
 100.0000    129.09
 105.0000    133.67
 110.0000    132.42
 115.0000    133.00
 120.0000    130.17
 125.0000    146.17
 130.0000    138.92
 135.0000    154.17
 140.0000    149.75
 145.0000    161.09
 150.0000    164.50
 155.0000    163.75
 160.0000    166.34
 165.0000    157.75
 170.0000    145.17
 175.0000    150.34
 180.0000    145.50
 185.0000    148.25
 190.0000    156.42
 195.0000    159.17
 200.0000    170.17
 205.0000    174.50
 210.0000    158.75
 215.0000    163.00
 220.0000    155.59
 225.0000    158.67
 230.0000    152.84
 235.0000    151.42
 240.0000    155.17
 245.0000    148.00
 250.0000    147.67
 255.0000    145.67
 260.0000    146.67
 265.0000    140.00
 270.0000    133.92
 275.0000    136.34
 280.0000    130.59
 285.0000    127.17
 290.0000    133.84
 295.0000    132.50
 300.0000    128.92
 305.0000    142.50
 310.0000    144.59
 315.0000    137.50
 320.0000    162.50
 325.0000    144.42
 330.0000    146.67
 335.0000    153.09
 340.0000    149.00
 345.0000    151.84
 350.0000    148.25
 355.0000    152.42
; (Data for Range number 11)
_DRIVE='PHI'
_STEPTIME=11.999800
_STEPSIZE=5.000000
_STEPMODE='C'
_START=0.000000
_THETA=27.283001
_2THETA=54.566002
_KHI=50.000000
_PHI=0.000000
_X=0.000000
_Y=0.000000
_Z=0.000000
_DIVERGENCE=0.200000
_ANTISCATTER=0.200000
_DETECTOR=1
; S.C.
_HV=683.500000
_GAIN=80.000000
_LLD=0.788000
_ULD=2.160000
_DETECTORSLIT='out'
_AUX1=0.000000
_AUX2=0.000000
_AUX3=0.000000
_TIMESTARTED=8708.000000
_TEMP_RATE=0.000000
_TEMP_DELAY=0.000000
_KV=40
_MA=30
_RANGE_WL=1.540600
_3DPLANE=0
_2THETACPS
   0.0000    148.67
   5.0000    151.00
  10.0000    152.67
  15.0000    149.67
  20.0000    147.59
  25.0000    147.92
  30.0000    149.25
  35.0000    142.67
  40.0000    141.67
  45.0000    140.34
  50.0000    145.59
  55.0000    147.42
  60.0000    136.09
  65.0000    130.92
  70.0000    143.09
  75.0000    145.84
  80.0000    128.75
  85.0000    131.09
  90.0000    127.34
  95.0000    125.67
 100.0000    127.34
 105.0000    125.25
 110.0000    128.17
 115.0000    124.75
 120.0000    139.25
 125.0000    125.50
 130.0000    146.09
 135.0000    144.84
 140.0000    149.50
 145.0000    162.92
 150.0000    163.42
 155.0000    166.42
 160.0000    161.09
 165.0000    150.67
 170.0000    134.17
 175.0000    139.59
 180.0000    136.50
 185.0000    132.42
 190.0000    157.25
 195.0000    155.50
 200.0000    158.75
 205.0000    151.92
 210.0000    156.92
 215.0000    149.00
 220.0000    154.59
 225.0000    149.00
 230.0000    149.34
 235.0000    149.34
 240.0000    144.59
 245.0000    147.59
 250.0000    147.92
 255.0000    149.67
 260.0000    136.09
 265.0000    142.75
 270.0000    130.34
 275.0000    118.50
 280.0000    126.67
 285.0000    131.59
 290.0000    125.50
 295.0000    133.75
 300.0000    137.00
 305.0000    139.75
 310.0000    151.09
 315.0000    150.25
 320.0000    148.42
 325.0000    146.75
 330.0000    147.25
 335.0000    152.59
 340.0000    147.17
 345.0000    155.42
 350.0000    143.59
 355.0000    138.17
; (Data for Range number 12)
_DRIVE='PHI'
_STEPTIME=11.999800
_STEPSIZE=5.000000
_STEPMODE='C'
_START=0.000000
_THETA=27.283001
_2THETA=54.566002
_KHI=55.000000
_PHI=0.000000
_X=0.000000
_Y=0.000000
_Z=0.000000
_DIVERGENCE=0.200000
_ANTISCATTER=0.200000
_DETECTOR=1
; S.C.
_HV=683.500000
_GAIN=80.000000
_LLD=0.788000
_ULD=2.160000
_DETECTORSLIT='out'
_AUX1=0.000000
_AUX2=0.000000
_AUX3=0.000000
_TIMESTARTED=9577.000000
_TEMP_RATE=0.000000
_TEMP_DELAY=0.000000
_KV=40
_MA=30
_RANGE_WL=1.540600
_3DPLANE=0
_2THETACPS
   0.0000    139.59
   5.0000    143.00
  10.0000    152.17
  15.0000    147.00
  20.0000    145.92
  25.0000    142.84
  30.0000    138.67
  35.0000    143.84
  40.0000    129.75
  45.0000    131.92
  50.0000    140.67
  55.0000    133.67
  60.0000    137.59
  65.0000    126.84
  70.0000    129.17
  75.0000    142.17
  80.0000    136.09
  85.0000    131.67
  90.0000    132.09
  95.0000    124.00
 100.0000    120.50
 105.0000    118.92
 110.0000    126.50
 115.0000    121.92
 120.0000    122.34
 125.0000    129.09
 130.0000    130.17
 135.0000    139.17
 140.0000    142.42
 145.0000    141.92
 150.0000    155.34
 155.0000    154.67
 160.0000    152.59
 165.0000    148.17
 170.0000    142.75
 175.0000    137.09
 180.0000    133.42
 185.0000    145.17
 190.0000    140.17
 195.0000    148.59
 200.0000    153.50
 205.0000    146.50
 210.0000    141.25
 215.0000    146.92
 220.0000    140.09
 225.0000    147.75
 230.0000    145.17
 235.0000    145.25
 240.0000    136.00
 245.0000    140.34
 250.0000    141.00
 255.0000    139.09
 260.0000    133.42
 265.0000    136.84
 270.0000    134.25
 275.0000    128.84
 280.0000    119.75
 285.0000    120.34
 290.0000    128.59
 295.0000    125.50
 300.0000    133.00
 305.0000    129.09
 310.0000    138.42
 315.0000    133.67
 320.0000    147.42
 325.0000    136.92
 330.0000    138.09
 335.0000    144.09
 340.0000    137.84
 345.0000    132.42
 350.0000    144.67
 355.0000    127.25
; (Data for Range number 13)
_DRIVE='PHI'
_STEPTIME=11.999800
_STEPSIZE=5.000000
_STEPMODE='C'
_START=0.000000
_THETA=27.283001
_2THETA=54.566002
_KHI=60.000000
_PHI=0.000000
_X=0.000000
_Y=0.000000
_Z=0.000000
_DIVERGENCE=0.200000
_ANTISCATTER=0.200000
_DETECTOR=1
; S.C.
_HV=683.500000
_GAIN=80.000000
_LLD=0.788000
_ULD=2.160000
_DETECTORSLIT='out'
_AUX1=0.000000
_AUX2=0.000000
_AUX3=0.000000
_TIMESTARTED=10445.000000
_TEMP_RATE=0.000000
_TEMP_DELAY=0.000000
_KV=40
_MA=30
_RANGE_WL=1.540600
_3DPLANE=0
_2THETACPS
   0.0000    131.67
   5.0000    136.00
  10.0000    137.67
  15.0000    142.17
  20.0000    140.42
  25.0000    134.84
  30.0000    128.67
  35.0000    132.00
  40.0000    127.84
  45.0000    129.75
  50.0000    130.09
  55.0000    124.84
  60.0000    124.50
  65.0000    122.25
  70.0000    128.25
  75.0000    127.67
  80.0000    125.75
  85.0000    122.09
  90.0000    126.42
  95.0000    119.42
 100.0000    113.34
 105.0000    117.67
 110.0000    123.75
 115.0000    114.84
 120.0000    122.59
 125.0000    117.84
 130.0000    124.42
 135.0000    128.00
 140.0000    136.00
 145.0000    137.75
 150.0000    146.09
 155.0000    149.84
 160.0000    150.84
 165.0000    144.25
 170.0000    139.50
 175.0000    124.67
 180.0000    122.00
 185.0000    134.34
 190.0000    132.92
 195.0000    147.59
 200.0000    135.59
 205.0000    145.67
 210.0000    142.09
 215.0000    142.42
 220.0000    138.17
 225.0000    136.75
 230.0000    135.92
 235.0000    136.17
 240.0000    130.09
 245.0000    131.09
 250.0000    140.09
 255.0000    136.50
 260.0000    129.17
 265.0000    136.00
 270.0000    126.92
 275.0000    122.09
 280.0000    119.50
 285.0000    121.09
 290.0000    117.75
 295.0000    123.34
 300.0000    125.67
 305.0000    135.59
 310.0000    124.92
 315.0000    131.75
 320.0000    137.84
 325.0000    137.67
 330.0000    137.25
 335.0000    136.00
 340.0000    136.50
 345.0000    130.75
 350.0000    130.09
 355.0000    131.25
; (Data for Range number 14)
_DRIVE='PHI'
_STEPTIME=11.999800
_STEPSIZE=5.000000
_STEPMODE='C'
_START=0.000000
_THETA=27.283001
_2THETA=54.566002
_KHI=65.000000
_PHI=0.000000
_X=0.000000
_Y=0.000000
_Z=0.000000
_DIVERGENCE=0.200000
_ANTISCATTER=0.200000
_DETECTOR=1
; S.C.
_HV=683.500000
_GAIN=80.000000
_LLD=0.788000
_ULD=2.160000
_DETECTORSLIT='out'
_AUX1=0.000000
_AUX2=0.000000
_AUX3=0.000000
_TIMESTARTED=11314.000000
_TEMP_RATE=0.000000
_TEMP_DELAY=0.000000
_KV=40
_MA=30
_RANGE_WL=1.540600
_3DPLANE=0
_2THETACPS
   0.0000    118.67
   5.0000    123.34
  10.0000    127.84
  15.0000    125.84
  20.0000    133.84
  25.0000    130.34
  30.0000    123.17
  35.0000    120.59
  40.0000    121.17
  45.0000    125.17
  50.0000    130.84
  55.0000    119.92
  60.0000    116.75
  65.0000    116.59
  70.0000    107.84
  75.0000    118.17
  80.0000    125.42
  85.0000    118.84
  90.0000    116.00
  95.0000    110.00
 100.0000    110.84
 105.0000    113.09
 110.0000    114.34
 115.0000    112.59
 120.0000    112.09
 125.0000    107.67
 130.0000    116.92
 135.0000    120.09
 140.0000    122.92
 145.0000    132.00
 150.0000    129.50
 155.0000    138.25
 160.0000    137.84
 165.0000    140.00
 170.0000    132.67
 175.0000    124.17
 180.0000    119.67
 185.0000    126.25
 190.0000    126.84
 195.0000    134.75
 200.0000    136.75
 205.0000    135.75
 210.0000    128.59
 215.0000    119.75
 220.0000    131.09
 225.0000    126.59
 230.0000    131.67
 235.0000    137.42
 240.0000    133.50
 245.0000    129.25
 250.0000    129.25
 255.0000    127.50
 260.0000    130.00
 265.0000    126.17
 270.0000    117.59
 275.0000    112.67
 280.0000    110.84
 285.0000    107.09
 290.0000    107.92
 295.0000    114.09
 300.0000    112.34
 305.0000    124.67
 310.0000    122.42
 315.0000    125.00
 320.0000    136.75
 325.0000    134.50
 330.0000    130.67
 335.0000    133.84
 340.0000    123.84
 345.0000    122.17
 350.0000    124.59
 355.0000    111.59
; (Data for Range number 15)
_DRIVE='PHI'
_STEPTIME=11.999800
_STEPSIZE=5.000000
_STEPMODE='C'
_START=0.000000
_THETA=27.283001
_2THETA=54.566002
_KHI=70.000000
_PHI=0.000000
_X=0.000000
_Y=0.000000
_Z=0.000000
_DIVERGENCE=0.200000
_ANTISCATTER=0.200000
_DETECTOR=1
; S.C.
_HV=683.500000
_GAIN=80.000000
_LLD=0.788000
_ULD=2.160000
_DETECTORSLIT='out'
_AUX1=0.000000
_AUX2=0.000000
_AUX3=0.000000
_TIMESTARTED=12183.000000
_TEMP_RATE=0.000000
_TEMP_DELAY=0.000000
_KV=40
_MA=30
_RANGE_WL=1.540600
_3DPLANE=0
_2THETACPS
   0.0000    104.42
   5.0000    105.25
  10.0000    118.09
  15.0000    118.00
  20.0000    122.25
  25.0000    119.09
  30.0000    111.75
  35.0000    106.34
  40.0000    111.59
  45.0000    107.67
  50.0000    108.92
  55.0000    109.17
  60.0000    101.00
  65.0000    102.59
  70.0000    96.835
  75.0000    107.50
  80.0000    111.59
  85.0000    104.67
  90.0000    107.00
  95.0000    98.168
 100.0000    103.09
 105.0000    100.09
 110.0000    98.168
 115.0000    101.59
 120.0000    101.67
 125.0000    104.25
 130.0000    101.92
 135.0000    109.75
 140.0000    114.50
 145.0000    110.25
 150.0000    121.50
 155.0000    125.00
 160.0000    125.42
 165.0000    116.34
 170.0000    115.09
 175.0000    113.59
 180.0000    105.75
 185.0000    108.84
 190.0000    111.92
 195.0000    116.09
 200.0000    120.25
 205.0000    118.09
 210.0000    113.59
 215.0000    109.92
 220.0000    113.25
 225.0000    116.34
 230.0000    120.75
 235.0000    123.75
 240.0000    113.50
 245.0000    117.67
 250.0000    117.00
 255.0000    120.75
 260.0000    112.84
 265.0000    110.09
 270.0000    113.09
 275.0000    105.92
 280.0000    102.50
 285.0000    104.25
 290.0000    96.835
 295.0000    98.585
 300.0000    103.67
 305.0000    109.92
 310.0000    109.50
 315.0000    117.25
 320.0000    113.34
 325.0000    118.42
 330.0000    109.75
 335.0000    115.42
 340.0000    118.50
 345.0000    114.75
 350.0000    107.09
 355.0000    111.17
; (Data for Range number 16)
_DRIVE='PHI'
_STEPTIME=11.999800
_STEPSIZE=5.000000
_STEPMODE='C'
_START=0.000000
_THETA=27.283001
_2THETA=54.566002
_KHI=75.000000
_PHI=0.000000
_X=0.000000
_Y=0.000000
_Z=0.000000
_DIVERGENCE=0.200000
_ANTISCATTER=0.200000
_DETECTOR=1
; S.C.
_HV=683.500000
_GAIN=80.000000
_LLD=0.788000
_ULD=2.160000
_DETECTORSLIT='out'
_AUX1=0.000000
_AUX2=0.000000
_AUX3=0.000000
_TIMESTARTED=13051.000000
_TEMP_RATE=0.000000
_TEMP_DELAY=0.000000
_KV=40
_MA=30
_RANGE_WL=1.540600
_3DPLANE=0
_2THETACPS
   0.0000    82.251
   5.0000    87.835
  10.0000    89.918
  15.0000    92.585
  20.0000    95.002
  25.0000    97.335
  30.0000    93.585
  35.0000    87.835
  40.0000    92.335
  45.0000    89.668
  50.0000    93.335
  55.0000    83.668
  60.0000    88.001
  65.0000    77.751
  70.0000    77.668
  75.0000    82.835
  80.0000    86.751
  85.0000    87.418
  90.0000    92.752
  95.0000    90.418
 100.0000    82.668
 105.0000    79.918
 110.0000    82.001
 115.0000    76.751
 120.0000    85.751
 125.0000    83.501
 130.0000    84.001
 135.0000    88.085
 140.0000    91.418
 145.0000    97.168
 150.0000    97.418
 155.0000    99.418
 160.0000    99.168
 165.0000    100.84
 170.0000    96.668
 175.0000    93.668
 180.0000    82.001
 185.0000    82.585
 190.0000    88.335
 195.0000    98.668
 200.0000    95.918
 205.0000    97.335
 210.0000    91.585
 215.0000    86.085
 220.0000    95.168
 225.0000    93.335
 230.0000    96.002
 235.0000    97.335
 240.0000    97.835
 245.0000    99.585
 250.0000    95.502
 255.0000    99.752
 260.0000    98.168
 265.0000    90.418
 270.0000    86.085
 275.0000    89.501
 280.0000    84.085
 285.0000    84.751
 290.0000    81.418
 295.0000    80.918
 300.0000    82.251
 305.0000    86.751
 310.0000    91.002
 315.0000    89.335
 320.0000    89.335
 325.0000    88.335
 330.0000    89.085
 335.0000    94.085
 340.0000    92.668
 345.0000    93.002
 350.0000    82.585
 355.0000    83.335