File: mtex-5.1.1/data/PoleFigure/ZnCuTi/ZnCuTi_defocusing_PF_002_R.UXD
; C:\Users\Stanis³aw\OneDrive\Documents\paracamgr\DANE DO MGR\24.03.2015\tekstura\TExtura\Defokusacja\ZnCuTi_defokusacja_PF_002_R.raw(Diffrac Plus V1.01 file) converted by XCH V1.0
_FILEVERSION=2
_SITE='Poland'
_USER='Administrator'
_SAMPLE_CHANGER_CODE=0
_ATTACHMENTS_CODE=0
_GONIOMETER_RADIUS=300.000000
_FIXED_DIVSLIT=0.600000
_FIXED_SAMPLESLIT=1.000000
_FIXED_DETSLIT=0.100000
_MONOCHROMATOR=0
; None
_THIN_FILM='N'
_BETA_FILTER='N'
_FIXED_ANTISLIT=0.600000
_ANALYZER_CODE=0
; None
_DATEMEASURED='31-Mar-2015 18:18:20'
_WL_UNIT='A'
_WL1=1.540600
_WL2=1.544390
_WL3=1.392220
_WLRATIO=0.500000
_ANODE='Cu'
; (Data for Range number 1)
_DRIVE='PHI'
_STEPTIME=11.999800
_STEPSIZE=5.000000
_STEPMODE='C'
_START=0.000000
_THETA=18.270000
_2THETA=36.540001
_KHI=0.000000
_PHI=0.000000
_X=0.000000
_Y=0.000000
_Z=0.000000
_DIVERGENCE=0.200000
_ANTISCATTER=0.200000
_DETECTOR=1
; S.C.
_HV=683.500000
_GAIN=80.000000
_LLD=0.788000
_ULD=2.160000
_DETECTORSLIT='out'
_AUX1=0.000000
_AUX2=0.000000
_AUX3=0.000000
_TIMESTARTED=22.000000
_TEMP_RATE=0.000000
_TEMP_DELAY=0.000000
_KV=40
_MA=30
_RANGE_WL=1.540600
_3DPLANE=0
_2THETACPS
   0.0000    234.75
   5.0000    242.92
  10.0000    253.25
  15.0000    250.84
  20.0000    211.75
  25.0000    243.34
  30.0000    237.59
  35.0000    228.84
  40.0000    249.84
  45.0000    248.09
  50.0000    227.67
  55.0000    243.09
  60.0000    229.25
  65.0000    232.59
  70.0000    221.84
  75.0000    219.42
  80.0000    230.92
  85.0000    220.34
  90.0000    229.59
  95.0000    260.59
 100.0000    252.42
 105.0000    231.92
 110.0000    247.42
 115.0000    245.75
 120.0000    232.00
 125.0000    227.25
 130.0000    226.50
 135.0000    222.84
 140.0000    208.59
 145.0000    206.25
 150.0000    215.00
 155.0000    194.84
 160.0000    195.50
 165.0000    207.17
 170.0000    200.75
 175.0000    198.92
 180.0000    208.92
 185.0000    205.75
 190.0000    234.00
 195.0000    228.84
 200.0000    227.09
 205.0000    234.17
 210.0000    226.17
 215.0000    240.09
 220.0000    246.50
 225.0000    261.25
 230.0000    230.00
 235.0000    225.09
 240.0000    229.67
 245.0000    228.34
 250.0000    240.09
 255.0000    227.17
 260.0000    225.00
 265.0000    199.92
 270.0000    202.75
 275.0000    207.75
 280.0000    200.25
 285.0000    192.84
 290.0000    192.50
 295.0000    190.59
 300.0000    185.17
 305.0000    186.67
 310.0000    182.25
 315.0000    188.67
 320.0000    183.67
 325.0000    199.34
 330.0000    210.17
 335.0000    193.75
 340.0000    224.25
 345.0000    249.00
 350.0000    242.67
 355.0000    258.00
; (Data for Range number 2)
_DRIVE='PHI'
_STEPTIME=11.999800
_STEPSIZE=5.000000
_STEPMODE='C'
_START=0.000000
_THETA=18.270000
_2THETA=36.540001
_KHI=5.000000
_PHI=0.000000
_X=0.000000
_Y=0.000000
_Z=0.000000
_DIVERGENCE=0.200000
_ANTISCATTER=0.200000
_DETECTOR=1
; S.C.
_HV=683.500000
_GAIN=80.000000
_LLD=0.788000
_ULD=2.160000
_DETECTORSLIT='out'
_AUX1=0.000000
_AUX2=0.000000
_AUX3=0.000000
_TIMESTARTED=891.000000
_TEMP_RATE=0.000000
_TEMP_DELAY=0.000000
_KV=40
_MA=30
_RANGE_WL=1.540600
_3DPLANE=0
_2THETACPS
   0.0000    229.34
   5.0000    275.25
  10.0000    215.34
  15.0000    264.92
  20.0000    295.84
  25.0000    244.42
  30.0000    227.09
  35.0000    222.92
  40.0000    217.00
  45.0000    213.09
  50.0000    236.84
  55.0000    215.25
  60.0000    249.50
  65.0000    219.50
  70.0000    345.09
  75.0000    234.25
  80.0000    231.84
  85.0000    368.76
  90.0000    349.34
  95.0000    235.25
 100.0000    317.67
 105.0000    247.09
 110.0000    228.59
 115.0000    219.92
 120.0000    241.00
 125.0000    243.59
 130.0000    221.50
 135.0000    229.09
 140.0000    236.75
 145.0000    242.00
 150.0000    239.42
 155.0000    229.59
 160.0000    224.00
 165.0000    221.25
 170.0000    213.50
 175.0000    205.09
 180.0000    197.59
 185.0000    213.67
 190.0000    232.67
 195.0000    249.00
 200.0000    226.67
 205.0000    235.34
 210.0000    241.67
 215.0000    235.25
 220.0000    224.92
 225.0000    226.25
 230.0000    239.59
 235.0000    235.59
 240.0000    302.17
 245.0000    254.75
 250.0000    217.67
 255.0000    213.00
 260.0000    232.75
 265.0000    219.92
 270.0000    213.42
 275.0000    215.67
 280.0000    223.67
 285.0000    260.00
 290.0000    227.67
 295.0000    204.75
 300.0000    205.42
 305.0000    207.75
 310.0000    186.59
 315.0000    198.59
 320.0000    201.17
 325.0000    203.67
 330.0000    215.67
 335.0000    189.75
 340.0000    246.00
 345.0000    221.50
 350.0000    227.17
 355.0000    209.42
; (Data for Range number 3)
_DRIVE='PHI'
_STEPTIME=11.999800
_STEPSIZE=5.000000
_STEPMODE='C'
_START=0.000000
_THETA=18.270000
_2THETA=36.540001
_KHI=10.000000
_PHI=0.000000
_X=0.000000
_Y=0.000000
_Z=0.000000
_DIVERGENCE=0.200000
_ANTISCATTER=0.200000
_DETECTOR=1
; S.C.
_HV=683.500000
_GAIN=80.000000
_LLD=0.788000
_ULD=2.160000
_DETECTORSLIT='out'
_AUX1=0.000000
_AUX2=0.000000
_AUX3=0.000000
_TIMESTARTED=1760.000000
_TEMP_RATE=0.000000
_TEMP_DELAY=0.000000
_KV=40
_MA=30
_RANGE_WL=1.540600
_3DPLANE=0
_2THETACPS
   0.0000    227.75
   5.0000    219.84
  10.0000    227.92
  15.0000    224.59
  20.0000    231.75
  25.0000    240.25
  30.0000    222.67
  35.0000    223.09
  40.0000    235.00
  45.0000    216.17
  50.0000    251.00
  55.0000    236.84
  60.0000    218.84
  65.0000    219.75
  70.0000    259.00
  75.0000    228.17
  80.0000    224.09
  85.0000    222.09
  90.0000    236.84
  95.0000    238.25
 100.0000    225.84
 105.0000    243.09
 110.0000    231.84
 115.0000    216.92
 120.0000    234.09
 125.0000    219.59
 130.0000    242.34
 135.0000    221.59
 140.0000    224.92
 145.0000    295.17
 150.0000    216.34
 155.0000    283.59
 160.0000    231.50
 165.0000    210.59
 170.0000    212.50
 175.0000    242.00
 180.0000    230.59
 185.0000    214.09
 190.0000    215.34
 195.0000    229.50
 200.0000    225.17
 205.0000    253.42
 210.0000    220.92
 215.0000    256.75
 220.0000    224.25
 225.0000    314.42
 230.0000    278.84
 235.0000    230.09
 240.0000    287.17
 245.0000    252.42
 250.0000    239.92
 255.0000    255.25
 260.0000    242.42
 265.0000    292.59
 270.0000    233.42
 275.0000    206.00
 280.0000    212.59
 285.0000    201.42
 290.0000    246.92
 295.0000    214.59
 300.0000    190.25
 305.0000    199.09
 310.0000    190.59
 315.0000    199.59
 320.0000    218.17
 325.0000    210.25
 330.0000    210.34
 335.0000    213.92
 340.0000    200.17
 345.0000    211.92
 350.0000    233.75
 355.0000    206.17
; (Data for Range number 4)
_DRIVE='PHI'
_STEPTIME=11.999800
_STEPSIZE=5.000000
_STEPMODE='C'
_START=0.000000
_THETA=18.270000
_2THETA=36.540001
_KHI=15.000000
_PHI=0.000000
_X=0.000000
_Y=0.000000
_Z=0.000000
_DIVERGENCE=0.200000
_ANTISCATTER=0.200000
_DETECTOR=1
; S.C.
_HV=683.500000
_GAIN=80.000000
_LLD=0.788000
_ULD=2.160000
_DETECTORSLIT='out'
_AUX1=0.000000
_AUX2=0.000000
_AUX3=0.000000
_TIMESTARTED=2628.000000
_TEMP_RATE=0.000000
_TEMP_DELAY=0.000000
_KV=40
_MA=30
_RANGE_WL=1.540600
_3DPLANE=0
_2THETACPS
   0.0000    206.59
   5.0000    237.75
  10.0000    229.75
  15.0000    234.34
  20.0000    238.67
  25.0000    231.09
  30.0000    227.34
  35.0000    234.84
  40.0000    223.00
  45.0000    245.75
  50.0000    230.42
  55.0000    217.67
  60.0000    218.34
  65.0000    226.75
  70.0000    228.17
  75.0000    229.67
  80.0000    240.00
  85.0000    238.42
  90.0000    314.76
  95.0000    228.59
 100.0000    219.34
 105.0000    221.67
 110.0000    242.09
 115.0000    234.25
 120.0000    239.34
 125.0000    213.59
 130.0000    218.75
 135.0000    233.17
 140.0000    230.17
 145.0000    250.17
 150.0000    225.42
 155.0000    222.92
 160.0000    273.00
 165.0000    231.84
 170.0000    209.75
 175.0000    214.34
 180.0000    232.92
 185.0000    245.09
 190.0000    207.17
 195.0000    232.17
 200.0000    227.50
 205.0000    219.42
 210.0000    237.92
 215.0000    217.75
 220.0000    226.42
 225.0000    253.50
 230.0000    264.09
 235.0000    289.67
 240.0000    214.50
 245.0000    202.25
 250.0000    214.67
 255.0000    215.75
 260.0000    220.75
 265.0000    208.59
 270.0000    221.34
 275.0000    231.84
 280.0000    206.42
 285.0000    206.59
 290.0000    208.59
 295.0000    197.25
 300.0000    190.50
 305.0000    214.59
 310.0000    193.25
 315.0000    215.09
 320.0000    223.09
 325.0000    215.59
 330.0000    265.92
 335.0000    222.17
 340.0000    225.92
 345.0000    235.92
 350.0000    228.59
 355.0000    211.34
; (Data for Range number 5)
_DRIVE='PHI'
_STEPTIME=11.999800
_STEPSIZE=5.000000
_STEPMODE='C'
_START=0.000000
_THETA=18.270000
_2THETA=36.540001
_KHI=20.000000
_PHI=0.000000
_X=0.000000
_Y=0.000000
_Z=0.000000
_DIVERGENCE=0.200000
_ANTISCATTER=0.200000
_DETECTOR=1
; S.C.
_HV=683.500000
_GAIN=80.000000
_LLD=0.788000
_ULD=2.160000
_DETECTORSLIT='out'
_AUX1=0.000000
_AUX2=0.000000
_AUX3=0.000000
_TIMESTARTED=3497.000000
_TEMP_RATE=0.000000
_TEMP_DELAY=0.000000
_KV=40
_MA=30
_RANGE_WL=1.540600
_3DPLANE=0
_2THETACPS
   0.0000    217.84
   5.0000    226.42
  10.0000    219.75
  15.0000    244.42
  20.0000    239.59
  25.0000    235.92
  30.0000    232.84
  35.0000    218.67
  40.0000    217.75
  45.0000    230.59
  50.0000    222.42
  55.0000    221.59
  60.0000    216.50
  65.0000    232.09
  70.0000    237.75
  75.0000    227.67
  80.0000    226.00
  85.0000    214.00
  90.0000    217.17
  95.0000    199.92
 100.0000    209.17
 105.0000    214.84
 110.0000    194.09
 115.0000    218.25
 120.0000    209.25
 125.0000    204.34
 130.0000    200.17
 135.0000    204.84
 140.0000    250.67
 145.0000    249.25
 150.0000    233.17
 155.0000    248.09
 160.0000    218.75
 165.0000    212.42
 170.0000    222.25
 175.0000    310.01
 180.0000    197.84
 185.0000    224.17
 190.0000    225.67
 195.0000    232.00
 200.0000    219.92
 205.0000    236.25
 210.0000    226.50
 215.0000    225.84
 220.0000    225.59
 225.0000    237.50
 230.0000    264.25
 235.0000    229.75
 240.0000    219.50
 245.0000    220.42
 250.0000    225.42
 255.0000    206.25
 260.0000    192.00
 265.0000    202.17
 270.0000    186.50
 275.0000    186.67
 280.0000    197.67
 285.0000    187.09
 290.0000    193.92
 295.0000    188.42
 300.0000    189.75
 305.0000    213.17
 310.0000    245.59
 315.0000    214.75
 320.0000    204.75
 325.0000    220.17
 330.0000    211.00
 335.0000    230.92
 340.0000    211.42
 345.0000    230.17
 350.0000    220.92
 355.0000    221.59
; (Data for Range number 6)
_DRIVE='PHI'
_STEPTIME=11.999800
_STEPSIZE=5.000000
_STEPMODE='C'
_START=0.000000
_THETA=18.270000
_2THETA=36.540001
_KHI=25.000000
_PHI=0.000000
_X=0.000000
_Y=0.000000
_Z=0.000000
_DIVERGENCE=0.200000
_ANTISCATTER=0.200000
_DETECTOR=1
; S.C.
_HV=683.500000
_GAIN=80.000000
_LLD=0.788000
_ULD=2.160000
_DETECTORSLIT='out'
_AUX1=0.000000
_AUX2=0.000000
_AUX3=0.000000
_TIMESTARTED=4366.000000
_TEMP_RATE=0.000000
_TEMP_DELAY=0.000000
_KV=40
_MA=30
_RANGE_WL=1.540600
_3DPLANE=0
_2THETACPS
   0.0000    232.67
   5.0000    239.75
  10.0000    238.59
  15.0000    225.75
  20.0000    213.75
  25.0000    227.00
  30.0000    234.67
  35.0000    240.25
  40.0000    231.75
  45.0000    207.75
  50.0000    234.67
  55.0000    237.92
  60.0000    226.67
  65.0000    202.25
  70.0000    217.92
  75.0000    197.67
  80.0000    206.34
  85.0000    199.17
  90.0000    199.17
  95.0000    201.50
 100.0000    216.42
 105.0000    208.75
 110.0000    212.75
 115.0000    210.92
 120.0000    187.92
 125.0000    190.92
 130.0000    198.42
 135.0000    260.67
 140.0000    230.50
 145.0000    214.09
 150.0000    211.84
 155.0000    213.84
 160.0000    226.59
 165.0000    215.00
 170.0000    226.34
 175.0000    200.50
 180.0000    199.25
 185.0000    201.67
 190.0000    204.17
 195.0000    247.92
 200.0000    228.50
 205.0000    208.42
 210.0000    217.09
 215.0000    231.59
 220.0000    226.59
 225.0000    228.92
 230.0000    206.75
 235.0000    309.92
 240.0000    203.25
 245.0000    208.17
 250.0000    214.75
 255.0000    212.42
 260.0000    191.09
 265.0000    204.17
 270.0000    198.34
 275.0000    182.92
 280.0000    200.17
 285.0000    177.00
 290.0000    196.34
 295.0000    202.67
 300.0000    189.92
 305.0000    214.25
 310.0000    187.92
 315.0000    213.59
 320.0000    207.75
 325.0000    204.84
 330.0000    212.84
 335.0000    229.84
 340.0000    233.34
 345.0000    242.17
 350.0000    227.50
 355.0000    225.50
; (Data for Range number 7)
_DRIVE='PHI'
_STEPTIME=11.999800
_STEPSIZE=5.000000
_STEPMODE='C'
_START=0.000000
_THETA=18.270000
_2THETA=36.540001
_KHI=30.000000
_PHI=0.000000
_X=0.000000
_Y=0.000000
_Z=0.000000
_DIVERGENCE=0.200000
_ANTISCATTER=0.200000
_DETECTOR=1
; S.C.
_HV=683.500000
_GAIN=80.000000
_LLD=0.788000
_ULD=2.160000
_DETECTORSLIT='out'
_AUX1=0.000000
_AUX2=0.000000
_AUX3=0.000000
_TIMESTARTED=5234.000000
_TEMP_RATE=0.000000
_TEMP_DELAY=0.000000
_KV=40
_MA=30
_RANGE_WL=1.540600
_3DPLANE=0
_2THETACPS
   0.0000    236.59
   5.0000    220.84
  10.0000    205.59
  15.0000    228.25
  20.0000    227.92
  25.0000    214.42
  30.0000    228.34
  35.0000    245.09
  40.0000    202.25
  45.0000    203.50
  50.0000    216.34
  55.0000    225.59
  60.0000    236.42
  65.0000    217.00
  70.0000    195.17
  75.0000    208.00
  80.0000    199.75
  85.0000    207.42
  90.0000    202.50
  95.0000    200.84
 100.0000    182.50
 105.0000    197.67
 110.0000    173.25
 115.0000    179.92
 120.0000    191.34
 125.0000    175.59
 130.0000    189.92
 135.0000    184.42
 140.0000    200.25
 145.0000    205.67
 150.0000    225.34
 155.0000    202.09
 160.0000    198.42
 165.0000    244.09
 170.0000    223.00
 175.0000    212.34
 180.0000    195.17
 185.0000    201.00
 190.0000    212.92
 195.0000    194.25
 200.0000    201.00
 205.0000    223.17
 210.0000    230.50
 215.0000    212.09
 220.0000    224.34
 225.0000    211.42
 230.0000    217.25
 235.0000    214.92
 240.0000    198.09
 245.0000    200.42
 250.0000    219.09
 255.0000    189.09
 260.0000    195.59
 265.0000    223.00
 270.0000    216.50
 275.0000    179.00
 280.0000    187.25
 285.0000    186.17
 290.0000    172.59
 295.0000    179.42
 300.0000    175.34
 305.0000    189.50
 310.0000    178.25
 315.0000    220.09
 320.0000    206.42
 325.0000    201.84
 330.0000    202.42
 335.0000    205.25
 340.0000    221.17
 345.0000    223.09
 350.0000    213.50
 355.0000    240.42
; (Data for Range number 8)
_DRIVE='PHI'
_STEPTIME=11.999800
_STEPSIZE=5.000000
_STEPMODE='C'
_START=0.000000
_THETA=18.270000
_2THETA=36.540001
_KHI=35.000000
_PHI=0.000000
_X=0.000000
_Y=0.000000
_Z=0.000000
_DIVERGENCE=0.200000
_ANTISCATTER=0.200000
_DETECTOR=1
; S.C.
_HV=683.500000
_GAIN=80.000000
_LLD=0.788000
_ULD=2.160000
_DETECTORSLIT='out'
_AUX1=0.000000
_AUX2=0.000000
_AUX3=0.000000
_TIMESTARTED=6103.000000
_TEMP_RATE=0.000000
_TEMP_DELAY=0.000000
_KV=40
_MA=30
_RANGE_WL=1.540600
_3DPLANE=0
_2THETACPS
   0.0000    204.09
   5.0000    239.25
  10.0000    205.17
  15.0000    223.92
  20.0000    229.25
  25.0000    217.34
  30.0000    231.50
  35.0000    202.34
  40.0000    196.17
  45.0000    201.84
  50.0000    219.59
  55.0000    223.00
  60.0000    231.84
  65.0000    220.34
  70.0000    187.67
  75.0000    206.84
  80.0000    188.17
  85.0000    183.34
  90.0000    183.42
  95.0000    194.09
 100.0000    184.34
 105.0000    178.42
 110.0000    182.09
 115.0000    187.92
 120.0000    173.67
 125.0000    174.59
 130.0000    176.17
 135.0000    184.75
 140.0000    198.09
 145.0000    195.25
 150.0000    209.42
 155.0000    210.84
 160.0000    218.25
 165.0000    234.09
 170.0000    200.84
 175.0000    202.67
 180.0000    182.92
 185.0000    185.92
 190.0000    193.84
 195.0000    187.00
 200.0000    216.09
 205.0000    190.75
 210.0000    207.67
 215.0000    197.17
 220.0000    207.34
 225.0000    204.75
 230.0000    188.59
 235.0000    184.59
 240.0000    186.59
 245.0000    195.84
 250.0000    207.84
 255.0000    188.25
 260.0000    195.59
 265.0000    192.09
 270.0000    182.17
 275.0000    182.09
 280.0000    178.00
 285.0000    180.92
 290.0000    170.34
 295.0000    162.34
 300.0000    184.34
 305.0000    179.84
 310.0000    195.92
 315.0000    202.09
 320.0000    207.92
 325.0000    189.84
 330.0000    196.92
 335.0000    204.67
 340.0000    212.59
 345.0000    209.00
 350.0000    213.00
 355.0000    205.84
; (Data for Range number 9)
_DRIVE='PHI'
_STEPTIME=11.999800
_STEPSIZE=5.000000
_STEPMODE='C'
_START=0.000000
_THETA=18.270000
_2THETA=36.540001
_KHI=40.000000
_PHI=0.000000
_X=0.000000
_Y=0.000000
_Z=0.000000
_DIVERGENCE=0.200000
_ANTISCATTER=0.200000
_DETECTOR=1
; S.C.
_HV=683.500000
_GAIN=80.000000
_LLD=0.788000
_ULD=2.160000
_DETECTORSLIT='out'
_AUX1=0.000000
_AUX2=0.000000
_AUX3=0.000000
_TIMESTARTED=6972.000000
_TEMP_RATE=0.000000
_TEMP_DELAY=0.000000
_KV=40
_MA=30
_RANGE_WL=1.540600
_3DPLANE=0
_2THETACPS
   0.0000    212.34
   5.0000    201.00
  10.0000    216.34
  15.0000    207.25
  20.0000    204.00
  25.0000    203.84
  30.0000    212.25
  35.0000    190.92
  40.0000    206.25
  45.0000    185.59
  50.0000    202.34
  55.0000    189.25
  60.0000    203.00
  65.0000    205.34
  70.0000    177.75
  75.0000    175.84
  80.0000    190.59
  85.0000    181.09
  90.0000    178.75
  95.0000    166.75
 100.0000    167.09
 105.0000    167.59
 110.0000    163.50
 115.0000    161.75
 120.0000    167.50
 125.0000    153.84
 130.0000    165.09
 135.0000    169.75
 140.0000    202.50
 145.0000    190.17
 150.0000    209.42
 155.0000    207.84
 160.0000    201.00
 165.0000    199.00
 170.0000    214.84
 175.0000    185.75
 180.0000    198.25
 185.0000    183.59
 190.0000    170.67
 195.0000    175.50
 200.0000    195.67
 205.0000    187.00
 210.0000    195.67
 215.0000    193.50
 220.0000    185.67
 225.0000    201.84
 230.0000    199.84
 235.0000    200.59
 240.0000    185.42
 245.0000    199.25
 250.0000    190.34
 255.0000    190.00
 260.0000    184.25
 265.0000    189.75
 270.0000    183.67
 275.0000    188.17
 280.0000    184.17
 285.0000    182.59
 290.0000    174.67
 295.0000    175.34
 300.0000    161.92
 305.0000    173.59
 310.0000    181.75
 315.0000    193.34
 320.0000    220.67
 325.0000    188.67
 330.0000    202.84
 335.0000    201.59
 340.0000    196.67
 345.0000    209.59
 350.0000    188.75
 355.0000    192.50
; (Data for Range number 10)
_DRIVE='PHI'
_STEPTIME=11.999800
_STEPSIZE=5.000000
_STEPMODE='C'
_START=0.000000
_THETA=18.270000
_2THETA=36.540001
_KHI=45.000000
_PHI=0.000000
_X=0.000000
_Y=0.000000
_Z=0.000000
_DIVERGENCE=0.200000
_ANTISCATTER=0.200000
_DETECTOR=1
; S.C.
_HV=683.500000
_GAIN=80.000000
_LLD=0.788000
_ULD=2.160000
_DETECTORSLIT='out'
_AUX1=0.000000
_AUX2=0.000000
_AUX3=0.000000
_TIMESTARTED=7841.000000
_TEMP_RATE=0.000000
_TEMP_DELAY=0.000000
_KV=40
_MA=30
_RANGE_WL=1.540600
_3DPLANE=0
_2THETACPS
   0.0000    180.84
   5.0000    183.34
  10.0000    191.59
  15.0000    201.34
  20.0000    181.84
  25.0000    190.92
  30.0000    211.50
  35.0000    210.92
  40.0000    182.75
  45.0000    179.17
  50.0000    183.67
  55.0000    185.92
  60.0000    181.42
  65.0000    185.34
  70.0000    220.09
  75.0000    172.92
  80.0000    174.17
  85.0000    169.59
  90.0000    174.34
  95.0000    157.09
 100.0000    155.34
 105.0000    167.75
 110.0000    159.67
 115.0000    148.00
 120.0000    154.42
 125.0000    168.92
 130.0000    173.34
 135.0000    159.09
 140.0000    172.75
 145.0000    190.50
 150.0000    209.25
 155.0000    197.00
 160.0000    208.75
 165.0000    195.59
 170.0000    203.75
 175.0000    178.34
 180.0000    177.75
 185.0000    170.59
 190.0000    178.50
 195.0000    169.92
 200.0000    186.50
 205.0000    208.67
 210.0000    188.42
 215.0000    186.84
 220.0000    174.75
 225.0000    181.92
 230.0000    185.59
 235.0000    189.34
 240.0000    185.50
 245.0000    184.75
 250.0000    172.75
 255.0000    169.34
 260.0000    173.17
 265.0000    188.67
 270.0000    166.34
 275.0000    174.67
 280.0000    180.25
 285.0000    157.25
 290.0000    160.42
 295.0000    163.00
 300.0000    158.42
 305.0000    170.59
 310.0000    165.84
 315.0000    178.25
 320.0000    183.09
 325.0000    181.25
 330.0000    218.50
 335.0000    187.00
 340.0000    192.25
 345.0000    193.67
 350.0000    183.50
 355.0000    186.17
; (Data for Range number 11)
_DRIVE='PHI'
_STEPTIME=11.999800
_STEPSIZE=5.000000
_STEPMODE='C'
_START=0.000000
_THETA=18.270000
_2THETA=36.540001
_KHI=50.000000
_PHI=0.000000
_X=0.000000
_Y=0.000000
_Z=0.000000
_DIVERGENCE=0.200000
_ANTISCATTER=0.200000
_DETECTOR=1
; S.C.
_HV=683.500000
_GAIN=80.000000
_LLD=0.788000
_ULD=2.160000
_DETECTORSLIT='out'
_AUX1=0.000000
_AUX2=0.000000
_AUX3=0.000000
_TIMESTARTED=8709.000000
_TEMP_RATE=0.000000
_TEMP_DELAY=0.000000
_KV=40
_MA=30
_RANGE_WL=1.540600
_3DPLANE=0
_2THETACPS
   0.0000    193.67
   5.0000    163.09
  10.0000    169.00
  15.0000    165.09
  20.0000    164.75
  25.0000    187.50
  30.0000    179.25
  35.0000    174.50
  40.0000    191.00
  45.0000    179.00
  50.0000    167.59
  55.0000    168.34
  60.0000    166.09
  65.0000    161.59
  70.0000    161.84
  75.0000    166.59
  80.0000    174.42
  85.0000    155.67
  90.0000    164.42
  95.0000    167.50
 100.0000    161.42
 105.0000    165.34
 110.0000    144.34
 115.0000    145.00
 120.0000    157.00
 125.0000    153.59
 130.0000    149.84
 135.0000    150.92
 140.0000    153.17
 145.0000    170.17
 150.0000    188.00
 155.0000    194.67
 160.0000    188.00
 165.0000    198.59
 170.0000    185.17
 175.0000    177.25
 180.0000    176.92
 185.0000    165.42
 190.0000    155.75
 195.0000    157.25
 200.0000    176.75
 205.0000    172.34
 210.0000    172.50
 215.0000    180.34
 220.0000    172.00
 225.0000    181.59
 230.0000    180.59
 235.0000    194.00
 240.0000    176.75
 245.0000    178.84
 250.0000    160.92
 255.0000    173.34
 260.0000    183.34
 265.0000    181.25
 270.0000    170.42
 275.0000    167.25
 280.0000    158.25
 285.0000    150.50
 290.0000    160.92
 295.0000    151.42
 300.0000    146.92
 305.0000    156.84
 310.0000    157.84
 315.0000    168.92
 320.0000    175.09
 325.0000    168.75
 330.0000    183.67
 335.0000    175.17
 340.0000    178.50
 345.0000    178.75
 350.0000    175.92
 355.0000    186.00
; (Data for Range number 12)
_DRIVE='PHI'
_STEPTIME=11.999800
_STEPSIZE=5.000000
_STEPMODE='C'
_START=0.000000
_THETA=18.270000
_2THETA=36.540001
_KHI=55.000000
_PHI=0.000000
_X=0.000000
_Y=0.000000
_Z=0.000000
_DIVERGENCE=0.200000
_ANTISCATTER=0.200000
_DETECTOR=1
; S.C.
_HV=683.500000
_GAIN=80.000000
_LLD=0.788000
_ULD=2.160000
_DETECTORSLIT='out'
_AUX1=0.000000
_AUX2=0.000000
_AUX3=0.000000
_TIMESTARTED=9578.000000
_TEMP_RATE=0.000000
_TEMP_DELAY=0.000000
_KV=40
_MA=30
_RANGE_WL=1.540600
_3DPLANE=0
_2THETACPS
   0.0000    160.84
   5.0000    159.50
  10.0000    164.34
  15.0000    153.50
  20.0000    182.50
  25.0000    172.50
  30.0000    171.59
  35.0000    181.09
  40.0000    174.59
  45.0000    161.75
  50.0000    165.25
  55.0000    166.50
  60.0000    158.50
  65.0000    156.59
  70.0000    153.09
  75.0000    140.75
  80.0000    147.25
  85.0000    150.92
  90.0000    163.75
  95.0000    150.75
 100.0000    158.17
 105.0000    148.34
 110.0000    162.92
 115.0000    145.75
 120.0000    147.00
 125.0000    149.50
 130.0000    146.92
 135.0000    144.67
 140.0000    165.67
 145.0000    155.84
 150.0000    176.34
 155.0000    191.84
 160.0000    185.50
 165.0000    173.42
 170.0000    170.34
 175.0000    161.17
 180.0000    164.09
 185.0000    179.59
 190.0000    163.67
 195.0000    174.67
 200.0000    172.17
 205.0000    175.17
 210.0000    175.42
 215.0000    167.09
 220.0000    158.92
 225.0000    200.25
 230.0000    182.67
 235.0000    172.75
 240.0000    163.17
 245.0000    171.59
 250.0000    165.75
 255.0000    160.09
 260.0000    158.92
 265.0000    173.25
 270.0000    169.84
 275.0000    164.59
 280.0000    154.84
 285.0000    154.25
 290.0000    142.17
 295.0000    145.59
 300.0000    148.84
 305.0000    144.17
 310.0000    150.25
 315.0000    173.00
 320.0000    162.42
 325.0000    166.00
 330.0000    161.00
 335.0000    177.25
 340.0000    166.67
 345.0000    163.09
 350.0000    152.34
 355.0000    149.67
; (Data for Range number 13)
_DRIVE='PHI'
_STEPTIME=11.999800
_STEPSIZE=5.000000
_STEPMODE='C'
_START=0.000000
_THETA=18.270000
_2THETA=36.540001
_KHI=60.000000
_PHI=0.000000
_X=0.000000
_Y=0.000000
_Z=0.000000
_DIVERGENCE=0.200000
_ANTISCATTER=0.200000
_DETECTOR=1
; S.C.
_HV=683.500000
_GAIN=80.000000
_LLD=0.788000
_ULD=2.160000
_DETECTORSLIT='out'
_AUX1=0.000000
_AUX2=0.000000
_AUX3=0.000000
_TIMESTARTED=10446.000000
_TEMP_RATE=0.000000
_TEMP_DELAY=0.000000
_KV=40
_MA=30
_RANGE_WL=1.540600
_3DPLANE=0
_2THETACPS
   0.0000    148.09
   5.0000    140.09
  10.0000    146.50
  15.0000    148.92
  20.0000    154.42
  25.0000    158.17
  30.0000    160.92
  35.0000    160.00
  40.0000    176.84
  45.0000    151.67
  50.0000    151.50
  55.0000    150.84
  60.0000    149.09
  65.0000    139.84
  70.0000    140.00
  75.0000    141.92
  80.0000    149.17
  85.0000    145.59
  90.0000    153.84
  95.0000    160.42
 100.0000    142.59
 105.0000    153.09
 110.0000    133.09
 115.0000    132.67
 120.0000    150.09
 125.0000    148.92
 130.0000    145.09
 135.0000    136.50
 140.0000    144.42
 145.0000    140.34
 150.0000    163.42
 155.0000    163.00
 160.0000    158.09
 165.0000    162.67
 170.0000    144.75
 175.0000    159.75
 180.0000    175.17
 185.0000    154.92
 190.0000    149.42
 195.0000    136.09
 200.0000    151.00
 205.0000    160.17
 210.0000    164.50
 215.0000    149.17
 220.0000    150.09
 225.0000    149.92
 230.0000    181.25
 235.0000    157.09
 240.0000    172.25
 245.0000    151.17
 250.0000    153.34
 255.0000    144.17
 260.0000    150.59
 265.0000    154.42
 270.0000    153.42
 275.0000    149.84
 280.0000    144.59
 285.0000    137.17
 290.0000    137.42
 295.0000    140.25
 300.0000    133.50
 305.0000    140.50
 310.0000    151.34
 315.0000    150.75
 320.0000    163.25
 325.0000    153.25
 330.0000    157.84
 335.0000    156.42
 340.0000    144.17
 345.0000    139.09
 350.0000    148.84
 355.0000    144.92
; (Data for Range number 14)
_DRIVE='PHI'
_STEPTIME=11.999800
_STEPSIZE=5.000000
_STEPMODE='C'
_START=0.000000
_THETA=18.270000
_2THETA=36.540001
_KHI=65.000000
_PHI=0.000000
_X=0.000000
_Y=0.000000
_Z=0.000000
_DIVERGENCE=0.200000
_ANTISCATTER=0.200000
_DETECTOR=1
; S.C.
_HV=683.500000
_GAIN=80.000000
_LLD=0.788000
_ULD=2.160000
_DETECTORSLIT='out'
_AUX1=0.000000
_AUX2=0.000000
_AUX3=0.000000
_TIMESTARTED=11315.000000
_TEMP_RATE=0.000000
_TEMP_DELAY=0.000000
_KV=40
_MA=30
_RANGE_WL=1.540600
_3DPLANE=0
_2THETACPS
   0.0000    130.75
   5.0000    143.34
  10.0000    135.25
  15.0000    130.25
  20.0000    140.17
  25.0000    134.00
  30.0000    149.42
  35.0000    146.09
  40.0000    149.59
  45.0000    142.25
  50.0000    133.34
  55.0000    138.84
  60.0000    133.00
  65.0000    133.42
  70.0000    126.09
  75.0000    118.25
  80.0000    126.42
  85.0000    136.92
  90.0000    140.84
  95.0000    138.34
 100.0000    143.59
 105.0000    126.50
 110.0000    123.50
 115.0000    126.75
 120.0000    138.50
 125.0000    133.84
 130.0000    133.34
 135.0000    133.84
 140.0000    142.75
 145.0000    138.42
 150.0000    136.42
 155.0000    153.42
 160.0000    156.25
 165.0000    157.42
 170.0000    130.92
 175.0000    140.50
 180.0000    130.34
 185.0000    125.92
 190.0000    128.34
 195.0000    127.42
 200.0000    132.34
 205.0000    142.67
 210.0000    140.75
 215.0000    142.09
 220.0000    140.59
 225.0000    139.84
 230.0000    151.34
 235.0000    144.34
 240.0000    160.42
 245.0000    141.92
 250.0000    141.75
 255.0000    134.42
 260.0000    141.67
 265.0000    133.50
 270.0000    134.67
 275.0000    135.34
 280.0000    134.75
 285.0000    133.59
 290.0000    122.92
 295.0000    134.67
 300.0000    144.75
 305.0000    142.17
 310.0000    145.92
 315.0000    136.59
 320.0000    134.42
 325.0000    132.25
 330.0000    135.00
 335.0000    136.25
 340.0000    134.67
 345.0000    142.00
 350.0000    127.92
 355.0000    122.09
; (Data for Range number 15)
_DRIVE='PHI'
_STEPTIME=11.999800
_STEPSIZE=5.000000
_STEPMODE='C'
_START=0.000000
_THETA=18.270000
_2THETA=36.540001
_KHI=70.000000
_PHI=0.000000
_X=0.000000
_Y=0.000000
_Z=0.000000
_DIVERGENCE=0.200000
_ANTISCATTER=0.200000
_DETECTOR=1
; S.C.
_HV=683.500000
_GAIN=80.000000
_LLD=0.788000
_ULD=2.160000
_DETECTORSLIT='out'
_AUX1=0.000000
_AUX2=0.000000
_AUX3=0.000000
_TIMESTARTED=12184.000000
_TEMP_RATE=0.000000
_TEMP_DELAY=0.000000
_KV=40
_MA=30
_RANGE_WL=1.540600
_3DPLANE=0
_2THETACPS
   0.0000    102.17
   5.0000    103.75
  10.0000    109.17
  15.0000    106.67
  20.0000    120.75
  25.0000    110.50
  30.0000    121.92
  35.0000    127.92
  40.0000    125.17
  45.0000    119.42
  50.0000    126.84
  55.0000    130.42
  60.0000    119.92
  65.0000    110.50
  70.0000    110.75
  75.0000    106.17
  80.0000    110.17
  85.0000    110.92
  90.0000    120.75
  95.0000    119.25
 100.0000    121.50
 105.0000    117.67
 110.0000    109.17
 115.0000    108.09
 120.0000    110.42
 125.0000    119.17
 130.0000    127.67
 135.0000    111.59
 140.0000    114.92
 145.0000    104.00
 150.0000    114.25
 155.0000    111.00
 160.0000    124.84
 165.0000    113.42
 170.0000    107.42
 175.0000    110.92
 180.0000    106.59
 185.0000    115.92
 190.0000    108.84
 195.0000    106.09
 200.0000    117.09
 205.0000    109.67
 210.0000    112.92
 215.0000    115.00
 220.0000    116.50
 225.0000    119.17
 230.0000    119.84
 235.0000    126.59
 240.0000    136.75
 245.0000    128.67
 250.0000    125.34
 255.0000    132.59
 260.0000    121.25
 265.0000    123.59
 270.0000    119.84
 275.0000    124.42
 280.0000    122.50
 285.0000    112.84
 290.0000    115.67
 295.0000    113.09
 300.0000    125.59
 305.0000    112.59
 310.0000    108.25
 315.0000    110.92
 320.0000    117.67
 325.0000    114.00
 330.0000    110.00
 335.0000    110.59
 340.0000    114.34
 345.0000    107.59
 350.0000    112.09
 355.0000    101.67
; (Data for Range number 16)
_DRIVE='PHI'
_STEPTIME=11.999800
_STEPSIZE=5.000000
_STEPMODE='C'
_START=0.000000
_THETA=18.270000
_2THETA=36.540001
_KHI=75.000000
_PHI=0.000000
_X=0.000000
_Y=0.000000
_Z=0.000000
_DIVERGENCE=0.200000
_ANTISCATTER=0.200000
_DETECTOR=1
; S.C.
_HV=683.500000
_GAIN=80.000000
_LLD=0.788000
_ULD=2.160000
_DETECTORSLIT='out'
_AUX1=0.000000
_AUX2=0.000000
_AUX3=0.000000
_TIMESTARTED=13052.000000
_TEMP_RATE=0.000000
_TEMP_DELAY=0.000000
_KV=40
_MA=30
_RANGE_WL=1.540600
_3DPLANE=0
_2THETACPS
   0.0000    61.334
   5.0000    64.418
  10.0000    61.584
  15.0000    62.584
  20.0000    72.418
  25.0000    85.251
  30.0000    83.835
  35.0000    90.502
  40.0000    85.168
  45.0000    86.168
  50.0000    96.918
  55.0000    97.085
  60.0000    91.085
  65.0000    86.001
  70.0000    83.918
  75.0000    75.585
  80.0000    85.335
  85.0000    95.002
  90.0000    93.585
  95.0000    99.002
 100.0000    104.25
 105.0000    88.835
 110.0000    102.34
 115.0000    89.585
 120.0000    101.75
 125.0000    93.335
 130.0000    85.585
 135.0000    80.335
 140.0000    76.501
 145.0000    71.085
 150.0000    68.168
 155.0000    76.418
 160.0000    77.918
 165.0000    73.501
 170.0000    77.585
 175.0000    70.251
 180.0000    68.501
 185.0000    66.501
 190.0000    69.418
 195.0000    81.751
 200.0000    72.918
 205.0000    70.668
 210.0000    77.918
 215.0000    81.585
 220.0000    93.335
 225.0000    85.835
 230.0000    96.752
 235.0000    106.25
 240.0000    107.34
 245.0000    100.17
 250.0000    96.585
 255.0000    105.25
 260.0000    95.002
 265.0000    95.252
 270.0000    94.085
 275.0000    101.25
 280.0000    97.252
 285.0000    90.502
 290.0000    95.335
 295.0000    82.418
 300.0000    78.168
 305.0000    91.835
 310.0000    82.251
 315.0000    88.751
 320.0000    87.251
 325.0000    74.501
 330.0000    75.085
 335.0000    73.168
 340.0000    72.251
 345.0000    63.834
 350.0000    62.918
 355.0000    65.751