File: mtex-5.1.1/data/PoleFigure/ZnCuTi/ZnCuTi_defocusing_PF_101_R.UXD
; C:\Users\Stanis³aw\OneDrive\Documents\paracamgr\DANE DO MGR\24.03.2015\tekstura\TExtura\Defokusacja\ZnCuTi_defokusacja_PF_101_R.raw(Diffrac Plus V1.01 file) converted by XCH V1.0
_FILEVERSION=2
_SITE='Poland'
_USER='Administrator'
_SAMPLE_CHANGER_CODE=0
_ATTACHMENTS_CODE=0
_GONIOMETER_RADIUS=300.000000
_FIXED_DIVSLIT=0.600000
_FIXED_SAMPLESLIT=1.000000
_FIXED_DETSLIT=0.100000
_MONOCHROMATOR=0
; None
_THIN_FILM='N'
_BETA_FILTER='N'
_FIXED_ANTISLIT=0.600000
_ANALYZER_CODE=0
; None
_DATEMEASURED='01-Apr-2015 02:02:13'
_WL_UNIT='A'
_WL1=1.540600
_WL2=1.544390
_WL3=1.392220
_WLRATIO=0.500000
_ANODE='Cu'
; (Data for Range number 1)
_DRIVE='PHI'
_STEPTIME=11.999800
_STEPSIZE=5.000000
_STEPMODE='C'
_START=0.000000
_THETA=21.697500
_2THETA=43.395000
_KHI=0.000000
_PHI=0.000000
_X=0.000000
_Y=0.000000
_Z=0.000000
_DIVERGENCE=0.200000
_ANTISCATTER=0.200000
_DETECTOR=1
; S.C.
_HV=683.500000
_GAIN=80.000000
_LLD=0.788000
_ULD=2.160000
_DETECTORSLIT='out'
_AUX1=0.000000
_AUX2=0.000000
_AUX3=0.000000
_TIMESTARTED=22.000000
_TEMP_RATE=0.000000
_TEMP_DELAY=0.000000
_KV=40
_MA=30
_RANGE_WL=1.540600
_3DPLANE=0
_2THETACPS
   0.0000    355.51
   5.0000    356.84
  10.0000    442.01
  15.0000    375.76
  20.0000    385.01
  25.0000    424.17
  30.0000    474.34
  35.0000    534.34
  40.0000    568.26
  45.0000    429.34
  50.0000    387.59
  55.0000    366.76
  60.0000    396.01
  65.0000    425.01
  70.0000    516.43
  75.0000    504.18
  80.0000    458.42
  85.0000    395.51
  90.0000    452.34
  95.0000    394.34
 100.0000    405.51
 105.0000    415.59
 110.0000    488.84
 115.0000    426.59
 120.0000    394.26
 125.0000    396.09
 130.0000    401.34
 135.0000    427.01
 140.0000    466.76
 145.0000    370.34
 150.0000    431.92
 155.0000    357.84
 160.0000    344.09
 165.0000    359.51
 170.0000    382.09
 175.0000    406.42
 180.0000    389.26
 185.0000    432.34
 190.0000    517.68
 195.0000    545.18
 200.0000    593.76
 205.0000    594.76
 210.0000    568.68
 215.0000    467.84
 220.0000    453.76
 225.0000    448.67
 230.0000    422.42
 235.0000    422.09
 240.0000    442.92
 245.0000    413.84
 250.0000    397.09
 255.0000    352.34
 260.0000    396.51
 265.0000    347.51
 270.0000    345.51
 275.0000    339.84
 280.0000    365.51
 285.0000    365.76
 290.0000    356.67
 295.0000    354.09
 300.0000    364.17
 305.0000    326.76
 310.0000    339.26
 315.0000    323.34
 320.0000    326.92
 325.0000    332.59
 330.0000    348.01
 335.0000    313.92
 340.0000    304.92
 345.0000    350.34
 350.0000    394.76
 355.0000    377.01
; (Data for Range number 2)
_DRIVE='PHI'
_STEPTIME=11.999800
_STEPSIZE=5.000000
_STEPMODE='C'
_START=0.000000
_THETA=21.697500
_2THETA=43.395000
_KHI=5.000000
_PHI=0.000000
_X=0.000000
_Y=0.000000
_Z=0.000000
_DIVERGENCE=0.200000
_ANTISCATTER=0.200000
_DETECTOR=1
; S.C.
_HV=683.500000
_GAIN=80.000000
_LLD=0.788000
_ULD=2.160000
_DETECTORSLIT='out'
_AUX1=0.000000
_AUX2=0.000000
_AUX3=0.000000
_TIMESTARTED=890.000000
_TEMP_RATE=0.000000
_TEMP_DELAY=0.000000
_KV=40
_MA=30
_RANGE_WL=1.540600
_3DPLANE=0
_2THETACPS
   0.0000    354.34
   5.0000    342.51
  10.0000    333.59
  15.0000    339.17
  20.0000    344.34
  25.0000    370.67
  30.0000    427.84
  35.0000    380.51
  40.0000    344.59
  45.0000    354.26
  50.0000    376.84
  55.0000    341.42
  60.0000    381.67
  65.0000    379.76
  70.0000    370.59
  75.0000    397.34
  80.0000    405.09
  85.0000    374.59
  90.0000    353.01
  95.0000    353.42
 100.0000    363.59
 105.0000    344.42
 110.0000    337.76
 115.0000    404.76
 120.0000    359.67
 125.0000    344.67
 130.0000    436.34
 135.0000    458.67
 140.0000    406.42
 145.0000    428.17
 150.0000    399.01
 155.0000    420.34
 160.0000    446.51
 165.0000    338.42
 170.0000    385.76
 175.0000    393.84
 180.0000    377.67
 185.0000    359.67
 190.0000    333.26
 195.0000    402.01
 200.0000    376.09
 205.0000    385.26
 210.0000    385.92
 215.0000    470.67
 220.0000    376.34
 225.0000    482.42
 230.0000    391.92
 235.0000    364.51
 240.0000    379.26
 245.0000    370.76
 250.0000    396.17
 255.0000    355.34
 260.0000    341.59
 265.0000    318.26
 270.0000    360.59
 275.0000    371.84
 280.0000    400.59
 285.0000    326.34
 290.0000    394.34
 295.0000    406.92
 300.0000    437.09
 305.0000    315.34
 310.0000    335.67
 315.0000    353.59
 320.0000    345.09
 325.0000    355.59
 330.0000    335.34
 335.0000    361.92
 340.0000    378.09
 345.0000    297.92
 350.0000    416.09
 355.0000    349.84
; (Data for Range number 3)
_DRIVE='PHI'
_STEPTIME=11.999800
_STEPSIZE=5.000000
_STEPMODE='C'
_START=0.000000
_THETA=21.697500
_2THETA=43.395000
_KHI=10.000000
_PHI=0.000000
_X=0.000000
_Y=0.000000
_Z=0.000000
_DIVERGENCE=0.200000
_ANTISCATTER=0.200000
_DETECTOR=1
; S.C.
_HV=683.500000
_GAIN=80.000000
_LLD=0.788000
_ULD=2.160000
_DETECTORSLIT='out'
_AUX1=0.000000
_AUX2=0.000000
_AUX3=0.000000
_TIMESTARTED=1759.000000
_TEMP_RATE=0.000000
_TEMP_DELAY=0.000000
_KV=40
_MA=30
_RANGE_WL=1.540600
_3DPLANE=0
_2THETACPS
   0.0000    391.51
   5.0000    412.01
  10.0000    461.51
  15.0000    374.92
  20.0000    373.92
  25.0000    335.42
  30.0000    376.26
  35.0000    359.51
  40.0000    409.84
  45.0000    406.84
  50.0000    359.01
  55.0000    363.42
  60.0000    347.01
  65.0000    356.26
  70.0000    406.26
  75.0000    392.67
  80.0000    382.51
  85.0000    365.34
  90.0000    399.42
  95.0000    355.26
 100.0000    326.84
 105.0000    380.67
 110.0000    370.51
 115.0000    352.51
 120.0000    371.67
 125.0000    359.59
 130.0000    431.92
 135.0000    377.76
 140.0000    388.09
 145.0000    375.92
 150.0000    367.34
 155.0000    386.67
 160.0000    422.67
 165.0000    392.17
 170.0000    367.17
 175.0000    355.67
 180.0000    372.34
 185.0000    373.09
 190.0000    415.01
 195.0000    371.84
 200.0000    432.67
 205.0000    424.84
 210.0000    459.92
 215.0000    398.34
 220.0000    376.01
 225.0000    384.26
 230.0000    391.67
 235.0000    374.42
 240.0000    394.67
 245.0000    343.92
 250.0000    349.09
 255.0000    392.84
 260.0000    345.59
 265.0000    378.01
 270.0000    328.59
 275.0000    348.34
 280.0000    318.42
 285.0000    320.59
 290.0000    350.42
 295.0000    356.34
 300.0000    318.76
 305.0000    349.51
 310.0000    365.17
 315.0000    333.26
 320.0000    339.92
 325.0000    330.67
 330.0000    306.34
 335.0000    342.42
 340.0000    350.59
 345.0000    369.59
 350.0000    340.76
 355.0000    338.92
; (Data for Range number 4)
_DRIVE='PHI'
_STEPTIME=11.999800
_STEPSIZE=5.000000
_STEPMODE='C'
_START=0.000000
_THETA=21.697500
_2THETA=43.395000
_KHI=15.000000
_PHI=0.000000
_X=0.000000
_Y=0.000000
_Z=0.000000
_DIVERGENCE=0.200000
_ANTISCATTER=0.200000
_DETECTOR=1
; S.C.
_HV=683.500000
_GAIN=80.000000
_LLD=0.788000
_ULD=2.160000
_DETECTORSLIT='out'
_AUX1=0.000000
_AUX2=0.000000
_AUX3=0.000000
_TIMESTARTED=2628.000000
_TEMP_RATE=0.000000
_TEMP_DELAY=0.000000
_KV=40
_MA=30
_RANGE_WL=1.540600
_3DPLANE=0
_2THETACPS
   0.0000    342.76
   5.0000    357.84
  10.0000    410.76
  15.0000    379.67
  20.0000    362.42
  25.0000    395.84
  30.0000    384.09
  35.0000    329.17
  40.0000    394.51
  45.0000    396.84
  50.0000    345.01
  55.0000    378.59
  60.0000    379.09
  65.0000    389.76
  70.0000    408.34
  75.0000    372.26
  80.0000    369.84
  85.0000    333.92
  90.0000    351.01
  95.0000    371.51
 100.0000    378.34
 105.0000    377.01
 110.0000    399.84
 115.0000    347.42
 120.0000    381.76
 125.0000    360.51
 130.0000    377.09
 135.0000    396.01
 140.0000    375.09
 145.0000    364.26
 150.0000    399.84
 155.0000    433.59
 160.0000    397.17
 165.0000    387.01
 170.0000    381.67
 175.0000    361.92
 180.0000    349.59
 185.0000    388.76
 190.0000    381.67
 195.0000    431.34
 200.0000    389.34
 205.0000    414.34
 210.0000    396.17
 215.0000    432.76
 220.0000    344.17
 225.0000    381.59
 230.0000    387.17
 235.0000    408.26
 240.0000    369.84
 245.0000    401.42
 250.0000    376.92
 255.0000    389.67
 260.0000    369.92
 265.0000    324.51
 270.0000    315.67
 275.0000    311.01
 280.0000    312.17
 285.0000    322.67
 290.0000    364.76
 295.0000    347.34
 300.0000    378.09
 305.0000    335.26
 310.0000    336.51
 315.0000    331.17
 320.0000    321.67
 325.0000    348.01
 330.0000    344.67
 335.0000    373.34
 340.0000    363.51
 345.0000    338.67
 350.0000    379.34
 355.0000    347.42
; (Data for Range number 5)
_DRIVE='PHI'
_STEPTIME=11.999800
_STEPSIZE=5.000000
_STEPMODE='C'
_START=0.000000
_THETA=21.697500
_2THETA=43.395000
_KHI=20.000000
_PHI=0.000000
_X=0.000000
_Y=0.000000
_Z=0.000000
_DIVERGENCE=0.200000
_ANTISCATTER=0.200000
_DETECTOR=1
; S.C.
_HV=683.500000
_GAIN=80.000000
_LLD=0.788000
_ULD=2.160000
_DETECTORSLIT='out'
_AUX1=0.000000
_AUX2=0.000000
_AUX3=0.000000
_TIMESTARTED=3496.000000
_TEMP_RATE=0.000000
_TEMP_DELAY=0.000000
_KV=40
_MA=30
_RANGE_WL=1.540600
_3DPLANE=0
_2THETACPS
   0.0000    351.59
   5.0000    367.42
  10.0000    353.01
  15.0000    419.09
  20.0000    362.34
  25.0000    373.51
  30.0000    351.01
  35.0000    393.26
  40.0000    367.01
  45.0000    359.76
  50.0000    364.09
  55.0000    377.51
  60.0000    395.92
  65.0000    346.01
  70.0000    362.34
  75.0000    402.01
  80.0000    344.92
  85.0000    327.59
  90.0000    378.01
  95.0000    374.92
 100.0000    363.09
 105.0000    356.76
 110.0000    382.26
 115.0000    342.42
 120.0000    337.76
 125.0000    363.59
 130.0000    391.92
 135.0000    363.09
 140.0000    369.67
 145.0000    335.17
 150.0000    412.59
 155.0000    371.17
 160.0000    422.26
 165.0000    413.01
 170.0000    384.17
 175.0000    336.09
 180.0000    357.67
 185.0000    383.34
 190.0000    379.51
 195.0000    386.67
 200.0000    369.09
 205.0000    345.34
 210.0000    411.92
 215.0000    355.84
 220.0000    346.34
 225.0000    446.34
 230.0000    355.67
 235.0000    363.01
 240.0000    375.09
 245.0000    395.51
 250.0000    362.01
 255.0000    356.84
 260.0000    318.34
 265.0000    342.42
 270.0000    310.92
 275.0000    329.67
 280.0000    335.09
 285.0000    320.59
 290.0000    304.59
 295.0000    315.17
 300.0000    321.92
 305.0000    332.67
 310.0000    327.34
 315.0000    343.76
 320.0000    333.59
 325.0000    345.67
 330.0000    367.01
 335.0000    326.59
 340.0000    352.76
 345.0000    373.76
 350.0000    398.59
 355.0000    360.42
; (Data for Range number 6)
_DRIVE='PHI'
_STEPTIME=11.999800
_STEPSIZE=5.000000
_STEPMODE='C'
_START=0.000000
_THETA=21.697500
_2THETA=43.395000
_KHI=25.000000
_PHI=0.000000
_X=0.000000
_Y=0.000000
_Z=0.000000
_DIVERGENCE=0.200000
_ANTISCATTER=0.200000
_DETECTOR=1
; S.C.
_HV=683.500000
_GAIN=80.000000
_LLD=0.788000
_ULD=2.160000
_DETECTORSLIT='out'
_AUX1=0.000000
_AUX2=0.000000
_AUX3=0.000000
_TIMESTARTED=4365.000000
_TEMP_RATE=0.000000
_TEMP_DELAY=0.000000
_KV=40
_MA=30
_RANGE_WL=1.540600
_3DPLANE=0
_2THETACPS
   0.0000    367.76
   5.0000    356.59
  10.0000    351.42
  15.0000    381.01
  20.0000    358.09
  25.0000    359.76
  30.0000    351.01
  35.0000    375.34
  40.0000    337.51
  45.0000    356.84
  50.0000    366.67
  55.0000    341.26
  60.0000    322.84
  65.0000    362.76
  70.0000    335.09
  75.0000    326.67
  80.0000    326.67
  85.0000    294.67
  90.0000    329.51
  95.0000    337.76
 100.0000    331.76
 105.0000    339.76
 110.0000    322.01
 115.0000    340.59
 120.0000    330.17
 125.0000    316.67
 130.0000    335.51
 135.0000    389.51
 140.0000    351.42
 145.0000    378.42
 150.0000    371.51
 155.0000    355.01
 160.0000    371.42
 165.0000    387.26
 170.0000    362.34
 175.0000    340.76
 180.0000    350.34
 185.0000    365.51
 190.0000    353.26
 195.0000    405.92
 200.0000    373.59
 205.0000    371.76
 210.0000    371.59
 215.0000    378.26
 220.0000    354.42
 225.0000    398.26
 230.0000    341.59
 235.0000    361.26
 240.0000    363.26
 245.0000    342.17
 250.0000    350.51
 255.0000    344.92
 260.0000    361.34
 265.0000    323.51
 270.0000    315.67
 275.0000    328.01
 280.0000    334.67
 285.0000    293.42
 290.0000    297.75
 295.0000    315.17
 300.0000    318.59
 305.0000    350.26
 310.0000    319.84
 315.0000    315.84
 320.0000    358.59
 325.0000    342.17
 330.0000    352.34
 335.0000    341.09
 340.0000    342.26
 345.0000    327.34
 350.0000    361.42
 355.0000    350.09
; (Data for Range number 7)
_DRIVE='PHI'
_STEPTIME=11.999800
_STEPSIZE=5.000000
_STEPMODE='C'
_START=0.000000
_THETA=21.697500
_2THETA=43.395000
_KHI=30.000000
_PHI=0.000000
_X=0.000000
_Y=0.000000
_Z=0.000000
_DIVERGENCE=0.200000
_ANTISCATTER=0.200000
_DETECTOR=1
; S.C.
_HV=683.500000
_GAIN=80.000000
_LLD=0.788000
_ULD=2.160000
_DETECTORSLIT='out'
_AUX1=0.000000
_AUX2=0.000000
_AUX3=0.000000
_TIMESTARTED=5234.000000
_TEMP_RATE=0.000000
_TEMP_DELAY=0.000000
_KV=40
_MA=30
_RANGE_WL=1.540600
_3DPLANE=0
_2THETACPS
   0.0000    336.17
   5.0000    348.01
  10.0000    362.59
  15.0000    327.17
  20.0000    327.42
  25.0000    362.17
  30.0000    338.01
  35.0000    367.34
  40.0000    368.67
  45.0000    345.34
  50.0000    329.76
  55.0000    336.51
  60.0000    335.34
  65.0000    323.01
  70.0000    333.34
  75.0000    302.67
  80.0000    307.09
  85.0000    299.09
  90.0000    293.34
  95.0000    287.09
 100.0000    327.84
 105.0000    303.26
 110.0000    312.01
 115.0000    320.09
 120.0000    317.09
 125.0000    359.76
 130.0000    312.51
 135.0000    311.34
 140.0000    348.76
 145.0000    374.76
 150.0000    350.84
 155.0000    342.84
 160.0000    345.17
 165.0000    365.09
 170.0000    337.01
 175.0000    348.51
 180.0000    297.75
 185.0000    338.84
 190.0000    319.42
 195.0000    346.17
 200.0000    373.67
 205.0000    381.17
 210.0000    370.76
 215.0000    376.17
 220.0000    342.17
 225.0000    372.92
 230.0000    392.59
 235.0000    362.51
 240.0000    329.09
 245.0000    332.51
 250.0000    351.67
 255.0000    329.84
 260.0000    344.59
 265.0000    312.51
 270.0000    322.26
 275.0000    330.67
 280.0000    282.67
 285.0000    329.17
 290.0000    308.84
 295.0000    283.92
 300.0000    294.75
 305.0000    293.59
 310.0000    302.67
 315.0000    330.51
 320.0000    313.92
 325.0000    325.84
 330.0000    327.67
 335.0000    350.59
 340.0000    341.76
 345.0000    333.92
 350.0000    339.34
 355.0000    333.51
; (Data for Range number 8)
_DRIVE='PHI'
_STEPTIME=11.999800
_STEPSIZE=5.000000
_STEPMODE='C'
_START=0.000000
_THETA=21.697500
_2THETA=43.395000
_KHI=35.000000
_PHI=0.000000
_X=0.000000
_Y=0.000000
_Z=0.000000
_DIVERGENCE=0.200000
_ANTISCATTER=0.200000
_DETECTOR=1
; S.C.
_HV=683.500000
_GAIN=80.000000
_LLD=0.788000
_ULD=2.160000
_DETECTORSLIT='out'
_AUX1=0.000000
_AUX2=0.000000
_AUX3=0.000000
_TIMESTARTED=6102.000000
_TEMP_RATE=0.000000
_TEMP_DELAY=0.000000
_KV=40
_MA=30
_RANGE_WL=1.540600
_3DPLANE=0
_2THETACPS
   0.0000    346.26
   5.0000    321.84
  10.0000    332.92
  15.0000    346.34
  20.0000    318.09
  25.0000    319.51
  30.0000    317.17
  35.0000    345.84
  40.0000    307.26
  45.0000    299.76
  50.0000    301.67
  55.0000    343.84
  60.0000    324.01
  65.0000    313.92
  70.0000    338.26
  75.0000    323.17
  80.0000    303.01
  85.0000    290.67
  90.0000    290.00
  95.0000    273.17
 100.0000    295.75
 105.0000    277.34
 110.0000    286.92
 115.0000    273.17
 120.0000    282.67
 125.0000    284.67
 130.0000    346.84
 135.0000    314.59
 140.0000    314.09
 145.0000    326.01
 150.0000    343.67
 155.0000    380.01
 160.0000    341.34
 165.0000    338.42
 170.0000    320.09
 175.0000    312.59
 180.0000    309.67
 185.0000    296.34
 190.0000    302.84
 195.0000    341.34
 200.0000    368.09
 205.0000    341.42
 210.0000    356.01
 215.0000    348.17
 220.0000    365.67
 225.0000    345.01
 230.0000    347.51
 235.0000    381.17
 240.0000    336.67
 245.0000    356.51
 250.0000    345.59
 255.0000    338.01
 260.0000    315.26
 265.0000    297.67
 270.0000    335.59
 275.0000    301.42
 280.0000    274.59
 285.0000    296.09
 290.0000    276.84
 295.0000    296.84
 300.0000    309.59
 305.0000    292.92
 310.0000    272.09
 315.0000    277.34
 320.0000    299.84
 325.0000    316.34
 330.0000    320.76
 335.0000    333.51
 340.0000    312.42
 345.0000    310.34
 350.0000    320.09
 355.0000    316.92
; (Data for Range number 9)
_DRIVE='PHI'
_STEPTIME=11.999800
_STEPSIZE=5.000000
_STEPMODE='C'
_START=0.000000
_THETA=21.697500
_2THETA=43.395000
_KHI=40.000000
_PHI=0.000000
_X=0.000000
_Y=0.000000
_Z=0.000000
_DIVERGENCE=0.200000
_ANTISCATTER=0.200000
_DETECTOR=1
; S.C.
_HV=683.500000
_GAIN=80.000000
_LLD=0.788000
_ULD=2.160000
_DETECTORSLIT='out'
_AUX1=0.000000
_AUX2=0.000000
_AUX3=0.000000
_TIMESTARTED=6971.000000
_TEMP_RATE=0.000000
_TEMP_DELAY=0.000000
_KV=40
_MA=30
_RANGE_WL=1.540600
_3DPLANE=0
_2THETACPS
   0.0000    322.01
   5.0000    294.09
  10.0000    320.34
  15.0000    294.50
  20.0000    304.01
  25.0000    301.34
  30.0000    314.67
  35.0000    299.84
  40.0000    307.42
  45.0000    307.51
  50.0000    299.67
  55.0000    310.84
  60.0000    302.17
  65.0000    294.67
  70.0000    302.42
  75.0000    284.17
  80.0000    264.09
  85.0000    288.50
  90.0000    285.25
  95.0000    270.92
 100.0000    254.92
 105.0000    248.75
 110.0000    261.92
 115.0000    255.84
 120.0000    287.34
 125.0000    286.75
 130.0000    278.00
 135.0000    296.59
 140.0000    306.34
 145.0000    348.51
 150.0000    323.34
 155.0000    338.92
 160.0000    311.01
 165.0000    303.84
 170.0000    314.92
 175.0000    294.84
 180.0000    308.17
 185.0000    292.59
 190.0000    293.59
 195.0000    293.59
 200.0000    344.42
 205.0000    354.09
 210.0000    342.92
 215.0000    341.34
 220.0000    355.67
 225.0000    309.42
 230.0000    308.42
 235.0000    316.51
 240.0000    313.67
 245.0000    304.51
 250.0000    302.59
 255.0000    304.67
 260.0000    299.59
 265.0000    284.84
 270.0000    276.17
 275.0000    274.92
 280.0000    288.34
 285.0000    268.92
 290.0000    280.00
 295.0000    279.09
 300.0000    254.34
 305.0000    269.00
 310.0000    281.42
 315.0000    287.67
 320.0000    275.17
 325.0000    294.42
 330.0000    307.34
 335.0000    295.67
 340.0000    316.51
 345.0000    288.84
 350.0000    286.67
 355.0000    308.59
; (Data for Range number 10)
_DRIVE='PHI'
_STEPTIME=11.999800
_STEPSIZE=5.000000
_STEPMODE='C'
_START=0.000000
_THETA=21.697500
_2THETA=43.395000
_KHI=45.000000
_PHI=0.000000
_X=0.000000
_Y=0.000000
_Z=0.000000
_DIVERGENCE=0.200000
_ANTISCATTER=0.200000
_DETECTOR=1
; S.C.
_HV=683.500000
_GAIN=80.000000
_LLD=0.788000
_ULD=2.160000
_DETECTORSLIT='out'
_AUX1=0.000000
_AUX2=0.000000
_AUX3=0.000000
_TIMESTARTED=7840.000000
_TEMP_RATE=0.000000
_TEMP_DELAY=0.000000
_KV=40
_MA=30
_RANGE_WL=1.540600
_3DPLANE=0
_2THETACPS
   0.0000    285.00
   5.0000    309.09
  10.0000    286.59
  15.0000    294.50
  20.0000    278.00
  25.0000    290.25
  30.0000    296.09
  35.0000    278.84
  40.0000    266.59
  45.0000    266.25
  50.0000    277.42
  55.0000    322.84
  60.0000    277.75
  65.0000    269.42
  70.0000    279.75
  75.0000    259.92
  80.0000    261.42
  85.0000    252.75
  90.0000    260.84
  95.0000    243.25
 100.0000    254.25
 105.0000    247.34
 110.0000    238.75
 115.0000    230.59
 120.0000    237.67
 125.0000    263.59
 130.0000    262.42
 135.0000    284.34
 140.0000    279.09
 145.0000    289.09
 150.0000    280.50
 155.0000    314.01
 160.0000    308.09
 165.0000    319.34
 170.0000    302.67
 175.0000    262.75
 180.0000    303.59
 185.0000    279.84
 190.0000    281.34
 195.0000    290.00
 200.0000    300.42
 205.0000    320.51
 210.0000    318.09
 215.0000    323.76
 220.0000    288.17
 225.0000    296.17
 230.0000    317.51
 235.0000    327.84
 240.0000    278.34
 245.0000    306.84
 250.0000    288.84
 255.0000    294.75
 260.0000    320.01
 265.0000    274.42
 270.0000    263.09
 275.0000    238.92
 280.0000    261.09
 285.0000    264.50
 290.0000    253.34
 295.0000    251.42
 300.0000    264.09
 305.0000    261.59
 310.0000    247.92
 315.0000    271.34
 320.0000    276.17
 325.0000    270.92
 330.0000    275.50
 335.0000    296.17
 340.0000    294.59
 345.0000    274.67
 350.0000    268.84
 355.0000    284.17
; (Data for Range number 11)
_DRIVE='PHI'
_STEPTIME=11.999800
_STEPSIZE=5.000000
_STEPMODE='C'
_START=0.000000
_THETA=21.697500
_2THETA=43.395000
_KHI=50.000000
_PHI=0.000000
_X=0.000000
_Y=0.000000
_Z=0.000000
_DIVERGENCE=0.200000
_ANTISCATTER=0.200000
_DETECTOR=1
; S.C.
_HV=683.500000
_GAIN=80.000000
_LLD=0.788000
_ULD=2.160000
_DETECTORSLIT='out'
_AUX1=0.000000
_AUX2=0.000000
_AUX3=0.000000
_TIMESTARTED=8709.000000
_TEMP_RATE=0.000000
_TEMP_DELAY=0.000000
_KV=40
_MA=30
_RANGE_WL=1.540600
_3DPLANE=0
_2THETACPS
   0.0000    271.17
   5.0000    264.34
  10.0000    258.42
  15.0000    279.84
  20.0000    255.25
  25.0000    266.84
  30.0000    276.67
  35.0000    267.00
  40.0000    259.42
  45.0000    243.09
  50.0000    253.92
  55.0000    257.84
  60.0000    254.42
  65.0000    242.42
  70.0000    244.09
  75.0000    245.00
  80.0000    228.34
  85.0000    234.59
  90.0000    230.09
  95.0000    236.50
 100.0000    211.75
 105.0000    207.09
 110.0000    233.17
 115.0000    224.42
 120.0000    213.67
 125.0000    226.34
 130.0000    223.09
 135.0000    227.25
 140.0000    253.34
 145.0000    271.25
 150.0000    278.42
 155.0000    268.67
 160.0000    284.75
 165.0000    291.92
 170.0000    272.17
 175.0000    279.42
 180.0000    252.34
 185.0000    254.75
 190.0000    266.67
 195.0000    272.59
 200.0000    275.84
 205.0000    281.75
 210.0000    308.01
 215.0000    294.50
 220.0000    270.42
 225.0000    298.75
 230.0000    278.50
 235.0000    289.42
 240.0000    281.59
 245.0000    275.67
 250.0000    272.92
 255.0000    259.25
 260.0000    273.84
 265.0000    274.17
 270.0000    263.84
 275.0000    260.67
 280.0000    237.42
 285.0000    224.42
 290.0000    225.67
 295.0000    246.75
 300.0000    225.84
 305.0000    240.59
 310.0000    246.75
 315.0000    252.42
 320.0000    250.75
 325.0000    276.09
 330.0000    259.75
 335.0000    255.00
 340.0000    262.34
 345.0000    260.17
 350.0000    264.75
 355.0000    275.50
; (Data for Range number 12)
_DRIVE='PHI'
_STEPTIME=11.999800
_STEPSIZE=5.000000
_STEPMODE='C'
_START=0.000000
_THETA=21.697500
_2THETA=43.395000
_KHI=55.000000
_PHI=0.000000
_X=0.000000
_Y=0.000000
_Z=0.000000
_DIVERGENCE=0.200000
_ANTISCATTER=0.200000
_DETECTOR=1
; S.C.
_HV=683.500000
_GAIN=80.000000
_LLD=0.788000
_ULD=2.160000
_DETECTORSLIT='out'
_AUX1=0.000000
_AUX2=0.000000
_AUX3=0.000000
_TIMESTARTED=9577.000000
_TEMP_RATE=0.000000
_TEMP_DELAY=0.000000
_KV=40
_MA=30
_RANGE_WL=1.540600
_3DPLANE=0
_2THETACPS
   0.0000    223.25
   5.0000    244.25
  10.0000    230.17
  15.0000    252.42
  20.0000    244.42
  25.0000    254.34
  30.0000    251.09
  35.0000    239.84
  40.0000    235.84
  45.0000    229.50
  50.0000    240.42
  55.0000    235.67
  60.0000    246.34
  65.0000    256.09
  70.0000    230.42
  75.0000    227.67
  80.0000    215.84
  85.0000    227.92
  90.0000    206.84
  95.0000    225.00
 100.0000    200.75
 105.0000    207.59
 110.0000    211.42
 115.0000    203.92
 120.0000    204.42
 125.0000    206.09
 130.0000    210.17
 135.0000    209.17
 140.0000    247.67
 145.0000    238.92
 150.0000    246.92
 155.0000    264.25
 160.0000    262.92
 165.0000    275.17
 170.0000    271.59
 175.0000    257.75
 180.0000    245.34
 185.0000    245.67
 190.0000    246.09
 195.0000    237.75
 200.0000    265.09
 205.0000    270.50
 210.0000    262.59
 215.0000    278.75
 220.0000    298.34
 225.0000    258.50
 230.0000    242.17
 235.0000    278.34
 240.0000    263.92
 245.0000    264.09
 250.0000    261.92
 255.0000    258.25
 260.0000    254.09
 265.0000    244.09
 270.0000    233.75
 275.0000    231.84
 280.0000    213.34
 285.0000    208.67
 290.0000    199.34
 295.0000    227.09
 300.0000    207.25
 305.0000    234.34
 310.0000    227.50
 315.0000    241.00
 320.0000    241.84
 325.0000    247.17
 330.0000    257.59
 335.0000    266.34
 340.0000    246.42
 345.0000    228.67
 350.0000    222.67
 355.0000    233.75
; (Data for Range number 13)
_DRIVE='PHI'
_STEPTIME=11.999800
_STEPSIZE=5.000000
_STEPMODE='C'
_START=0.000000
_THETA=21.697500
_2THETA=43.395000
_KHI=60.000000
_PHI=0.000000
_X=0.000000
_Y=0.000000
_Z=0.000000
_DIVERGENCE=0.200000
_ANTISCATTER=0.200000
_DETECTOR=1
; S.C.
_HV=683.500000
_GAIN=80.000000
_LLD=0.788000
_ULD=2.160000
_DETECTORSLIT='out'
_AUX1=0.000000
_AUX2=0.000000
_AUX3=0.000000
_TIMESTARTED=10446.000000
_TEMP_RATE=0.000000
_TEMP_DELAY=0.000000
_KV=40
_MA=30
_RANGE_WL=1.540600
_3DPLANE=0
_2THETACPS
   0.0000    205.84
   5.0000    227.92
  10.0000    221.75
  15.0000    214.92
  20.0000    218.09
  25.0000    231.84
  30.0000    242.17
  35.0000    222.59
  40.0000    230.50
  45.0000    221.25
  50.0000    211.34
  55.0000    218.42
  60.0000    238.25
  65.0000    199.59
  70.0000    202.09
  75.0000    199.59
  80.0000    203.25
  85.0000    211.17
  90.0000    204.75
  95.0000    192.42
 100.0000    197.92
 105.0000    197.17
 110.0000    181.50
 115.0000    177.59
 120.0000    190.17
 125.0000    205.17
 130.0000    202.75
 135.0000    205.00
 140.0000    214.84
 145.0000    208.42
 150.0000    236.50
 155.0000    234.67
 160.0000    247.17
 165.0000    236.59
 170.0000    240.34
 175.0000    238.17
 180.0000    235.17
 185.0000    238.92
 190.0000    219.42
 195.0000    214.00
 200.0000    225.59
 205.0000    239.42
 210.0000    225.42
 215.0000    240.25
 220.0000    232.84
 225.0000    233.50
 230.0000    237.75
 235.0000    243.34
 240.0000    229.25
 245.0000    247.17
 250.0000    237.92
 255.0000    247.59
 260.0000    240.09
 265.0000    221.25
 270.0000    222.84
 275.0000    224.67
 280.0000    190.09
 285.0000    194.09
 290.0000    207.59
 295.0000    194.34
 300.0000    200.59
 305.0000    212.92
 310.0000    196.59
 315.0000    203.25
 320.0000    214.09
 325.0000    211.50
 330.0000    221.75
 335.0000    222.84
 340.0000    226.92
 345.0000    222.59
 350.0000    217.59
 355.0000    228.25
; (Data for Range number 14)
_DRIVE='PHI'
_STEPTIME=11.999800
_STEPSIZE=5.000000
_STEPMODE='C'
_START=0.000000
_THETA=21.697500
_2THETA=43.395000
_KHI=65.000000
_PHI=0.000000
_X=0.000000
_Y=0.000000
_Z=0.000000
_DIVERGENCE=0.200000
_ANTISCATTER=0.200000
_DETECTOR=1
; S.C.
_HV=683.500000
_GAIN=80.000000
_LLD=0.788000
_ULD=2.160000
_DETECTORSLIT='out'
_AUX1=0.000000
_AUX2=0.000000
_AUX3=0.000000
_TIMESTARTED=11314.000000
_TEMP_RATE=0.000000
_TEMP_DELAY=0.000000
_KV=40
_MA=30
_RANGE_WL=1.540600
_3DPLANE=0
_2THETACPS
   0.0000    172.42
   5.0000    181.42
  10.0000    205.34
  15.0000    187.59
  20.0000    203.42
  25.0000    216.25
  30.0000    217.92
  35.0000    206.17
  40.0000    190.75
  45.0000    181.42
  50.0000    197.09
  55.0000    200.34
  60.0000    187.42
  65.0000    193.92
  70.0000    176.09
  75.0000    184.34
  80.0000    172.50
  85.0000    183.17
  90.0000    195.17
  95.0000    185.67
 100.0000    168.75
 105.0000    173.75
 110.0000    166.50
 115.0000    169.84
 120.0000    165.34
 125.0000    171.00
 130.0000    190.84
 135.0000    182.42
 140.0000    179.84
 145.0000    192.84
 150.0000    196.84
 155.0000    229.25
 160.0000    220.59
 165.0000    219.59
 170.0000    199.50
 175.0000    207.00
 180.0000    190.09
 185.0000    198.34
 190.0000    190.09
 195.0000    186.09
 200.0000    210.75
 205.0000    219.59
 210.0000    202.59
 215.0000    203.84
 220.0000    210.09
 225.0000    212.84
 230.0000    209.25
 235.0000    207.67
 240.0000    200.84
 245.0000    199.25
 250.0000    198.59
 255.0000    214.67
 260.0000    213.50
 265.0000    214.09
 270.0000    203.17
 275.0000    193.42
 280.0000    177.75
 285.0000    173.67
 290.0000    175.25
 295.0000    189.59
 300.0000    184.17
 305.0000    199.09
 310.0000    170.75
 315.0000    188.17
 320.0000    185.75
 325.0000    208.50
 330.0000    202.17
 335.0000    202.59
 340.0000    211.09
 345.0000    198.50
 350.0000    201.09
 355.0000    189.34
; (Data for Range number 15)
_DRIVE='PHI'
_STEPTIME=11.999800
_STEPSIZE=5.000000
_STEPMODE='C'
_START=0.000000
_THETA=21.697500
_2THETA=43.395000
_KHI=70.000000
_PHI=0.000000
_X=0.000000
_Y=0.000000
_Z=0.000000
_DIVERGENCE=0.200000
_ANTISCATTER=0.200000
_DETECTOR=1
; S.C.
_HV=683.500000
_GAIN=80.000000
_LLD=0.788000
_ULD=2.160000
_DETECTORSLIT='out'
_AUX1=0.000000
_AUX2=0.000000
_AUX3=0.000000
_TIMESTARTED=12183.000000
_TEMP_RATE=0.000000
_TEMP_DELAY=0.000000
_KV=40
_MA=30
_RANGE_WL=1.540600
_3DPLANE=0
_2THETACPS
   0.0000    155.84
   5.0000    158.84
  10.0000    171.50
  15.0000    186.00
  20.0000    175.17
  25.0000    166.92
  30.0000    181.34
  35.0000    171.00
  40.0000    161.59
  45.0000    160.25
  50.0000    176.42
  55.0000    152.92
  60.0000    155.84
  65.0000    155.34
  70.0000    154.67
  75.0000    149.25
  80.0000    162.00
  85.0000    153.75
  90.0000    160.84
  95.0000    150.92
 100.0000    154.59
 105.0000    150.34
 110.0000    147.34
 115.0000    138.42
 120.0000    137.34
 125.0000    143.50
 130.0000    158.00
 135.0000    157.17
 140.0000    160.00
 145.0000    172.25
 150.0000    185.92
 155.0000    185.25
 160.0000    187.42
 165.0000    187.00
 170.0000    187.34
 175.0000    155.59
 180.0000    180.25
 185.0000    175.84
 190.0000    158.17
 195.0000    167.92
 200.0000    168.59
 205.0000    172.59
 210.0000    201.09
 215.0000    185.92
 220.0000    173.75
 225.0000    175.42
 230.0000    181.34
 235.0000    179.75
 240.0000    184.67
 245.0000    175.84
 250.0000    185.42
 255.0000    182.75
 260.0000    189.50
 265.0000    182.34
 270.0000    172.34
 275.0000    165.42
 280.0000    162.84
 285.0000    158.25
 290.0000    157.09
 295.0000    144.92
 300.0000    156.34
 305.0000    155.00
 310.0000    151.17
 315.0000    177.67
 320.0000    163.75
 325.0000    168.42
 330.0000    168.42
 335.0000    167.50
 340.0000    182.42
 345.0000    164.00
 350.0000    154.00
 355.0000    159.84
; (Data for Range number 16)
_DRIVE='PHI'
_STEPTIME=11.999800
_STEPSIZE=5.000000
_STEPMODE='C'
_START=0.000000
_THETA=21.697500
_2THETA=43.395000
_KHI=75.000000
_PHI=0.000000
_X=0.000000
_Y=0.000000
_Z=0.000000
_DIVERGENCE=0.200000
_ANTISCATTER=0.200000
_DETECTOR=1
; S.C.
_HV=683.500000
_GAIN=80.000000
_LLD=0.788000
_ULD=2.160000
_DETECTORSLIT='out'
_AUX1=0.000000
_AUX2=0.000000
_AUX3=0.000000
_TIMESTARTED=13051.000000
_TEMP_RATE=0.000000
_TEMP_DELAY=0.000000
_KV=40
_MA=30
_RANGE_WL=1.540600
_3DPLANE=0
_2THETACPS
   0.0000    110.42
   5.0000    115.92
  10.0000    113.42
  15.0000    122.17
  20.0000    129.75
  25.0000    122.59
  30.0000    141.84
  35.0000    140.75
  40.0000    135.75
  45.0000    123.92
  50.0000    125.09
  55.0000    129.09
  60.0000    130.00
  65.0000    111.00
  70.0000    117.42
  75.0000    117.42
  80.0000    114.75
  85.0000    124.09
  90.0000    117.84
  95.0000    124.09
 100.0000    130.25
 105.0000    107.59
 110.0000    109.59
 115.0000    110.59
 120.0000    113.25
 125.0000    119.59
 130.0000    118.59
 135.0000    119.25
 140.0000    150.84
 145.0000    121.59
 150.0000    124.75
 155.0000    129.67
 160.0000    130.00
 165.0000    141.34
 170.0000    139.92
 175.0000    126.42
 180.0000    111.67
 185.0000    123.25
 190.0000    118.67
 195.0000    126.67
 200.0000    132.67
 205.0000    131.50
 210.0000    144.75
 215.0000    140.50
 220.0000    126.84
 225.0000    136.42
 230.0000    146.59
 235.0000    145.92
 240.0000    143.59
 245.0000    142.34
 250.0000    146.84
 255.0000    140.59
 260.0000    148.92
 265.0000    135.84
 270.0000    129.25
 275.0000    142.25
 280.0000    126.59
 285.0000    122.25
 290.0000    112.59
 295.0000    120.17
 300.0000    124.92
 305.0000    134.50
 310.0000    118.09
 315.0000    125.75
 320.0000    131.42
 325.0000    136.42
 330.0000    127.67
 335.0000    125.59
 340.0000    126.92
 345.0000    116.92
 350.0000    115.50
 355.0000    113.84