File: mtex-5.1.1/data/PoleFigure/ZnCuTi/ZnCuTi_Wal_50_5x5_PF_100_R.UXD
; C:\Users\Stanis³aw\OneDrive\Documents\paracamgr\DANE DO MGR\24.03.2015\tekstura\TExtura\Tekstura\ZnCuTi_Wal_50_5x5_PF_100_R.raw(Diffrac Plus V1.01 file) converted by XCH V1.0
_FILEVERSION=2
_SITE='Poland'
_USER='Administrator'
_SAMPLE_CHANGER_CODE=0
_ATTACHMENTS_CODE=0
_GONIOMETER_RADIUS=300.000000
_FIXED_DIVSLIT=0.600000
_FIXED_SAMPLESLIT=1.000000
_FIXED_DETSLIT=0.100000
_MONOCHROMATOR=0
; None
_THIN_FILM='N'
_BETA_FILTER='N'
_FIXED_ANTISLIT=0.600000
_ANALYZER_CODE=0
; None
_DATEMEASURED='25-Feb-2015 22:53:16'
_WL_UNIT='A'
_WL1=1.540600
_WL2=1.544390
_WL3=1.392220
_WLRATIO=0.500000
_ANODE='Cu'
; (Data for Range number 1)
_DRIVE='PHI'
_STEPTIME=11.999800
_STEPSIZE=5.000000
_STEPMODE='C'
_START=0.000000
_THETA=19.565001
_2THETA=39.130001
_KHI=0.000000
_PHI=0.000000
_X=0.000000
_Y=0.000000
_Z=0.000000
_DIVERGENCE=0.200000
_ANTISCATTER=0.200000
_DETECTOR=1
; S.C.
_HV=683.500000
_GAIN=80.000000
_LLD=0.788000
_ULD=2.160000
_DETECTORSLIT='out'
_AUX1=0.000000
_AUX2=0.000000
_AUX3=0.000000
_TIMESTARTED=22.000000
_TEMP_RATE=0.000000
_TEMP_DELAY=0.000000
_KV=40
_MA=30
_RANGE_WL=1.540600
_3DPLANE=0
_2THETACPS
   0.0000    542.59
   5.0000    531.59
  10.0000    542.76
  15.0000    552.34
  20.0000    548.76
  25.0000    549.84
  30.0000    570.59
  35.0000    567.43
  40.0000    556.01
  45.0000    558.34
  50.0000    551.26
  55.0000    577.09
  60.0000    572.51
  65.0000    556.59
  70.0000    576.51
  75.0000    576.09
  80.0000    564.34
  85.0000    575.01
  90.0000    580.18
  95.0000    559.51
 100.0000    561.43
 105.0000    582.51
 110.0000    562.84
 115.0000    573.76
 120.0000    591.43
 125.0000    584.18
 130.0000    586.09
 135.0000    579.59
 140.0000    589.43
 145.0000    582.18
 150.0000    593.51
 155.0000    587.51
 160.0000    599.68
 165.0000    594.84
 170.0000    599.68
 175.0000    603.59
 180.0000    604.68
 185.0000    599.34
 190.0000    598.26
 195.0000    608.59
 200.0000    588.18
 205.0000    592.76
 210.0000    586.01
 215.0000    593.18
 220.0000    586.18
 225.0000    586.84
 230.0000    599.09
 235.0000    588.09
 240.0000    587.51
 245.0000    584.34
 250.0000    578.84
 255.0000    591.68
 260.0000    575.09
 265.0000    579.01
 270.0000    569.51
 275.0000    580.84
 280.0000    559.59
 285.0000    566.51
 290.0000    556.93
 295.0000    550.76
 300.0000    540.93
 305.0000    547.34
 310.0000    536.26
 315.0000    550.01
 320.0000    541.76
 325.0000    544.93
 330.0000    547.26
 335.0000    535.18
 340.0000    542.26
 345.0000    547.26
 350.0000    536.34
 355.0000    537.01
; (Data for Range number 2)
_DRIVE='PHI'
_STEPTIME=11.999800
_STEPSIZE=5.000000
_STEPMODE='C'
_START=0.000000
_THETA=19.565001
_2THETA=39.130001
_KHI=5.000000
_PHI=0.000000
_X=0.000000
_Y=0.000000
_Z=0.000000
_DIVERGENCE=0.200000
_ANTISCATTER=0.200000
_DETECTOR=1
; S.C.
_HV=683.500000
_GAIN=80.000000
_LLD=0.788000
_ULD=2.160000
_DETECTORSLIT='out'
_AUX1=0.000000
_AUX2=0.000000
_AUX3=0.000000
_TIMESTARTED=892.000000
_TEMP_RATE=0.000000
_TEMP_DELAY=0.000000
_KV=40
_MA=30
_RANGE_WL=1.540600
_3DPLANE=0
_2THETACPS
   0.0000    521.51
   5.0000    524.01
  10.0000    513.93
  15.0000    521.84
  20.0000    535.93
  25.0000    524.76
  30.0000    527.01
  35.0000    547.43
  40.0000    558.34
  45.0000    555.84
  50.0000    568.93
  55.0000    552.26
  60.0000    577.51
  65.0000    570.59
  70.0000    568.93
  75.0000    569.93
  80.0000    583.51
  85.0000    575.34
  90.0000    584.09
  95.0000    573.34
 100.0000    570.34
 105.0000    581.26
 110.0000    587.68
 115.0000    584.51
 120.0000    566.84
 125.0000    578.59
 130.0000    584.59
 135.0000    591.68
 140.0000    601.43
 145.0000    583.09
 150.0000    581.59
 155.0000    585.76
 160.0000    585.43
 165.0000    567.84
 170.0000    550.51
 175.0000    546.76
 180.0000    543.93
 185.0000    547.68
 190.0000    542.76
 195.0000    560.26
 200.0000    585.84
 205.0000    583.34
 210.0000    583.84
 215.0000    607.34
 220.0000    609.84
 225.0000    600.34
 230.0000    595.01
 235.0000    586.93
 240.0000    577.93
 245.0000    579.26
 250.0000    585.68
 255.0000    577.68
 260.0000    566.76
 265.0000    566.43
 270.0000    567.26
 275.0000    575.76
 280.0000    578.51
 285.0000    573.76
 290.0000    571.01
 295.0000    582.84
 300.0000    570.18
 305.0000    550.93
 310.0000    552.51
 315.0000    562.84
 320.0000    570.09
 325.0000    552.26
 330.0000    543.76
 335.0000    533.18
 340.0000    541.34
 345.0000    531.93
 350.0000    526.84
 355.0000    521.76
; (Data for Range number 3)
_DRIVE='PHI'
_STEPTIME=11.999800
_STEPSIZE=5.000000
_STEPMODE='C'
_START=0.000000
_THETA=19.565001
_2THETA=39.130001
_KHI=10.000000
_PHI=0.000000
_X=0.000000
_Y=0.000000
_Z=0.000000
_DIVERGENCE=0.200000
_ANTISCATTER=0.200000
_DETECTOR=1
; S.C.
_HV=683.500000
_GAIN=80.000000
_LLD=0.788000
_ULD=2.160000
_DETECTORSLIT='out'
_AUX1=0.000000
_AUX2=0.000000
_AUX3=0.000000
_TIMESTARTED=1760.000000
_TEMP_RATE=0.000000
_TEMP_DELAY=0.000000
_KV=40
_MA=30
_RANGE_WL=1.540600
_3DPLANE=0
_2THETACPS
   0.0000    488.42
   5.0000    478.34
  10.0000    489.92
  15.0000    488.34
  20.0000    491.42
  25.0000    480.01
  30.0000    476.42
  35.0000    502.01
  40.0000    512.68
  45.0000    523.59
  50.0000    522.43
  55.0000    520.59
  60.0000    520.18
  65.0000    534.26
  70.0000    545.26
  75.0000    565.09
  80.0000    571.68
  85.0000    559.18
  90.0000    566.01
  95.0000    564.18
 100.0000    558.18
 105.0000    546.01
 110.0000    552.84
 115.0000    574.09
 120.0000    559.84
 125.0000    559.43
 130.0000    559.34
 135.0000    567.34
 140.0000    547.01
 145.0000    552.68
 150.0000    572.09
 155.0000    578.84
 160.0000    570.59
 165.0000    574.43
 170.0000    556.84
 175.0000    536.68
 180.0000    542.68
 185.0000    562.09
 190.0000    583.84
 195.0000    573.68
 200.0000    574.43
 205.0000    582.68
 210.0000    569.18
 215.0000    563.51
 220.0000    560.34
 225.0000    552.09
 230.0000    563.43
 235.0000    562.76
 240.0000    576.93
 245.0000    558.51
 250.0000    563.43
 255.0000    549.43
 260.0000    538.59
 265.0000    548.34
 270.0000    563.76
 275.0000    562.34
 280.0000    544.34
 285.0000    556.93
 290.0000    557.76
 295.0000    554.18
 300.0000    556.43
 305.0000    546.93
 310.0000    567.26
 315.0000    564.18
 320.0000    544.84
 325.0000    547.51
 330.0000    533.93
 335.0000    520.18
 340.0000    504.18
 345.0000    494.84
 350.0000    484.67
 355.0000    473.51
; (Data for Range number 4)
_DRIVE='PHI'
_STEPTIME=11.999800
_STEPSIZE=5.000000
_STEPMODE='C'
_START=0.000000
_THETA=19.565001
_2THETA=39.130001
_KHI=15.000000
_PHI=0.000000
_X=0.000000
_Y=0.000000
_Z=0.000000
_DIVERGENCE=0.200000
_ANTISCATTER=0.200000
_DETECTOR=1
; S.C.
_HV=683.500000
_GAIN=80.000000
_LLD=0.788000
_ULD=2.160000
_DETECTORSLIT='out'
_AUX1=0.000000
_AUX2=0.000000
_AUX3=0.000000
_TIMESTARTED=2629.000000
_TEMP_RATE=0.000000
_TEMP_DELAY=0.000000
_KV=40
_MA=30
_RANGE_WL=1.540600
_3DPLANE=0
_2THETACPS
   0.0000    479.51
   5.0000    486.92
  10.0000    498.84
  15.0000    507.76
  20.0000    488.84
  25.0000    475.92
  30.0000    487.17
  35.0000    513.43
  40.0000    506.68
  45.0000    516.68
  50.0000    536.51
  55.0000    536.76
  60.0000    552.26
  65.0000    584.93
  70.0000    600.76
  75.0000    602.68
  80.0000    584.01
  85.0000    557.84
  90.0000    547.93
  95.0000    571.09
 100.0000    569.09
 105.0000    577.34
 110.0000    576.34
 115.0000    563.51
 120.0000    565.68
 125.0000    563.34
 130.0000    551.43
 135.0000    553.93
 140.0000    559.18
 145.0000    561.09
 150.0000    565.59
 155.0000    580.84
 160.0000    560.76
 165.0000    537.26
 170.0000    553.34
 175.0000    578.34
 180.0000    584.84
 185.0000    605.09
 190.0000    594.76
 195.0000    581.59
 200.0000    554.59
 205.0000    550.26
 210.0000    554.76
 215.0000    561.18
 220.0000    543.76
 225.0000    532.76
 230.0000    550.59
 235.0000    531.51
 240.0000    525.01
 245.0000    500.34
 250.0000    500.59
 255.0000    484.51
 260.0000    502.18
 265.0000    507.09
 270.0000    497.84
 275.0000    509.09
 280.0000    532.26
 285.0000    539.51
 290.0000    554.18
 295.0000    546.59
 300.0000    532.34
 305.0000    534.76
 310.0000    544.68
 315.0000    554.43
 320.0000    540.51
 325.0000    529.76
 330.0000    532.68
 335.0000    533.84
 340.0000    493.51
 345.0000    477.09
 350.0000    471.42
 355.0000    479.26
; (Data for Range number 5)
_DRIVE='PHI'
_STEPTIME=11.999800
_STEPSIZE=5.000000
_STEPMODE='C'
_START=0.000000
_THETA=19.565001
_2THETA=39.130001
_KHI=20.000000
_PHI=0.000000
_X=0.000000
_Y=0.000000
_Z=0.000000
_DIVERGENCE=0.200000
_ANTISCATTER=0.200000
_DETECTOR=1
; S.C.
_HV=683.500000
_GAIN=80.000000
_LLD=0.788000
_ULD=2.160000
_DETECTORSLIT='out'
_AUX1=0.000000
_AUX2=0.000000
_AUX3=0.000000
_TIMESTARTED=3497.000000
_TEMP_RATE=0.000000
_TEMP_DELAY=0.000000
_KV=40
_MA=30
_RANGE_WL=1.540600
_3DPLANE=0
_2THETACPS
   0.0000    505.34
   5.0000    498.59
  10.0000    498.01
  15.0000    500.84
  20.0000    487.01
  25.0000    511.51
  30.0000    511.76
  35.0000    529.93
  40.0000    554.84
  45.0000    561.01
  50.0000    600.76
  55.0000    606.68
  60.0000    598.84
  65.0000    573.51
  70.0000    567.59
  75.0000    582.43
  80.0000    598.09
  85.0000    585.18
  90.0000    618.93
  95.0000    581.76
 100.0000    557.18
 105.0000    557.84
 110.0000    566.34
 115.0000    591.26
 120.0000    601.68
 125.0000    595.93
 130.0000    579.84
 135.0000    573.84
 140.0000    558.26
 145.0000    535.68
 150.0000    569.59
 155.0000    570.01
 160.0000    570.34
 165.0000    543.34
 170.0000    542.84
 175.0000    582.18
 180.0000    592.76
 185.0000    587.76
 190.0000    546.68
 195.0000    565.43
 200.0000    610.68
 205.0000    618.59
 210.0000    579.59
 215.0000    552.68
 220.0000    552.84
 225.0000    533.59
 230.0000    547.09
 235.0000    543.26
 240.0000    541.84
 245.0000    536.68
 250.0000    537.68
 255.0000    530.34
 260.0000    517.84
 265.0000    539.18
 270.0000    535.68
 275.0000    533.68
 280.0000    554.59
 285.0000    563.26
 290.0000    560.34
 295.0000    550.84
 300.0000    518.01
 305.0000    521.43
 310.0000    523.76
 315.0000    536.01
 320.0000    518.76
 325.0000    516.34
 330.0000    533.34
 335.0000    525.51
 340.0000    529.59
 345.0000    540.76
 350.0000    528.26
 355.0000    521.59
; (Data for Range number 6)
_DRIVE='PHI'
_STEPTIME=11.999800
_STEPSIZE=5.000000
_STEPMODE='C'
_START=0.000000
_THETA=19.565001
_2THETA=39.130001
_KHI=25.000000
_PHI=0.000000
_X=0.000000
_Y=0.000000
_Z=0.000000
_DIVERGENCE=0.200000
_ANTISCATTER=0.200000
_DETECTOR=1
; S.C.
_HV=683.500000
_GAIN=80.000000
_LLD=0.788000
_ULD=2.160000
_DETECTORSLIT='out'
_AUX1=0.000000
_AUX2=0.000000
_AUX3=0.000000
_TIMESTARTED=4365.000000
_TEMP_RATE=0.000000
_TEMP_DELAY=0.000000
_KV=40
_MA=30
_RANGE_WL=1.540600
_3DPLANE=0
_2THETACPS
   0.0000    557.26
   5.0000    530.93
  10.0000    491.84
  15.0000    499.17
  20.0000    492.76
  25.0000    500.43
  30.0000    516.93
  35.0000    550.76
  40.0000    582.76
  45.0000    599.51
  50.0000    607.34
  55.0000    634.68
  60.0000    634.76
  65.0000    609.76
  70.0000    588.59
  75.0000    567.76
  80.0000    577.84
  85.0000    584.51
  90.0000    599.01
  95.0000    598.34
 100.0000    574.18
 105.0000    549.09
 110.0000    563.68
 115.0000    587.01
 120.0000    611.51
 125.0000    604.68
 130.0000    563.34
 135.0000    569.59
 140.0000    584.18
 145.0000    556.34
 150.0000    566.59
 155.0000    588.01
 160.0000    581.09
 165.0000    573.68
 170.0000    565.09
 175.0000    585.76
 180.0000    562.34
 185.0000    580.43
 190.0000    572.76
 195.0000    611.34
 200.0000    629.09
 205.0000    589.43
 210.0000    583.34
 215.0000    595.51
 220.0000    564.51
 225.0000    581.51
 230.0000    591.76
 235.0000    595.01
 240.0000    578.26
 245.0000    565.01
 250.0000    594.26
 255.0000    643.68
 260.0000    636.34
 265.0000    625.59
 270.0000    594.51
 275.0000    555.51
 280.0000    522.76
 285.0000    515.18
 290.0000    529.76
 295.0000    531.76
 300.0000    571.34
 305.0000    555.93
 310.0000    527.68
 315.0000    528.51
 320.0000    546.51
 325.0000    549.84
 330.0000    544.51
 335.0000    534.43
 340.0000    522.18
 345.0000    539.34
 350.0000    544.51
 355.0000    538.09
; (Data for Range number 7)
_DRIVE='PHI'
_STEPTIME=11.999800
_STEPSIZE=5.000000
_STEPMODE='C'
_START=0.000000
_THETA=19.565001
_2THETA=39.130001
_KHI=30.000000
_PHI=0.000000
_X=0.000000
_Y=0.000000
_Z=0.000000
_DIVERGENCE=0.200000
_ANTISCATTER=0.200000
_DETECTOR=1
; S.C.
_HV=683.500000
_GAIN=80.000000
_LLD=0.788000
_ULD=2.160000
_DETECTORSLIT='out'
_AUX1=0.000000
_AUX2=0.000000
_AUX3=0.000000
_TIMESTARTED=5234.000000
_TEMP_RATE=0.000000
_TEMP_DELAY=0.000000
_KV=40
_MA=30
_RANGE_WL=1.540600
_3DPLANE=0
_2THETACPS
   0.0000    541.59
   5.0000    540.09
  10.0000    538.51
  15.0000    552.76
  20.0000    550.76
  25.0000    530.26
  30.0000    566.09
  35.0000    583.59
  40.0000    599.59
  45.0000    607.76
  50.0000    638.09
  55.0000    679.84
  60.0000    699.68
  65.0000    640.26
  70.0000    619.59
  75.0000    614.26
  80.0000    629.68
  85.0000    612.59
  90.0000    605.43
  95.0000    582.09
 100.0000    570.84
 105.0000    569.51
 110.0000    554.59
 115.0000    541.43
 120.0000    563.93
 125.0000    566.51
 130.0000    595.51
 135.0000    572.68
 140.0000    593.76
 145.0000    565.93
 150.0000    572.93
 155.0000    580.18
 160.0000    557.76
 165.0000    575.09
 170.0000    599.68
 175.0000    560.01
 180.0000    558.76
 185.0000    592.43
 190.0000    582.59
 195.0000    608.26
 200.0000    569.76
 205.0000    580.01
 210.0000    617.34
 215.0000    602.68
 220.0000    583.01
 225.0000    605.43
 230.0000    642.51
 235.0000    626.43
 240.0000    584.34
 245.0000    558.01
 250.0000    558.43
 255.0000    548.76
 260.0000    563.18
 265.0000    578.51
 270.0000    578.59
 275.0000    588.84
 280.0000    588.51
 285.0000    575.84
 290.0000    552.76
 295.0000    551.51
 300.0000    552.93
 305.0000    522.76
 310.0000    534.93
 315.0000    533.51
 320.0000    545.51
 325.0000    563.84
 330.0000    554.26
 335.0000    525.59
 340.0000    519.59
 345.0000    515.93
 350.0000    541.43
 355.0000    535.76
; (Data for Range number 8)
_DRIVE='PHI'
_STEPTIME=11.999800
_STEPSIZE=5.000000
_STEPMODE='C'
_START=0.000000
_THETA=19.565001
_2THETA=39.130001
_KHI=35.000000
_PHI=0.000000
_X=0.000000
_Y=0.000000
_Z=0.000000
_DIVERGENCE=0.200000
_ANTISCATTER=0.200000
_DETECTOR=1
; S.C.
_HV=683.500000
_GAIN=80.000000
_LLD=0.788000
_ULD=2.160000
_DETECTORSLIT='out'
_AUX1=0.000000
_AUX2=0.000000
_AUX3=0.000000
_TIMESTARTED=6103.000000
_TEMP_RATE=0.000000
_TEMP_DELAY=0.000000
_KV=40
_MA=30
_RANGE_WL=1.540600
_3DPLANE=0
_2THETACPS
   0.0000    498.26
   5.0000    510.34
  10.0000    515.26
  15.0000    510.93
  20.0000    509.76
  25.0000    517.76
  30.0000    553.43
  35.0000    551.59
  40.0000    602.51
  45.0000    624.09
  50.0000    588.93
  55.0000    581.84
  60.0000    588.76
  65.0000    568.43
  70.0000    570.26
  75.0000    579.84
  80.0000    612.34
  85.0000    585.01
  90.0000    598.26
  95.0000    631.93
 100.0000    655.43
 105.0000    656.26
 110.0000    586.26
 115.0000    538.93
 120.0000    531.51
 125.0000    532.01
 130.0000    562.43
 135.0000    561.18
 140.0000    589.84
 145.0000    583.51
 150.0000    564.26
 155.0000    579.18
 160.0000    554.84
 165.0000    579.01
 170.0000    578.59
 175.0000    574.43
 180.0000    563.26
 185.0000    589.59
 190.0000    584.18
 195.0000    546.68
 200.0000    546.59
 205.0000    552.59
 210.0000    536.93
 215.0000    562.93
 220.0000    569.51
 225.0000    599.59
 230.0000    636.84
 235.0000    607.93
 240.0000    584.34
 245.0000    533.26
 250.0000    539.76
 255.0000    535.76
 260.0000    540.43
 265.0000    574.43
 270.0000    569.51
 275.0000    573.84
 280.0000    567.51
 285.0000    561.43
 290.0000    582.68
 295.0000    580.43
 300.0000    557.43
 305.0000    555.43
 310.0000    584.68
 315.0000    547.18
 320.0000    556.59
 325.0000    516.84
 330.0000    511.76
 335.0000    498.26
 340.0000    497.34
 345.0000    499.51
 350.0000    507.18
 355.0000    492.42
; (Data for Range number 9)
_DRIVE='PHI'
_STEPTIME=11.999800
_STEPSIZE=5.000000
_STEPMODE='C'
_START=0.000000
_THETA=19.565001
_2THETA=39.130001
_KHI=40.000000
_PHI=0.000000
_X=0.000000
_Y=0.000000
_Z=0.000000
_DIVERGENCE=0.200000
_ANTISCATTER=0.200000
_DETECTOR=1
; S.C.
_HV=683.500000
_GAIN=80.000000
_LLD=0.788000
_ULD=2.160000
_DETECTORSLIT='out'
_AUX1=0.000000
_AUX2=0.000000
_AUX3=0.000000
_TIMESTARTED=6971.000000
_TEMP_RATE=0.000000
_TEMP_DELAY=0.000000
_KV=40
_MA=30
_RANGE_WL=1.540600
_3DPLANE=0
_2THETACPS
   0.0000    478.17
   5.0000    480.34
  10.0000    493.26
  15.0000    489.92
  20.0000    513.43
  25.0000    508.01
  30.0000    487.76
  35.0000    526.93
  40.0000    563.18
  45.0000    567.76
  50.0000    560.68
  55.0000    563.09
  60.0000    564.09
  65.0000    551.68
  70.0000    553.51
  75.0000    531.34
  80.0000    528.59
  85.0000    535.93
  90.0000    557.84
  95.0000    570.09
 100.0000    580.26
 105.0000    557.18
 110.0000    546.34
 115.0000    538.34
 120.0000    518.51
 125.0000    506.68
 130.0000    521.68
 135.0000    517.51
 140.0000    562.51
 145.0000    549.84
 150.0000    536.68
 155.0000    568.59
 160.0000    536.93
 165.0000    553.09
 170.0000    575.59
 175.0000    556.09
 180.0000    545.76
 185.0000    536.01
 190.0000    515.01
 195.0000    519.84
 200.0000    495.42
 205.0000    482.51
 210.0000    550.34
 215.0000    570.68
 220.0000    546.93
 225.0000    546.09
 230.0000    524.51
 235.0000    515.84
 240.0000    511.93
 245.0000    497.67
 250.0000    507.18
 255.0000    536.51
 260.0000    498.51
 265.0000    520.34
 270.0000    516.26
 275.0000    526.18
 280.0000    519.84
 285.0000    510.18
 290.0000    550.01
 295.0000    533.34
 300.0000    528.18
 305.0000    521.34
 310.0000    514.51
 315.0000    501.34
 320.0000    492.34
 325.0000    502.84
 330.0000    466.51
 335.0000    487.92
 340.0000    489.34
 345.0000    466.59
 350.0000    457.26
 355.0000    455.67
; (Data for Range number 10)
_DRIVE='PHI'
_STEPTIME=11.999800
_STEPSIZE=5.000000
_STEPMODE='C'
_START=0.000000
_THETA=19.565001
_2THETA=39.130001
_KHI=45.000000
_PHI=0.000000
_X=0.000000
_Y=0.000000
_Z=0.000000
_DIVERGENCE=0.200000
_ANTISCATTER=0.200000
_DETECTOR=1
; S.C.
_HV=683.500000
_GAIN=80.000000
_LLD=0.788000
_ULD=2.160000
_DETECTORSLIT='out'
_AUX1=0.000000
_AUX2=0.000000
_AUX3=0.000000
_TIMESTARTED=7840.000000
_TEMP_RATE=0.000000
_TEMP_DELAY=0.000000
_KV=40
_MA=30
_RANGE_WL=1.540600
_3DPLANE=0
_2THETACPS
   0.0000    459.51
   5.0000    461.34
  10.0000    481.76
  15.0000    489.76
  20.0000    473.42
  25.0000    491.09
  30.0000    514.93
  35.0000    531.26
  40.0000    550.34
  45.0000    478.84
  50.0000    473.01
  55.0000    481.92
  60.0000    494.09
  65.0000    516.84
  70.0000    559.51
  75.0000    554.34
  80.0000    574.01
  85.0000    542.26
  90.0000    536.76
  95.0000    540.84
 100.0000    555.84
 105.0000    524.26
 110.0000    506.01
 115.0000    477.34
 120.0000    482.59
 125.0000    506.01
 130.0000    519.68
 135.0000    501.09
 140.0000    513.18
 145.0000    536.84
 150.0000    513.51
 155.0000    512.76
 160.0000    514.76
 165.0000    519.51
 170.0000    517.59
 175.0000    526.18
 180.0000    508.43
 185.0000    503.68
 190.0000    496.51
 195.0000    473.42
 200.0000    467.17
 205.0000    515.18
 210.0000    549.43
 215.0000    534.34
 220.0000    540.84
 225.0000    499.68
 230.0000    494.26
 235.0000    478.09
 240.0000    480.01
 245.0000    493.76
 250.0000    496.84
 255.0000    478.92
 260.0000    479.26
 265.0000    487.42
 270.0000    509.76
 275.0000    518.43
 280.0000    512.51
 285.0000    483.42
 290.0000    475.59
 295.0000    488.92
 300.0000    505.84
 305.0000    465.34
 310.0000    471.42
 315.0000    442.51
 320.0000    461.01
 325.0000    450.26
 330.0000    428.76
 335.0000    451.76
 340.0000    482.26
 345.0000    462.09
 350.0000    473.09
 355.0000    491.59
; (Data for Range number 11)
_DRIVE='PHI'
_STEPTIME=11.999800
_STEPSIZE=5.000000
_STEPMODE='C'
_START=0.000000
_THETA=19.565001
_2THETA=39.130001
_KHI=50.000000
_PHI=0.000000
_X=0.000000
_Y=0.000000
_Z=0.000000
_DIVERGENCE=0.200000
_ANTISCATTER=0.200000
_DETECTOR=1
; S.C.
_HV=683.500000
_GAIN=80.000000
_LLD=0.788000
_ULD=2.160000
_DETECTORSLIT='out'
_AUX1=0.000000
_AUX2=0.000000
_AUX3=0.000000
_TIMESTARTED=8709.000000
_TEMP_RATE=0.000000
_TEMP_DELAY=0.000000
_KV=40
_MA=30
_RANGE_WL=1.540600
_3DPLANE=0
_2THETACPS
   0.0000    448.42
   5.0000    465.67
  10.0000    457.01
  15.0000    454.42
  20.0000    449.34
  25.0000    478.09
  30.0000    486.17
  35.0000    483.26
  40.0000    467.92
  45.0000    461.51
  50.0000    474.26
  55.0000    458.09
  60.0000    444.34
  65.0000    464.26
  70.0000    492.92
  75.0000    523.51
  80.0000    511.68
  85.0000    529.68
  90.0000    525.34
  95.0000    503.01
 100.0000    479.84
 105.0000    468.26
 110.0000    465.01
 115.0000    448.92
 120.0000    448.67
 125.0000    463.67
 130.0000    507.09
 135.0000    481.59
 140.0000    456.84
 145.0000    479.26
 150.0000    463.01
 155.0000    459.92
 160.0000    488.17
 165.0000    483.84
 170.0000    475.09
 175.0000    477.26
 180.0000    483.67
 185.0000    475.09
 190.0000    463.26
 195.0000    450.26
 200.0000    484.51
 205.0000    489.17
 210.0000    515.68
 215.0000    493.42
 220.0000    496.01
 225.0000    428.92
 230.0000    422.67
 235.0000    430.84
 240.0000    459.51
 245.0000    458.17
 250.0000    465.42
 255.0000    462.76
 260.0000    451.92
 265.0000    447.34
 270.0000    450.17
 275.0000    474.76
 280.0000    457.76
 285.0000    460.09
 290.0000    459.09
 295.0000    451.01
 300.0000    456.51
 305.0000    438.01
 310.0000    438.01
 315.0000    441.42
 320.0000    437.76
 325.0000    448.01
 330.0000    437.01
 335.0000    416.51
 340.0000    419.42
 345.0000    429.51
 350.0000    459.42
 355.0000    441.34
; (Data for Range number 12)
_DRIVE='PHI'
_STEPTIME=11.999800
_STEPSIZE=5.000000
_STEPMODE='C'
_START=0.000000
_THETA=19.565001
_2THETA=39.130001
_KHI=55.000000
_PHI=0.000000
_X=0.000000
_Y=0.000000
_Z=0.000000
_DIVERGENCE=0.200000
_ANTISCATTER=0.200000
_DETECTOR=1
; S.C.
_HV=683.500000
_GAIN=80.000000
_LLD=0.788000
_ULD=2.160000
_DETECTORSLIT='out'
_AUX1=0.000000
_AUX2=0.000000
_AUX3=0.000000
_TIMESTARTED=9577.000000
_TEMP_RATE=0.000000
_TEMP_DELAY=0.000000
_KV=40
_MA=30
_RANGE_WL=1.540600
_3DPLANE=0
_2THETACPS
   0.0000    413.17
   5.0000    440.17
  10.0000    427.34
  15.0000    439.59
  20.0000    431.09
  25.0000    442.67
  30.0000    458.09
  35.0000    429.59
  40.0000    443.09
  45.0000    406.26
  50.0000    396.76
  55.0000    403.59
  60.0000    397.92
  65.0000    409.17
  70.0000    413.01
  75.0000    439.42
  80.0000    447.76
  85.0000    440.84
  90.0000    474.59
  95.0000    457.09
 100.0000    425.84
 105.0000    435.76
 110.0000    446.42
 115.0000    422.67
 120.0000    392.51
 125.0000    420.67
 130.0000    461.67
 135.0000    450.84
 140.0000    457.67
 145.0000    475.26
 150.0000    447.01
 155.0000    453.01
 160.0000    454.92
 165.0000    458.01
 170.0000    447.67
 175.0000    439.09
 180.0000    424.51
 185.0000    435.76
 190.0000    431.76
 195.0000    444.42
 200.0000    453.26
 205.0000    482.67
 210.0000    491.17
 215.0000    451.51
 220.0000    442.67
 225.0000    414.17
 230.0000    383.26
 235.0000    408.01
 240.0000    438.67
 245.0000    457.34
 250.0000    436.92
 255.0000    425.76
 260.0000    460.01
 265.0000    424.92
 270.0000    419.67
 275.0000    444.59
 280.0000    458.26
 285.0000    460.09
 290.0000    425.84
 295.0000    414.09
 300.0000    464.26
 305.0000    443.59
 310.0000    444.42
 315.0000    435.17
 320.0000    402.92
 325.0000    406.42
 330.0000    422.42
 335.0000    419.01
 340.0000    404.34
 345.0000    416.09
 350.0000    402.51
 355.0000    409.01
; (Data for Range number 13)
_DRIVE='PHI'
_STEPTIME=11.999800
_STEPSIZE=5.000000
_STEPMODE='C'
_START=0.000000
_THETA=19.565001
_2THETA=39.130001
_KHI=60.000000
_PHI=0.000000
_X=0.000000
_Y=0.000000
_Z=0.000000
_DIVERGENCE=0.200000
_ANTISCATTER=0.200000
_DETECTOR=1
; S.C.
_HV=683.500000
_GAIN=80.000000
_LLD=0.788000
_ULD=2.160000
_DETECTORSLIT='out'
_AUX1=0.000000
_AUX2=0.000000
_AUX3=0.000000
_TIMESTARTED=10446.000000
_TEMP_RATE=0.000000
_TEMP_DELAY=0.000000
_KV=40
_MA=30
_RANGE_WL=1.540600
_3DPLANE=0
_2THETACPS
   0.0000    371.59
   5.0000    372.17
  10.0000    370.34
  15.0000    393.59
  20.0000    387.76
  25.0000    386.01
  30.0000    393.67
  35.0000    389.92
  40.0000    390.34
  45.0000    374.17
  50.0000    369.84
  55.0000    352.67
  60.0000    356.59
  65.0000    388.92
  70.0000    386.51
  75.0000    409.26
  80.0000    405.51
  85.0000    389.84
  90.0000    397.34
  95.0000    417.51
 100.0000    392.84
 105.0000    396.67
 110.0000    373.34
 115.0000    381.51
 120.0000    380.51
 125.0000    375.51
 130.0000    390.34
 135.0000    387.76
 140.0000    411.26
 145.0000    430.09
 150.0000    438.84
 155.0000    420.01
 160.0000    420.76
 165.0000    421.76
 170.0000    412.09
 175.0000    395.84
 180.0000    377.51
 185.0000    403.92
 190.0000    409.42
 195.0000    424.01
 200.0000    412.01
 205.0000    408.59
 210.0000    419.59
 215.0000    411.34
 220.0000    400.42
 225.0000    364.34
 230.0000    368.01
 235.0000    385.84
 240.0000    371.84
 245.0000    373.76
 250.0000    386.26
 255.0000    419.01
 260.0000    400.59
 265.0000    392.67
 270.0000    412.09
 275.0000    417.17
 280.0000    378.76
 285.0000    379.76
 290.0000    389.09
 295.0000    374.26
 300.0000    393.76
 305.0000    407.17
 310.0000    376.84
 315.0000    396.09
 320.0000    384.01
 325.0000    365.17
 330.0000    382.42
 335.0000    383.42
 340.0000    363.76
 345.0000    365.59
 350.0000    347.92
 355.0000    369.92
; (Data for Range number 14)
_DRIVE='PHI'
_STEPTIME=11.999800
_STEPSIZE=5.000000
_STEPMODE='C'
_START=0.000000
_THETA=19.565001
_2THETA=39.130001
_KHI=65.000000
_PHI=0.000000
_X=0.000000
_Y=0.000000
_Z=0.000000
_DIVERGENCE=0.200000
_ANTISCATTER=0.200000
_DETECTOR=1
; S.C.
_HV=683.500000
_GAIN=80.000000
_LLD=0.788000
_ULD=2.160000
_DETECTORSLIT='out'
_AUX1=0.000000
_AUX2=0.000000
_AUX3=0.000000
_TIMESTARTED=11315.000000
_TEMP_RATE=0.000000
_TEMP_DELAY=0.000000
_KV=40
_MA=30
_RANGE_WL=1.540600
_3DPLANE=0
_2THETACPS
   0.0000    326.42
   5.0000    345.17
  10.0000    347.09
  15.0000    350.42
  20.0000    340.26
  25.0000    331.67
  30.0000    358.17
  35.0000    339.84
  40.0000    355.09
  45.0000    340.67
  50.0000    342.09
  55.0000    338.34
  60.0000    336.17
  65.0000    337.67
  70.0000    360.17
  75.0000    333.76
  80.0000    330.59
  85.0000    328.76
  90.0000    325.84
  95.0000    340.76
 100.0000    352.76
 105.0000    363.59
 110.0000    344.76
 115.0000    332.34
 120.0000    345.76
 125.0000    353.34
 130.0000    358.84
 135.0000    350.26
 140.0000    360.67
 145.0000    370.17
 150.0000    376.51
 155.0000    378.67
 160.0000    372.92
 165.0000    338.34
 170.0000    355.09
 175.0000    336.01
 180.0000    327.59
 185.0000    344.26
 190.0000    372.59
 195.0000    363.09
 200.0000    353.59
 205.0000    360.09
 210.0000    365.09
 215.0000    351.42
 220.0000    338.26
 225.0000    313.42
 230.0000    356.76
 235.0000    338.76
 240.0000    333.84
 245.0000    330.34
 250.0000    359.17
 255.0000    369.01
 260.0000    361.92
 265.0000    357.59
 270.0000    349.92
 275.0000    352.59
 280.0000    339.76
 285.0000    344.26
 290.0000    332.51
 295.0000    325.92
 300.0000    343.51
 305.0000    385.17
 310.0000    358.17
 315.0000    344.76
 320.0000    343.09
 325.0000    319.59
 330.0000    331.84
 335.0000    341.76
 340.0000    333.67
 345.0000    320.67
 350.0000    312.59
 355.0000    317.17
; (Data for Range number 15)
_DRIVE='PHI'
_STEPTIME=11.999800
_STEPSIZE=5.000000
_STEPMODE='C'
_START=0.000000
_THETA=19.565001
_2THETA=39.130001
_KHI=70.000000
_PHI=0.000000
_X=0.000000
_Y=0.000000
_Z=0.000000
_DIVERGENCE=0.200000
_ANTISCATTER=0.200000
_DETECTOR=1
; S.C.
_HV=683.500000
_GAIN=80.000000
_LLD=0.788000
_ULD=2.160000
_DETECTORSLIT='out'
_AUX1=0.000000
_AUX2=0.000000
_AUX3=0.000000
_TIMESTARTED=12183.000000
_TEMP_RATE=0.000000
_TEMP_DELAY=0.000000
_KV=40
_MA=30
_RANGE_WL=1.540600
_3DPLANE=0
_2THETACPS
   0.0000    267.92
   5.0000    277.00
  10.0000    287.34
  15.0000    292.00
  20.0000    302.92
  25.0000    284.67
  30.0000    282.67
  35.0000    298.42
  40.0000    290.34
  45.0000    280.25
  50.0000    271.00
  55.0000    278.42
  60.0000    283.42
  65.0000    273.25
  70.0000    281.25
  75.0000    278.84
  80.0000    273.25
  85.0000    286.67
  90.0000    289.42
  95.0000    292.75
 100.0000    297.25
 105.0000    316.59
 110.0000    314.09
 115.0000    305.67
 120.0000    312.84
 125.0000    315.17
 130.0000    306.59
 135.0000    305.59
 140.0000    300.51
 145.0000    312.01
 150.0000    296.75
 155.0000    306.01
 160.0000    307.84
 165.0000    277.50
 170.0000    279.50
 175.0000    288.67
 180.0000    274.59
 185.0000    279.25
 190.0000    293.50
 195.0000    292.42
 200.0000    295.84
 205.0000    302.67
 210.0000    314.34
 215.0000    302.01
 220.0000    282.42
 225.0000    290.50
 230.0000    304.09
 235.0000    296.09
 240.0000    283.84
 245.0000    272.17
 250.0000    298.25
 255.0000    296.84
 260.0000    287.00
 265.0000    293.34
 270.0000    310.17
 275.0000    307.51
 280.0000    291.42
 285.0000    302.92
 290.0000    300.67
 295.0000    307.42
 300.0000    299.00
 305.0000    292.84
 310.0000    311.01
 315.0000    311.42
 320.0000    295.42
 325.0000    269.92
 330.0000    277.75
 335.0000    269.92
 340.0000    269.75
 345.0000    283.92
 350.0000    275.67
 355.0000    268.59
; (Data for Range number 16)
_DRIVE='PHI'
_STEPTIME=11.999800
_STEPSIZE=5.000000
_STEPMODE='C'
_START=0.000000
_THETA=19.565001
_2THETA=39.130001
_KHI=75.000000
_PHI=0.000000
_X=0.000000
_Y=0.000000
_Z=0.000000
_DIVERGENCE=0.200000
_ANTISCATTER=0.200000
_DETECTOR=1
; S.C.
_HV=683.500000
_GAIN=80.000000
_LLD=0.788000
_ULD=2.160000
_DETECTORSLIT='out'
_AUX1=0.000000
_AUX2=0.000000
_AUX3=0.000000
_TIMESTARTED=13051.000000
_TEMP_RATE=0.000000
_TEMP_DELAY=0.000000
_KV=40
_MA=30
_RANGE_WL=1.540600
_3DPLANE=0
_2THETACPS
   0.0000    147.75
   5.0000    142.75
  10.0000    158.34
  15.0000    175.67
  20.0000    175.84
  25.0000    189.84
  30.0000    194.42
  35.0000    204.25
  40.0000    205.50
  45.0000    204.59
  50.0000    197.59
  55.0000    214.84
  60.0000    216.92
  65.0000    234.42
  70.0000    218.00
  75.0000    224.42
  80.0000    218.59
  85.0000    217.84
  90.0000    219.75
  95.0000    247.00
 100.0000    221.67
 105.0000    240.92
 110.0000    251.75
 115.0000    246.42
 120.0000    242.09
 125.0000    242.17
 130.0000    241.50
 135.0000    235.84
 140.0000    218.00
 145.0000    209.50
 150.0000    193.50
 155.0000    180.75
 160.0000    177.34
 165.0000    163.84
 170.0000    157.00
 175.0000    149.84
 180.0000    150.25
 185.0000    160.00
 190.0000    153.75
 195.0000    167.92
 200.0000    178.84
 205.0000    183.75
 210.0000    199.00
 215.0000    205.84
 220.0000    211.25
 225.0000    234.00
 230.0000    235.25
 235.0000    227.09
 240.0000    220.09
 245.0000    212.34
 250.0000    235.34
 255.0000    209.67
 260.0000    210.17
 265.0000    218.00
 270.0000    230.84
 275.0000    231.84
 280.0000    229.92
 285.0000    226.75
 290.0000    230.42
 295.0000    240.84
 300.0000    245.92
 305.0000    243.42
 310.0000    230.09
 315.0000    224.25
 320.0000    198.17
 325.0000    188.25
 330.0000    177.17
 335.0000    165.67
 340.0000    169.34
 345.0000    151.09
 350.0000    154.25
 355.0000    150.34