File: mtex-5.1.1/data/PoleFigure/ZnCuTi/ZnCuTi_Wal_50_5x5_PF_101_R.UXD
; C:\Users\Stanis³aw\OneDrive\Documents\paracamgr\DANE DO MGR\24.03.2015\tekstura\TExtura\Tekstura\ZnCuTi_Wal_50_5x5_PF_101_R.raw(Diffrac Plus V1.01 file) converted by XCH V1.0
_FILEVERSION=2
_SITE='Poland'
_USER='Administrator'
_SAMPLE_CHANGER_CODE=0
_ATTACHMENTS_CODE=0
_GONIOMETER_RADIUS=300.000000
_FIXED_DIVSLIT=0.600000
_FIXED_SAMPLESLIT=1.000000
_FIXED_DETSLIT=0.100000
_MONOCHROMATOR=0
; None
_THIN_FILM='N'
_BETA_FILTER='N'
_FIXED_ANTISLIT=0.600000
_ANALYZER_CODE=0
; None
_DATEMEASURED='26-Feb-2015 02:45:12'
_WL_UNIT='A'
_WL1=1.540600
_WL2=1.544390
_WL3=1.392220
_WLRATIO=0.500000
_ANODE='Cu'
; (Data for Range number 1)
_DRIVE='PHI'
_STEPTIME=11.999800
_STEPSIZE=5.000000
_STEPMODE='C'
_START=0.000000
_THETA=21.697500
_2THETA=43.395000
_KHI=0.000000
_PHI=0.000000
_X=0.000000
_Y=0.000000
_Z=0.000000
_DIVERGENCE=0.200000
_ANTISCATTER=0.200000
_DETECTOR=1
; S.C.
_HV=683.500000
_GAIN=80.000000
_LLD=0.788000
_ULD=2.160000
_DETECTORSLIT='out'
_AUX1=0.000000
_AUX2=0.000000
_AUX3=0.000000
_TIMESTARTED=22.000000
_TEMP_RATE=0.000000
_TEMP_DELAY=0.000000
_KV=40
_MA=30
_RANGE_WL=1.540600
_3DPLANE=0
_2THETACPS
   0.0000    1024.1
   5.0000    1028.4
  10.0000    1039.4
  15.0000    1045.9
  20.0000    1071.3
  25.0000    1060.2
  30.0000    1070.2
  35.0000    1080.4
  40.0000    1055.4
  45.0000    1070.9
  50.0000    1065.7
  55.0000    1092.4
  60.0000    1079.7
  65.0000    1083.9
  70.0000    1074.4
  75.0000    1096.1
  80.0000    1072.9
  85.0000    1062.5
  90.0000    1058.4
  95.0000    1050.0
 100.0000    1051.0
 105.0000    1037.4
 110.0000    1064.9
 115.0000    1050.0
 120.0000    1024.8
 125.0000    1004.2
 130.0000    1012.5
 135.0000    1027.2
 140.0000    1017.5
 145.0000    1010.9
 150.0000    1025.6
 155.0000    1013.3
 160.0000    1031.6
 165.0000    1036.9
 170.0000    1013.9
 175.0000    1028.8
 180.0000    1020.4
 185.0000    1047.3
 190.0000    1037.7
 195.0000    1035.4
 200.0000    1030.8
 205.0000    1002.5
 210.0000    1022.7
 215.0000    1004.3
 220.0000    993.52
 225.0000    989.52
 230.0000    987.85
 235.0000    979.27
 240.0000    991.10
 245.0000    990.02
 250.0000    1010.4
 255.0000    981.77
 260.0000    994.93
 265.0000    1006.3
 270.0000    989.85
 275.0000    995.02
 280.0000    999.18
 285.0000    1010.0
 290.0000    1007.2
 295.0000    1023.8
 300.0000    989.77
 305.0000    995.52
 310.0000    1023.0
 315.0000    1027.9
 320.0000    1032.6
 325.0000    1013.2
 330.0000    1032.0
 335.0000    1025.0
 340.0000    1034.7
 345.0000    1028.3
 350.0000    1017.2
 355.0000    1020.8
; (Data for Range number 2)
_DRIVE='PHI'
_STEPTIME=11.999800
_STEPSIZE=5.000000
_STEPMODE='C'
_START=0.000000
_THETA=21.697500
_2THETA=43.395000
_KHI=5.000000
_PHI=0.000000
_X=0.000000
_Y=0.000000
_Z=0.000000
_DIVERGENCE=0.200000
_ANTISCATTER=0.200000
_DETECTOR=1
; S.C.
_HV=683.500000
_GAIN=80.000000
_LLD=0.788000
_ULD=2.160000
_DETECTORSLIT='out'
_AUX1=0.000000
_AUX2=0.000000
_AUX3=0.000000
_TIMESTARTED=891.000000
_TEMP_RATE=0.000000
_TEMP_DELAY=0.000000
_KV=40
_MA=30
_RANGE_WL=1.540600
_3DPLANE=0
_2THETACPS
   0.0000    966.10
   5.0000    977.60
  10.0000    968.52
  15.0000    969.35
  20.0000    943.93
  25.0000    980.02
  30.0000    979.85
  35.0000    982.93
  40.0000    970.77
  45.0000    993.85
  50.0000    1000.9
  55.0000    991.27
  60.0000    1014.2
  65.0000    1034.2
  70.0000    1023.4
  75.0000    1038.9
  80.0000    1074.2
  85.0000    1062.4
  90.0000    1062.2
  95.0000    1064.4
 100.0000    1048.2
 105.0000    1026.4
 110.0000    1023.6
 115.0000    1017.9
 120.0000    991.02
 125.0000    1013.4
 130.0000    1025.7
 135.0000    1019.7
 140.0000    1001.6
 145.0000    970.77
 150.0000    967.60
 155.0000    978.85
 160.0000    968.60
 165.0000    971.43
 170.0000    934.10
 175.0000    919.02
 180.0000    897.68
 185.0000    943.68
 190.0000    947.35
 195.0000    981.52
 200.0000    973.60
 205.0000    1007.6
 210.0000    1049.9
 215.0000    1050.4
 220.0000    1050.4
 225.0000    1054.2
 230.0000    1034.9
 235.0000    1024.1
 240.0000    1028.1
 245.0000    1021.4
 250.0000    1024.2
 255.0000    1010.4
 260.0000    1016.0
 265.0000    1023.5
 270.0000    1043.1
 275.0000    1047.9
 280.0000    1039.9
 285.0000    1055.1
 290.0000    1054.4
 295.0000    1024.4
 300.0000    1031.7
 305.0000    1047.7
 310.0000    1043.2
 315.0000    1054.4
 320.0000    1055.9
 325.0000    1063.7
 330.0000    1043.5
 335.0000    985.93
 340.0000    982.93
 345.0000    1000.8
 350.0000    982.43
 355.0000    974.77
; (Data for Range number 3)
_DRIVE='PHI'
_STEPTIME=11.999800
_STEPSIZE=5.000000
_STEPMODE='C'
_START=0.000000
_THETA=21.697500
_2THETA=43.395000
_KHI=10.000000
_PHI=0.000000
_X=0.000000
_Y=0.000000
_Z=0.000000
_DIVERGENCE=0.200000
_ANTISCATTER=0.200000
_DETECTOR=1
; S.C.
_HV=683.500000
_GAIN=80.000000
_LLD=0.788000
_ULD=2.160000
_DETECTORSLIT='out'
_AUX1=0.000000
_AUX2=0.000000
_AUX3=0.000000
_TIMESTARTED=1759.000000
_TEMP_RATE=0.000000
_TEMP_DELAY=0.000000
_KV=40
_MA=30
_RANGE_WL=1.540600
_3DPLANE=0
_2THETACPS
   0.0000    858.76
   5.0000    865.68
  10.0000    894.18
  15.0000    911.10
  20.0000    904.60
  25.0000    902.68
  30.0000    891.68
  35.0000    903.77
  40.0000    937.43
  45.0000    972.93
  50.0000    991.77
  55.0000    981.85
  60.0000    998.18
  65.0000    991.02
  70.0000    991.18
  75.0000    1008.4
  80.0000    1004.0
  85.0000    1022.2
  90.0000    1048.4
  95.0000    1073.0
 100.0000    1066.7
 105.0000    1068.9
 110.0000    1022.6
 115.0000    1014.9
 120.0000    988.93
 125.0000    973.85
 130.0000    955.10
 135.0000    939.18
 140.0000    941.35
 145.0000    938.10
 150.0000    938.93
 155.0000    955.35
 160.0000    964.85
 165.0000    976.43
 170.0000    908.52
 175.0000    936.77
 180.0000    939.77
 185.0000    985.43
 190.0000    1046.2
 195.0000    1041.5
 200.0000    1060.4
 205.0000    1053.8
 210.0000    1034.9
 215.0000    1021.2
 220.0000    1038.4
 225.0000    1042.0
 230.0000    1081.9
 235.0000    1083.6
 240.0000    1170.4
 245.0000    1166.8
 250.0000    1149.2
 255.0000    1131.0
 260.0000    1101.5
 265.0000    1117.8
 270.0000    1108.9
 275.0000    1129.1
 280.0000    1099.3
 285.0000    1069.3
 290.0000    1004.0
 295.0000    1052.2
 300.0000    1107.9
 305.0000    1019.1
 310.0000    1002.2
 315.0000    996.52
 320.0000    971.77
 325.0000    942.27
 330.0000    976.43
 335.0000    968.02
 340.0000    918.60
 345.0000    884.85
 350.0000    843.01
 355.0000    866.68
; (Data for Range number 4)
_DRIVE='PHI'
_STEPTIME=11.999800
_STEPSIZE=5.000000
_STEPMODE='C'
_START=0.000000
_THETA=21.697500
_2THETA=43.395000
_KHI=15.000000
_PHI=0.000000
_X=0.000000
_Y=0.000000
_Z=0.000000
_DIVERGENCE=0.200000
_ANTISCATTER=0.200000
_DETECTOR=1
; S.C.
_HV=683.500000
_GAIN=80.000000
_LLD=0.788000
_ULD=2.160000
_DETECTORSLIT='out'
_AUX1=0.000000
_AUX2=0.000000
_AUX3=0.000000
_TIMESTARTED=2628.000000
_TEMP_RATE=0.000000
_TEMP_DELAY=0.000000
_KV=40
_MA=30
_RANGE_WL=1.540600
_3DPLANE=0
_2THETACPS
   0.0000    835.18
   5.0000    832.93
  10.0000    829.93
  15.0000    839.18
  20.0000    813.68
  25.0000    801.93
  30.0000    885.68
  35.0000    936.18
  40.0000    939.68
  45.0000    951.18
  50.0000    971.60
  55.0000    970.77
  60.0000    989.93
  65.0000    1013.4
  70.0000    1029.6
  75.0000    1041.3
  80.0000    1039.9
  85.0000    1074.6
  90.0000    1055.7
  95.0000    1055.9
 100.0000    1095.9
 105.0000    1137.1
 110.0000    1117.2
 115.0000    1135.3
 120.0000    1095.9
 125.0000    1062.9
 130.0000    1022.4
 135.0000    1008.9
 140.0000    958.27
 145.0000    920.18
 150.0000    876.18
 155.0000    882.60
 160.0000    905.43
 165.0000    902.52
 170.0000    955.60
 175.0000    1016.5
 180.0000    1055.4
 185.0000    1136.2
 190.0000    1048.5
 195.0000    1055.6
 200.0000    1013.1
 205.0000    954.60
 210.0000    953.02
 215.0000    958.77
 220.0000    987.68
 225.0000    990.85
 230.0000    946.77
 235.0000    939.18
 240.0000    948.77
 245.0000    958.93
 250.0000    928.77
 255.0000    880.35
 260.0000    851.85
 265.0000    881.93
 270.0000    860.60
 275.0000    899.35
 280.0000    938.02
 285.0000    921.43
 290.0000    917.35
 295.0000    887.93
 300.0000    875.10
 305.0000    894.76
 310.0000    866.51
 315.0000    901.43
 320.0000    894.93
 325.0000    908.27
 330.0000    943.60
 335.0000    939.52
 340.0000    828.51
 345.0000    784.93
 350.0000    752.68
 355.0000    802.93
; (Data for Range number 5)
_DRIVE='PHI'
_STEPTIME=11.999800
_STEPSIZE=5.000000
_STEPMODE='C'
_START=0.000000
_THETA=21.697500
_2THETA=43.395000
_KHI=20.000000
_PHI=0.000000
_X=0.000000
_Y=0.000000
_Z=0.000000
_DIVERGENCE=0.200000
_ANTISCATTER=0.200000
_DETECTOR=1
; S.C.
_HV=683.500000
_GAIN=80.000000
_LLD=0.788000
_ULD=2.160000
_DETECTORSLIT='out'
_AUX1=0.000000
_AUX2=0.000000
_AUX3=0.000000
_TIMESTARTED=3496.000000
_TEMP_RATE=0.000000
_TEMP_DELAY=0.000000
_KV=40
_MA=30
_RANGE_WL=1.540600
_3DPLANE=0
_2THETACPS
   0.0000    828.01
   5.0000    860.43
  10.0000    800.93
  15.0000    761.76
  20.0000    760.10
  25.0000    814.43
  30.0000    913.60
  35.0000    910.52
  40.0000    921.43
  45.0000    967.77
  50.0000    1010.2
  55.0000    998.10
  60.0000    985.52
  65.0000    979.43
  70.0000    970.52
  75.0000    977.77
  80.0000    1037.6
  85.0000    1055.4
  90.0000    1071.0
  95.0000    1067.0
 100.0000    1110.5
 105.0000    1148.3
 110.0000    1141.7
 115.0000    1163.1
 120.0000    1187.2
 125.0000    1132.2
 130.0000    1103.1
 135.0000    1055.4
 140.0000    981.18
 145.0000    922.52
 150.0000    894.68
 155.0000    876.68
 160.0000    877.26
 165.0000    901.85
 170.0000    905.85
 175.0000    969.27
 180.0000    1061.3
 185.0000    989.77
 190.0000    943.27
 195.0000    987.10
 200.0000    989.35
 205.0000    1038.6
 210.0000    964.68
 215.0000    958.68
 220.0000    1003.3
 225.0000    1045.9
 230.0000    1075.8
 235.0000    1024.9
 240.0000    930.77
 245.0000    903.52
 250.0000    891.18
 255.0000    893.51
 260.0000    893.85
 265.0000    949.27
 270.0000    984.68
 275.0000    1004.9
 280.0000    1006.0
 285.0000    950.02
 290.0000    895.60
 295.0000    837.68
 300.0000    785.68
 305.0000    767.10
 310.0000    820.85
 315.0000    775.60
 320.0000    782.60
 325.0000    768.93
 330.0000    788.85
 335.0000    815.93
 340.0000    790.76
 345.0000    780.10
 350.0000    792.26
 355.0000    783.60
; (Data for Range number 6)
_DRIVE='PHI'
_STEPTIME=11.999800
_STEPSIZE=5.000000
_STEPMODE='C'
_START=0.000000
_THETA=21.697500
_2THETA=43.395000
_KHI=25.000000
_PHI=0.000000
_X=0.000000
_Y=0.000000
_Z=0.000000
_DIVERGENCE=0.200000
_ANTISCATTER=0.200000
_DETECTOR=1
; S.C.
_HV=683.500000
_GAIN=80.000000
_LLD=0.788000
_ULD=2.160000
_DETECTORSLIT='out'
_AUX1=0.000000
_AUX2=0.000000
_AUX3=0.000000
_TIMESTARTED=4365.000000
_TEMP_RATE=0.000000
_TEMP_DELAY=0.000000
_KV=40
_MA=30
_RANGE_WL=1.540600
_3DPLANE=0
_2THETACPS
   0.0000    822.43
   5.0000    861.18
  10.0000    796.68
  15.0000    759.10
  20.0000    776.68
  25.0000    808.10
  30.0000    820.18
  35.0000    854.76
  40.0000    881.76
  45.0000    904.93
  50.0000    951.52
  55.0000    992.27
  60.0000    1040.7
  65.0000    1050.8
  70.0000    1029.7
  75.0000    971.68
  80.0000    963.10
  85.0000    1038.8
  90.0000    1090.9
  95.0000    1119.4
 100.0000    1069.8
 105.0000    1008.9
 110.0000    1014.4
 115.0000    1067.8
 120.0000    1128.9
 125.0000    1137.4
 130.0000    1026.2
 135.0000    990.60
 140.0000    980.60
 145.0000    963.27
 150.0000    907.60
 155.0000    863.51
 160.0000    855.10
 165.0000    890.01
 170.0000    845.93
 175.0000    893.60
 180.0000    891.18
 185.0000    911.43
 190.0000    931.93
 195.0000    1024.2
 200.0000    979.68
 205.0000    979.35
 210.0000    945.35
 215.0000    964.10
 220.0000    1028.7
 225.0000    1114.6
 230.0000    1141.8
 235.0000    1093.9
 240.0000    1041.8
 245.0000    1007.4
 250.0000    1008.6
 255.0000    1002.7
 260.0000    988.52
 265.0000    968.27
 270.0000    942.60
 275.0000    900.27
 280.0000    886.60
 285.0000    950.35
 290.0000    988.27
 295.0000    879.18
 300.0000    845.76
 305.0000    804.10
 310.0000    760.26
 315.0000    734.51
 320.0000    766.43
 325.0000    798.18
 330.0000    786.93
 335.0000    748.35
 340.0000    728.26
 345.0000    730.26
 350.0000    732.51
 355.0000    761.43
; (Data for Range number 7)
_DRIVE='PHI'
_STEPTIME=11.999800
_STEPSIZE=5.000000
_STEPMODE='C'
_START=0.000000
_THETA=21.697500
_2THETA=43.395000
_KHI=30.000000
_PHI=0.000000
_X=0.000000
_Y=0.000000
_Z=0.000000
_DIVERGENCE=0.200000
_ANTISCATTER=0.200000
_DETECTOR=1
; S.C.
_HV=683.500000
_GAIN=80.000000
_LLD=0.788000
_ULD=2.160000
_DETECTORSLIT='out'
_AUX1=0.000000
_AUX2=0.000000
_AUX3=0.000000
_TIMESTARTED=5234.000000
_TEMP_RATE=0.000000
_TEMP_DELAY=0.000000
_KV=40
_MA=30
_RANGE_WL=1.540600
_3DPLANE=0
_2THETACPS
   0.0000    856.43
   5.0000    901.10
  10.0000    904.77
  15.0000    851.10
  20.0000    834.93
  25.0000    840.18
  30.0000    895.60
  35.0000    906.60
  40.0000    900.60
  45.0000    908.18
  50.0000    895.85
  55.0000    968.60
  60.0000    981.85
  65.0000    1024.2
  70.0000    1017.4
  75.0000    1017.1
  80.0000    989.77
  85.0000    1011.2
  90.0000    941.10
  95.0000    930.85
 100.0000    947.85
 105.0000    910.27
 110.0000    860.01
 115.0000    854.35
 120.0000    869.10
 125.0000    903.10
 130.0000    968.43
 135.0000    927.10
 140.0000    897.35
 145.0000    884.85
 150.0000    937.10
 155.0000    901.35
 160.0000    801.93
 165.0000    794.43
 170.0000    829.10
 175.0000    828.76
 180.0000    729.43
 185.0000    814.01
 190.0000    830.68
 195.0000    853.26
 200.0000    848.10
 205.0000    825.85
 210.0000    920.35
 215.0000    951.77
 220.0000    885.18
 225.0000    1029.4
 230.0000    1079.5
 235.0000    1117.8
 240.0000    1094.4
 245.0000    1036.7
 250.0000    1000.0
 255.0000    958.02
 260.0000    973.35
 265.0000    1030.4
 270.0000    1048.4
 275.0000    1074.4
 280.0000    1039.9
 285.0000    1021.2
 290.0000    915.77
 295.0000    911.02
 300.0000    842.68
 305.0000    770.43
 310.0000    794.10
 315.0000    771.68
 320.0000    774.26
 325.0000    763.51
 330.0000    765.85
 335.0000    739.51
 340.0000    695.93
 345.0000    718.10
 350.0000    753.60
 355.0000    769.51
; (Data for Range number 8)
_DRIVE='PHI'
_STEPTIME=11.999800
_STEPSIZE=5.000000
_STEPMODE='C'
_START=0.000000
_THETA=21.697500
_2THETA=43.395000
_KHI=35.000000
_PHI=0.000000
_X=0.000000
_Y=0.000000
_Z=0.000000
_DIVERGENCE=0.200000
_ANTISCATTER=0.200000
_DETECTOR=1
; S.C.
_HV=683.500000
_GAIN=80.000000
_LLD=0.788000
_ULD=2.160000
_DETECTORSLIT='out'
_AUX1=0.000000
_AUX2=0.000000
_AUX3=0.000000
_TIMESTARTED=6102.000000
_TEMP_RATE=0.000000
_TEMP_DELAY=0.000000
_KV=40
_MA=30
_RANGE_WL=1.540600
_3DPLANE=0
_2THETACPS
   0.0000    734.10
   5.0000    865.18
  10.0000    790.43
  15.0000    782.60
  20.0000    753.35
  25.0000    796.60
  30.0000    885.76
  35.0000    807.51
  40.0000    796.01
  45.0000    890.51
  50.0000    867.68
  55.0000    878.43
  60.0000    874.43
  65.0000    862.18
  70.0000    855.35
  75.0000    926.10
  80.0000    994.93
  85.0000    1026.9
  90.0000    1052.9
  95.0000    1030.1
 100.0000    1117.5
 105.0000    1079.4
 110.0000    946.85
 115.0000    835.76
 120.0000    772.35
 125.0000    736.76
 130.0000    827.60
 135.0000    884.35
 140.0000    859.26
 145.0000    825.10
 150.0000    848.01
 155.0000    854.26
 160.0000    808.35
 165.0000    811.68
 170.0000    789.01
 175.0000    770.43
 180.0000    722.01
 185.0000    846.93
 190.0000    789.43
 195.0000    709.01
 200.0000    692.18
 205.0000    747.51
 210.0000    833.93
 215.0000    900.52
 220.0000    889.01
 225.0000    900.43
 230.0000    1054.3
 235.0000    1098.6
 240.0000    1061.6
 245.0000    919.27
 250.0000    908.85
 255.0000    925.18
 260.0000    908.93
 265.0000    1020.8
 270.0000    1063.9
 275.0000    1035.8
 280.0000    977.60
 285.0000    992.60
 290.0000    1050.0
 295.0000    961.60
 300.0000    895.26
 305.0000    1023.9
 310.0000    1011.2
 315.0000    826.35
 320.0000    881.85
 325.0000    822.60
 330.0000    740.43
 335.0000    709.35
 340.0000    707.35
 345.0000    734.26
 350.0000    720.18
 355.0000    698.26
; (Data for Range number 9)
_DRIVE='PHI'
_STEPTIME=11.999800
_STEPSIZE=5.000000
_STEPMODE='C'
_START=0.000000
_THETA=21.697500
_2THETA=43.395000
_KHI=40.000000
_PHI=0.000000
_X=0.000000
_Y=0.000000
_Z=0.000000
_DIVERGENCE=0.200000
_ANTISCATTER=0.200000
_DETECTOR=1
; S.C.
_HV=683.500000
_GAIN=80.000000
_LLD=0.788000
_ULD=2.160000
_DETECTORSLIT='out'
_AUX1=0.000000
_AUX2=0.000000
_AUX3=0.000000
_TIMESTARTED=6971.000000
_TEMP_RATE=0.000000
_TEMP_DELAY=0.000000
_KV=40
_MA=30
_RANGE_WL=1.540600
_3DPLANE=0
_2THETACPS
   0.0000    734.01
   5.0000    741.10
  10.0000    729.93
  15.0000    782.35
  20.0000    815.68
  25.0000    769.35
  30.0000    714.43
  35.0000    727.01
  40.0000    800.76
  45.0000    822.01
  50.0000    809.93
  55.0000    817.85
  60.0000    823.18
  65.0000    809.93
  70.0000    822.93
  75.0000    842.10
  80.0000    861.68
  85.0000    963.93
  90.0000    924.93
  95.0000    946.77
 100.0000    963.93
 105.0000    974.68
 110.0000    965.35
 115.0000    891.93
 120.0000    813.01
 125.0000    763.01
 130.0000    705.35
 135.0000    770.93
 140.0000    756.93
 145.0000    773.18
 150.0000    741.26
 155.0000    771.85
 160.0000    698.34
 165.0000    749.35
 170.0000    796.51
 175.0000    756.26
 180.0000    745.18
 185.0000    769.76
 190.0000    761.68
 195.0000    701.60
 200.0000    679.84
 205.0000    696.51
 210.0000    786.43
 215.0000    812.10
 220.0000    728.68
 225.0000    750.68
 230.0000    776.35
 235.0000    773.60
 240.0000    793.01
 245.0000    812.43
 250.0000    822.35
 255.0000    835.43
 260.0000    772.35
 265.0000    802.01
 270.0000    844.26
 275.0000    846.60
 280.0000    798.35
 285.0000    833.35
 290.0000    956.77
 295.0000    918.43
 300.0000    790.26
 305.0000    790.10
 310.0000    829.68
 315.0000    754.10
 320.0000    765.60
 325.0000    781.10
 330.0000    694.09
 335.0000    701.76
 340.0000    732.10
 345.0000    726.68
 350.0000    665.34
 355.0000    653.26
; (Data for Range number 10)
_DRIVE='PHI'
_STEPTIME=11.999800
_STEPSIZE=5.000000
_STEPMODE='C'
_START=0.000000
_THETA=21.697500
_2THETA=43.395000
_KHI=45.000000
_PHI=0.000000
_X=0.000000
_Y=0.000000
_Z=0.000000
_DIVERGENCE=0.200000
_ANTISCATTER=0.200000
_DETECTOR=1
; S.C.
_HV=683.500000
_GAIN=80.000000
_LLD=0.788000
_ULD=2.160000
_DETECTORSLIT='out'
_AUX1=0.000000
_AUX2=0.000000
_AUX3=0.000000
_TIMESTARTED=7840.000000
_TEMP_RATE=0.000000
_TEMP_DELAY=0.000000
_KV=40
_MA=30
_RANGE_WL=1.540600
_3DPLANE=0
_2THETACPS
   0.0000    665.68
   5.0000    670.01
  10.0000    730.43
  15.0000    742.51
  20.0000    721.18
  25.0000    678.43
  30.0000    693.26
  35.0000    729.85
  40.0000    718.26
  45.0000    718.85
  50.0000    817.26
  55.0000    812.76
  60.0000    814.76
  65.0000    865.76
  70.0000    927.02
  75.0000    985.77
  80.0000    916.35
  85.0000    884.18
  90.0000    873.10
  95.0000    890.35
 100.0000    875.85
 105.0000    910.52
 110.0000    841.93
 115.0000    745.18
 120.0000    742.26
 125.0000    761.51
 130.0000    769.43
 135.0000    756.35
 140.0000    665.09
 145.0000    679.93
 150.0000    671.26
 155.0000    696.43
 160.0000    647.68
 165.0000    663.09
 170.0000    716.18
 175.0000    730.76
 180.0000    737.18
 185.0000    719.93
 190.0000    736.01
 195.0000    663.59
 200.0000    636.84
 205.0000    730.18
 210.0000    794.10
 215.0000    734.18
 220.0000    721.76
 225.0000    669.09
 230.0000    692.09
 235.0000    698.93
 240.0000    788.43
 245.0000    849.51
 250.0000    853.68
 255.0000    837.60
 260.0000    781.76
 265.0000    761.35
 270.0000    701.76
 275.0000    694.68
 280.0000    774.85
 285.0000    775.51
 290.0000    842.68
 295.0000    893.26
 300.0000    712.60
 305.0000    731.93
 310.0000    681.34
 315.0000    614.93
 320.0000    673.18
 325.0000    700.35
 330.0000    645.84
 335.0000    688.01
 340.0000    754.51
 345.0000    692.76
 350.0000    650.68
 355.0000    657.76
; (Data for Range number 11)
_DRIVE='PHI'
_STEPTIME=11.999800
_STEPSIZE=5.000000
_STEPMODE='C'
_START=0.000000
_THETA=21.697500
_2THETA=43.395000
_KHI=50.000000
_PHI=0.000000
_X=0.000000
_Y=0.000000
_Z=0.000000
_DIVERGENCE=0.200000
_ANTISCATTER=0.200000
_DETECTOR=1
; S.C.
_HV=683.500000
_GAIN=80.000000
_LLD=0.788000
_ULD=2.160000
_DETECTORSLIT='out'
_AUX1=0.000000
_AUX2=0.000000
_AUX3=0.000000
_TIMESTARTED=8708.000000
_TEMP_RATE=0.000000
_TEMP_DELAY=0.000000
_KV=40
_MA=30
_RANGE_WL=1.540600
_3DPLANE=0
_2THETACPS
   0.0000    591.18
   5.0000    676.68
  10.0000    674.93
  15.0000    674.84
  20.0000    652.18
  25.0000    664.51
  30.0000    724.43
  35.0000    702.68
  40.0000    648.76
  45.0000    706.35
  50.0000    762.43
  55.0000    759.68
  60.0000    704.10
  65.0000    728.35
  70.0000    899.10
  75.0000    937.85
  80.0000    838.68
  85.0000    816.10
  90.0000    851.60
  95.0000    770.01
 100.0000    729.93
 105.0000    765.01
 110.0000    711.76
 115.0000    644.76
 120.0000    657.01
 125.0000    710.51
 130.0000    785.10
 135.0000    705.51
 140.0000    640.76
 145.0000    617.09
 150.0000    597.09
 155.0000    656.51
 160.0000    643.34
 165.0000    687.34
 170.0000    655.76
 175.0000    666.18
 180.0000    670.84
 185.0000    676.84
 190.0000    642.51
 195.0000    617.09
 200.0000    625.93
 205.0000    673.76
 210.0000    632.43
 215.0000    586.76
 220.0000    590.26
 225.0000    555.26
 230.0000    564.76
 235.0000    630.09
 240.0000    730.51
 245.0000    725.60
 250.0000    756.26
 255.0000    732.18
 260.0000    690.84
 265.0000    663.93
 270.0000    727.76
 275.0000    755.85
 280.0000    670.26
 285.0000    706.51
 290.0000    718.51
 295.0000    813.93
 300.0000    665.59
 305.0000    618.34
 310.0000    620.59
 315.0000    586.68
 320.0000    582.09
 325.0000    626.51
 330.0000    632.26
 335.0000    582.84
 340.0000    625.76
 345.0000    644.59
 350.0000    687.68
 355.0000    594.34
; (Data for Range number 12)
_DRIVE='PHI'
_STEPTIME=11.999800
_STEPSIZE=5.000000
_STEPMODE='C'
_START=0.000000
_THETA=21.697500
_2THETA=43.395000
_KHI=55.000000
_PHI=0.000000
_X=0.000000
_Y=0.000000
_Z=0.000000
_DIVERGENCE=0.200000
_ANTISCATTER=0.200000
_DETECTOR=1
; S.C.
_HV=683.500000
_GAIN=80.000000
_LLD=0.788000
_ULD=2.160000
_DETECTORSLIT='out'
_AUX1=0.000000
_AUX2=0.000000
_AUX3=0.000000
_TIMESTARTED=9577.000000
_TEMP_RATE=0.000000
_TEMP_DELAY=0.000000
_KV=40
_MA=30
_RANGE_WL=1.540600
_3DPLANE=0
_2THETACPS
   0.0000    586.43
   5.0000    579.68
  10.0000    581.51
  15.0000    587.84
  20.0000    633.09
  25.0000    656.18
  30.0000    691.51
  35.0000    677.51
  40.0000    636.34
  45.0000    603.76
  50.0000    568.09
  55.0000    571.59
  60.0000    563.93
  65.0000    635.93
  70.0000    659.84
  75.0000    685.84
  80.0000    692.76
  85.0000    656.01
  90.0000    671.84
  95.0000    656.59
 100.0000    632.51
 105.0000    670.18
 110.0000    657.01
 115.0000    551.68
 120.0000    553.34
 125.0000    580.18
 130.0000    672.59
 135.0000    687.76
 140.0000    661.09
 145.0000    651.93
 150.0000    542.84
 155.0000    572.68
 160.0000    623.01
 165.0000    700.93
 170.0000    680.68
 175.0000    611.59
 180.0000    596.26
 185.0000    581.68
 190.0000    585.59
 195.0000    560.59
 200.0000    586.93
 205.0000    609.68
 210.0000    597.34
 215.0000    539.51
 220.0000    549.09
 225.0000    509.34
 230.0000    519.84
 235.0000    623.59
 240.0000    726.18
 245.0000    733.35
 250.0000    758.01
 255.0000    707.18
 260.0000    747.68
 265.0000    725.51
 270.0000    668.84
 275.0000    693.34
 280.0000    686.51
 285.0000    659.76
 290.0000    615.76
 295.0000    620.18
 300.0000    638.59
 305.0000    604.93
 310.0000    579.68
 315.0000    564.18
 320.0000    532.09
 325.0000    528.84
 330.0000    530.59
 335.0000    533.18
 340.0000    534.01
 345.0000    566.93
 350.0000    605.76
 355.0000    555.18
; (Data for Range number 13)
_DRIVE='PHI'
_STEPTIME=11.999800
_STEPSIZE=5.000000
_STEPMODE='C'
_START=0.000000
_THETA=21.697500
_2THETA=43.395000
_KHI=60.000000
_PHI=0.000000
_X=0.000000
_Y=0.000000
_Z=0.000000
_DIVERGENCE=0.200000
_ANTISCATTER=0.200000
_DETECTOR=1
; S.C.
_HV=683.500000
_GAIN=80.000000
_LLD=0.788000
_ULD=2.160000
_DETECTORSLIT='out'
_AUX1=0.000000
_AUX2=0.000000
_AUX3=0.000000
_TIMESTARTED=10446.000000
_TEMP_RATE=0.000000
_TEMP_DELAY=0.000000
_KV=40
_MA=30
_RANGE_WL=1.540600
_3DPLANE=0
_2THETACPS
   0.0000    474.76
   5.0000    487.59
  10.0000    501.93
  15.0000    541.43
  20.0000    559.76
  25.0000    569.84
  30.0000    556.68
  35.0000    541.43
  40.0000    523.18
  45.0000    506.76
  50.0000    511.18
  55.0000    482.59
  60.0000    532.59
  65.0000    605.18
  70.0000    612.18
  75.0000    553.76
  80.0000    491.01
  85.0000    514.93
  90.0000    553.18
  95.0000    578.51
 100.0000    532.01
 105.0000    594.59
 110.0000    587.26
 115.0000    541.76
 120.0000    521.59
 125.0000    531.76
 130.0000    547.68
 135.0000    542.43
 140.0000    588.93
 145.0000    605.93
 150.0000    524.68
 155.0000    515.34
 160.0000    577.76
 165.0000    637.76
 170.0000    639.43
 175.0000    556.34
 180.0000    525.51
 185.0000    504.51
 190.0000    511.26
 195.0000    561.09
 200.0000    525.09
 205.0000    530.43
 210.0000    536.09
 215.0000    515.26
 220.0000    490.34
 225.0000    540.18
 230.0000    528.43
 235.0000    574.34
 240.0000    594.76
 245.0000    635.34
 250.0000    627.01
 255.0000    646.26
 260.0000    568.34
 265.0000    564.76
 270.0000    624.43
 275.0000    677.68
 280.0000    608.68
 285.0000    533.93
 290.0000    554.59
 295.0000    582.34
 300.0000    553.01
 305.0000    501.84
 310.0000    476.42
 315.0000    505.26
 320.0000    512.26
 325.0000    465.76
 330.0000    483.59
 335.0000    499.76
 340.0000    504.18
 345.0000    492.34
 350.0000    496.42
 355.0000    506.76
; (Data for Range number 14)
_DRIVE='PHI'
_STEPTIME=11.999800
_STEPSIZE=5.000000
_STEPMODE='C'
_START=0.000000
_THETA=21.697500
_2THETA=43.395000
_KHI=65.000000
_PHI=0.000000
_X=0.000000
_Y=0.000000
_Z=0.000000
_DIVERGENCE=0.200000
_ANTISCATTER=0.200000
_DETECTOR=1
; S.C.
_HV=683.500000
_GAIN=80.000000
_LLD=0.788000
_ULD=2.160000
_DETECTORSLIT='out'
_AUX1=0.000000
_AUX2=0.000000
_AUX3=0.000000
_TIMESTARTED=11314.000000
_TEMP_RATE=0.000000
_TEMP_DELAY=0.000000
_KV=40
_MA=30
_RANGE_WL=1.540600
_3DPLANE=0
_2THETACPS
   0.0000    446.26
   5.0000    448.01
  10.0000    476.34
  15.0000    504.01
  20.0000    491.92
  25.0000    469.17
  30.0000    451.42
  35.0000    479.59
  40.0000    471.76
  45.0000    434.51
  50.0000    439.59
  55.0000    426.01
  60.0000    445.76
  65.0000    503.26
  70.0000    507.43
  75.0000    499.01
  80.0000    399.01
  85.0000    428.59
  90.0000    452.67
  95.0000    496.01
 100.0000    572.09
 105.0000    614.18
 110.0000    520.18
 115.0000    489.34
 120.0000    487.01
 125.0000    520.68
 130.0000    532.18
 135.0000    482.84
 140.0000    505.26
 145.0000    529.26
 150.0000    505.84
 155.0000    473.92
 160.0000    525.34
 165.0000    535.59
 170.0000    526.34
 175.0000    509.76
 180.0000    448.26
 185.0000    426.42
 190.0000    474.17
 195.0000    480.09
 200.0000    463.17
 205.0000    482.42
 210.0000    486.51
 215.0000    525.51
 220.0000    468.92
 225.0000    443.84
 230.0000    472.92
 235.0000    468.34
 240.0000    470.59
 245.0000    499.43
 250.0000    599.76
 255.0000    542.84
 260.0000    494.17
 265.0000    491.34
 270.0000    527.51
 275.0000    502.26
 280.0000    494.51
 285.0000    473.17
 290.0000    462.17
 295.0000    466.76
 300.0000    460.42
 305.0000    471.26
 310.0000    469.09
 315.0000    425.67
 320.0000    465.76
 325.0000    402.59
 330.0000    417.26
 335.0000    456.01
 340.0000    450.34
 345.0000    440.92
 350.0000    434.42
 355.0000    442.26
; (Data for Range number 15)
_DRIVE='PHI'
_STEPTIME=11.999800
_STEPSIZE=5.000000
_STEPMODE='C'
_START=0.000000
_THETA=21.697500
_2THETA=43.395000
_KHI=70.000000
_PHI=0.000000
_X=0.000000
_Y=0.000000
_Z=0.000000
_DIVERGENCE=0.200000
_ANTISCATTER=0.200000
_DETECTOR=1
; S.C.
_HV=683.500000
_GAIN=80.000000
_LLD=0.788000
_ULD=2.160000
_DETECTORSLIT='out'
_AUX1=0.000000
_AUX2=0.000000
_AUX3=0.000000
_TIMESTARTED=12183.000000
_TEMP_RATE=0.000000
_TEMP_DELAY=0.000000
_KV=40
_MA=30
_RANGE_WL=1.540600
_3DPLANE=0
_2THETACPS
   0.0000    378.59
   5.0000    418.92
  10.0000    420.01
  15.0000    432.59
  20.0000    424.84
  25.0000    408.17
  30.0000    399.01
  35.0000    415.51
  40.0000    396.76
  45.0000    364.92
  50.0000    339.92
  55.0000    343.59
  60.0000    382.51
  65.0000    435.34
  70.0000    407.92
  75.0000    352.92
  80.0000    345.67
  85.0000    363.17
  90.0000    389.92
  95.0000    429.42
 100.0000    442.92
 105.0000    514.68
 110.0000    465.92
 115.0000    471.51
 120.0000    447.84
 125.0000    460.26
 130.0000    431.17
 135.0000    432.42
 140.0000    430.76
 145.0000    437.09
 150.0000    417.01
 155.0000    385.17
 160.0000    449.59
 165.0000    440.76
 170.0000    417.34
 175.0000    398.34
 180.0000    374.84
 185.0000    382.76
 190.0000    393.17
 195.0000    392.01
 200.0000    411.09
 205.0000    409.59
 210.0000    412.92
 215.0000    441.17
 220.0000    384.42
 225.0000    396.76
 230.0000    420.92
 235.0000    382.26
 240.0000    358.42
 245.0000    384.42
 250.0000    410.92
 255.0000    376.42
 260.0000    340.84
 265.0000    352.09
 270.0000    361.01
 275.0000    392.76
 280.0000    421.76
 285.0000    416.84
 290.0000    397.51
 295.0000    432.01
 300.0000    374.09
 305.0000    396.92
 310.0000    387.17
 315.0000    358.34
 320.0000    366.34
 325.0000    356.09
 330.0000    358.67
 335.0000    376.42
 340.0000    373.76
 345.0000    363.01
 350.0000    353.17
 355.0000    354.67
; (Data for Range number 16)
_DRIVE='PHI'
_STEPTIME=11.999800
_STEPSIZE=5.000000
_STEPMODE='C'
_START=0.000000
_THETA=21.697500
_2THETA=43.395000
_KHI=75.000000
_PHI=0.000000
_X=0.000000
_Y=0.000000
_Z=0.000000
_DIVERGENCE=0.200000
_ANTISCATTER=0.200000
_DETECTOR=1
; S.C.
_HV=683.500000
_GAIN=80.000000
_LLD=0.788000
_ULD=2.160000
_DETECTORSLIT='out'
_AUX1=0.000000
_AUX2=0.000000
_AUX3=0.000000
_TIMESTARTED=13051.000000
_TEMP_RATE=0.000000
_TEMP_DELAY=0.000000
_KV=40
_MA=30
_RANGE_WL=1.540600
_3DPLANE=0
_2THETACPS
   0.0000    256.09
   5.0000    278.92
  10.0000    301.42
  15.0000    341.76
  20.0000    314.92
  25.0000    328.92
  30.0000    321.42
  35.0000    338.34
  40.0000    314.76
  45.0000    256.50
  50.0000    256.25
  55.0000    287.00
  60.0000    301.84
  65.0000    329.42
  70.0000    318.34
  75.0000    322.42
  80.0000    299.25
  85.0000    307.34
  90.0000    301.84
  95.0000    306.92
 100.0000    317.42
 105.0000    346.67
 110.0000    351.34
 115.0000    373.01
 120.0000    355.42
 125.0000    360.51
 130.0000    357.17
 135.0000    334.01
 140.0000    324.59
 145.0000    314.84
 150.0000    299.92
 155.0000    286.00
 160.0000    306.59
 165.0000    315.26
 170.0000    302.17
 175.0000    284.00
 180.0000    263.34
 185.0000    277.59
 190.0000    267.92
 195.0000    292.09
 200.0000    300.84
 205.0000    307.34
 210.0000    314.17
 215.0000    324.84
 220.0000    318.76
 225.0000    321.67
 230.0000    320.51
 235.0000    318.67
 240.0000    307.51
 245.0000    297.92
 250.0000    304.84
 255.0000    280.84
 260.0000    275.84
 265.0000    285.84
 270.0000    305.76
 275.0000    293.84
 280.0000    304.01
 285.0000    321.09
 290.0000    311.17
 295.0000    347.42
 300.0000    337.09
 305.0000    329.26
 310.0000    305.92
 315.0000    291.00
 320.0000    286.67
 325.0000    278.50
 330.0000    270.17
 335.0000    294.75
 340.0000    274.25
 345.0000    273.50
 350.0000    274.09
 355.0000    265.92