File: mtex-5.1.1/data/PoleFigure/ZnCuTi/ZnCuTi_defocusing_PF_100_R.UXD
; C:\Users\Stanis³aw\OneDrive\Documents\paracamgr\DANE DO MGR\24.03.2015\tekstura\TExtura\Defokusacja\ZnCuTi_defokusacja_PF_100_R.raw(Diffrac Plus V1.01 file) converted by XCH V1.0
_FILEVERSION=2
_SITE='Poland'
_USER='Administrator'
_SAMPLE_CHANGER_CODE=0
_ATTACHMENTS_CODE=0
_GONIOMETER_RADIUS=300.000000
_FIXED_DIVSLIT=0.600000
_FIXED_SAMPLESLIT=1.000000
_FIXED_DETSLIT=0.100000
_MONOCHROMATOR=0
; None
_THIN_FILM='N'
_BETA_FILTER='N'
_FIXED_ANTISLIT=0.600000
_ANALYZER_CODE=0
; None
_DATEMEASURED='31-Mar-2015 22:10:17'
_WL_UNIT='A'
_WL1=1.540600
_WL2=1.544390
_WL3=1.392220
_WLRATIO=0.500000
_ANODE='Cu'
; (Data for Range number 1)
_DRIVE='PHI'
_STEPTIME=11.999800
_STEPSIZE=5.000000
_STEPMODE='C'
_START=0.000000
_THETA=19.565001
_2THETA=39.130001
_KHI=0.000000
_PHI=0.000000
_X=0.000000
_Y=0.000000
_Z=0.000000
_DIVERGENCE=0.200000
_ANTISCATTER=0.200000
_DETECTOR=1
; S.C.
_HV=683.500000
_GAIN=80.000000
_LLD=0.788000
_ULD=2.160000
_DETECTORSLIT='out'
_AUX1=0.000000
_AUX2=0.000000
_AUX3=0.000000
_TIMESTARTED=22.000000
_TEMP_RATE=0.000000
_TEMP_DELAY=0.000000
_KV=40
_MA=30
_RANGE_WL=1.540600
_3DPLANE=0
_2THETACPS
   0.0000    232.34
   5.0000    233.42
  10.0000    236.59
  15.0000    229.17
  20.0000    234.75
  25.0000    262.42
  30.0000    243.92
  35.0000    288.17
  40.0000    283.34
  45.0000    259.17
  50.0000    276.59
  55.0000    280.92
  60.0000    266.25
  65.0000    312.51
  70.0000    295.92
  75.0000    312.26
  80.0000    290.34
  85.0000    295.42
  90.0000    283.84
  95.0000    292.42
 100.0000    302.84
 105.0000    303.51
 110.0000    261.67
 115.0000    263.34
 120.0000    260.34
 125.0000    259.84
 130.0000    267.42
 135.0000    241.75
 140.0000    244.75
 145.0000    275.50
 150.0000    264.75
 155.0000    233.34
 160.0000    237.42
 165.0000    242.42
 170.0000    256.25
 175.0000    286.09
 180.0000    248.00
 185.0000    277.84
 190.0000    247.09
 195.0000    240.59
 200.0000    248.67
 205.0000    254.09
 210.0000    250.42
 215.0000    263.59
 220.0000    328.09
 225.0000    338.84
 230.0000    271.92
 235.0000    265.42
 240.0000    258.34
 245.0000    253.84
 250.0000    248.42
 255.0000    271.67
 260.0000    237.34
 265.0000    256.59
 270.0000    234.84
 275.0000    236.42
 280.0000    232.67
 285.0000    228.67
 290.0000    226.50
 295.0000    206.84
 300.0000    219.00
 305.0000    203.50
 310.0000    219.92
 315.0000    205.50
 320.0000    195.50
 325.0000    211.00
 330.0000    214.75
 335.0000    227.59
 340.0000    218.84
 345.0000    238.67
 350.0000    224.92
 355.0000    222.25
; (Data for Range number 2)
_DRIVE='PHI'
_STEPTIME=11.999800
_STEPSIZE=5.000000
_STEPMODE='C'
_START=0.000000
_THETA=19.565001
_2THETA=39.130001
_KHI=5.000000
_PHI=0.000000
_X=0.000000
_Y=0.000000
_Z=0.000000
_DIVERGENCE=0.200000
_ANTISCATTER=0.200000
_DETECTOR=1
; S.C.
_HV=683.500000
_GAIN=80.000000
_LLD=0.788000
_ULD=2.160000
_DETECTORSLIT='out'
_AUX1=0.000000
_AUX2=0.000000
_AUX3=0.000000
_TIMESTARTED=890.000000
_TEMP_RATE=0.000000
_TEMP_DELAY=0.000000
_KV=40
_MA=30
_RANGE_WL=1.540600
_3DPLANE=0
_2THETACPS
   0.0000    238.67
   5.0000    254.09
  10.0000    284.50
  15.0000    243.92
  20.0000    254.84
  25.0000    256.67
  30.0000    250.59
  35.0000    254.92
  40.0000    260.50
  45.0000    274.42
  50.0000    259.25
  55.0000    240.00
  60.0000    255.09
  65.0000    249.25
  70.0000    273.25
  75.0000    284.75
  80.0000    269.42
  85.0000    243.50
  90.0000    255.59
  95.0000    244.25
 100.0000    245.92
 105.0000    265.17
 110.0000    243.67
 115.0000    257.42
 120.0000    253.67
 125.0000    231.75
 130.0000    295.00
 135.0000    299.59
 140.0000    257.09
 145.0000    270.17
 150.0000    263.00
 155.0000    261.09
 160.0000    251.00
 165.0000    253.42
 170.0000    242.50
 175.0000    247.67
 180.0000    268.00
 185.0000    239.84
 190.0000    234.50
 195.0000    281.50
 200.0000    264.92
 205.0000    279.34
 210.0000    292.25
 215.0000    281.50
 220.0000    247.50
 225.0000    284.34
 230.0000    266.59
 235.0000    243.84
 240.0000    252.84
 245.0000    248.75
 250.0000    272.34
 255.0000    249.00
 260.0000    234.59
 265.0000    230.92
 270.0000    224.17
 275.0000    246.50
 280.0000    275.67
 285.0000    221.50
 290.0000    252.67
 295.0000    237.17
 300.0000    269.25
 305.0000    207.17
 310.0000    236.34
 315.0000    217.92
 320.0000    221.34
 325.0000    237.34
 330.0000    226.42
 335.0000    251.84
 340.0000    235.09
 345.0000    231.17
 350.0000    271.00
 355.0000    231.67
; (Data for Range number 3)
_DRIVE='PHI'
_STEPTIME=11.999800
_STEPSIZE=5.000000
_STEPMODE='C'
_START=0.000000
_THETA=19.565001
_2THETA=39.130001
_KHI=10.000000
_PHI=0.000000
_X=0.000000
_Y=0.000000
_Z=0.000000
_DIVERGENCE=0.200000
_ANTISCATTER=0.200000
_DETECTOR=1
; S.C.
_HV=683.500000
_GAIN=80.000000
_LLD=0.788000
_ULD=2.160000
_DETECTORSLIT='out'
_AUX1=0.000000
_AUX2=0.000000
_AUX3=0.000000
_TIMESTARTED=1759.000000
_TEMP_RATE=0.000000
_TEMP_DELAY=0.000000
_KV=40
_MA=30
_RANGE_WL=1.540600
_3DPLANE=0
_2THETACPS
   0.0000    253.67
   5.0000    255.67
  10.0000    280.84
  15.0000    245.75
  20.0000    239.67
  25.0000    241.67
  30.0000    269.00
  35.0000    251.09
  40.0000    265.09
  45.0000    281.00
  50.0000    241.34
  55.0000    250.17
  60.0000    285.17
  65.0000    260.00
  70.0000    267.34
  75.0000    248.50
  80.0000    253.50
  85.0000    263.00
  90.0000    264.17
  95.0000    249.67
 100.0000    256.92
 105.0000    270.67
 110.0000    250.34
 115.0000    247.00
 120.0000    250.59
 125.0000    240.00
 130.0000    265.59
 135.0000    239.92
 140.0000    250.50
 145.0000    275.75
 150.0000    233.34
 155.0000    250.17
 160.0000    284.25
 165.0000    281.59
 170.0000    241.50
 175.0000    247.25
 180.0000    244.92
 185.0000    252.84
 190.0000    262.92
 195.0000    259.92
 200.0000    276.25
 205.0000    313.09
 210.0000    289.50
 215.0000    264.00
 220.0000    258.00
 225.0000    268.34
 230.0000    254.92
 235.0000    237.75
 240.0000    258.75
 245.0000    252.50
 250.0000    255.67
 255.0000    256.25
 260.0000    244.00
 265.0000    252.17
 270.0000    232.34
 275.0000    222.34
 280.0000    224.67
 285.0000    229.17
 290.0000    228.42
 295.0000    225.25
 300.0000    231.34
 305.0000    242.59
 310.0000    232.34
 315.0000    244.34
 320.0000    245.59
 325.0000    226.59
 330.0000    222.59
 335.0000    232.00
 340.0000    228.17
 345.0000    241.42
 350.0000    231.42
 355.0000    243.25
; (Data for Range number 4)
_DRIVE='PHI'
_STEPTIME=11.999800
_STEPSIZE=5.000000
_STEPMODE='C'
_START=0.000000
_THETA=19.565001
_2THETA=39.130001
_KHI=15.000000
_PHI=0.000000
_X=0.000000
_Y=0.000000
_Z=0.000000
_DIVERGENCE=0.200000
_ANTISCATTER=0.200000
_DETECTOR=1
; S.C.
_HV=683.500000
_GAIN=80.000000
_LLD=0.788000
_ULD=2.160000
_DETECTORSLIT='out'
_AUX1=0.000000
_AUX2=0.000000
_AUX3=0.000000
_TIMESTARTED=2628.000000
_TEMP_RATE=0.000000
_TEMP_DELAY=0.000000
_KV=40
_MA=30
_RANGE_WL=1.540600
_3DPLANE=0
_2THETACPS
   0.0000    230.75
   5.0000    245.42
  10.0000    246.84
  15.0000    243.25
  20.0000    238.17
  25.0000    246.92
  30.0000    249.34
  35.0000    239.00
  40.0000    241.67
  45.0000    273.34
  50.0000    233.84
  55.0000    252.84
  60.0000    254.59
  65.0000    264.67
  70.0000    261.09
  75.0000    264.17
  80.0000    245.67
  85.0000    233.67
  90.0000    217.34
  95.0000    245.67
 100.0000    262.00
 105.0000    246.17
 110.0000    249.84
 115.0000    242.67
 120.0000    237.50
 125.0000    259.25
 130.0000    254.59
 135.0000    259.92
 140.0000    252.17
 145.0000    253.67
 150.0000    267.59
 155.0000    278.09
 160.0000    266.17
 165.0000    241.34
 170.0000    232.92
 175.0000    243.92
 180.0000    238.34
 185.0000    246.09
 190.0000    262.84
 195.0000    259.09
 200.0000    271.09
 205.0000    266.25
 210.0000    254.09
 215.0000    267.25
 220.0000    243.42
 225.0000    253.25
 230.0000    269.50
 235.0000    255.92
 240.0000    243.50
 245.0000    248.59
 250.0000    234.00
 255.0000    241.67
 260.0000    246.09
 265.0000    232.67
 270.0000    229.59
 275.0000    200.67
 280.0000    223.25
 285.0000    209.92
 290.0000    231.09
 295.0000    216.00
 300.0000    235.25
 305.0000    212.17
 310.0000    225.67
 315.0000    218.09
 320.0000    217.67
 325.0000    225.50
 330.0000    234.84
 335.0000    235.92
 340.0000    235.59
 345.0000    233.67
 350.0000    237.84
 355.0000    243.25
; (Data for Range number 5)
_DRIVE='PHI'
_STEPTIME=11.999800
_STEPSIZE=5.000000
_STEPMODE='C'
_START=0.000000
_THETA=19.565001
_2THETA=39.130001
_KHI=20.000000
_PHI=0.000000
_X=0.000000
_Y=0.000000
_Z=0.000000
_DIVERGENCE=0.200000
_ANTISCATTER=0.200000
_DETECTOR=1
; S.C.
_HV=683.500000
_GAIN=80.000000
_LLD=0.788000
_ULD=2.160000
_DETECTORSLIT='out'
_AUX1=0.000000
_AUX2=0.000000
_AUX3=0.000000
_TIMESTARTED=3496.000000
_TEMP_RATE=0.000000
_TEMP_DELAY=0.000000
_KV=40
_MA=30
_RANGE_WL=1.540600
_3DPLANE=0
_2THETACPS
   0.0000    241.17
   5.0000    234.42
  10.0000    245.75
  15.0000    260.17
  20.0000    236.00
  25.0000    239.75
  30.0000    244.25
  35.0000    256.42
  40.0000    231.25
  45.0000    234.09
  50.0000    245.00
  55.0000    246.59
  60.0000    258.00
  65.0000    226.34
  70.0000    225.42
  75.0000    236.17
  80.0000    233.42
  85.0000    219.75
  90.0000    230.67
  95.0000    229.17
 100.0000    226.67
 105.0000    238.42
 110.0000    245.92
 115.0000    235.59
 120.0000    233.84
 125.0000    237.34
 130.0000    239.00
 135.0000    245.34
 140.0000    255.42
 145.0000    230.42
 150.0000    272.00
 155.0000    251.42
 160.0000    251.75
 165.0000    254.84
 170.0000    267.25
 175.0000    255.59
 180.0000    234.75
 185.0000    218.42
 190.0000    248.25
 195.0000    265.17
 200.0000    262.92
 205.0000    246.42
 210.0000    271.50
 215.0000    256.92
 220.0000    267.92
 225.0000    282.17
 230.0000    252.75
 235.0000    249.75
 240.0000    242.42
 245.0000    259.17
 250.0000    234.75
 255.0000    225.50
 260.0000    233.75
 265.0000    234.92
 270.0000    225.17
 275.0000    220.84
 280.0000    227.17
 285.0000    217.34
 290.0000    208.59
 295.0000    216.67
 300.0000    218.42
 305.0000    215.09
 310.0000    223.50
 315.0000    232.50
 320.0000    213.25
 325.0000    235.84
 330.0000    246.42
 335.0000    230.09
 340.0000    234.84
 345.0000    243.34
 350.0000    247.75
 355.0000    257.00
; (Data for Range number 6)
_DRIVE='PHI'
_STEPTIME=11.999800
_STEPSIZE=5.000000
_STEPMODE='C'
_START=0.000000
_THETA=19.565001
_2THETA=39.130001
_KHI=25.000000
_PHI=0.000000
_X=0.000000
_Y=0.000000
_Z=0.000000
_DIVERGENCE=0.200000
_ANTISCATTER=0.200000
_DETECTOR=1
; S.C.
_HV=683.500000
_GAIN=80.000000
_LLD=0.788000
_ULD=2.160000
_DETECTORSLIT='out'
_AUX1=0.000000
_AUX2=0.000000
_AUX3=0.000000
_TIMESTARTED=4365.000000
_TEMP_RATE=0.000000
_TEMP_DELAY=0.000000
_KV=40
_MA=30
_RANGE_WL=1.540600
_3DPLANE=0
_2THETACPS
   0.0000    241.00
   5.0000    241.25
  10.0000    233.34
  15.0000    251.42
  20.0000    240.92
  25.0000    239.34
  30.0000    226.84
  35.0000    238.09
  40.0000    230.09
  45.0000    231.59
  50.0000    259.92
  55.0000    239.75
  60.0000    229.59
  65.0000    228.00
  70.0000    216.00
  75.0000    222.59
  80.0000    223.92
  85.0000    224.09
  90.0000    217.50
  95.0000    231.84
 100.0000    231.34
 105.0000    216.17
 110.0000    209.75
 115.0000    205.09
 120.0000    223.84
 125.0000    229.00
 130.0000    219.17
 135.0000    249.09
 140.0000    243.34
 145.0000    251.17
 150.0000    242.00
 155.0000    232.59
 160.0000    235.67
 165.0000    244.50
 170.0000    237.50
 175.0000    228.84
 180.0000    231.75
 185.0000    229.75
 190.0000    240.17
 195.0000    248.84
 200.0000    244.00
 205.0000    257.92
 210.0000    252.67
 215.0000    253.84
 220.0000    244.50
 225.0000    258.42
 230.0000    234.34
 235.0000    238.34
 240.0000    239.34
 245.0000    228.09
 250.0000    232.17
 255.0000    237.00
 260.0000    234.17
 265.0000    221.75
 270.0000    220.67
 275.0000    220.75
 280.0000    215.00
 285.0000    218.00
 290.0000    197.92
 295.0000    223.09
 300.0000    211.75
 305.0000    220.59
 310.0000    206.50
 315.0000    219.34
 320.0000    228.75
 325.0000    221.34
 330.0000    243.34
 335.0000    210.67
 340.0000    245.25
 345.0000    220.09
 350.0000    231.67
 355.0000    229.34
; (Data for Range number 7)
_DRIVE='PHI'
_STEPTIME=11.999800
_STEPSIZE=5.000000
_STEPMODE='C'
_START=0.000000
_THETA=19.565001
_2THETA=39.130001
_KHI=30.000000
_PHI=0.000000
_X=0.000000
_Y=0.000000
_Z=0.000000
_DIVERGENCE=0.200000
_ANTISCATTER=0.200000
_DETECTOR=1
; S.C.
_HV=683.500000
_GAIN=80.000000
_LLD=0.788000
_ULD=2.160000
_DETECTORSLIT='out'
_AUX1=0.000000
_AUX2=0.000000
_AUX3=0.000000
_TIMESTARTED=5233.000000
_TEMP_RATE=0.000000
_TEMP_DELAY=0.000000
_KV=40
_MA=30
_RANGE_WL=1.540600
_3DPLANE=0
_2THETACPS
   0.0000    218.00
   5.0000    226.75
  10.0000    238.25
  15.0000    238.25
  20.0000    230.84
  25.0000    241.17
  30.0000    221.84
  35.0000    236.09
  40.0000    238.92
  45.0000    216.00
  50.0000    224.50
  55.0000    233.25
  60.0000    229.59
  65.0000    220.75
  70.0000    227.34
  75.0000    195.42
  80.0000    206.00
  85.0000    211.75
  90.0000    198.50
  95.0000    204.67
 100.0000    211.34
 105.0000    209.00
 110.0000    211.75
 115.0000    202.25
 120.0000    213.42
 125.0000    217.42
 130.0000    215.92
 135.0000    207.92
 140.0000    228.00
 145.0000    225.67
 150.0000    242.92
 155.0000    227.00
 160.0000    251.00
 165.0000    234.00
 170.0000    225.09
 175.0000    219.17
 180.0000    212.67
 185.0000    235.34
 190.0000    231.67
 195.0000    230.34
 200.0000    244.84
 205.0000    259.17
 210.0000    248.42
 215.0000    253.50
 220.0000    247.25
 225.0000    240.84
 230.0000    249.42
 235.0000    233.50
 240.0000    247.09
 245.0000    228.09
 250.0000    225.09
 255.0000    230.09
 260.0000    227.84
 265.0000    219.50
 270.0000    244.59
 275.0000    221.84
 280.0000    189.50
 285.0000    203.09
 290.0000    213.09
 295.0000    189.00
 300.0000    196.34
 305.0000    213.75
 310.0000    210.42
 315.0000    214.67
 320.0000    222.84
 325.0000    234.92
 330.0000    217.50
 335.0000    221.50
 340.0000    232.00
 345.0000    239.67
 350.0000    228.75
 355.0000    225.92
; (Data for Range number 8)
_DRIVE='PHI'
_STEPTIME=11.999800
_STEPSIZE=5.000000
_STEPMODE='C'
_START=0.000000
_THETA=19.565001
_2THETA=39.130001
_KHI=35.000000
_PHI=0.000000
_X=0.000000
_Y=0.000000
_Z=0.000000
_DIVERGENCE=0.200000
_ANTISCATTER=0.200000
_DETECTOR=1
; S.C.
_HV=683.500000
_GAIN=80.000000
_LLD=0.788000
_ULD=2.160000
_DETECTORSLIT='out'
_AUX1=0.000000
_AUX2=0.000000
_AUX3=0.000000
_TIMESTARTED=6102.000000
_TEMP_RATE=0.000000
_TEMP_DELAY=0.000000
_KV=40
_MA=30
_RANGE_WL=1.540600
_3DPLANE=0
_2THETACPS
   0.0000    224.50
   5.0000    224.59
  10.0000    223.00
  15.0000    226.59
  20.0000    237.25
  25.0000    226.42
  30.0000    217.75
  35.0000    229.59
  40.0000    217.67
  45.0000    213.42
  50.0000    215.50
  55.0000    219.42
  60.0000    223.50
  65.0000    200.59
  70.0000    230.59
  75.0000    214.25
  80.0000    203.09
  85.0000    195.09
  90.0000    204.17
  95.0000    200.17
 100.0000    190.17
 105.0000    189.67
 110.0000    200.84
 115.0000    186.92
 120.0000    192.50
 125.0000    197.92
 130.0000    202.84
 135.0000    201.84
 140.0000    223.34
 145.0000    211.09
 150.0000    218.84
 155.0000    241.34
 160.0000    235.92
 165.0000    229.00
 170.0000    239.00
 175.0000    231.92
 180.0000    205.84
 185.0000    204.00
 190.0000    216.75
 195.0000    208.59
 200.0000    236.84
 205.0000    234.17
 210.0000    249.50
 215.0000    239.42
 220.0000    244.84
 225.0000    240.59
 230.0000    235.00
 235.0000    248.67
 240.0000    218.34
 245.0000    222.09
 250.0000    239.75
 255.0000    229.34
 260.0000    217.75
 265.0000    209.25
 270.0000    223.17
 275.0000    216.75
 280.0000    193.67
 285.0000    195.92
 290.0000    215.92
 295.0000    197.59
 300.0000    201.50
 305.0000    193.09
 310.0000    198.25
 315.0000    216.34
 320.0000    222.42
 325.0000    212.50
 330.0000    223.84
 335.0000    219.09
 340.0000    220.42
 345.0000    216.92
 350.0000    212.09
 355.0000    214.67
; (Data for Range number 9)
_DRIVE='PHI'
_STEPTIME=11.999800
_STEPSIZE=5.000000
_STEPMODE='C'
_START=0.000000
_THETA=19.565001
_2THETA=39.130001
_KHI=40.000000
_PHI=0.000000
_X=0.000000
_Y=0.000000
_Z=0.000000
_DIVERGENCE=0.200000
_ANTISCATTER=0.200000
_DETECTOR=1
; S.C.
_HV=683.500000
_GAIN=80.000000
_LLD=0.788000
_ULD=2.160000
_DETECTORSLIT='out'
_AUX1=0.000000
_AUX2=0.000000
_AUX3=0.000000
_TIMESTARTED=6971.000000
_TEMP_RATE=0.000000
_TEMP_DELAY=0.000000
_KV=40
_MA=30
_RANGE_WL=1.540600
_3DPLANE=0
_2THETACPS
   0.0000    213.92
   5.0000    199.17
  10.0000    220.34
  15.0000    224.09
  20.0000    228.92
  25.0000    216.84
  30.0000    217.09
  35.0000    210.42
  40.0000    212.75
  45.0000    217.92
  50.0000    216.75
  55.0000    220.50
  60.0000    204.42
  65.0000    204.25
  70.0000    200.75
  75.0000    196.67
  80.0000    192.34
  85.0000    206.92
  90.0000    194.59
  95.0000    202.75
 100.0000    188.42
 105.0000    200.50
 110.0000    182.25
 115.0000    179.00
 120.0000    196.59
 125.0000    192.42
 130.0000    185.84
 135.0000    196.34
 140.0000    212.67
 145.0000    225.17
 150.0000    227.75
 155.0000    238.67
 160.0000    213.59
 165.0000    222.17
 170.0000    208.50
 175.0000    207.34
 180.0000    219.50
 185.0000    212.92
 190.0000    206.75
 195.0000    212.75
 200.0000    232.00
 205.0000    231.67
 210.0000    226.34
 215.0000    238.75
 220.0000    237.34
 225.0000    236.75
 230.0000    232.59
 235.0000    227.42
 240.0000    216.92
 245.0000    196.17
 250.0000    225.09
 255.0000    229.34
 260.0000    226.50
 265.0000    208.09
 270.0000    203.09
 275.0000    211.59
 280.0000    198.34
 285.0000    185.09
 290.0000    195.59
 295.0000    188.09
 300.0000    184.59
 305.0000    188.17
 310.0000    194.50
 315.0000    185.42
 320.0000    209.00
 325.0000    204.92
 330.0000    226.59
 335.0000    208.67
 340.0000    219.09
 345.0000    211.92
 350.0000    211.50
 355.0000    202.50
; (Data for Range number 10)
_DRIVE='PHI'
_STEPTIME=11.999800
_STEPSIZE=5.000000
_STEPMODE='C'
_START=0.000000
_THETA=19.565001
_2THETA=39.130001
_KHI=45.000000
_PHI=0.000000
_X=0.000000
_Y=0.000000
_Z=0.000000
_DIVERGENCE=0.200000
_ANTISCATTER=0.200000
_DETECTOR=1
; S.C.
_HV=683.500000
_GAIN=80.000000
_LLD=0.788000
_ULD=2.160000
_DETECTORSLIT='out'
_AUX1=0.000000
_AUX2=0.000000
_AUX3=0.000000
_TIMESTARTED=7840.000000
_TEMP_RATE=0.000000
_TEMP_DELAY=0.000000
_KV=40
_MA=30
_RANGE_WL=1.540600
_3DPLANE=0
_2THETACPS
   0.0000    203.42
   5.0000    219.34
  10.0000    209.75
  15.0000    212.50
  20.0000    210.00
  25.0000    207.25
  30.0000    212.75
  35.0000    197.50
  40.0000    201.75
  45.0000    199.59
  50.0000    203.84
  55.0000    202.59
  60.0000    195.67
  65.0000    192.00
  70.0000    197.59
  75.0000    197.00
  80.0000    193.09
  85.0000    184.59
  90.0000    182.50
  95.0000    199.59
 100.0000    185.84
 105.0000    183.34
 110.0000    177.25
 115.0000    181.00
 120.0000    173.25
 125.0000    193.25
 130.0000    184.17
 135.0000    187.17
 140.0000    206.50
 145.0000    202.34
 150.0000    212.34
 155.0000    226.67
 160.0000    226.67
 165.0000    217.92
 170.0000    217.59
 175.0000    203.09
 180.0000    210.42
 185.0000    200.17
 190.0000    206.42
 195.0000    203.00
 200.0000    209.09
 205.0000    224.84
 210.0000    225.00
 215.0000    224.75
 220.0000    213.67
 225.0000    222.75
 230.0000    224.75
 235.0000    218.00
 240.0000    215.92
 245.0000    210.25
 250.0000    209.42
 255.0000    210.75
 260.0000    213.75
 265.0000    204.59
 270.0000    206.59
 275.0000    196.25
 280.0000    196.17
 285.0000    187.09
 290.0000    182.75
 295.0000    175.67
 300.0000    195.42
 305.0000    184.84
 310.0000    190.50
 315.0000    187.59
 320.0000    192.09
 325.0000    189.00
 330.0000    204.59
 335.0000    204.84
 340.0000    209.25
 345.0000    199.59
 350.0000    202.50
 355.0000    200.92
; (Data for Range number 11)
_DRIVE='PHI'
_STEPTIME=11.999800
_STEPSIZE=5.000000
_STEPMODE='C'
_START=0.000000
_THETA=19.565001
_2THETA=39.130001
_KHI=50.000000
_PHI=0.000000
_X=0.000000
_Y=0.000000
_Z=0.000000
_DIVERGENCE=0.200000
_ANTISCATTER=0.200000
_DETECTOR=1
; S.C.
_HV=683.500000
_GAIN=80.000000
_LLD=0.788000
_ULD=2.160000
_DETECTORSLIT='out'
_AUX1=0.000000
_AUX2=0.000000
_AUX3=0.000000
_TIMESTARTED=8708.000000
_TEMP_RATE=0.000000
_TEMP_DELAY=0.000000
_KV=40
_MA=30
_RANGE_WL=1.540600
_3DPLANE=0
_2THETACPS
   0.0000    193.67
   5.0000    190.50
  10.0000    194.67
  15.0000    206.50
  20.0000    195.09
  25.0000    198.00
  30.0000    195.75
  35.0000    196.42
  40.0000    188.00
  45.0000    174.17
  50.0000    186.84
  55.0000    183.50
  60.0000    191.75
  65.0000    185.09
  70.0000    190.59
  75.0000    181.42
  80.0000    181.34
  85.0000    181.84
  90.0000    176.84
  95.0000    178.17
 100.0000    170.84
 105.0000    168.59
 110.0000    166.42
 115.0000    160.84
 120.0000    166.42
 125.0000    167.59
 130.0000    174.17
 135.0000    175.42
 140.0000    192.92
 145.0000    206.00
 150.0000    191.75
 155.0000    199.50
 160.0000    203.84
 165.0000    209.09
 170.0000    206.42
 175.0000    201.34
 180.0000    207.17
 185.0000    185.00
 190.0000    207.67
 195.0000    200.42
 200.0000    197.92
 205.0000    198.50
 210.0000    217.75
 215.0000    211.84
 220.0000    204.59
 225.0000    215.92
 230.0000    211.00
 235.0000    211.50
 240.0000    205.25
 245.0000    217.92
 250.0000    208.67
 255.0000    199.17
 260.0000    198.67
 265.0000    205.50
 270.0000    196.09
 275.0000    197.00
 280.0000    192.59
 285.0000    169.59
 290.0000    178.92
 295.0000    176.00
 300.0000    180.00
 305.0000    178.25
 310.0000    184.59
 315.0000    172.84
 320.0000    190.92
 325.0000    200.25
 330.0000    198.75
 335.0000    204.92
 340.0000    204.67
 345.0000    194.92
 350.0000    192.50
 355.0000    202.09
; (Data for Range number 12)
_DRIVE='PHI'
_STEPTIME=11.999800
_STEPSIZE=5.000000
_STEPMODE='C'
_START=0.000000
_THETA=19.565001
_2THETA=39.130001
_KHI=55.000000
_PHI=0.000000
_X=0.000000
_Y=0.000000
_Z=0.000000
_DIVERGENCE=0.200000
_ANTISCATTER=0.200000
_DETECTOR=1
; S.C.
_HV=683.500000
_GAIN=80.000000
_LLD=0.788000
_ULD=2.160000
_DETECTORSLIT='out'
_AUX1=0.000000
_AUX2=0.000000
_AUX3=0.000000
_TIMESTARTED=9577.000000
_TEMP_RATE=0.000000
_TEMP_DELAY=0.000000
_KV=40
_MA=30
_RANGE_WL=1.540600
_3DPLANE=0
_2THETACPS
   0.0000    171.92
   5.0000    175.59
  10.0000    179.84
  15.0000    189.00
  20.0000    195.34
  25.0000    195.17
  30.0000    184.75
  35.0000    171.84
  40.0000    184.92
  45.0000    181.09
  50.0000    176.92
  55.0000    172.42
  60.0000    170.25
  65.0000    176.75
  70.0000    179.09
  75.0000    168.00
  80.0000    165.17
  85.0000    174.67
  90.0000    173.67
  95.0000    173.42
 100.0000    166.17
 105.0000    159.75
 110.0000    156.25
 115.0000    153.59
 120.0000    163.50
 125.0000    163.75
 130.0000    166.25
 135.0000    167.75
 140.0000    176.25
 145.0000    177.67
 150.0000    186.09
 155.0000    186.25
 160.0000    197.75
 165.0000    209.42
 170.0000    203.42
 175.0000    192.50
 180.0000    178.50
 185.0000    191.17
 190.0000    184.25
 195.0000    180.34
 200.0000    195.34
 205.0000    199.17
 210.0000    209.25
 215.0000    195.50
 220.0000    211.42
 225.0000    190.92
 230.0000    201.84
 235.0000    197.59
 240.0000    198.59
 245.0000    195.00
 250.0000    193.17
 255.0000    188.00
 260.0000    191.34
 265.0000    193.34
 270.0000    181.17
 275.0000    176.17
 280.0000    168.42
 285.0000    159.75
 290.0000    159.75
 295.0000    164.09
 300.0000    155.17
 305.0000    165.17
 310.0000    167.17
 315.0000    180.92
 320.0000    180.50
 325.0000    178.92
 330.0000    189.84
 335.0000    190.59
 340.0000    179.34
 345.0000    183.84
 350.0000    179.09
 355.0000    171.25
; (Data for Range number 13)
_DRIVE='PHI'
_STEPTIME=11.999800
_STEPSIZE=5.000000
_STEPMODE='C'
_START=0.000000
_THETA=19.565001
_2THETA=39.130001
_KHI=60.000000
_PHI=0.000000
_X=0.000000
_Y=0.000000
_Z=0.000000
_DIVERGENCE=0.200000
_ANTISCATTER=0.200000
_DETECTOR=1
; S.C.
_HV=683.500000
_GAIN=80.000000
_LLD=0.788000
_ULD=2.160000
_DETECTORSLIT='out'
_AUX1=0.000000
_AUX2=0.000000
_AUX3=0.000000
_TIMESTARTED=10446.000000
_TEMP_RATE=0.000000
_TEMP_DELAY=0.000000
_KV=40
_MA=30
_RANGE_WL=1.540600
_3DPLANE=0
_2THETACPS
   0.0000    165.34
   5.0000    159.42
  10.0000    160.09
  15.0000    163.25
  20.0000    175.34
  25.0000    181.34
  30.0000    181.67
  35.0000    175.59
  40.0000    184.84
  45.0000    171.17
  50.0000    173.92
  55.0000    159.00
  60.0000    172.59
  65.0000    160.67
  70.0000    161.42
  75.0000    158.50
  80.0000    172.75
  85.0000    166.67
  90.0000    165.42
  95.0000    167.09
 100.0000    165.42
 105.0000    157.17
 110.0000    141.92
 115.0000    148.34
 120.0000    148.50
 125.0000    157.92
 130.0000    156.59
 135.0000    164.42
 140.0000    166.17
 145.0000    166.25
 150.0000    180.17
 155.0000    179.50
 160.0000    188.42
 165.0000    185.59
 170.0000    175.17
 175.0000    179.09
 180.0000    182.25
 185.0000    175.92
 190.0000    186.00
 195.0000    174.92
 200.0000    171.59
 205.0000    187.67
 210.0000    171.17
 215.0000    177.84
 220.0000    183.84
 225.0000    185.59
 230.0000    177.34
 235.0000    196.59
 240.0000    181.92
 245.0000    189.42
 250.0000    180.67
 255.0000    188.50
 260.0000    176.34
 265.0000    178.17
 270.0000    170.34
 275.0000    169.92
 280.0000    157.34
 285.0000    163.25
 290.0000    156.34
 295.0000    156.09
 300.0000    155.67
 305.0000    159.42
 310.0000    151.75
 315.0000    158.50
 320.0000    168.00
 325.0000    171.50
 330.0000    171.75
 335.0000    175.34
 340.0000    171.59
 345.0000    174.67
 350.0000    172.92
 355.0000    170.25
; (Data for Range number 14)
_DRIVE='PHI'
_STEPTIME=11.999800
_STEPSIZE=5.000000
_STEPMODE='C'
_START=0.000000
_THETA=19.565001
_2THETA=39.130001
_KHI=65.000000
_PHI=0.000000
_X=0.000000
_Y=0.000000
_Z=0.000000
_DIVERGENCE=0.200000
_ANTISCATTER=0.200000
_DETECTOR=1
; S.C.
_HV=683.500000
_GAIN=80.000000
_LLD=0.788000
_ULD=2.160000
_DETECTORSLIT='out'
_AUX1=0.000000
_AUX2=0.000000
_AUX3=0.000000
_TIMESTARTED=11315.000000
_TEMP_RATE=0.000000
_TEMP_DELAY=0.000000
_KV=40
_MA=30
_RANGE_WL=1.540600
_3DPLANE=0
_2THETACPS
   0.0000    137.75
   5.0000    137.67
  10.0000    146.50
  15.0000    147.34
  20.0000    154.75
  25.0000    159.00
  30.0000    174.50
  35.0000    166.92
  40.0000    156.17
  45.0000    147.17
  50.0000    163.00
  55.0000    162.42
  60.0000    159.09
  65.0000    162.84
  70.0000    138.00
  75.0000    149.50
  80.0000    145.00
  85.0000    157.75
  90.0000    153.09
  95.0000    146.67
 100.0000    145.09
 105.0000    142.92
 110.0000    139.59
 115.0000    136.17
 120.0000    139.50
 125.0000    142.84
 130.0000    152.84
 135.0000    149.42
 140.0000    146.17
 145.0000    150.92
 150.0000    158.17
 155.0000    161.00
 160.0000    164.09
 165.0000    164.42
 170.0000    152.67
 175.0000    152.75
 180.0000    143.92
 185.0000    157.84
 190.0000    151.42
 195.0000    154.84
 200.0000    158.17
 205.0000    166.92
 210.0000    168.92
 215.0000    159.34
 220.0000    157.92
 225.0000    155.17
 230.0000    167.84
 235.0000    165.92
 240.0000    162.09
 245.0000    159.92
 250.0000    162.59
 255.0000    162.75
 260.0000    161.42
 265.0000    168.34
 270.0000    152.75
 275.0000    162.92
 280.0000    150.25
 285.0000    136.09
 290.0000    134.92
 295.0000    148.84
 300.0000    136.50
 305.0000    144.50
 310.0000    136.00
 315.0000    149.84
 320.0000    145.84
 325.0000    166.34
 330.0000    157.67
 335.0000    150.50
 340.0000    153.34
 345.0000    147.42
 350.0000    154.67
 355.0000    138.59
; (Data for Range number 15)
_DRIVE='PHI'
_STEPTIME=11.999800
_STEPSIZE=5.000000
_STEPMODE='C'
_START=0.000000
_THETA=19.565001
_2THETA=39.130001
_KHI=70.000000
_PHI=0.000000
_X=0.000000
_Y=0.000000
_Z=0.000000
_DIVERGENCE=0.200000
_ANTISCATTER=0.200000
_DETECTOR=1
; S.C.
_HV=683.500000
_GAIN=80.000000
_LLD=0.788000
_ULD=2.160000
_DETECTORSLIT='out'
_AUX1=0.000000
_AUX2=0.000000
_AUX3=0.000000
_TIMESTARTED=12183.000000
_TEMP_RATE=0.000000
_TEMP_DELAY=0.000000
_KV=40
_MA=30
_RANGE_WL=1.540600
_3DPLANE=0
_2THETACPS
   0.0000    119.09
   5.0000    120.42
  10.0000    124.59
  15.0000    124.42
  20.0000    126.25
  25.0000    129.67
  30.0000    134.34
  35.0000    135.92
  40.0000    138.09
  45.0000    131.92
  50.0000    136.00
  55.0000    137.00
  60.0000    126.59
  65.0000    127.25
  70.0000    131.50
  75.0000    126.42
  80.0000    127.67
  85.0000    134.00
  90.0000    133.75
  95.0000    133.42
 100.0000    140.25
 105.0000    120.75
 110.0000    120.00
 115.0000    121.17
 120.0000    117.67
 125.0000    120.17
 130.0000    129.67
 135.0000    134.25
 140.0000    130.67
 145.0000    127.09
 150.0000    138.09
 155.0000    134.17
 160.0000    130.50
 165.0000    138.50
 170.0000    129.00
 175.0000    131.75
 180.0000    133.50
 185.0000    123.75
 190.0000    129.67
 195.0000    130.84
 200.0000    134.00
 205.0000    136.50
 210.0000    138.17
 215.0000    146.84
 220.0000    138.25
 225.0000    142.67
 230.0000    131.42
 235.0000    143.92
 240.0000    143.75
 245.0000    143.25
 250.0000    152.92
 255.0000    145.17
 260.0000    143.59
 265.0000    135.42
 270.0000    137.25
 275.0000    131.59
 280.0000    132.50
 285.0000    132.34
 290.0000    123.67
 295.0000    125.25
 300.0000    124.09
 305.0000    124.67
 310.0000    117.17
 315.0000    130.17
 320.0000    127.00
 325.0000    132.84
 330.0000    133.34
 335.0000    131.84
 340.0000    128.00
 345.0000    135.00
 350.0000    132.17
 355.0000    118.59
; (Data for Range number 16)
_DRIVE='PHI'
_STEPTIME=11.999800
_STEPSIZE=5.000000
_STEPMODE='C'
_START=0.000000
_THETA=19.565001
_2THETA=39.130001
_KHI=75.000000
_PHI=0.000000
_X=0.000000
_Y=0.000000
_Z=0.000000
_DIVERGENCE=0.200000
_ANTISCATTER=0.200000
_DETECTOR=1
; S.C.
_HV=683.500000
_GAIN=80.000000
_LLD=0.788000
_ULD=2.160000
_DETECTORSLIT='out'
_AUX1=0.000000
_AUX2=0.000000
_AUX3=0.000000
_TIMESTARTED=13052.000000
_TEMP_RATE=0.000000
_TEMP_DELAY=0.000000
_KV=40
_MA=30
_RANGE_WL=1.540600
_3DPLANE=0
_2THETACPS
   0.0000    80.501
   5.0000    85.001
  10.0000    80.168
  15.0000    82.668
  20.0000    92.085
  25.0000    94.502
  30.0000    110.09
  35.0000    116.84
  40.0000    108.84
  45.0000    103.50
  50.0000    99.502
  55.0000    101.34
  60.0000    106.09
  65.0000    97.418
  70.0000    97.002
  75.0000    99.752
  80.0000    99.335
  85.0000    109.67
  90.0000    101.84
  95.0000    105.92
 100.0000    108.50
 105.0000    102.00
 110.0000    92.168
 115.0000    98.335
 120.0000    97.252
 125.0000    97.502
 130.0000    97.835
 135.0000    94.252
 140.0000    92.085
 145.0000    87.668
 150.0000    91.418
 155.0000    92.252
 160.0000    96.085
 165.0000    98.418
 170.0000    101.59
 175.0000    90.668
 180.0000    80.585
 185.0000    90.752
 190.0000    86.418
 195.0000    87.085
 200.0000    96.335
 205.0000    99.252
 210.0000    99.835
 215.0000    105.75
 220.0000    99.085
 225.0000    107.34
 230.0000    111.59
 235.0000    112.00
 240.0000    110.00
 245.0000    106.42
 250.0000    112.59
 255.0000    116.92
 260.0000    112.09
 265.0000    107.84
 270.0000    107.84
 275.0000    112.00
 280.0000    110.67
 285.0000    102.67
 290.0000    97.502
 295.0000    101.75
 300.0000    96.835
 305.0000    100.75
 310.0000    93.002
 315.0000    95.752
 320.0000    96.168
 325.0000    100.09
 330.0000    103.92
 335.0000    100.09
 340.0000    99.835
 345.0000    85.918
 350.0000    86.335
 355.0000    80.501