File: mtex-5.1.1/data/PoleFigure/ZnCuTi/ZnCuTi_Wal_50_5x5_PF_102_R.UXD
; C:\Users\Stanis³aw\OneDrive\Documents\paracamgr\DANE DO MGR\24.03.2015\tekstura\TExtura\Tekstura\ZnCuTi_Wal_50_5x5_PF_102_R.raw(Diffrac Plus V1.01 file) converted by XCH V1.0
_FILEVERSION=2
_SITE='Poland'
_USER='Administrator'
_SAMPLE_CHANGER_CODE=0
_ATTACHMENTS_CODE=0
_GONIOMETER_RADIUS=300.000000
_FIXED_DIVSLIT=0.600000
_FIXED_SAMPLESLIT=1.000000
_FIXED_DETSLIT=0.100000
_MONOCHROMATOR=0
; None
_THIN_FILM='N'
_BETA_FILTER='N'
_FIXED_ANTISLIT=0.600000
_ANALYZER_CODE=0
; None
_DATEMEASURED='26-Feb-2015 06:37:09'
_WL_UNIT='A'
_WL1=1.540600
_WL2=1.544390
_WL3=1.392220
_WLRATIO=0.500000
_ANODE='Cu'
; (Data for Range number 1)
_DRIVE='PHI'
_STEPTIME=11.999800
_STEPSIZE=5.000000
_STEPMODE='C'
_START=0.000000
_THETA=27.283001
_2THETA=54.566002
_KHI=0.000000
_PHI=0.000000
_X=0.000000
_Y=0.000000
_Z=0.000000
_DIVERGENCE=0.200000
_ANTISCATTER=0.200000
_DETECTOR=1
; S.C.
_HV=683.500000
_GAIN=80.000000
_LLD=0.788000
_ULD=2.160000
_DETECTORSLIT='out'
_AUX1=0.000000
_AUX2=0.000000
_AUX3=0.000000
_TIMESTARTED=22.000000
_TEMP_RATE=0.000000
_TEMP_DELAY=0.000000
_KV=40
_MA=30
_RANGE_WL=1.540600
_3DPLANE=0
_2THETACPS
   0.0000    425.76
   5.0000    426.59
  10.0000    416.67
  15.0000    422.59
  20.0000    419.09
  25.0000    426.01
  30.0000    416.76
  35.0000    401.42
  40.0000    405.42
  45.0000    413.67
  50.0000    406.01
  55.0000    409.34
  60.0000    415.09
  65.0000    405.67
  70.0000    400.92
  75.0000    405.01
  80.0000    390.76
  85.0000    395.42
  90.0000    384.42
  95.0000    406.76
 100.0000    394.17
 105.0000    393.76
 110.0000    395.59
 115.0000    386.17
 120.0000    391.42
 125.0000    384.67
 130.0000    387.84
 135.0000    386.51
 140.0000    384.26
 145.0000    387.84
 150.0000    396.59
 155.0000    388.76
 160.0000    391.26
 165.0000    382.01
 170.0000    396.42
 175.0000    395.51
 180.0000    400.09
 185.0000    384.17
 190.0000    399.01
 195.0000    402.09
 200.0000    399.01
 205.0000    395.92
 210.0000    395.34
 215.0000    395.59
 220.0000    415.51
 225.0000    416.84
 230.0000    420.34
 235.0000    426.92
 240.0000    413.92
 245.0000    435.17
 250.0000    424.42
 255.0000    415.51
 260.0000    411.59
 265.0000    426.09
 270.0000    411.67
 275.0000    416.42
 280.0000    410.51
 285.0000    423.92
 290.0000    418.42
 295.0000    423.01
 300.0000    421.67
 305.0000    429.42
 310.0000    432.76
 315.0000    419.84
 320.0000    425.26
 325.0000    435.84
 330.0000    429.34
 335.0000    435.76
 340.0000    433.67
 345.0000    427.92
 350.0000    426.34
 355.0000    438.59
; (Data for Range number 2)
_DRIVE='PHI'
_STEPTIME=11.999800
_STEPSIZE=5.000000
_STEPMODE='C'
_START=0.000000
_THETA=27.283001
_2THETA=54.566002
_KHI=5.000000
_PHI=0.000000
_X=0.000000
_Y=0.000000
_Z=0.000000
_DIVERGENCE=0.200000
_ANTISCATTER=0.200000
_DETECTOR=1
; S.C.
_HV=683.500000
_GAIN=80.000000
_LLD=0.788000
_ULD=2.160000
_DETECTORSLIT='out'
_AUX1=0.000000
_AUX2=0.000000
_AUX3=0.000000
_TIMESTARTED=891.000000
_TEMP_RATE=0.000000
_TEMP_DELAY=0.000000
_KV=40
_MA=30
_RANGE_WL=1.540600
_3DPLANE=0
_2THETACPS
   0.0000    442.26
   5.0000    432.84
  10.0000    430.01
  15.0000    432.51
  20.0000    412.92
  25.0000    432.09
  30.0000    423.42
  35.0000    417.09
  40.0000    425.84
  45.0000    417.01
  50.0000    409.92
  55.0000    408.17
  60.0000    411.26
  65.0000    412.59
  70.0000    400.26
  75.0000    403.76
  80.0000    405.01
  85.0000    393.67
  90.0000    385.84
  95.0000    395.84
 100.0000    398.01
 105.0000    394.67
 110.0000    384.67
 115.0000    389.59
 120.0000    383.01
 125.0000    378.42
 130.0000    377.09
 135.0000    380.26
 140.0000    375.59
 145.0000    370.92
 150.0000    389.17
 155.0000    380.34
 160.0000    392.51
 165.0000    386.51
 170.0000    394.01
 175.0000    404.51
 180.0000    414.67
 185.0000    407.26
 190.0000    404.59
 195.0000    402.01
 200.0000    404.51
 205.0000    423.09
 210.0000    422.51
 215.0000    412.59
 220.0000    407.76
 225.0000    408.76
 230.0000    416.42
 235.0000    404.51
 240.0000    415.51
 245.0000    415.09
 250.0000    406.76
 255.0000    409.51
 260.0000    409.51
 265.0000    404.59
 270.0000    396.34
 275.0000    403.51
 280.0000    401.01
 285.0000    394.26
 290.0000    413.42
 295.0000    424.34
 300.0000    417.26
 305.0000    408.92
 310.0000    417.09
 315.0000    414.59
 320.0000    431.17
 325.0000    423.76
 330.0000    447.17
 335.0000    449.01
 340.0000    435.09
 345.0000    437.01
 350.0000    433.01
 355.0000    430.51
; (Data for Range number 3)
_DRIVE='PHI'
_STEPTIME=11.999800
_STEPSIZE=5.000000
_STEPMODE='C'
_START=0.000000
_THETA=27.283001
_2THETA=54.566002
_KHI=10.000000
_PHI=0.000000
_X=0.000000
_Y=0.000000
_Z=0.000000
_DIVERGENCE=0.200000
_ANTISCATTER=0.200000
_DETECTOR=1
; S.C.
_HV=683.500000
_GAIN=80.000000
_LLD=0.788000
_ULD=2.160000
_DETECTORSLIT='out'
_AUX1=0.000000
_AUX2=0.000000
_AUX3=0.000000
_TIMESTARTED=1759.000000
_TEMP_RATE=0.000000
_TEMP_DELAY=0.000000
_KV=40
_MA=30
_RANGE_WL=1.540600
_3DPLANE=0
_2THETACPS
   0.0000    406.26
   5.0000    414.34
  10.0000    413.42
  15.0000    409.34
  20.0000    415.92
  25.0000    424.92
  30.0000    425.17
  35.0000    416.34
  40.0000    404.01
  45.0000    398.01
  50.0000    405.34
  55.0000    400.17
  60.0000    396.34
  65.0000    397.67
  70.0000    386.92
  75.0000    381.67
  80.0000    383.76
  85.0000    382.09
  90.0000    401.42
  95.0000    384.26
 100.0000    390.59
 105.0000    393.17
 110.0000    380.59
 115.0000    384.67
 120.0000    374.26
 125.0000    384.01
 130.0000    364.59
 135.0000    375.84
 140.0000    369.17
 145.0000    371.17
 150.0000    376.42
 155.0000    370.51
 160.0000    367.92
 165.0000    375.51
 170.0000    390.51
 175.0000    385.92
 180.0000    378.76
 185.0000    389.42
 190.0000    379.17
 195.0000    387.76
 200.0000    404.67
 205.0000    393.26
 210.0000    396.51
 215.0000    393.59
 220.0000    396.26
 225.0000    383.76
 230.0000    374.09
 235.0000    381.59
 240.0000    382.42
 245.0000    393.26
 250.0000    387.34
 255.0000    384.84
 260.0000    393.92
 265.0000    381.17
 270.0000    377.09
 275.0000    382.01
 280.0000    399.09
 285.0000    397.01
 290.0000    397.59
 295.0000    401.09
 300.0000    416.26
 305.0000    427.26
 310.0000    421.92
 315.0000    426.59
 320.0000    442.09
 325.0000    451.67
 330.0000    451.42
 335.0000    452.26
 340.0000    442.67
 345.0000    429.92
 350.0000    396.76
 355.0000    402.84
; (Data for Range number 4)
_DRIVE='PHI'
_STEPTIME=11.999800
_STEPSIZE=5.000000
_STEPMODE='C'
_START=0.000000
_THETA=27.283001
_2THETA=54.566002
_KHI=15.000000
_PHI=0.000000
_X=0.000000
_Y=0.000000
_Z=0.000000
_DIVERGENCE=0.200000
_ANTISCATTER=0.200000
_DETECTOR=1
; S.C.
_HV=683.500000
_GAIN=80.000000
_LLD=0.788000
_ULD=2.160000
_DETECTORSLIT='out'
_AUX1=0.000000
_AUX2=0.000000
_AUX3=0.000000
_TIMESTARTED=2628.000000
_TEMP_RATE=0.000000
_TEMP_DELAY=0.000000
_KV=40
_MA=30
_RANGE_WL=1.540600
_3DPLANE=0
_2THETACPS
   0.0000    399.26
   5.0000    399.59
  10.0000    392.51
  15.0000    391.76
  20.0000    407.59
  25.0000    408.76
  30.0000    405.76
  35.0000    404.59
  40.0000    401.51
  45.0000    385.92
  50.0000    394.01
  55.0000    387.01
  60.0000    375.51
  65.0000    384.09
  70.0000    379.26
  75.0000    382.09
  80.0000    385.09
  85.0000    391.67
  90.0000    376.76
  95.0000    377.09
 100.0000    387.67
 105.0000    372.76
 110.0000    378.01
 115.0000    380.67
 120.0000    385.01
 125.0000    377.01
 130.0000    387.59
 135.0000    375.76
 140.0000    390.17
 145.0000    375.09
 150.0000    374.59
 155.0000    360.42
 160.0000    354.17
 165.0000    369.34
 170.0000    383.01
 175.0000    392.92
 180.0000    372.84
 185.0000    389.59
 190.0000    389.84
 195.0000    383.34
 200.0000    375.76
 205.0000    384.76
 210.0000    388.67
 215.0000    389.51
 220.0000    393.51
 225.0000    392.34
 230.0000    393.76
 235.0000    401.84
 240.0000    399.17
 245.0000    386.42
 250.0000    383.67
 255.0000    372.26
 260.0000    379.59
 265.0000    374.26
 270.0000    380.51
 275.0000    383.67
 280.0000    384.84
 285.0000    390.84
 290.0000    392.92
 295.0000    394.09
 300.0000    392.92
 305.0000    394.09
 310.0000    408.59
 315.0000    408.09
 320.0000    415.01
 325.0000    414.92
 330.0000    434.01
 335.0000    439.51
 340.0000    442.09
 345.0000    397.76
 350.0000    395.26
 355.0000    388.67
; (Data for Range number 5)
_DRIVE='PHI'
_STEPTIME=11.999800
_STEPSIZE=5.000000
_STEPMODE='C'
_START=0.000000
_THETA=27.283001
_2THETA=54.566002
_KHI=20.000000
_PHI=0.000000
_X=0.000000
_Y=0.000000
_Z=0.000000
_DIVERGENCE=0.200000
_ANTISCATTER=0.200000
_DETECTOR=1
; S.C.
_HV=683.500000
_GAIN=80.000000
_LLD=0.788000
_ULD=2.160000
_DETECTORSLIT='out'
_AUX1=0.000000
_AUX2=0.000000
_AUX3=0.000000
_TIMESTARTED=3496.000000
_TEMP_RATE=0.000000
_TEMP_DELAY=0.000000
_KV=40
_MA=30
_RANGE_WL=1.540600
_3DPLANE=0
_2THETACPS
   0.0000    362.76
   5.0000    385.51
  10.0000    371.76
  15.0000    376.26
  20.0000    375.34
  25.0000    377.67
  30.0000    383.76
  35.0000    368.09
  40.0000    357.59
  45.0000    365.17
  50.0000    379.42
  55.0000    387.59
  60.0000    375.67
  65.0000    368.76
  70.0000    368.09
  75.0000    379.67
  80.0000    372.17
  85.0000    371.17
  90.0000    367.59
  95.0000    366.76
 100.0000    363.42
 105.0000    365.01
 110.0000    363.42
 115.0000    371.17
 120.0000    367.51
 125.0000    357.09
 130.0000    354.01
 135.0000    370.09
 140.0000    368.67
 145.0000    358.17
 150.0000    372.67
 155.0000    357.01
 160.0000    368.42
 165.0000    369.59
 170.0000    374.67
 175.0000    384.42
 180.0000    362.26
 185.0000    356.09
 190.0000    344.67
 195.0000    352.67
 200.0000    354.09
 205.0000    358.26
 210.0000    369.59
 215.0000    382.51
 220.0000    397.92
 225.0000    378.67
 230.0000    379.84
 235.0000    373.17
 240.0000    389.67
 245.0000    374.51
 250.0000    375.59
 255.0000    372.34
 260.0000    371.26
 265.0000    376.67
 270.0000    366.42
 275.0000    357.17
 280.0000    383.01
 285.0000    390.17
 290.0000    382.26
 295.0000    384.67
 300.0000    378.09
 305.0000    398.01
 310.0000    385.67
 315.0000    396.59
 320.0000    391.09
 325.0000    383.51
 330.0000    382.59
 335.0000    376.51
 340.0000    367.17
 345.0000    376.84
 350.0000    366.92
 355.0000    373.42
; (Data for Range number 6)
_DRIVE='PHI'
_STEPTIME=11.999800
_STEPSIZE=5.000000
_STEPMODE='C'
_START=0.000000
_THETA=27.283001
_2THETA=54.566002
_KHI=25.000000
_PHI=0.000000
_X=0.000000
_Y=0.000000
_Z=0.000000
_DIVERGENCE=0.200000
_ANTISCATTER=0.200000
_DETECTOR=1
; S.C.
_HV=683.500000
_GAIN=80.000000
_LLD=0.788000
_ULD=2.160000
_DETECTORSLIT='out'
_AUX1=0.000000
_AUX2=0.000000
_AUX3=0.000000
_TIMESTARTED=4365.000000
_TEMP_RATE=0.000000
_TEMP_DELAY=0.000000
_KV=40
_MA=30
_RANGE_WL=1.540600
_3DPLANE=0
_2THETACPS
   0.0000    358.67
   5.0000    353.92
  10.0000    349.42
  15.0000    350.17
  20.0000    361.42
  25.0000    350.51
  30.0000    351.51
  35.0000    340.34
  40.0000    351.92
  45.0000    350.59
  50.0000    350.67
  55.0000    359.51
  60.0000    361.01
  65.0000    356.26
  70.0000    362.17
  75.0000    367.76
  80.0000    360.51
  85.0000    370.67
  90.0000    349.76
  95.0000    363.76
 100.0000    368.59
 105.0000    367.09
 110.0000    351.76
 115.0000    340.84
 120.0000    344.76
 125.0000    328.59
 130.0000    329.92
 135.0000    336.67
 140.0000    347.17
 145.0000    345.92
 150.0000    341.34
 155.0000    343.01
 160.0000    354.26
 165.0000    359.26
 170.0000    354.26
 175.0000    351.84
 180.0000    345.26
 185.0000    343.34
 190.0000    338.76
 195.0000    340.17
 200.0000    336.67
 205.0000    335.76
 210.0000    354.84
 215.0000    360.34
 220.0000    352.51
 225.0000    345.67
 230.0000    350.84
 235.0000    374.67
 240.0000    379.92
 245.0000    393.84
 250.0000    385.84
 255.0000    385.67
 260.0000    381.26
 265.0000    380.67
 270.0000    368.26
 275.0000    347.42
 280.0000    346.01
 285.0000    346.09
 290.0000    345.26
 295.0000    374.67
 300.0000    365.17
 305.0000    364.84
 310.0000    364.84
 315.0000    369.01
 320.0000    375.26
 325.0000    373.59
 330.0000    373.92
 335.0000    362.51
 340.0000    353.59
 345.0000    342.42
 350.0000    337.42
 355.0000    354.09
; (Data for Range number 7)
_DRIVE='PHI'
_STEPTIME=11.999800
_STEPSIZE=5.000000
_STEPMODE='C'
_START=0.000000
_THETA=27.283001
_2THETA=54.566002
_KHI=30.000000
_PHI=0.000000
_X=0.000000
_Y=0.000000
_Z=0.000000
_DIVERGENCE=0.200000
_ANTISCATTER=0.200000
_DETECTOR=1
; S.C.
_HV=683.500000
_GAIN=80.000000
_LLD=0.788000
_ULD=2.160000
_DETECTORSLIT='out'
_AUX1=0.000000
_AUX2=0.000000
_AUX3=0.000000
_TIMESTARTED=5234.000000
_TEMP_RATE=0.000000
_TEMP_DELAY=0.000000
_KV=40
_MA=30
_RANGE_WL=1.540600
_3DPLANE=0
_2THETACPS
   0.0000    333.42
   5.0000    347.76
  10.0000    332.51
  15.0000    335.01
  20.0000    346.92
  25.0000    335.59
  30.0000    340.01
  35.0000    346.26
  40.0000    358.34
  45.0000    351.34
  50.0000    356.34
  55.0000    354.34
  60.0000    369.17
  65.0000    372.01
  70.0000    378.34
  75.0000    373.17
  80.0000    371.59
  85.0000    364.42
  90.0000    356.09
  95.0000    362.84
 100.0000    361.76
 105.0000    358.09
 110.0000    354.42
 115.0000    347.34
 120.0000    342.51
 125.0000    336.84
 130.0000    339.92
 135.0000    348.51
 140.0000    338.92
 145.0000    330.76
 150.0000    319.59
 155.0000    336.26
 160.0000    331.76
 165.0000    330.34
 170.0000    330.17
 175.0000    336.51
 180.0000    330.09
 185.0000    334.51
 190.0000    334.59
 195.0000    328.92
 200.0000    346.59
 205.0000    348.42
 210.0000    343.92
 215.0000    333.67
 220.0000    355.67
 225.0000    347.76
 230.0000    364.01
 235.0000    345.34
 240.0000    357.34
 245.0000    359.67
 250.0000    351.42
 255.0000    347.26
 260.0000    364.09
 265.0000    370.59
 270.0000    359.92
 275.0000    364.09
 280.0000    348.01
 285.0000    346.51
 290.0000    340.26
 295.0000    337.92
 300.0000    342.92
 305.0000    360.09
 310.0000    349.76
 315.0000    340.01
 320.0000    332.76
 325.0000    349.01
 330.0000    352.26
 335.0000    356.26
 340.0000    352.67
 345.0000    340.51
 350.0000    341.84
 355.0000    332.01
; (Data for Range number 8)
_DRIVE='PHI'
_STEPTIME=11.999800
_STEPSIZE=5.000000
_STEPMODE='C'
_START=0.000000
_THETA=27.283001
_2THETA=54.566002
_KHI=35.000000
_PHI=0.000000
_X=0.000000
_Y=0.000000
_Z=0.000000
_DIVERGENCE=0.200000
_ANTISCATTER=0.200000
_DETECTOR=1
; S.C.
_HV=683.500000
_GAIN=80.000000
_LLD=0.788000
_ULD=2.160000
_DETECTORSLIT='out'
_AUX1=0.000000
_AUX2=0.000000
_AUX3=0.000000
_TIMESTARTED=6102.000000
_TEMP_RATE=0.000000
_TEMP_DELAY=0.000000
_KV=40
_MA=30
_RANGE_WL=1.540600
_3DPLANE=0
_2THETACPS
   0.0000    332.42
   5.0000    330.76
  10.0000    331.26
  15.0000    337.01
  20.0000    342.92
  25.0000    346.26
  30.0000    349.84
  35.0000    354.17
  40.0000    349.59
  45.0000    342.42
  50.0000    348.01
  55.0000    359.17
  60.0000    364.84
  65.0000    358.26
  70.0000    364.84
  75.0000    354.59
  80.0000    356.17
  85.0000    353.76
  90.0000    363.01
  95.0000    365.34
 100.0000    359.76
 105.0000    354.59
 110.0000    358.26
 115.0000    344.76
 120.0000    357.84
 125.0000    343.34
 130.0000    341.09
 135.0000    335.84
 140.0000    334.17
 145.0000    341.26
 150.0000    331.26
 155.0000    320.51
 160.0000    310.01
 165.0000    321.59
 170.0000    320.42
 175.0000    326.01
 180.0000    326.76
 185.0000    323.76
 190.0000    324.01
 195.0000    324.59
 200.0000    330.84
 205.0000    342.51
 210.0000    338.59
 215.0000    338.01
 220.0000    356.42
 225.0000    353.09
 230.0000    348.59
 235.0000    336.92
 240.0000    328.59
 245.0000    345.26
 250.0000    363.17
 255.0000    371.51
 260.0000    372.09
 265.0000    370.01
 270.0000    375.67
 275.0000    363.67
 280.0000    357.42
 285.0000    329.76
 290.0000    336.17
 295.0000    362.17
 300.0000    335.51
 305.0000    348.17
 310.0000    360.26
 315.0000    347.92
 320.0000    358.01
 325.0000    330.26
 330.0000    337.76
 335.0000    353.09
 340.0000    345.17
 345.0000    333.92
 350.0000    331.84
 355.0000    339.67
; (Data for Range number 9)
_DRIVE='PHI'
_STEPTIME=11.999800
_STEPSIZE=5.000000
_STEPMODE='C'
_START=0.000000
_THETA=27.283001
_2THETA=54.566002
_KHI=40.000000
_PHI=0.000000
_X=0.000000
_Y=0.000000
_Z=0.000000
_DIVERGENCE=0.200000
_ANTISCATTER=0.200000
_DETECTOR=1
; S.C.
_HV=683.500000
_GAIN=80.000000
_LLD=0.788000
_ULD=2.160000
_DETECTORSLIT='out'
_AUX1=0.000000
_AUX2=0.000000
_AUX3=0.000000
_TIMESTARTED=6971.000000
_TEMP_RATE=0.000000
_TEMP_DELAY=0.000000
_KV=40
_MA=30
_RANGE_WL=1.540600
_3DPLANE=0
_2THETACPS
   0.0000    339.92
   5.0000    345.84
  10.0000    343.59
  15.0000    324.84
  20.0000    327.17
  25.0000    342.67
  30.0000    341.51
  35.0000    335.26
  40.0000    342.76
  45.0000    347.92
  50.0000    337.51
  55.0000    353.42
  60.0000    347.51
  65.0000    351.26
  70.0000    346.09
  75.0000    334.51
  80.0000    331.26
  85.0000    330.26
  90.0000    338.17
  95.0000    341.01
 100.0000    347.76
 105.0000    353.84
 110.0000    362.51
 115.0000    355.51
 120.0000    347.42
 125.0000    338.26
 130.0000    325.67
 135.0000    339.09
 140.0000    342.26
 145.0000    321.76
 150.0000    323.92
 155.0000    315.17
 160.0000    308.84
 165.0000    321.17
 170.0000    330.76
 175.0000    336.67
 180.0000    325.34
 185.0000    324.42
 190.0000    325.51
 195.0000    317.67
 200.0000    330.34
 205.0000    327.51
 210.0000    324.42
 215.0000    330.09
 220.0000    328.67
 225.0000    334.59
 230.0000    331.51
 235.0000    333.92
 240.0000    340.51
 245.0000    356.42
 250.0000    375.67
 255.0000    383.59
 260.0000    376.84
 265.0000    383.76
 270.0000    383.59
 275.0000    367.76
 280.0000    360.84
 285.0000    346.92
 290.0000    338.34
 295.0000    351.01
 300.0000    357.67
 305.0000    353.34
 310.0000    350.34
 315.0000    355.26
 320.0000    329.92
 325.0000    330.84
 330.0000    326.26
 335.0000    323.17
 340.0000    326.92
 345.0000    323.17
 350.0000    323.26
 355.0000    332.92
; (Data for Range number 10)
_DRIVE='PHI'
_STEPTIME=11.999800
_STEPSIZE=5.000000
_STEPMODE='C'
_START=0.000000
_THETA=27.283001
_2THETA=54.566002
_KHI=45.000000
_PHI=0.000000
_X=0.000000
_Y=0.000000
_Z=0.000000
_DIVERGENCE=0.200000
_ANTISCATTER=0.200000
_DETECTOR=1
; S.C.
_HV=683.500000
_GAIN=80.000000
_LLD=0.788000
_ULD=2.160000
_DETECTORSLIT='out'
_AUX1=0.000000
_AUX2=0.000000
_AUX3=0.000000
_TIMESTARTED=7839.000000
_TEMP_RATE=0.000000
_TEMP_DELAY=0.000000
_KV=40
_MA=30
_RANGE_WL=1.540600
_3DPLANE=0
_2THETACPS
   0.0000    315.42
   5.0000    325.84
  10.0000    328.92
  15.0000    330.09
  20.0000    340.01
  25.0000    322.76
  30.0000    323.76
  35.0000    322.59
  40.0000    327.09
  45.0000    320.59
  50.0000    330.17
  55.0000    322.84
  60.0000    333.51
  65.0000    329.51
  70.0000    337.92
  75.0000    334.01
  80.0000    314.17
  85.0000    319.84
  90.0000    312.67
  95.0000    327.76
 100.0000    336.26
 105.0000    337.17
 110.0000    348.09
 115.0000    353.51
 120.0000    353.09
 125.0000    342.67
 130.0000    344.51
 135.0000    322.42
 140.0000    317.09
 145.0000    326.09
 150.0000    320.67
 155.0000    321.26
 160.0000    311.84
 165.0000    302.42
 170.0000    314.51
 175.0000    317.09
 180.0000    319.42
 185.0000    301.67
 190.0000    315.92
 195.0000    310.51
 200.0000    313.92
 205.0000    315.34
 210.0000    318.42
 215.0000    333.17
 220.0000    320.51
 225.0000    329.84
 230.0000    339.67
 235.0000    338.17
 240.0000    350.84
 245.0000    360.59
 250.0000    357.84
 255.0000    357.26
 260.0000    358.01
 265.0000    369.01
 270.0000    344.42
 275.0000    346.92
 280.0000    339.26
 285.0000    347.34
 290.0000    342.01
 295.0000    350.17
 300.0000    333.34
 305.0000    343.26
 310.0000    342.01
 315.0000    343.42
 320.0000    330.59
 325.0000    318.51
 330.0000    315.01
 335.0000    319.26
 340.0000    317.67
 345.0000    321.59
 350.0000    324.42
 355.0000    329.09
; (Data for Range number 11)
_DRIVE='PHI'
_STEPTIME=11.999800
_STEPSIZE=5.000000
_STEPMODE='C'
_START=0.000000
_THETA=27.283001
_2THETA=54.566002
_KHI=50.000000
_PHI=0.000000
_X=0.000000
_Y=0.000000
_Z=0.000000
_DIVERGENCE=0.200000
_ANTISCATTER=0.200000
_DETECTOR=1
; S.C.
_HV=683.500000
_GAIN=80.000000
_LLD=0.788000
_ULD=2.160000
_DETECTORSLIT='out'
_AUX1=0.000000
_AUX2=0.000000
_AUX3=0.000000
_TIMESTARTED=8708.000000
_TEMP_RATE=0.000000
_TEMP_DELAY=0.000000
_KV=40
_MA=30
_RANGE_WL=1.540600
_3DPLANE=0
_2THETACPS
   0.0000    333.76
   5.0000    339.67
  10.0000    333.01
  15.0000    328.59
  20.0000    320.92
  25.0000    311.76
  30.0000    309.92
  35.0000    317.67
  40.0000    321.67
  45.0000    297.42
  50.0000    310.51
  55.0000    305.92
  60.0000    330.17
  65.0000    317.42
  70.0000    303.59
  75.0000    313.76
  80.0000    315.84
  85.0000    312.76
  90.0000    321.67
  95.0000    325.84
 100.0000    330.09
 105.0000    330.26
 110.0000    343.84
 115.0000    345.01
 120.0000    338.42
 125.0000    327.26
 130.0000    324.76
 135.0000    321.76
 140.0000    300.59
 145.0000    307.42
 150.0000    310.51
 155.0000    324.84
 160.0000    308.26
 165.0000    312.34
 170.0000    305.17
 175.0000    308.51
 180.0000    308.34
 185.0000    303.92
 190.0000    298.50
 195.0000    297.25
 200.0000    301.26
 205.0000    299.59
 210.0000    306.34
 215.0000    305.76
 220.0000    305.26
 225.0000    316.09
 230.0000    335.84
 235.0000    313.42
 240.0000    332.84
 245.0000    340.67
 250.0000    330.17
 255.0000    321.17
 260.0000    342.17
 265.0000    349.01
 270.0000    349.01
 275.0000    345.92
 280.0000    334.26
 285.0000    336.84
 290.0000    339.59
 295.0000    329.67
 300.0000    326.76
 305.0000    343.51
 310.0000    342.17
 315.0000    337.17
 320.0000    326.84
 325.0000    315.59
 330.0000    301.09
 335.0000    311.92
 340.0000    310.51
 345.0000    321.17
 350.0000    307.01
 355.0000    320.84
; (Data for Range number 12)
_DRIVE='PHI'
_STEPTIME=11.999800
_STEPSIZE=5.000000
_STEPMODE='C'
_START=0.000000
_THETA=27.283001
_2THETA=54.566002
_KHI=55.000000
_PHI=0.000000
_X=0.000000
_Y=0.000000
_Z=0.000000
_DIVERGENCE=0.200000
_ANTISCATTER=0.200000
_DETECTOR=1
; S.C.
_HV=683.500000
_GAIN=80.000000
_LLD=0.788000
_ULD=2.160000
_DETECTORSLIT='out'
_AUX1=0.000000
_AUX2=0.000000
_AUX3=0.000000
_TIMESTARTED=9577.000000
_TEMP_RATE=0.000000
_TEMP_DELAY=0.000000
_KV=40
_MA=30
_RANGE_WL=1.540600
_3DPLANE=0
_2THETACPS
   0.0000    344.01
   5.0000    348.67
  10.0000    338.84
  15.0000    319.67
  20.0000    328.84
  25.0000    307.84
  30.0000    323.84
  35.0000    305.67
  40.0000    303.76
  45.0000    303.51
  50.0000    299.42
  55.0000    311.51
  60.0000    311.01
  65.0000    307.26
  70.0000    306.76
  75.0000    299.25
  80.0000    317.51
  85.0000    301.84
  90.0000    314.51
  95.0000    311.42
 100.0000    316.84
 105.0000    332.92
 110.0000    334.09
 115.0000    345.76
 120.0000    337.92
 125.0000    321.01
 130.0000    310.42
 135.0000    309.42
 140.0000    299.59
 145.0000    311.34
 150.0000    301.92
 155.0000    305.67
 160.0000    305.34
 165.0000    309.17
 170.0000    309.76
 175.0000    305.01
 180.0000    316.34
 185.0000    308.84
 190.0000    310.76
 195.0000    302.92
 200.0000    306.34
 205.0000    306.42
 210.0000    304.59
 215.0000    304.26
 220.0000    302.01
 225.0000    304.67
 230.0000    306.59
 235.0000    310.26
 240.0000    299.42
 245.0000    300.59
 250.0000    286.92
 255.0000    301.84
 260.0000    316.17
 265.0000    299.59
 270.0000    305.34
 275.0000    310.26
 280.0000    316.26
 285.0000    308.92
 290.0000    307.67
 295.0000    321.01
 300.0000    317.67
 305.0000    339.26
 310.0000    363.92
 315.0000    326.17
 320.0000    319.42
 325.0000    314.51
 330.0000    305.09
 335.0000    310.01
 340.0000    321.51
 345.0000    313.01
 350.0000    315.09
 355.0000    311.01
; (Data for Range number 13)
_DRIVE='PHI'
_STEPTIME=11.999800
_STEPSIZE=5.000000
_STEPMODE='C'
_START=0.000000
_THETA=27.283001
_2THETA=54.566002
_KHI=60.000000
_PHI=0.000000
_X=0.000000
_Y=0.000000
_Z=0.000000
_DIVERGENCE=0.200000
_ANTISCATTER=0.200000
_DETECTOR=1
; S.C.
_HV=683.500000
_GAIN=80.000000
_LLD=0.788000
_ULD=2.160000
_DETECTORSLIT='out'
_AUX1=0.000000
_AUX2=0.000000
_AUX3=0.000000
_TIMESTARTED=10445.000000
_TEMP_RATE=0.000000
_TEMP_DELAY=0.000000
_KV=40
_MA=30
_RANGE_WL=1.540600
_3DPLANE=0
_2THETACPS
   0.0000    330.17
   5.0000    326.01
  10.0000    328.92
  15.0000    323.09
  20.0000    300.92
  25.0000    312.76
  30.0000    320.84
  35.0000    286.17
  40.0000    285.59
  45.0000    280.00
  50.0000    287.67
  55.0000    290.34
  60.0000    282.09
  65.0000    290.00
  70.0000    286.59
  75.0000    284.34
  80.0000    271.84
  85.0000    286.17
  90.0000    276.00
  95.0000    288.25
 100.0000    304.84
 105.0000    328.51
 110.0000    326.17
 115.0000    310.09
 120.0000    310.59
 125.0000    305.17
 130.0000    311.67
 135.0000    302.76
 140.0000    308.59
 145.0000    293.42
 150.0000    304.67
 155.0000    299.09
 160.0000    306.92
 165.0000    309.51
 170.0000    304.01
 175.0000    300.26
 180.0000    300.84
 185.0000    299.25
 190.0000    299.00
 195.0000    305.92
 200.0000    308.42
 205.0000    298.67
 210.0000    288.25
 215.0000    290.84
 220.0000    279.67
 225.0000    291.84
 230.0000    289.42
 235.0000    292.42
 240.0000    284.67
 245.0000    285.84
 250.0000    276.59
 255.0000    278.25
 260.0000    295.42
 265.0000    276.17
 270.0000    278.75
 275.0000    279.75
 280.0000    290.09
 285.0000    297.09
 290.0000    313.59
 295.0000    301.42
 300.0000    306.34
 305.0000    309.01
 310.0000    318.59
 315.0000    311.09
 320.0000    308.92
 325.0000    302.67
 330.0000    296.09
 335.0000    291.84
 340.0000    308.26
 345.0000    313.01
 350.0000    322.01
 355.0000    326.42
; (Data for Range number 14)
_DRIVE='PHI'
_STEPTIME=11.999800
_STEPSIZE=5.000000
_STEPMODE='C'
_START=0.000000
_THETA=27.283001
_2THETA=54.566002
_KHI=65.000000
_PHI=0.000000
_X=0.000000
_Y=0.000000
_Z=0.000000
_DIVERGENCE=0.200000
_ANTISCATTER=0.200000
_DETECTOR=1
; S.C.
_HV=683.500000
_GAIN=80.000000
_LLD=0.788000
_ULD=2.160000
_DETECTORSLIT='out'
_AUX1=0.000000
_AUX2=0.000000
_AUX3=0.000000
_TIMESTARTED=11314.000000
_TEMP_RATE=0.000000
_TEMP_DELAY=0.000000
_KV=40
_MA=30
_RANGE_WL=1.540600
_3DPLANE=0
_2THETACPS
   0.0000    309.76
   5.0000    317.67
  10.0000    310.09
  15.0000    305.84
  20.0000    301.76
  25.0000    306.59
  30.0000    289.17
  35.0000    268.17
  40.0000    259.50
  45.0000    257.00
  50.0000    256.67
  55.0000    258.75
  60.0000    244.42
  65.0000    250.00
  70.0000    251.67
  75.0000    243.42
  80.0000    257.67
  85.0000    252.42
  90.0000    260.59
  95.0000    270.17
 100.0000    260.84
 105.0000    281.25
 110.0000    302.09
 115.0000    296.09
 120.0000    288.17
 125.0000    289.00
 130.0000    295.00
 135.0000    297.67
 140.0000    298.00
 145.0000    281.67
 150.0000    280.75
 155.0000    294.67
 160.0000    288.09
 165.0000    302.26
 170.0000    300.67
 175.0000    297.09
 180.0000    292.75
 185.0000    291.25
 190.0000    300.51
 195.0000    291.34
 200.0000    295.00
 205.0000    279.25
 210.0000    274.25
 215.0000    256.67
 220.0000    258.84
 225.0000    255.92
 230.0000    274.00
 235.0000    257.67
 240.0000    246.00
 245.0000    248.59
 250.0000    261.17
 255.0000    260.25
 260.0000    248.17
 265.0000    250.34
 270.0000    261.59
 275.0000    269.34
 280.0000    262.34
 285.0000    264.17
 290.0000    276.75
 295.0000    289.00
 300.0000    301.84
 305.0000    297.17
 310.0000    284.00
 315.0000    291.17
 320.0000    288.42
 325.0000    274.67
 330.0000    288.34
 335.0000    277.42
 340.0000    285.59
 345.0000    295.84
 350.0000    302.59
 355.0000    313.17
; (Data for Range number 15)
_DRIVE='PHI'
_STEPTIME=11.999800
_STEPSIZE=5.000000
_STEPMODE='C'
_START=0.000000
_THETA=27.283001
_2THETA=54.566002
_KHI=70.000000
_PHI=0.000000
_X=0.000000
_Y=0.000000
_Z=0.000000
_DIVERGENCE=0.200000
_ANTISCATTER=0.200000
_DETECTOR=1
; S.C.
_HV=683.500000
_GAIN=80.000000
_LLD=0.788000
_ULD=2.160000
_DETECTORSLIT='out'
_AUX1=0.000000
_AUX2=0.000000
_AUX3=0.000000
_TIMESTARTED=12183.000000
_TEMP_RATE=0.000000
_TEMP_DELAY=0.000000
_KV=40
_MA=30
_RANGE_WL=1.540600
_3DPLANE=0
_2THETACPS
   0.0000    281.42
   5.0000    286.34
  10.0000    269.17
  15.0000    263.42
  20.0000    257.92
  25.0000    260.25
  30.0000    247.34
  35.0000    235.25
  40.0000    222.25
  45.0000    221.25
  50.0000    217.17
  55.0000    207.34
  60.0000    201.75
  65.0000    213.59
  70.0000    223.42
  75.0000    219.34
  80.0000    214.75
  85.0000    219.25
  90.0000    227.25
  95.0000    229.92
 100.0000    240.67
 105.0000    250.25
 110.0000    252.59
 115.0000    262.42
 120.0000    255.09
 125.0000    270.84
 130.0000    271.84
 135.0000    268.67
 140.0000    262.17
 145.0000    254.67
 150.0000    257.75
 155.0000    263.00
 160.0000    265.50
 165.0000    269.09
 170.0000    268.34
 175.0000    262.17
 180.0000    263.09
 185.0000    271.59
 190.0000    267.25
 195.0000    278.42
 200.0000    266.59
 205.0000    260.42
 210.0000    236.92
 215.0000    237.42
 220.0000    231.75
 225.0000    229.34
 230.0000    220.67
 235.0000    221.17
 240.0000    208.92
 245.0000    210.92
 250.0000    219.09
 255.0000    218.92
 260.0000    214.50
 265.0000    216.34
 270.0000    215.75
 275.0000    221.17
 280.0000    230.67
 285.0000    239.00
 290.0000    246.75
 295.0000    253.34
 300.0000    259.17
 305.0000    260.67
 310.0000    251.09
 315.0000    255.09
 320.0000    263.17
 325.0000    253.84
 330.0000    241.75
 335.0000    249.00
 340.0000    253.67
 345.0000    265.67
 350.0000    278.75
 355.0000    284.59
; (Data for Range number 16)
_DRIVE='PHI'
_STEPTIME=11.999800
_STEPSIZE=5.000000
_STEPMODE='C'
_START=0.000000
_THETA=27.283001
_2THETA=54.566002
_KHI=75.000000
_PHI=0.000000
_X=0.000000
_Y=0.000000
_Z=0.000000
_DIVERGENCE=0.200000
_ANTISCATTER=0.200000
_DETECTOR=1
; S.C.
_HV=683.500000
_GAIN=80.000000
_LLD=0.788000
_ULD=2.160000
_DETECTORSLIT='out'
_AUX1=0.000000
_AUX2=0.000000
_AUX3=0.000000
_TIMESTARTED=13052.000000
_TEMP_RATE=0.000000
_TEMP_DELAY=0.000000
_KV=40
_MA=30
_RANGE_WL=1.540600
_3DPLANE=0
_2THETACPS
   0.0000    236.00
   5.0000    232.67
  10.0000    230.09
  15.0000    226.17
  20.0000    220.00
  25.0000    209.25
  30.0000    202.75
  35.0000    181.50
  40.0000    187.92
  45.0000    178.92
  50.0000    171.92
  55.0000    173.09
  60.0000    176.67
  65.0000    172.75
  70.0000    164.17
  75.0000    174.84
  80.0000    169.25
  85.0000    177.59
  90.0000    180.59
  95.0000    186.75
 100.0000    191.67
 105.0000    188.34
 110.0000    192.34
 115.0000    211.00
 120.0000    206.84
 125.0000    221.84
 130.0000    222.75
 135.0000    228.67
 140.0000    214.84
 145.0000    206.00
 150.0000    215.67
 155.0000    219.50
 160.0000    221.75
 165.0000    222.92
 170.0000    216.92
 175.0000    222.50
 180.0000    222.50
 185.0000    218.67
 190.0000    225.84
 195.0000    234.84
 200.0000    228.00
 205.0000    217.17
 210.0000    200.50
 215.0000    191.67
 220.0000    191.59
 225.0000    173.25
 230.0000    171.17
 235.0000    173.09
 240.0000    173.34
 245.0000    165.50
 250.0000    163.34
 255.0000    165.50
 260.0000    163.92
 265.0000    179.25
 270.0000    171.84
 275.0000    178.17
 280.0000    188.75
 285.0000    184.42
 290.0000    195.67
 295.0000    203.84
 300.0000    214.67
 305.0000    220.42
 310.0000    210.34
 315.0000    205.34
 320.0000    206.84
 325.0000    210.59
 330.0000    208.09
 335.0000    209.84
 340.0000    209.59
 345.0000    233.42
 350.0000    221.09
 355.0000    228.84