File: mtex-5.1.1/data/PoleFigure/ZnCuTi/ZnCuTi_Wal_50_5x5_PF_002_R.UXD
; C:\Users\Stanis³aw\OneDrive\Documents\paracamgr\DANE DO MGR\24.03.2015\tekstura\TExtura\Tekstura\ZnCuTi_Wal_50_5x5_PF_002_R.raw(Diffrac Plus V1.01 file) converted by XCH V1.0
_FILEVERSION=2
_SITE='Poland'
_USER='Administrator'
_SAMPLE_CHANGER_CODE=0
_ATTACHMENTS_CODE=0
_GONIOMETER_RADIUS=300.000000
_FIXED_DIVSLIT=0.600000
_FIXED_SAMPLESLIT=1.000000
_FIXED_DETSLIT=0.100000
_MONOCHROMATOR=0
; None
_THIN_FILM='N'
_BETA_FILTER='N'
_FIXED_ANTISLIT=0.600000
_ANALYZER_CODE=0
; None
_DATEMEASURED='25-Feb-2015 19:01:21'
_WL_UNIT='A'
_WL1=1.540600
_WL2=1.544390
_WL3=1.392220
_WLRATIO=0.500000
_ANODE='Cu'
; (Data for Range number 1)
_DRIVE='PHI'
_STEPTIME=11.999800
_STEPSIZE=5.000000
_STEPMODE='C'
_START=0.000000
_THETA=18.270000
_2THETA=36.540001
_KHI=0.000000
_PHI=0.000000
_X=0.000000
_Y=0.000000
_Z=0.000000
_DIVERGENCE=0.200000
_ANTISCATTER=0.200000
_DETECTOR=1
; S.C.
_HV=683.500000
_GAIN=80.000000
_LLD=0.788000
_ULD=2.160000
_DETECTORSLIT='out'
_AUX1=0.000000
_AUX2=0.000000
_AUX3=0.000000
_TIMESTARTED=4.000000
_TEMP_RATE=0.000000
_TEMP_DELAY=0.000000
_KV=40
_MA=30
_RANGE_WL=1.540600
_3DPLANE=0
_2THETACPS
   0.0000    351.67
   5.0000    345.17
  10.0000    340.84
  15.0000    352.26
  20.0000    340.17
  25.0000    343.09
  30.0000    342.42
  35.0000    337.67
  40.0000    333.26
  45.0000    328.84
  50.0000    341.26
  55.0000    342.76
  60.0000    340.01
  65.0000    342.59
  70.0000    335.01
  75.0000    341.26
  80.0000    332.26
  85.0000    332.76
  90.0000    342.51
  95.0000    347.17
 100.0000    348.84
 105.0000    351.92
 110.0000    343.09
 115.0000    350.17
 120.0000    342.34
 125.0000    344.17
 130.0000    345.01
 135.0000    346.01
 140.0000    350.84
 145.0000    347.76
 150.0000    346.42
 155.0000    352.76
 160.0000    350.17
 165.0000    341.51
 170.0000    350.42
 175.0000    348.84
 180.0000    360.59
 185.0000    348.92
 190.0000    344.17
 195.0000    341.76
 200.0000    355.34
 205.0000    344.09
 210.0000    346.92
 215.0000    351.51
 220.0000    347.17
 225.0000    341.01
 230.0000    347.34
 235.0000    356.01
 240.0000    349.59
 245.0000    337.76
 250.0000    347.26
 255.0000    350.01
 260.0000    347.26
 265.0000    347.51
 270.0000    356.76
 275.0000    345.59
 280.0000    352.51
 285.0000    346.51
 290.0000    354.59
 295.0000    340.51
 300.0000    355.76
 305.0000    340.59
 310.0000    349.59
 315.0000    363.84
 320.0000    368.76
 325.0000    369.09
 330.0000    371.76
 335.0000    368.59
 340.0000    357.84
 345.0000    363.09
 350.0000    363.92
 355.0000    358.76
; (Data for Range number 2)
_DRIVE='PHI'
_STEPTIME=11.999800
_STEPSIZE=5.000000
_STEPMODE='C'
_START=0.000000
_THETA=18.270000
_2THETA=36.540001
_KHI=5.000000
_PHI=0.000000
_X=0.000000
_Y=0.000000
_Z=0.000000
_DIVERGENCE=0.200000
_ANTISCATTER=0.200000
_DETECTOR=1
; S.C.
_HV=683.500000
_GAIN=80.000000
_LLD=0.788000
_ULD=2.160000
_DETECTORSLIT='out'
_AUX1=0.000000
_AUX2=0.000000
_AUX3=0.000000
_TIMESTARTED=872.000000
_TEMP_RATE=0.000000
_TEMP_DELAY=0.000000
_KV=40
_MA=30
_RANGE_WL=1.540600
_3DPLANE=0
_2THETACPS
   0.0000    361.92
   5.0000    364.67
  10.0000    369.76
  15.0000    363.92
  20.0000    383.84
  25.0000    372.09
  30.0000    376.17
  35.0000    349.09
  40.0000    351.76
  45.0000    351.34
  50.0000    338.01
  55.0000    338.26
  60.0000    337.67
  65.0000    333.17
  70.0000    336.84
  75.0000    331.09
  80.0000    333.51
  85.0000    334.51
  90.0000    336.01
  95.0000    334.09
 100.0000    347.42
 105.0000    351.17
 110.0000    346.17
 115.0000    345.17
 120.0000    344.51
 125.0000    345.51
 130.0000    354.76
 135.0000    352.34
 140.0000    357.17
 145.0000    367.42
 150.0000    372.34
 155.0000    369.59
 160.0000    365.17
 165.0000    359.26
 170.0000    351.26
 175.0000    355.01
 180.0000    342.42
 185.0000    339.01
 190.0000    345.76
 195.0000    338.84
 200.0000    353.84
 205.0000    343.51
 210.0000    345.01
 215.0000    351.01
 220.0000    351.76
 225.0000    343.67
 230.0000    342.51
 235.0000    355.59
 240.0000    348.92
 245.0000    346.09
 250.0000    351.51
 255.0000    346.17
 260.0000    344.67
 265.0000    342.59
 270.0000    331.76
 275.0000    344.42
 280.0000    342.34
 285.0000    336.17
 290.0000    347.67
 295.0000    344.59
 300.0000    346.34
 305.0000    346.42
 310.0000    342.92
 315.0000    334.42
 320.0000    341.17
 325.0000    347.84
 330.0000    351.67
 335.0000    341.51
 340.0000    342.01
 345.0000    341.17
 350.0000    351.42
 355.0000    347.76
; (Data for Range number 3)
_DRIVE='PHI'
_STEPTIME=11.999800
_STEPSIZE=5.000000
_STEPMODE='C'
_START=0.000000
_THETA=18.270000
_2THETA=36.540001
_KHI=10.000000
_PHI=0.000000
_X=0.000000
_Y=0.000000
_Z=0.000000
_DIVERGENCE=0.200000
_ANTISCATTER=0.200000
_DETECTOR=1
; S.C.
_HV=683.500000
_GAIN=80.000000
_LLD=0.788000
_ULD=2.160000
_DETECTORSLIT='out'
_AUX1=0.000000
_AUX2=0.000000
_AUX3=0.000000
_TIMESTARTED=1741.000000
_TEMP_RATE=0.000000
_TEMP_DELAY=0.000000
_KV=40
_MA=30
_RANGE_WL=1.540600
_3DPLANE=0
_2THETACPS
   0.0000    353.42
   5.0000    362.92
  10.0000    359.76
  15.0000    366.26
  20.0000    363.51
  25.0000    362.01
  30.0000    370.92
  35.0000    371.59
  40.0000    360.76
  45.0000    354.51
  50.0000    352.59
  55.0000    337.17
  60.0000    342.17
  65.0000    341.34
  70.0000    352.92
  75.0000    347.92
  80.0000    339.01
  85.0000    342.34
  90.0000    339.67
  95.0000    340.26
 100.0000    342.59
 105.0000    343.17
 110.0000    351.17
 115.0000    343.67
 120.0000    346.92
 125.0000    347.76
 130.0000    355.67
 135.0000    350.34
 140.0000    364.42
 145.0000    381.17
 150.0000    373.09
 155.0000    376.51
 160.0000    377.26
 165.0000    375.92
 170.0000    366.76
 175.0000    358.59
 180.0000    384.76
 185.0000    378.84
 190.0000    387.59
 195.0000    375.17
 200.0000    387.17
 205.0000    377.09
 210.0000    378.26
 215.0000    363.76
 220.0000    358.17
 225.0000    352.42
 230.0000    346.34
 235.0000    345.76
 240.0000    349.34
 245.0000    342.17
 250.0000    348.17
 255.0000    332.26
 260.0000    333.01
 265.0000    334.67
 270.0000    330.59
 275.0000    335.59
 280.0000    356.84
 285.0000    366.09
 290.0000    375.26
 295.0000    390.42
 300.0000    379.67
 305.0000    375.17
 310.0000    375.92
 315.0000    383.76
 320.0000    401.09
 325.0000    412.34
 330.0000    434.17
 335.0000    415.17
 340.0000    396.17
 345.0000    371.42
 350.0000    375.42
 355.0000    363.17
; (Data for Range number 4)
_DRIVE='PHI'
_STEPTIME=11.999800
_STEPSIZE=5.000000
_STEPMODE='C'
_START=0.000000
_THETA=18.270000
_2THETA=36.540001
_KHI=15.000000
_PHI=0.000000
_X=0.000000
_Y=0.000000
_Z=0.000000
_DIVERGENCE=0.200000
_ANTISCATTER=0.200000
_DETECTOR=1
; S.C.
_HV=683.500000
_GAIN=80.000000
_LLD=0.788000
_ULD=2.160000
_DETECTORSLIT='out'
_AUX1=0.000000
_AUX2=0.000000
_AUX3=0.000000
_TIMESTARTED=2610.000000
_TEMP_RATE=0.000000
_TEMP_DELAY=0.000000
_KV=40
_MA=30
_RANGE_WL=1.540600
_3DPLANE=0
_2THETACPS
   0.0000    438.01
   5.0000    435.76
  10.0000    404.01
  15.0000    407.51
  20.0000    417.01
  25.0000    428.42
  30.0000    422.42
  35.0000    416.09
  40.0000    389.92
  45.0000    384.67
  50.0000    373.67
  55.0000    366.34
  60.0000    378.17
  65.0000    372.01
  70.0000    368.76
  75.0000    362.84
  80.0000    359.76
  85.0000    352.84
  90.0000    359.01
  95.0000    351.59
 100.0000    346.26
 105.0000    354.92
 110.0000    354.42
 115.0000    366.67
 120.0000    355.34
 125.0000    360.26
 130.0000    367.84
 135.0000    363.84
 140.0000    378.92
 145.0000    401.34
 150.0000    398.92
 155.0000    420.34
 160.0000    426.26
 165.0000    400.34
 170.0000    408.67
 175.0000    418.51
 180.0000    444.67
 185.0000    433.59
 190.0000    452.01
 195.0000    468.01
 200.0000    458.51
 205.0000    435.42
 210.0000    446.76
 215.0000    436.26
 220.0000    413.42
 225.0000    382.09
 230.0000    373.84
 235.0000    376.34
 240.0000    351.26
 245.0000    361.34
 250.0000    346.26
 255.0000    339.34
 260.0000    352.67
 265.0000    374.67
 270.0000    362.17
 275.0000    365.09
 280.0000    374.51
 285.0000    398.34
 290.0000    433.09
 295.0000    408.84
 300.0000    399.01
 305.0000    422.42
 310.0000    460.51
 315.0000    449.67
 320.0000    441.01
 325.0000    451.59
 330.0000    462.92
 335.0000    478.26
 340.0000    492.59
 345.0000    487.51
 350.0000    464.34
 355.0000    440.67
; (Data for Range number 5)
_DRIVE='PHI'
_STEPTIME=11.999800
_STEPSIZE=5.000000
_STEPMODE='C'
_START=0.000000
_THETA=18.270000
_2THETA=36.540001
_KHI=20.000000
_PHI=0.000000
_X=0.000000
_Y=0.000000
_Z=0.000000
_DIVERGENCE=0.200000
_ANTISCATTER=0.200000
_DETECTOR=1
; S.C.
_HV=683.500000
_GAIN=80.000000
_LLD=0.788000
_ULD=2.160000
_DETECTORSLIT='out'
_AUX1=0.000000
_AUX2=0.000000
_AUX3=0.000000
_TIMESTARTED=3478.000000
_TEMP_RATE=0.000000
_TEMP_DELAY=0.000000
_KV=40
_MA=30
_RANGE_WL=1.540600
_3DPLANE=0
_2THETACPS
   0.0000    569.59
   5.0000    524.84
  10.0000    495.59
  15.0000    475.67
  20.0000    478.09
  25.0000    470.42
  30.0000    465.59
  35.0000    464.17
  40.0000    460.01
  45.0000    454.76
  50.0000    439.01
  55.0000    421.84
  60.0000    408.17
  65.0000    393.42
  70.0000    385.76
  75.0000    375.92
  80.0000    367.92
  85.0000    373.26
  90.0000    375.92
  95.0000    372.09
 100.0000    368.17
 105.0000    361.67
 110.0000    354.92
 115.0000    378.09
 120.0000    371.17
 125.0000    368.17
 130.0000    385.01
 135.0000    390.01
 140.0000    410.17
 145.0000    417.67
 150.0000    451.76
 155.0000    473.59
 160.0000    478.42
 165.0000    445.17
 170.0000    451.76
 175.0000    491.34
 180.0000    548.09
 185.0000    546.93
 190.0000    525.59
 195.0000    535.76
 200.0000    561.43
 205.0000    599.84
 210.0000    545.93
 215.0000    452.42
 220.0000    395.84
 225.0000    406.84
 230.0000    393.01
 235.0000    387.67
 240.0000    374.26
 245.0000    371.01
 250.0000    367.17
 255.0000    351.84
 260.0000    359.09
 265.0000    361.59
 270.0000    381.17
 275.0000    396.09
 280.0000    401.76
 285.0000    420.51
 290.0000    418.67
 295.0000    449.92
 300.0000    450.42
 305.0000    452.92
 310.0000    475.59
 315.0000    513.18
 320.0000    524.34
 325.0000    540.93
 330.0000    514.26
 335.0000    573.68
 340.0000    613.51
 345.0000    655.18
 350.0000    677.26
 355.0000    640.01
; (Data for Range number 6)
_DRIVE='PHI'
_STEPTIME=11.999800
_STEPSIZE=5.000000
_STEPMODE='C'
_START=0.000000
_THETA=18.270000
_2THETA=36.540001
_KHI=25.000000
_PHI=0.000000
_X=0.000000
_Y=0.000000
_Z=0.000000
_DIVERGENCE=0.200000
_ANTISCATTER=0.200000
_DETECTOR=1
; S.C.
_HV=683.500000
_GAIN=80.000000
_LLD=0.788000
_ULD=2.160000
_DETECTORSLIT='out'
_AUX1=0.000000
_AUX2=0.000000
_AUX3=0.000000
_TIMESTARTED=4347.000000
_TEMP_RATE=0.000000
_TEMP_DELAY=0.000000
_KV=40
_MA=30
_RANGE_WL=1.540600
_3DPLANE=0
_2THETACPS
   0.0000    719.18
   5.0000    630.34
  10.0000    557.76
  15.0000    553.18
  20.0000    573.84
  25.0000    545.01
  30.0000    523.26
  35.0000    527.26
  40.0000    537.01
  45.0000    518.18
  50.0000    506.76
  55.0000    488.42
  60.0000    443.09
  65.0000    409.26
  70.0000    394.01
  75.0000    385.92
  80.0000    389.17
  85.0000    378.59
  90.0000    368.09
  95.0000    384.09
 100.0000    373.92
 105.0000    369.51
 110.0000    368.34
 115.0000    398.26
 120.0000    392.76
 125.0000    421.17
 130.0000    411.26
 135.0000    429.17
 140.0000    443.67
 145.0000    465.01
 150.0000    476.26
 155.0000    491.84
 160.0000    518.34
 165.0000    523.84
 170.0000    515.84
 175.0000    575.01
 180.0000    604.18
 185.0000    660.59
 190.0000    663.76
 195.0000    719.85
 200.0000    723.93
 205.0000    621.59
 210.0000    523.18
 215.0000    484.92
 220.0000    454.84
 225.0000    449.92
 230.0000    448.34
 235.0000    453.51
 240.0000    424.59
 245.0000    411.92
 250.0000    393.01
 255.0000    382.42
 260.0000    380.34
 265.0000    380.84
 270.0000    392.34
 275.0000    392.92
 280.0000    388.17
 285.0000    411.67
 290.0000    426.34
 295.0000    471.26
 300.0000    502.93
 305.0000    481.34
 310.0000    497.26
 315.0000    519.68
 320.0000    571.51
 325.0000    602.09
 330.0000    603.76
 335.0000    639.01
 340.0000    738.68
 345.0000    809.35
 350.0000    837.76
 355.0000    774.51
; (Data for Range number 7)
_DRIVE='PHI'
_STEPTIME=11.999800
_STEPSIZE=5.000000
_STEPMODE='C'
_START=0.000000
_THETA=18.270000
_2THETA=36.540001
_KHI=30.000000
_PHI=0.000000
_X=0.000000
_Y=0.000000
_Z=0.000000
_DIVERGENCE=0.200000
_ANTISCATTER=0.200000
_DETECTOR=1
; S.C.
_HV=683.500000
_GAIN=80.000000
_LLD=0.788000
_ULD=2.160000
_DETECTORSLIT='out'
_AUX1=0.000000
_AUX2=0.000000
_AUX3=0.000000
_TIMESTARTED=5215.000000
_TEMP_RATE=0.000000
_TEMP_DELAY=0.000000
_KV=40
_MA=30
_RANGE_WL=1.540600
_3DPLANE=0
_2THETACPS
   0.0000    828.18
   5.0000    709.35
  10.0000    683.84
  15.0000    663.01
  20.0000    629.09
  25.0000    583.59
  30.0000    564.76
  35.0000    560.51
  40.0000    533.01
  45.0000    531.43
  50.0000    560.51
  55.0000    559.43
  60.0000    511.68
  65.0000    474.34
  70.0000    424.76
  75.0000    409.84
  80.0000    391.84
  85.0000    376.34
  90.0000    363.01
  95.0000    367.26
 100.0000    387.67
 105.0000    393.59
 110.0000    404.26
 115.0000    417.67
 120.0000    410.59
 125.0000    431.67
 130.0000    452.67
 135.0000    469.17
 140.0000    491.42
 145.0000    488.42
 150.0000    523.09
 155.0000    552.26
 160.0000    539.93
 165.0000    581.34
 170.0000    578.26
 175.0000    613.43
 180.0000    674.93
 185.0000    707.18
 190.0000    801.18
 195.0000    789.26
 200.0000    769.85
 205.0000    628.43
 210.0000    594.43
 215.0000    551.68
 220.0000    508.09
 225.0000    506.18
 230.0000    509.43
 235.0000    479.26
 240.0000    444.92
 245.0000    416.51
 250.0000    366.34
 255.0000    356.42
 260.0000    352.92
 265.0000    357.59
 270.0000    386.09
 275.0000    385.59
 280.0000    390.84
 285.0000    417.92
 290.0000    462.42
 295.0000    522.84
 300.0000    564.84
 305.0000    552.59
 310.0000    549.01
 315.0000    585.09
 320.0000    641.09
 325.0000    693.26
 330.0000    756.10
 335.0000    826.51
 340.0000    842.35
 345.0000    875.76
 350.0000    908.18
 355.0000    843.51
; (Data for Range number 8)
_DRIVE='PHI'
_STEPTIME=11.999800
_STEPSIZE=5.000000
_STEPMODE='C'
_START=0.000000
_THETA=18.270000
_2THETA=36.540001
_KHI=35.000000
_PHI=0.000000
_X=0.000000
_Y=0.000000
_Z=0.000000
_DIVERGENCE=0.200000
_ANTISCATTER=0.200000
_DETECTOR=1
; S.C.
_HV=683.500000
_GAIN=80.000000
_LLD=0.788000
_ULD=2.160000
_DETECTORSLIT='out'
_AUX1=0.000000
_AUX2=0.000000
_AUX3=0.000000
_TIMESTARTED=6083.000000
_TEMP_RATE=0.000000
_TEMP_DELAY=0.000000
_KV=40
_MA=30
_RANGE_WL=1.540600
_3DPLANE=0
_2THETACPS
   0.0000    836.93
   5.0000    731.93
  10.0000    671.26
  15.0000    658.09
  20.0000    626.59
  25.0000    580.01
  30.0000    574.68
  35.0000    590.01
  40.0000    558.51
  45.0000    538.01
  50.0000    522.51
  55.0000    513.26
  60.0000    467.92
  65.0000    469.76
  70.0000    420.59
  75.0000    366.01
  80.0000    368.42
  85.0000    356.09
  90.0000    353.51
  95.0000    362.42
 100.0000    380.84
 105.0000    388.67
 110.0000    409.09
 115.0000    399.84
 120.0000    415.26
 125.0000    424.42
 130.0000    467.67
 135.0000    496.67
 140.0000    532.84
 145.0000    544.43
 150.0000    542.76
 155.0000    610.34
 160.0000    589.43
 165.0000    585.18
 170.0000    617.76
 175.0000    669.34
 180.0000    717.26
 185.0000    722.35
 190.0000    717.60
 195.0000    719.76
 200.0000    696.51
 205.0000    652.76
 210.0000    648.59
 215.0000    595.34
 220.0000    543.93
 225.0000    549.43
 230.0000    573.18
 235.0000    499.68
 240.0000    424.34
 245.0000    390.76
 250.0000    374.51
 255.0000    337.67
 260.0000    337.09
 265.0000    352.67
 270.0000    358.01
 275.0000    372.26
 280.0000    383.09
 285.0000    401.76
 290.0000    469.17
 295.0000    537.68
 300.0000    567.51
 305.0000    595.93
 310.0000    626.51
 315.0000    755.76
 320.0000    752.18
 325.0000    708.51
 330.0000    718.43
 335.0000    816.35
 340.0000    823.93
 345.0000    823.68
 350.0000    826.93
 355.0000    820.51
; (Data for Range number 9)
_DRIVE='PHI'
_STEPTIME=11.999800
_STEPSIZE=5.000000
_STEPMODE='C'
_START=0.000000
_THETA=18.270000
_2THETA=36.540001
_KHI=40.000000
_PHI=0.000000
_X=0.000000
_Y=0.000000
_Z=0.000000
_DIVERGENCE=0.200000
_ANTISCATTER=0.200000
_DETECTOR=1
; S.C.
_HV=683.500000
_GAIN=80.000000
_LLD=0.788000
_ULD=2.160000
_DETECTORSLIT='out'
_AUX1=0.000000
_AUX2=0.000000
_AUX3=0.000000
_TIMESTARTED=6952.000000
_TEMP_RATE=0.000000
_TEMP_DELAY=0.000000
_KV=40
_MA=30
_RANGE_WL=1.540600
_3DPLANE=0
_2THETACPS
   0.0000    701.26
   5.0000    590.18
  10.0000    571.26
  15.0000    575.59
  20.0000    593.18
  25.0000    576.26
  30.0000    579.93
  35.0000    601.51
  40.0000    551.26
  45.0000    538.18
  50.0000    506.51
  55.0000    454.59
  60.0000    415.84
  65.0000    406.76
  70.0000    397.67
  75.0000    359.34
  80.0000    340.17
  85.0000    326.76
  90.0000    320.51
  95.0000    328.17
 100.0000    358.34
 105.0000    345.67
 110.0000    357.17
 115.0000    386.42
 120.0000    392.01
 125.0000    393.92
 130.0000    432.76
 135.0000    460.42
 140.0000    528.68
 145.0000    529.18
 150.0000    528.93
 155.0000    580.76
 160.0000    570.84
 165.0000    577.93
 170.0000    626.43
 175.0000    669.01
 180.0000    671.51
 185.0000    692.51
 190.0000    614.93
 195.0000    608.84
 200.0000    592.84
 205.0000    631.51
 210.0000    596.84
 215.0000    532.59
 220.0000    496.34
 225.0000    518.34
 230.0000    492.76
 235.0000    443.51
 240.0000    402.92
 245.0000    367.84
 250.0000    358.92
 255.0000    349.34
 260.0000    323.17
 265.0000    316.51
 270.0000    334.76
 275.0000    355.51
 280.0000    373.34
 285.0000    394.92
 290.0000    438.76
 295.0000    502.18
 300.0000    524.01
 305.0000    562.01
 310.0000    573.43
 315.0000    665.01
 320.0000    738.93
 325.0000    712.35
 330.0000    670.93
 335.0000    745.85
 340.0000    807.93
 345.0000    733.76
 350.0000    779.51
 355.0000    724.68
; (Data for Range number 10)
_DRIVE='PHI'
_STEPTIME=11.999800
_STEPSIZE=5.000000
_STEPMODE='C'
_START=0.000000
_THETA=18.270000
_2THETA=36.540001
_KHI=45.000000
_PHI=0.000000
_X=0.000000
_Y=0.000000
_Z=0.000000
_DIVERGENCE=0.200000
_ANTISCATTER=0.200000
_DETECTOR=1
; S.C.
_HV=683.500000
_GAIN=80.000000
_LLD=0.788000
_ULD=2.160000
_DETECTORSLIT='out'
_AUX1=0.000000
_AUX2=0.000000
_AUX3=0.000000
_TIMESTARTED=7821.000000
_TEMP_RATE=0.000000
_TEMP_DELAY=0.000000
_KV=40
_MA=30
_RANGE_WL=1.540600
_3DPLANE=0
_2THETACPS
   0.0000    629.43
   5.0000    543.43
  10.0000    543.18
  15.0000    571.18
  20.0000    551.26
  25.0000    523.68
  30.0000    545.43
  35.0000    531.34
  40.0000    520.51
  45.0000    473.09
  50.0000    459.67
  55.0000    403.26
  60.0000    369.59
  65.0000    359.34
  70.0000    351.09
  75.0000    321.67
  80.0000    324.26
  85.0000    318.17
  90.0000    302.59
  95.0000    308.59
 100.0000    327.84
 105.0000    320.17
 110.0000    330.34
 115.0000    370.17
 120.0000    380.76
 125.0000    382.34
 130.0000    400.84
 135.0000    443.34
 140.0000    499.76
 145.0000    536.59
 150.0000    564.01
 155.0000    589.68
 160.0000    544.68
 165.0000    526.59
 170.0000    564.59
 175.0000    579.76
 180.0000    584.34
 185.0000    595.01
 190.0000    575.18
 195.0000    554.26
 200.0000    542.01
 205.0000    584.43
 210.0000    586.76
 215.0000    491.59
 220.0000    437.51
 225.0000    396.34
 230.0000    398.34
 235.0000    392.51
 240.0000    401.67
 245.0000    397.34
 250.0000    332.51
 255.0000    312.17
 260.0000    313.59
 265.0000    321.42
 270.0000    332.09
 275.0000    353.01
 280.0000    353.76
 285.0000    348.67
 290.0000    408.84
 295.0000    427.84
 300.0000    440.84
 305.0000    510.09
 310.0000    543.09
 315.0000    594.09
 320.0000    701.43
 325.0000    698.09
 330.0000    680.84
 335.0000    650.76
 340.0000    701.60
 345.0000    661.09
 350.0000    679.43
 355.0000    649.09
; (Data for Range number 11)
_DRIVE='PHI'
_STEPTIME=11.999800
_STEPSIZE=5.000000
_STEPMODE='C'
_START=0.000000
_THETA=18.270000
_2THETA=36.540001
_KHI=50.000000
_PHI=0.000000
_X=0.000000
_Y=0.000000
_Z=0.000000
_DIVERGENCE=0.200000
_ANTISCATTER=0.200000
_DETECTOR=1
; S.C.
_HV=683.500000
_GAIN=80.000000
_LLD=0.788000
_ULD=2.160000
_DETECTORSLIT='out'
_AUX1=0.000000
_AUX2=0.000000
_AUX3=0.000000
_TIMESTARTED=8689.000000
_TEMP_RATE=0.000000
_TEMP_DELAY=0.000000
_KV=40
_MA=30
_RANGE_WL=1.540600
_3DPLANE=0
_2THETACPS
   0.0000    577.09
   5.0000    540.84
  10.0000    562.76
  15.0000    564.84
  20.0000    477.92
  25.0000    495.17
  30.0000    503.43
  35.0000    470.26
  40.0000    460.01
  45.0000    402.76
  50.0000    382.34
  55.0000    356.26
  60.0000    339.51
  65.0000    312.76
  70.0000    316.26
  75.0000    297.92
  80.0000    288.42
  85.0000    292.84
  90.0000    294.75
  95.0000    290.67
 100.0000    299.76
 105.0000    310.67
 110.0000    309.42
 115.0000    326.26
 120.0000    355.17
 125.0000    375.17
 130.0000    383.51
 135.0000    420.67
 140.0000    485.59
 145.0000    513.01
 150.0000    510.51
 155.0000    527.09
 160.0000    506.43
 165.0000    490.42
 170.0000    519.01
 175.0000    505.84
 180.0000    495.76
 185.0000    494.34
 190.0000    532.09
 195.0000    542.76
 200.0000    510.68
 205.0000    569.93
 210.0000    542.84
 215.0000    433.67
 220.0000    377.17
 225.0000    361.59
 230.0000    361.01
 235.0000    377.42
 240.0000    396.51
 245.0000    356.17
 250.0000    301.67
 255.0000    290.92
 260.0000    313.67
 265.0000    295.17
 270.0000    298.09
 275.0000    321.92
 280.0000    310.76
 285.0000    328.34
 290.0000    371.67
 295.0000    367.34
 300.0000    413.67
 305.0000    479.17
 310.0000    486.26
 315.0000    530.01
 320.0000    598.76
 325.0000    683.18
 330.0000    620.76
 335.0000    607.01
 340.0000    612.84
 345.0000    582.59
 350.0000    632.26
 355.0000    588.34
; (Data for Range number 12)
_DRIVE='PHI'
_STEPTIME=11.999800
_STEPSIZE=5.000000
_STEPMODE='C'
_START=0.000000
_THETA=18.270000
_2THETA=36.540001
_KHI=55.000000
_PHI=0.000000
_X=0.000000
_Y=0.000000
_Z=0.000000
_DIVERGENCE=0.200000
_ANTISCATTER=0.200000
_DETECTOR=1
; S.C.
_HV=683.500000
_GAIN=80.000000
_LLD=0.788000
_ULD=2.160000
_DETECTORSLIT='out'
_AUX1=0.000000
_AUX2=0.000000
_AUX3=0.000000
_TIMESTARTED=9558.000000
_TEMP_RATE=0.000000
_TEMP_DELAY=0.000000
_KV=40
_MA=30
_RANGE_WL=1.540600
_3DPLANE=0
_2THETACPS
   0.0000    511.26
   5.0000    528.93
  10.0000    503.18
  15.0000    497.09
  20.0000    468.51
  25.0000    477.76
  30.0000    483.92
  35.0000    449.01
  40.0000    400.26
  45.0000    360.26
  50.0000    342.01
  55.0000    335.51
  60.0000    314.92
  65.0000    304.76
  70.0000    280.50
  75.0000    278.25
  80.0000    265.42
  85.0000    272.09
  90.0000    265.09
  95.0000    262.84
 100.0000    270.67
 105.0000    298.59
 110.0000    296.09
 115.0000    314.09
 120.0000    323.17
 125.0000    352.84
 130.0000    352.42
 135.0000    389.26
 140.0000    423.84
 145.0000    452.51
 150.0000    472.59
 155.0000    497.17
 160.0000    511.09
 165.0000    510.18
 170.0000    497.84
 175.0000    493.67
 180.0000    475.76
 185.0000    477.26
 190.0000    496.26
 195.0000    539.51
 200.0000    506.26
 205.0000    517.09
 210.0000    492.59
 215.0000    428.92
 220.0000    361.76
 225.0000    348.26
 230.0000    334.34
 235.0000    326.17
 240.0000    322.51
 245.0000    311.26
 250.0000    281.00
 255.0000    274.17
 260.0000    274.92
 265.0000    270.75
 270.0000    271.84
 275.0000    292.42
 280.0000    289.00
 285.0000    305.26
 290.0000    327.92
 295.0000    343.92
 300.0000    389.01
 305.0000    415.92
 310.0000    462.26
 315.0000    458.01
 320.0000    526.26
 325.0000    542.18
 330.0000    588.01
 335.0000    522.84
 340.0000    517.01
 345.0000    531.76
 350.0000    582.18
 355.0000    524.68
; (Data for Range number 13)
_DRIVE='PHI'
_STEPTIME=11.999800
_STEPSIZE=5.000000
_STEPMODE='C'
_START=0.000000
_THETA=18.270000
_2THETA=36.540001
_KHI=60.000000
_PHI=0.000000
_X=0.000000
_Y=0.000000
_Z=0.000000
_DIVERGENCE=0.200000
_ANTISCATTER=0.200000
_DETECTOR=1
; S.C.
_HV=683.500000
_GAIN=80.000000
_LLD=0.788000
_ULD=2.160000
_DETECTORSLIT='out'
_AUX1=0.000000
_AUX2=0.000000
_AUX3=0.000000
_TIMESTARTED=10426.000000
_TEMP_RATE=0.000000
_TEMP_DELAY=0.000000
_KV=40
_MA=30
_RANGE_WL=1.540600
_3DPLANE=0
_2THETACPS
   0.0000    466.09
   5.0000    463.17
  10.0000    454.09
  15.0000    443.17
  20.0000    408.34
  25.0000    422.59
  30.0000    452.34
  35.0000    384.42
  40.0000    337.59
  45.0000    318.01
  50.0000    319.92
  55.0000    288.92
  60.0000    290.92
  65.0000    289.00
  70.0000    253.00
  75.0000    236.84
  80.0000    237.34
  85.0000    251.00
  90.0000    246.75
  95.0000    246.25
 100.0000    249.75
 105.0000    261.67
 110.0000    265.50
 115.0000    281.92
 120.0000    300.26
 125.0000    317.09
 130.0000    326.92
 135.0000    346.84
 140.0000    368.84
 145.0000    389.84
 150.0000    423.26
 155.0000    500.93
 160.0000    505.76
 165.0000    510.18
 170.0000    453.76
 175.0000    442.42
 180.0000    447.67
 185.0000    469.17
 190.0000    462.67
 195.0000    504.01
 200.0000    460.51
 205.0000    464.26
 210.0000    450.92
 215.0000    404.17
 220.0000    349.92
 225.0000    295.92
 230.0000    291.67
 235.0000    298.50
 240.0000    282.17
 245.0000    276.17
 250.0000    245.84
 255.0000    249.17
 260.0000    245.09
 265.0000    239.00
 270.0000    248.92
 275.0000    263.00
 280.0000    270.59
 285.0000    282.09
 290.0000    289.92
 295.0000    300.17
 300.0000    333.59
 305.0000    371.84
 310.0000    378.26
 315.0000    422.92
 320.0000    431.67
 325.0000    468.92
 330.0000    516.51
 335.0000    520.26
 340.0000    476.42
 345.0000    521.01
 350.0000    529.01
 355.0000    472.76
; (Data for Range number 14)
_DRIVE='PHI'
_STEPTIME=11.999800
_STEPSIZE=5.000000
_STEPMODE='C'
_START=0.000000
_THETA=18.270000
_2THETA=36.540001
_KHI=65.000000
_PHI=0.000000
_X=0.000000
_Y=0.000000
_Z=0.000000
_DIVERGENCE=0.200000
_ANTISCATTER=0.200000
_DETECTOR=1
; S.C.
_HV=683.500000
_GAIN=80.000000
_LLD=0.788000
_ULD=2.160000
_DETECTORSLIT='out'
_AUX1=0.000000
_AUX2=0.000000
_AUX3=0.000000
_TIMESTARTED=11294.000000
_TEMP_RATE=0.000000
_TEMP_DELAY=0.000000
_KV=40
_MA=30
_RANGE_WL=1.540600
_3DPLANE=0
_2THETACPS
   0.0000    373.26
   5.0000    378.76
  10.0000    399.26
  15.0000    379.59
  20.0000    326.92
  25.0000    329.51
  30.0000    351.42
  35.0000    324.59
  40.0000    297.75
  45.0000    284.34
  50.0000    265.09
  55.0000    243.59
  60.0000    256.42
  65.0000    247.17
  70.0000    215.50
  75.0000    210.25
  80.0000    211.92
  85.0000    204.67
  90.0000    209.59
  95.0000    205.59
 100.0000    216.92
 105.0000    226.67
 110.0000    237.34
 115.0000    246.00
 120.0000    261.25
 125.0000    275.67
 130.0000    302.17
 135.0000    314.92
 140.0000    329.59
 145.0000    336.51
 150.0000    384.01
 155.0000    471.51
 160.0000    451.76
 165.0000    415.67
 170.0000    398.76
 175.0000    413.42
 180.0000    411.76
 185.0000    457.42
 190.0000    432.26
 195.0000    433.26
 200.0000    389.01
 205.0000    397.76
 210.0000    396.92
 215.0000    340.17
 220.0000    292.42
 225.0000    260.09
 230.0000    262.75
 235.0000    249.00
 240.0000    265.50
 245.0000    236.42
 250.0000    213.67
 255.0000    210.17
 260.0000    212.75
 265.0000    212.34
 270.0000    211.00
 275.0000    219.00
 280.0000    246.50
 285.0000    247.84
 290.0000    251.42
 295.0000    261.34
 300.0000    284.84
 305.0000    339.34
 310.0000    342.26
 315.0000    353.84
 320.0000    353.84
 325.0000    384.42
 330.0000    435.76
 335.0000    440.76
 340.0000    417.51
 345.0000    430.84
 350.0000    442.76
 355.0000    416.34
; (Data for Range number 15)
_DRIVE='PHI'
_STEPTIME=11.999800
_STEPSIZE=5.000000
_STEPMODE='C'
_START=0.000000
_THETA=18.270000
_2THETA=36.540001
_KHI=70.000000
_PHI=0.000000
_X=0.000000
_Y=0.000000
_Z=0.000000
_DIVERGENCE=0.200000
_ANTISCATTER=0.200000
_DETECTOR=1
; S.C.
_HV=683.500000
_GAIN=80.000000
_LLD=0.788000
_ULD=2.160000
_DETECTORSLIT='out'
_AUX1=0.000000
_AUX2=0.000000
_AUX3=0.000000
_TIMESTARTED=12163.000000
_TEMP_RATE=0.000000
_TEMP_DELAY=0.000000
_KV=40
_MA=30
_RANGE_WL=1.540600
_3DPLANE=0
_2THETACPS
   0.0000    283.09
   5.0000    272.09
  10.0000    277.75
  15.0000    271.59
  20.0000    266.92
  25.0000    279.84
  30.0000    276.59
  35.0000    258.17
  40.0000    256.92
  45.0000    232.59
  50.0000    209.92
  55.0000    204.67
  60.0000    202.09
  65.0000    199.84
  70.0000    188.17
  75.0000    167.25
  80.0000    167.17
  85.0000    175.17
  90.0000    170.42
  95.0000    171.34
 100.0000    177.17
 105.0000    197.34
 110.0000    214.59
 115.0000    212.84
 120.0000    219.42
 125.0000    241.75
 130.0000    261.34
 135.0000    274.09
 140.0000    269.59
 145.0000    278.17
 150.0000    312.59
 155.0000    383.84
 160.0000    375.84
 165.0000    318.01
 170.0000    304.67
 175.0000    344.17
 180.0000    354.34
 185.0000    336.01
 190.0000    324.17
 195.0000    305.92
 200.0000    300.51
 205.0000    327.51
 210.0000    330.42
 215.0000    282.67
 220.0000    243.34
 225.0000    233.34
 230.0000    215.75
 235.0000    217.50
 240.0000    223.75
 245.0000    208.92
 250.0000    189.09
 255.0000    168.84
 260.0000    164.42
 265.0000    175.25
 270.0000    181.09
 275.0000    179.00
 280.0000    183.59
 285.0000    199.75
 290.0000    209.84
 295.0000    226.84
 300.0000    239.67
 305.0000    260.84
 310.0000    287.42
 315.0000    311.59
 320.0000    298.09
 325.0000    294.67
 330.0000    311.34
 335.0000    307.17
 340.0000    322.51
 345.0000    314.92
 350.0000    322.42
 355.0000    333.01
; (Data for Range number 16)
_DRIVE='PHI'
_STEPTIME=11.999800
_STEPSIZE=5.000000
_STEPMODE='C'
_START=0.000000
_THETA=18.270000
_2THETA=36.540001
_KHI=75.000000
_PHI=0.000000
_X=0.000000
_Y=0.000000
_Z=0.000000
_DIVERGENCE=0.200000
_ANTISCATTER=0.200000
_DETECTOR=1
; S.C.
_HV=683.500000
_GAIN=80.000000
_LLD=0.788000
_ULD=2.160000
_DETECTORSLIT='out'
_AUX1=0.000000
_AUX2=0.000000
_AUX3=0.000000
_TIMESTARTED=13032.000000
_TEMP_RATE=0.000000
_TEMP_DELAY=0.000000
_KV=40
_MA=30
_RANGE_WL=1.540600
_3DPLANE=0
_2THETACPS
   0.0000    101.75
   5.0000    109.25
  10.0000    111.09
  15.0000    117.92
  20.0000    123.59
  25.0000    141.92
  30.0000    151.75
  35.0000    151.75
  40.0000    162.59
  45.0000    156.84
  50.0000    154.34
  55.0000    160.75
  60.0000    152.50
  65.0000    154.17
  70.0000    149.25
  75.0000    136.59
  80.0000    137.67
  85.0000    138.34
  90.0000    133.50
  95.0000    129.17
 100.0000    140.17
 105.0000    163.17
 110.0000    160.00
 115.0000    171.00
 120.0000    173.59
 125.0000    185.75
 130.0000    181.42
 135.0000    189.67
 140.0000    177.09
 145.0000    173.42
 150.0000    188.09
 155.0000    182.25
 160.0000    151.00
 165.0000    141.42
 170.0000    118.84
 175.0000    148.25
 180.0000    161.59
 185.0000    140.84
 190.0000    121.75
 195.0000    129.17
 200.0000    146.25
 205.0000    166.92
 210.0000    168.92
 215.0000    158.50
 220.0000    158.92
 225.0000    160.17
 230.0000    166.00
 235.0000    175.67
 240.0000    175.17
 245.0000    173.42
 250.0000    140.92
 255.0000    132.17
 260.0000    133.50
 265.0000    137.42
 270.0000    139.92
 275.0000    146.67
 280.0000    152.42
 285.0000    154.25
 290.0000    174.17
 295.0000    187.59
 300.0000    192.25
 305.0000    190.00
 310.0000    199.50
 315.0000    193.25
 320.0000    187.17
 325.0000    193.50
 330.0000    178.75
 335.0000    159.59
 340.0000    148.67
 345.0000    142.17
 350.0000    136.42
 355.0000    129.25